2024-07-19 12:02:05,029 ERROR frappe Could not take error snapshot: (2003, "Can't connect to MySQL server on '127.0.0.1' ([Errno 111] Connection refused)")
Site: erp.grupoatu.com
Form Dict: {'doc': '{"name":"Total Outgoing Bills","owner":"Administrator","creation":"2020-07-17 11:25:34.725416","modified":"2020-07-22 13:07:19.633101","modified_by":"Administrator","docstatus":0,"idx":0,"is_standard":1,"module":"Accounts","label":"Total Outgoing Bills","type":"Document Type","function":"Sum","aggregate_function_based_on":"base_net_total","document_type":"Sales Invoice","is_public":1,"show_percentage_stats":1,"stats_time_interval":"Monthly","filters_json":"[[\\"Sales Invoice\\",\\"docstatus\\",\\"=\\",\\"1\\",false],[\\"Sales Invoice\\",\\"posting_date\\",\\"Timespan\\",\\"this year\\",false]]","doctype":"Number Card","__last_sync_on":"2024-07-19T09:09:55.185Z"}', 'filters': '[["Sales Invoice","docstatus","=","1",false],["Sales Invoice","posting_date","Timespan","this year",false]]', 'cmd': 'frappe.desk.doctype.number_card.number_card.get_result'}
Traceback (most recent call last):
  File "/home/frappe/frappe-bench/env/lib/python3.10/site-packages/pymysql/connections.py", line 644, in connect
    sock = socket.create_connection(
  File "/usr/lib/python3.10/socket.py", line 845, in create_connection
    raise err
  File "/usr/lib/python3.10/socket.py", line 833, in create_connection
    sock.connect(sa)
ConnectionRefusedError: [Errno 111] Connection refused

During handling of the above exception, another exception occurred:

Traceback (most recent call last):
  File "/home/frappe/frappe-bench/apps/frappe/frappe/app.py", line 110, in application
    response = frappe.api.handle(request)
  File "/home/frappe/frappe-bench/apps/frappe/frappe/api/__init__.py", line 49, in handle
    data = endpoint(**arguments)
  File "/home/frappe/frappe-bench/apps/frappe/frappe/api/v1.py", line 36, in handle_rpc_call
    return frappe.handler.handle()
  File "/home/frappe/frappe-bench/apps/frappe/frappe/handler.py", line 49, in handle
    data = execute_cmd(cmd)
  File "/home/frappe/frappe-bench/apps/frappe/frappe/handler.py", line 85, in execute_cmd
    return frappe.call(method, **frappe.form_dict)
  File "/home/frappe/frappe-bench/apps/frappe/frappe/__init__.py", line 1761, in call
    return fn(*args, **newargs)
  File "/home/frappe/frappe-bench/apps/frappe/frappe/utils/typing_validations.py", line 31, in wrapper
    return func(*args, **kwargs)
  File "/home/frappe/frappe-bench/apps/frappe/frappe/desk/doctype/number_card/number_card.py", line 154, in get_result
    res = frappe.get_list(
  File "/home/frappe/frappe-bench/apps/frappe/frappe/__init__.py", line 2025, in get_list
    return frappe.model.db_query.DatabaseQuery(doctype).execute(*args, **kwargs)
  File "/home/frappe/frappe-bench/apps/frappe/frappe/model/db_query.py", line 191, in execute
    result = self.build_and_run()
  File "/home/frappe/frappe-bench/apps/frappe/frappe/model/db_query.py", line 232, in build_and_run
    return frappe.db.sql(
  File "/home/frappe/frappe-bench/apps/frappe/frappe/database/database.py", line 211, in sql
    self.connect()
  File "/home/frappe/frappe-bench/apps/frappe/frappe/database/database.py", line 117, in connect
    self._conn: "MariadbConnection" | "PostgresConnection" = self.get_connection()
  File "/home/frappe/frappe-bench/apps/frappe/frappe/database/mariadb/database.py", line 107, in get_connection
    conn = self._get_connection()
  File "/home/frappe/frappe-bench/apps/frappe/frappe/database/mariadb/database.py", line 113, in _get_connection
    return self.create_connection()
  File "/home/frappe/frappe-bench/apps/frappe/frappe/database/mariadb/database.py", line 116, in create_connection
    return pymysql.connect(**self.get_connection_settings())
  File "/home/frappe/frappe-bench/env/lib/python3.10/site-packages/pymysql/connections.py", line 358, in __init__
    self.connect()
  File "/home/frappe/frappe-bench/env/lib/python3.10/site-packages/pymysql/connections.py", line 711, in connect
    raise exc
pymysql.err.OperationalError: (2003, "Can't connect to MySQL server on '127.0.0.1' ([Errno 111] Connection refused)")

During handling of the above exception, another exception occurred:

Traceback (most recent call last):
  File "/home/frappe/frappe-bench/env/lib/python3.10/site-packages/pymysql/connections.py", line 644, in connect
    sock = socket.create_connection(
  File "/usr/lib/python3.10/socket.py", line 845, in create_connection
    raise err
  File "/usr/lib/python3.10/socket.py", line 833, in create_connection
    sock.connect(sa)
ConnectionRefusedError: [Errno 111] Connection refused

During handling of the above exception, another exception occurred:

Traceback (most recent call last):
  File "/home/frappe/frappe-bench/apps/frappe/frappe/utils/error.py", line 86, in log_error_snapshot
    log_error(title=str(exception), defer_insert=True)
  File "/home/frappe/frappe-bench/apps/frappe/frappe/utils/error.py", line 61, in log_error
    error_log = frappe.get_doc(
  File "/home/frappe/frappe-bench/apps/frappe/frappe/__init__.py", line 1329, in get_doc
    doc = frappe.model.document.get_doc(*args, **kwargs)
  File "/home/frappe/frappe-bench/apps/frappe/frappe/model/document.py", line 83, in get_doc
    controller = get_controller(doctype)
  File "/home/frappe/frappe-bench/apps/frappe/frappe/model/base_document.py", line 70, in get_controller
    site_controllers[doctype] = import_controller(doctype)
  File "/home/frappe/frappe-bench/apps/frappe/frappe/model/base_document.py", line 81, in import_controller
    doctype_info = frappe.db.get_value("DocType", doctype, fieldname="*")
  File "/home/frappe/frappe-bench/apps/frappe/frappe/database/database.py", line 519, in get_value
    result = self.get_values(
  File "/home/frappe/frappe-bench/apps/frappe/frappe/database/database.py", line 623, in get_values
    out = self._get_values_from_table(
  File "/home/frappe/frappe-bench/apps/frappe/frappe/database/database.py", line 896, in _get_values_from_table
    return query.run(as_dict=as_dict, debug=debug, update=update, run=run, pluck=pluck)
  File "/home/frappe/frappe-bench/apps/frappe/frappe/query_builder/utils.py", line 87, in execute_query
    result = frappe.db.sql(query, params, *args, **kwargs)  # nosemgrep
  File "/home/frappe/frappe-bench/apps/frappe/frappe/database/database.py", line 211, in sql
    self.connect()
  File "/home/frappe/frappe-bench/apps/frappe/frappe/database/database.py", line 117, in connect
    self._conn: "MariadbConnection" | "PostgresConnection" = self.get_connection()
  File "/home/frappe/frappe-bench/apps/frappe/frappe/database/mariadb/database.py", line 107, in get_connection
    conn = self._get_connection()
  File "/home/frappe/frappe-bench/apps/frappe/frappe/database/mariadb/database.py", line 113, in _get_connection
    return self.create_connection()
  File "/home/frappe/frappe-bench/apps/frappe/frappe/database/mariadb/database.py", line 116, in create_connection
    return pymysql.connect(**self.get_connection_settings())
  File "/home/frappe/frappe-bench/env/lib/python3.10/site-packages/pymysql/connections.py", line 358, in __init__
    self.connect()
  File "/home/frappe/frappe-bench/env/lib/python3.10/site-packages/pymysql/connections.py", line 711, in connect
    raise exc
pymysql.err.OperationalError: (2003, "Can't connect to MySQL server on '127.0.0.1' ([Errno 111] Connection refused)")
2024-07-19 12:02:23,137 ERROR frappe Could not take error snapshot: (2003, "Can't connect to MySQL server on '127.0.0.1' ([Errno 111] Connection refused)")
Site: erp.grupoatu.com
Form Dict: {}
Traceback (most recent call last):
  File "/home/frappe/frappe-bench/env/lib/python3.10/site-packages/pymysql/connections.py", line 644, in connect
    sock = socket.create_connection(
  File "/usr/lib/python3.10/socket.py", line 845, in create_connection
    raise err
  File "/usr/lib/python3.10/socket.py", line 833, in create_connection
    sock.connect(sa)
ConnectionRefusedError: [Errno 111] Connection refused

During handling of the above exception, another exception occurred:

Traceback (most recent call last):
  File "/home/frappe/frappe-bench/apps/frappe/frappe/website/serve.py", line 19, in get_response
    endpoint, renderer_instance = path_resolver.resolve()
  File "/home/frappe/frappe-bench/apps/frappe/frappe/website/path_resolver.py", line 38, in resolve
    resolve_redirect(self.path, request.query_string)
  File "/home/frappe/frappe-bench/apps/frappe/frappe/website/path_resolver.py", line 118, in resolve_redirect
    redirects += frappe.get_all("Website Route Redirect", ["source", "target"], order_by=None)
  File "/home/frappe/frappe-bench/apps/frappe/frappe/__init__.py", line 2050, in get_all
    return get_list(doctype, *args, **kwargs)
  File "/home/frappe/frappe-bench/apps/frappe/frappe/__init__.py", line 2025, in get_list
    return frappe.model.db_query.DatabaseQuery(doctype).execute(*args, **kwargs)
  File "/home/frappe/frappe-bench/apps/frappe/frappe/model/db_query.py", line 191, in execute
    result = self.build_and_run()
  File "/home/frappe/frappe-bench/apps/frappe/frappe/model/db_query.py", line 232, in build_and_run
    return frappe.db.sql(
  File "/home/frappe/frappe-bench/apps/frappe/frappe/database/database.py", line 211, in sql
    self.connect()
  File "/home/frappe/frappe-bench/apps/frappe/frappe/database/database.py", line 117, in connect
    self._conn: "MariadbConnection" | "PostgresConnection" = self.get_connection()
  File "/home/frappe/frappe-bench/apps/frappe/frappe/database/mariadb/database.py", line 107, in get_connection
    conn = self._get_connection()
  File "/home/frappe/frappe-bench/apps/frappe/frappe/database/mariadb/database.py", line 113, in _get_connection
    return self.create_connection()
  File "/home/frappe/frappe-bench/apps/frappe/frappe/database/mariadb/database.py", line 116, in create_connection
    return pymysql.connect(**self.get_connection_settings())
  File "/home/frappe/frappe-bench/env/lib/python3.10/site-packages/pymysql/connections.py", line 358, in __init__
    self.connect()
  File "/home/frappe/frappe-bench/env/lib/python3.10/site-packages/pymysql/connections.py", line 711, in connect
    raise exc
pymysql.err.OperationalError: (2003, "Can't connect to MySQL server on '127.0.0.1' ([Errno 111] Connection refused)")

During handling of the above exception, another exception occurred:

Traceback (most recent call last):
  File "/home/frappe/frappe-bench/env/lib/python3.10/site-packages/pymysql/connections.py", line 644, in connect
    sock = socket.create_connection(
  File "/usr/lib/python3.10/socket.py", line 845, in create_connection
    raise err
  File "/usr/lib/python3.10/socket.py", line 833, in create_connection
    sock.connect(sa)
ConnectionRefusedError: [Errno 111] Connection refused

During handling of the above exception, another exception occurred:

Traceback (most recent call last):
  File "/home/frappe/frappe-bench/apps/frappe/frappe/app.py", line 119, in application
    response = get_response()
  File "/home/frappe/frappe-bench/apps/frappe/frappe/website/serve.py", line 28, in get_response
    response = ErrorPage(exception=e).render()
  File "/home/frappe/frappe-bench/apps/frappe/frappe/website/page_renderers/template_page.py", line 84, in render
    html = self.get_html()
  File "/home/frappe/frappe-bench/apps/frappe/frappe/website/utils.py", line 523, in cache_html_decorator
    html = func(*args, **kwargs)
  File "/home/frappe/frappe-bench/apps/frappe/frappe/website/page_renderers/template_page.py", line 92, in get_html
    self.init_context()
  File "/home/frappe/frappe-bench/apps/frappe/frappe/website/page_renderers/error_page.py", line 14, in init_context
    super().init_context()
  File "/home/frappe/frappe-bench/apps/frappe/frappe/website/page_renderers/base_template_page.py", line 15, in init_context
    self.context.update(get_website_settings())
  File "/home/frappe/frappe-bench/apps/frappe/frappe/website/doctype/website_settings/website_settings.py", line 263, in get_website_settings
    context.boot = get_boot_data()
  File "/home/frappe/frappe-bench/apps/frappe/frappe/website/utils.py", line 179, in get_boot_data
    "user": frappe.db.get_value("User", frappe.session.user, "time_zone") or get_system_timezone(),
  File "/home/frappe/frappe-bench/apps/frappe/frappe/database/database.py", line 519, in get_value
    result = self.get_values(
  File "/home/frappe/frappe-bench/apps/frappe/frappe/database/database.py", line 623, in get_values
    out = self._get_values_from_table(
  File "/home/frappe/frappe-bench/apps/frappe/frappe/database/database.py", line 896, in _get_values_from_table
    return query.run(as_dict=as_dict, debug=debug, update=update, run=run, pluck=pluck)
  File "/home/frappe/frappe-bench/apps/frappe/frappe/query_builder/utils.py", line 87, in execute_query
    result = frappe.db.sql(query, params, *args, **kwargs)  # nosemgrep
  File "/home/frappe/frappe-bench/apps/frappe/frappe/database/database.py", line 211, in sql
    self.connect()
  File "/home/frappe/frappe-bench/apps/frappe/frappe/database/database.py", line 117, in connect
    self._conn: "MariadbConnection" | "PostgresConnection" = self.get_connection()
  File "/home/frappe/frappe-bench/apps/frappe/frappe/database/mariadb/database.py", line 107, in get_connection
    conn = self._get_connection()
  File "/home/frappe/frappe-bench/apps/frappe/frappe/database/mariadb/database.py", line 113, in _get_connection
    return self.create_connection()
  File "/home/frappe/frappe-bench/apps/frappe/frappe/database/mariadb/database.py", line 116, in create_connection
    return pymysql.connect(**self.get_connection_settings())
  File "/home/frappe/frappe-bench/env/lib/python3.10/site-packages/pymysql/connections.py", line 358, in __init__
    self.connect()
  File "/home/frappe/frappe-bench/env/lib/python3.10/site-packages/pymysql/connections.py", line 711, in connect
    raise exc
pymysql.err.OperationalError: (2003, "Can't connect to MySQL server on '127.0.0.1' ([Errno 111] Connection refused)")

During handling of the above exception, another exception occurred:

Traceback (most recent call last):
  File "/home/frappe/frappe-bench/env/lib/python3.10/site-packages/pymysql/connections.py", line 644, in connect
    sock = socket.create_connection(
  File "/usr/lib/python3.10/socket.py", line 845, in create_connection
    raise err
  File "/usr/lib/python3.10/socket.py", line 833, in create_connection
    sock.connect(sa)
ConnectionRefusedError: [Errno 111] Connection refused

During handling of the above exception, another exception occurred:

Traceback (most recent call last):
  File "/home/frappe/frappe-bench/apps/frappe/frappe/utils/error.py", line 86, in log_error_snapshot
    log_error(title=str(exception), defer_insert=True)
  File "/home/frappe/frappe-bench/apps/frappe/frappe/utils/error.py", line 61, in log_error
    error_log = frappe.get_doc(
  File "/home/frappe/frappe-bench/apps/frappe/frappe/__init__.py", line 1329, in get_doc
    doc = frappe.model.document.get_doc(*args, **kwargs)
  File "/home/frappe/frappe-bench/apps/frappe/frappe/model/document.py", line 83, in get_doc
    controller = get_controller(doctype)
  File "/home/frappe/frappe-bench/apps/frappe/frappe/model/base_document.py", line 70, in get_controller
    site_controllers[doctype] = import_controller(doctype)
  File "/home/frappe/frappe-bench/apps/frappe/frappe/model/base_document.py", line 81, in import_controller
    doctype_info = frappe.db.get_value("DocType", doctype, fieldname="*")
  File "/home/frappe/frappe-bench/apps/frappe/frappe/database/database.py", line 519, in get_value
    result = self.get_values(
  File "/home/frappe/frappe-bench/apps/frappe/frappe/database/database.py", line 623, in get_values
    out = self._get_values_from_table(
  File "/home/frappe/frappe-bench/apps/frappe/frappe/database/database.py", line 896, in _get_values_from_table
    return query.run(as_dict=as_dict, debug=debug, update=update, run=run, pluck=pluck)
  File "/home/frappe/frappe-bench/apps/frappe/frappe/query_builder/utils.py", line 87, in execute_query
    result = frappe.db.sql(query, params, *args, **kwargs)  # nosemgrep
  File "/home/frappe/frappe-bench/apps/frappe/frappe/database/database.py", line 211, in sql
    self.connect()
  File "/home/frappe/frappe-bench/apps/frappe/frappe/database/database.py", line 117, in connect
    self._conn: "MariadbConnection" | "PostgresConnection" = self.get_connection()
  File "/home/frappe/frappe-bench/apps/frappe/frappe/database/mariadb/database.py", line 107, in get_connection
    conn = self._get_connection()
  File "/home/frappe/frappe-bench/apps/frappe/frappe/database/mariadb/database.py", line 113, in _get_connection
    return self.create_connection()
  File "/home/frappe/frappe-bench/apps/frappe/frappe/database/mariadb/database.py", line 116, in create_connection
    return pymysql.connect(**self.get_connection_settings())
  File "/home/frappe/frappe-bench/env/lib/python3.10/site-packages/pymysql/connections.py", line 358, in __init__
    self.connect()
  File "/home/frappe/frappe-bench/env/lib/python3.10/site-packages/pymysql/connections.py", line 711, in connect
    raise exc
pymysql.err.OperationalError: (2003, "Can't connect to MySQL server on '127.0.0.1' ([Errno 111] Connection refused)")
2024-07-19 12:04:15,912 ERROR frappe Could not take error snapshot: (2003, "Can't connect to MySQL server on '127.0.0.1' ([Errno 111] Connection refused)")
Site: erp.grupoatu.com
Form Dict: {}
Traceback (most recent call last):
  File "/home/frappe/frappe-bench/env/lib/python3.10/site-packages/pymysql/connections.py", line 644, in connect
    sock = socket.create_connection(
  File "/usr/lib/python3.10/socket.py", line 845, in create_connection
    raise err
  File "/usr/lib/python3.10/socket.py", line 833, in create_connection
    sock.connect(sa)
ConnectionRefusedError: [Errno 111] Connection refused

During handling of the above exception, another exception occurred:

Traceback (most recent call last):
  File "/home/frappe/frappe-bench/apps/frappe/frappe/website/serve.py", line 19, in get_response
    endpoint, renderer_instance = path_resolver.resolve()
  File "/home/frappe/frappe-bench/apps/frappe/frappe/website/path_resolver.py", line 38, in resolve
    resolve_redirect(self.path, request.query_string)
  File "/home/frappe/frappe-bench/apps/frappe/frappe/website/path_resolver.py", line 118, in resolve_redirect
    redirects += frappe.get_all("Website Route Redirect", ["source", "target"], order_by=None)
  File "/home/frappe/frappe-bench/apps/frappe/frappe/__init__.py", line 2050, in get_all
    return get_list(doctype, *args, **kwargs)
  File "/home/frappe/frappe-bench/apps/frappe/frappe/__init__.py", line 2025, in get_list
    return frappe.model.db_query.DatabaseQuery(doctype).execute(*args, **kwargs)
  File "/home/frappe/frappe-bench/apps/frappe/frappe/model/db_query.py", line 191, in execute
    result = self.build_and_run()
  File "/home/frappe/frappe-bench/apps/frappe/frappe/model/db_query.py", line 232, in build_and_run
    return frappe.db.sql(
  File "/home/frappe/frappe-bench/apps/frappe/frappe/database/database.py", line 211, in sql
    self.connect()
  File "/home/frappe/frappe-bench/apps/frappe/frappe/database/database.py", line 117, in connect
    self._conn: "MariadbConnection" | "PostgresConnection" = self.get_connection()
  File "/home/frappe/frappe-bench/apps/frappe/frappe/database/mariadb/database.py", line 107, in get_connection
    conn = self._get_connection()
  File "/home/frappe/frappe-bench/apps/frappe/frappe/database/mariadb/database.py", line 113, in _get_connection
    return self.create_connection()
  File "/home/frappe/frappe-bench/apps/frappe/frappe/database/mariadb/database.py", line 116, in create_connection
    return pymysql.connect(**self.get_connection_settings())
  File "/home/frappe/frappe-bench/env/lib/python3.10/site-packages/pymysql/connections.py", line 358, in __init__
    self.connect()
  File "/home/frappe/frappe-bench/env/lib/python3.10/site-packages/pymysql/connections.py", line 711, in connect
    raise exc
pymysql.err.OperationalError: (2003, "Can't connect to MySQL server on '127.0.0.1' ([Errno 111] Connection refused)")

During handling of the above exception, another exception occurred:

Traceback (most recent call last):
  File "/home/frappe/frappe-bench/env/lib/python3.10/site-packages/pymysql/connections.py", line 644, in connect
    sock = socket.create_connection(
  File "/usr/lib/python3.10/socket.py", line 845, in create_connection
    raise err
  File "/usr/lib/python3.10/socket.py", line 833, in create_connection
    sock.connect(sa)
ConnectionRefusedError: [Errno 111] Connection refused

During handling of the above exception, another exception occurred:

Traceback (most recent call last):
  File "/home/frappe/frappe-bench/apps/frappe/frappe/app.py", line 119, in application
    response = get_response()
  File "/home/frappe/frappe-bench/apps/frappe/frappe/website/serve.py", line 28, in get_response
    response = ErrorPage(exception=e).render()
  File "/home/frappe/frappe-bench/apps/frappe/frappe/website/page_renderers/template_page.py", line 84, in render
    html = self.get_html()
  File "/home/frappe/frappe-bench/apps/frappe/frappe/website/utils.py", line 523, in cache_html_decorator
    html = func(*args, **kwargs)
  File "/home/frappe/frappe-bench/apps/frappe/frappe/website/page_renderers/template_page.py", line 92, in get_html
    self.init_context()
  File "/home/frappe/frappe-bench/apps/frappe/frappe/website/page_renderers/error_page.py", line 14, in init_context
    super().init_context()
  File "/home/frappe/frappe-bench/apps/frappe/frappe/website/page_renderers/base_template_page.py", line 15, in init_context
    self.context.update(get_website_settings())
  File "/home/frappe/frappe-bench/apps/frappe/frappe/website/doctype/website_settings/website_settings.py", line 263, in get_website_settings
    context.boot = get_boot_data()
  File "/home/frappe/frappe-bench/apps/frappe/frappe/website/utils.py", line 179, in get_boot_data
    "user": frappe.db.get_value("User", frappe.session.user, "time_zone") or get_system_timezone(),
  File "/home/frappe/frappe-bench/apps/frappe/frappe/database/database.py", line 519, in get_value
    result = self.get_values(
  File "/home/frappe/frappe-bench/apps/frappe/frappe/database/database.py", line 623, in get_values
    out = self._get_values_from_table(
  File "/home/frappe/frappe-bench/apps/frappe/frappe/database/database.py", line 896, in _get_values_from_table
    return query.run(as_dict=as_dict, debug=debug, update=update, run=run, pluck=pluck)
  File "/home/frappe/frappe-bench/apps/frappe/frappe/query_builder/utils.py", line 87, in execute_query
    result = frappe.db.sql(query, params, *args, **kwargs)  # nosemgrep
  File "/home/frappe/frappe-bench/apps/frappe/frappe/database/database.py", line 211, in sql
    self.connect()
  File "/home/frappe/frappe-bench/apps/frappe/frappe/database/database.py", line 117, in connect
    self._conn: "MariadbConnection" | "PostgresConnection" = self.get_connection()
  File "/home/frappe/frappe-bench/apps/frappe/frappe/database/mariadb/database.py", line 107, in get_connection
    conn = self._get_connection()
  File "/home/frappe/frappe-bench/apps/frappe/frappe/database/mariadb/database.py", line 113, in _get_connection
    return self.create_connection()
  File "/home/frappe/frappe-bench/apps/frappe/frappe/database/mariadb/database.py", line 116, in create_connection
    return pymysql.connect(**self.get_connection_settings())
  File "/home/frappe/frappe-bench/env/lib/python3.10/site-packages/pymysql/connections.py", line 358, in __init__
    self.connect()
  File "/home/frappe/frappe-bench/env/lib/python3.10/site-packages/pymysql/connections.py", line 711, in connect
    raise exc
pymysql.err.OperationalError: (2003, "Can't connect to MySQL server on '127.0.0.1' ([Errno 111] Connection refused)")

During handling of the above exception, another exception occurred:

Traceback (most recent call last):
  File "/home/frappe/frappe-bench/env/lib/python3.10/site-packages/pymysql/connections.py", line 644, in connect
    sock = socket.create_connection(
  File "/usr/lib/python3.10/socket.py", line 845, in create_connection
    raise err
  File "/usr/lib/python3.10/socket.py", line 833, in create_connection
    sock.connect(sa)
ConnectionRefusedError: [Errno 111] Connection refused

During handling of the above exception, another exception occurred:

Traceback (most recent call last):
  File "/home/frappe/frappe-bench/apps/frappe/frappe/utils/error.py", line 86, in log_error_snapshot
    log_error(title=str(exception), defer_insert=True)
  File "/home/frappe/frappe-bench/apps/frappe/frappe/utils/error.py", line 61, in log_error
    error_log = frappe.get_doc(
  File "/home/frappe/frappe-bench/apps/frappe/frappe/__init__.py", line 1329, in get_doc
    doc = frappe.model.document.get_doc(*args, **kwargs)
  File "/home/frappe/frappe-bench/apps/frappe/frappe/model/document.py", line 83, in get_doc
    controller = get_controller(doctype)
  File "/home/frappe/frappe-bench/apps/frappe/frappe/model/base_document.py", line 70, in get_controller
    site_controllers[doctype] = import_controller(doctype)
  File "/home/frappe/frappe-bench/apps/frappe/frappe/model/base_document.py", line 81, in import_controller
    doctype_info = frappe.db.get_value("DocType", doctype, fieldname="*")
  File "/home/frappe/frappe-bench/apps/frappe/frappe/database/database.py", line 519, in get_value
    result = self.get_values(
  File "/home/frappe/frappe-bench/apps/frappe/frappe/database/database.py", line 623, in get_values
    out = self._get_values_from_table(
  File "/home/frappe/frappe-bench/apps/frappe/frappe/database/database.py", line 896, in _get_values_from_table
    return query.run(as_dict=as_dict, debug=debug, update=update, run=run, pluck=pluck)
  File "/home/frappe/frappe-bench/apps/frappe/frappe/query_builder/utils.py", line 87, in execute_query
    result = frappe.db.sql(query, params, *args, **kwargs)  # nosemgrep
  File "/home/frappe/frappe-bench/apps/frappe/frappe/database/database.py", line 211, in sql
    self.connect()
  File "/home/frappe/frappe-bench/apps/frappe/frappe/database/database.py", line 117, in connect
    self._conn: "MariadbConnection" | "PostgresConnection" = self.get_connection()
  File "/home/frappe/frappe-bench/apps/frappe/frappe/database/mariadb/database.py", line 107, in get_connection
    conn = self._get_connection()
  File "/home/frappe/frappe-bench/apps/frappe/frappe/database/mariadb/database.py", line 113, in _get_connection
    return self.create_connection()
  File "/home/frappe/frappe-bench/apps/frappe/frappe/database/mariadb/database.py", line 116, in create_connection
    return pymysql.connect(**self.get_connection_settings())
  File "/home/frappe/frappe-bench/env/lib/python3.10/site-packages/pymysql/connections.py", line 358, in __init__
    self.connect()
  File "/home/frappe/frappe-bench/env/lib/python3.10/site-packages/pymysql/connections.py", line 711, in connect
    raise exc
pymysql.err.OperationalError: (2003, "Can't connect to MySQL server on '127.0.0.1' ([Errno 111] Connection refused)")
2024-07-19 12:04:16,079 ERROR frappe Could not take error snapshot: (2003, "Can't connect to MySQL server on '127.0.0.1' ([Errno 111] Connection refused)")
Site: erp.grupoatu.com
Form Dict: {}
Traceback (most recent call last):
  File "/home/frappe/frappe-bench/env/lib/python3.10/site-packages/pymysql/connections.py", line 644, in connect
    sock = socket.create_connection(
  File "/usr/lib/python3.10/socket.py", line 845, in create_connection
    raise err
  File "/usr/lib/python3.10/socket.py", line 833, in create_connection
    sock.connect(sa)
ConnectionRefusedError: [Errno 111] Connection refused

During handling of the above exception, another exception occurred:

Traceback (most recent call last):
  File "/home/frappe/frappe-bench/apps/frappe/frappe/website/serve.py", line 19, in get_response
    endpoint, renderer_instance = path_resolver.resolve()
  File "/home/frappe/frappe-bench/apps/frappe/frappe/website/path_resolver.py", line 38, in resolve
    resolve_redirect(self.path, request.query_string)
  File "/home/frappe/frappe-bench/apps/frappe/frappe/website/path_resolver.py", line 118, in resolve_redirect
    redirects += frappe.get_all("Website Route Redirect", ["source", "target"], order_by=None)
  File "/home/frappe/frappe-bench/apps/frappe/frappe/__init__.py", line 2050, in get_all
    return get_list(doctype, *args, **kwargs)
  File "/home/frappe/frappe-bench/apps/frappe/frappe/__init__.py", line 2025, in get_list
    return frappe.model.db_query.DatabaseQuery(doctype).execute(*args, **kwargs)
  File "/home/frappe/frappe-bench/apps/frappe/frappe/model/db_query.py", line 191, in execute
    result = self.build_and_run()
  File "/home/frappe/frappe-bench/apps/frappe/frappe/model/db_query.py", line 232, in build_and_run
    return frappe.db.sql(
  File "/home/frappe/frappe-bench/apps/frappe/frappe/database/database.py", line 211, in sql
    self.connect()
  File "/home/frappe/frappe-bench/apps/frappe/frappe/database/database.py", line 117, in connect
    self._conn: "MariadbConnection" | "PostgresConnection" = self.get_connection()
  File "/home/frappe/frappe-bench/apps/frappe/frappe/database/mariadb/database.py", line 107, in get_connection
    conn = self._get_connection()
  File "/home/frappe/frappe-bench/apps/frappe/frappe/database/mariadb/database.py", line 113, in _get_connection
    return self.create_connection()
  File "/home/frappe/frappe-bench/apps/frappe/frappe/database/mariadb/database.py", line 116, in create_connection
    return pymysql.connect(**self.get_connection_settings())
  File "/home/frappe/frappe-bench/env/lib/python3.10/site-packages/pymysql/connections.py", line 358, in __init__
    self.connect()
  File "/home/frappe/frappe-bench/env/lib/python3.10/site-packages/pymysql/connections.py", line 711, in connect
    raise exc
pymysql.err.OperationalError: (2003, "Can't connect to MySQL server on '127.0.0.1' ([Errno 111] Connection refused)")

During handling of the above exception, another exception occurred:

Traceback (most recent call last):
  File "/home/frappe/frappe-bench/env/lib/python3.10/site-packages/pymysql/connections.py", line 644, in connect
    sock = socket.create_connection(
  File "/usr/lib/python3.10/socket.py", line 845, in create_connection
    raise err
  File "/usr/lib/python3.10/socket.py", line 833, in create_connection
    sock.connect(sa)
ConnectionRefusedError: [Errno 111] Connection refused

During handling of the above exception, another exception occurred:

Traceback (most recent call last):
  File "/home/frappe/frappe-bench/apps/frappe/frappe/app.py", line 119, in application
    response = get_response()
  File "/home/frappe/frappe-bench/apps/frappe/frappe/website/serve.py", line 28, in get_response
    response = ErrorPage(exception=e).render()
  File "/home/frappe/frappe-bench/apps/frappe/frappe/website/page_renderers/template_page.py", line 84, in render
    html = self.get_html()
  File "/home/frappe/frappe-bench/apps/frappe/frappe/website/utils.py", line 523, in cache_html_decorator
    html = func(*args, **kwargs)
  File "/home/frappe/frappe-bench/apps/frappe/frappe/website/page_renderers/template_page.py", line 92, in get_html
    self.init_context()
  File "/home/frappe/frappe-bench/apps/frappe/frappe/website/page_renderers/error_page.py", line 14, in init_context
    super().init_context()
  File "/home/frappe/frappe-bench/apps/frappe/frappe/website/page_renderers/base_template_page.py", line 15, in init_context
    self.context.update(get_website_settings())
  File "/home/frappe/frappe-bench/apps/frappe/frappe/website/doctype/website_settings/website_settings.py", line 263, in get_website_settings
    context.boot = get_boot_data()
  File "/home/frappe/frappe-bench/apps/frappe/frappe/website/utils.py", line 179, in get_boot_data
    "user": frappe.db.get_value("User", frappe.session.user, "time_zone") or get_system_timezone(),
  File "/home/frappe/frappe-bench/apps/frappe/frappe/database/database.py", line 519, in get_value
    result = self.get_values(
  File "/home/frappe/frappe-bench/apps/frappe/frappe/database/database.py", line 623, in get_values
    out = self._get_values_from_table(
  File "/home/frappe/frappe-bench/apps/frappe/frappe/database/database.py", line 896, in _get_values_from_table
    return query.run(as_dict=as_dict, debug=debug, update=update, run=run, pluck=pluck)
  File "/home/frappe/frappe-bench/apps/frappe/frappe/query_builder/utils.py", line 87, in execute_query
    result = frappe.db.sql(query, params, *args, **kwargs)  # nosemgrep
  File "/home/frappe/frappe-bench/apps/frappe/frappe/database/database.py", line 211, in sql
    self.connect()
  File "/home/frappe/frappe-bench/apps/frappe/frappe/database/database.py", line 117, in connect
    self._conn: "MariadbConnection" | "PostgresConnection" = self.get_connection()
  File "/home/frappe/frappe-bench/apps/frappe/frappe/database/mariadb/database.py", line 107, in get_connection
    conn = self._get_connection()
  File "/home/frappe/frappe-bench/apps/frappe/frappe/database/mariadb/database.py", line 113, in _get_connection
    return self.create_connection()
  File "/home/frappe/frappe-bench/apps/frappe/frappe/database/mariadb/database.py", line 116, in create_connection
    return pymysql.connect(**self.get_connection_settings())
  File "/home/frappe/frappe-bench/env/lib/python3.10/site-packages/pymysql/connections.py", line 358, in __init__
    self.connect()
  File "/home/frappe/frappe-bench/env/lib/python3.10/site-packages/pymysql/connections.py", line 711, in connect
    raise exc
pymysql.err.OperationalError: (2003, "Can't connect to MySQL server on '127.0.0.1' ([Errno 111] Connection refused)")

During handling of the above exception, another exception occurred:

Traceback (most recent call last):
  File "/home/frappe/frappe-bench/env/lib/python3.10/site-packages/pymysql/connections.py", line 644, in connect
    sock = socket.create_connection(
  File "/usr/lib/python3.10/socket.py", line 845, in create_connection
    raise err
  File "/usr/lib/python3.10/socket.py", line 833, in create_connection
    sock.connect(sa)
ConnectionRefusedError: [Errno 111] Connection refused

During handling of the above exception, another exception occurred:

Traceback (most recent call last):
  File "/home/frappe/frappe-bench/apps/frappe/frappe/utils/error.py", line 86, in log_error_snapshot
    log_error(title=str(exception), defer_insert=True)
  File "/home/frappe/frappe-bench/apps/frappe/frappe/utils/error.py", line 61, in log_error
    error_log = frappe.get_doc(
  File "/home/frappe/frappe-bench/apps/frappe/frappe/__init__.py", line 1329, in get_doc
    doc = frappe.model.document.get_doc(*args, **kwargs)
  File "/home/frappe/frappe-bench/apps/frappe/frappe/model/document.py", line 83, in get_doc
    controller = get_controller(doctype)
  File "/home/frappe/frappe-bench/apps/frappe/frappe/model/base_document.py", line 70, in get_controller
    site_controllers[doctype] = import_controller(doctype)
  File "/home/frappe/frappe-bench/apps/frappe/frappe/model/base_document.py", line 81, in import_controller
    doctype_info = frappe.db.get_value("DocType", doctype, fieldname="*")
  File "/home/frappe/frappe-bench/apps/frappe/frappe/database/database.py", line 519, in get_value
    result = self.get_values(
  File "/home/frappe/frappe-bench/apps/frappe/frappe/database/database.py", line 623, in get_values
    out = self._get_values_from_table(
  File "/home/frappe/frappe-bench/apps/frappe/frappe/database/database.py", line 896, in _get_values_from_table
    return query.run(as_dict=as_dict, debug=debug, update=update, run=run, pluck=pluck)
  File "/home/frappe/frappe-bench/apps/frappe/frappe/query_builder/utils.py", line 87, in execute_query
    result = frappe.db.sql(query, params, *args, **kwargs)  # nosemgrep
  File "/home/frappe/frappe-bench/apps/frappe/frappe/database/database.py", line 211, in sql
    self.connect()
  File "/home/frappe/frappe-bench/apps/frappe/frappe/database/database.py", line 117, in connect
    self._conn: "MariadbConnection" | "PostgresConnection" = self.get_connection()
  File "/home/frappe/frappe-bench/apps/frappe/frappe/database/mariadb/database.py", line 107, in get_connection
    conn = self._get_connection()
  File "/home/frappe/frappe-bench/apps/frappe/frappe/database/mariadb/database.py", line 113, in _get_connection
    return self.create_connection()
  File "/home/frappe/frappe-bench/apps/frappe/frappe/database/mariadb/database.py", line 116, in create_connection
    return pymysql.connect(**self.get_connection_settings())
  File "/home/frappe/frappe-bench/env/lib/python3.10/site-packages/pymysql/connections.py", line 358, in __init__
    self.connect()
  File "/home/frappe/frappe-bench/env/lib/python3.10/site-packages/pymysql/connections.py", line 711, in connect
    raise exc
pymysql.err.OperationalError: (2003, "Can't connect to MySQL server on '127.0.0.1' ([Errno 111] Connection refused)")
2024-07-19 12:04:17,760 ERROR frappe Could not take error snapshot: (2003, "Can't connect to MySQL server on '127.0.0.1' ([Errno 111] Connection refused)")
Site: erp.grupoatu.com
Form Dict: {}
Traceback (most recent call last):
  File "/home/frappe/frappe-bench/env/lib/python3.10/site-packages/pymysql/connections.py", line 644, in connect
    sock = socket.create_connection(
  File "/usr/lib/python3.10/socket.py", line 845, in create_connection
    raise err
  File "/usr/lib/python3.10/socket.py", line 833, in create_connection
    sock.connect(sa)
ConnectionRefusedError: [Errno 111] Connection refused

During handling of the above exception, another exception occurred:

Traceback (most recent call last):
  File "/home/frappe/frappe-bench/apps/frappe/frappe/website/serve.py", line 19, in get_response
    endpoint, renderer_instance = path_resolver.resolve()
  File "/home/frappe/frappe-bench/apps/frappe/frappe/website/path_resolver.py", line 38, in resolve
    resolve_redirect(self.path, request.query_string)
  File "/home/frappe/frappe-bench/apps/frappe/frappe/website/path_resolver.py", line 118, in resolve_redirect
    redirects += frappe.get_all("Website Route Redirect", ["source", "target"], order_by=None)
  File "/home/frappe/frappe-bench/apps/frappe/frappe/__init__.py", line 2050, in get_all
    return get_list(doctype, *args, **kwargs)
  File "/home/frappe/frappe-bench/apps/frappe/frappe/__init__.py", line 2025, in get_list
    return frappe.model.db_query.DatabaseQuery(doctype).execute(*args, **kwargs)
  File "/home/frappe/frappe-bench/apps/frappe/frappe/model/db_query.py", line 191, in execute
    result = self.build_and_run()
  File "/home/frappe/frappe-bench/apps/frappe/frappe/model/db_query.py", line 232, in build_and_run
    return frappe.db.sql(
  File "/home/frappe/frappe-bench/apps/frappe/frappe/database/database.py", line 211, in sql
    self.connect()
  File "/home/frappe/frappe-bench/apps/frappe/frappe/database/database.py", line 117, in connect
    self._conn: "MariadbConnection" | "PostgresConnection" = self.get_connection()
  File "/home/frappe/frappe-bench/apps/frappe/frappe/database/mariadb/database.py", line 107, in get_connection
    conn = self._get_connection()
  File "/home/frappe/frappe-bench/apps/frappe/frappe/database/mariadb/database.py", line 113, in _get_connection
    return self.create_connection()
  File "/home/frappe/frappe-bench/apps/frappe/frappe/database/mariadb/database.py", line 116, in create_connection
    return pymysql.connect(**self.get_connection_settings())
  File "/home/frappe/frappe-bench/env/lib/python3.10/site-packages/pymysql/connections.py", line 358, in __init__
    self.connect()
  File "/home/frappe/frappe-bench/env/lib/python3.10/site-packages/pymysql/connections.py", line 711, in connect
    raise exc
pymysql.err.OperationalError: (2003, "Can't connect to MySQL server on '127.0.0.1' ([Errno 111] Connection refused)")

During handling of the above exception, another exception occurred:

Traceback (most recent call last):
  File "/home/frappe/frappe-bench/env/lib/python3.10/site-packages/pymysql/connections.py", line 644, in connect
    sock = socket.create_connection(
  File "/usr/lib/python3.10/socket.py", line 845, in create_connection
    raise err
  File "/usr/lib/python3.10/socket.py", line 833, in create_connection
    sock.connect(sa)
ConnectionRefusedError: [Errno 111] Connection refused

During handling of the above exception, another exception occurred:

Traceback (most recent call last):
  File "/home/frappe/frappe-bench/apps/frappe/frappe/app.py", line 119, in application
    response = get_response()
  File "/home/frappe/frappe-bench/apps/frappe/frappe/website/serve.py", line 28, in get_response
    response = ErrorPage(exception=e).render()
  File "/home/frappe/frappe-bench/apps/frappe/frappe/website/page_renderers/template_page.py", line 84, in render
    html = self.get_html()
  File "/home/frappe/frappe-bench/apps/frappe/frappe/website/utils.py", line 523, in cache_html_decorator
    html = func(*args, **kwargs)
  File "/home/frappe/frappe-bench/apps/frappe/frappe/website/page_renderers/template_page.py", line 92, in get_html
    self.init_context()
  File "/home/frappe/frappe-bench/apps/frappe/frappe/website/page_renderers/error_page.py", line 14, in init_context
    super().init_context()
  File "/home/frappe/frappe-bench/apps/frappe/frappe/website/page_renderers/base_template_page.py", line 15, in init_context
    self.context.update(get_website_settings())
  File "/home/frappe/frappe-bench/apps/frappe/frappe/website/doctype/website_settings/website_settings.py", line 263, in get_website_settings
    context.boot = get_boot_data()
  File "/home/frappe/frappe-bench/apps/frappe/frappe/website/utils.py", line 179, in get_boot_data
    "user": frappe.db.get_value("User", frappe.session.user, "time_zone") or get_system_timezone(),
  File "/home/frappe/frappe-bench/apps/frappe/frappe/database/database.py", line 519, in get_value
    result = self.get_values(
  File "/home/frappe/frappe-bench/apps/frappe/frappe/database/database.py", line 623, in get_values
    out = self._get_values_from_table(
  File "/home/frappe/frappe-bench/apps/frappe/frappe/database/database.py", line 896, in _get_values_from_table
    return query.run(as_dict=as_dict, debug=debug, update=update, run=run, pluck=pluck)
  File "/home/frappe/frappe-bench/apps/frappe/frappe/query_builder/utils.py", line 87, in execute_query
    result = frappe.db.sql(query, params, *args, **kwargs)  # nosemgrep
  File "/home/frappe/frappe-bench/apps/frappe/frappe/database/database.py", line 211, in sql
    self.connect()
  File "/home/frappe/frappe-bench/apps/frappe/frappe/database/database.py", line 117, in connect
    self._conn: "MariadbConnection" | "PostgresConnection" = self.get_connection()
  File "/home/frappe/frappe-bench/apps/frappe/frappe/database/mariadb/database.py", line 107, in get_connection
    conn = self._get_connection()
  File "/home/frappe/frappe-bench/apps/frappe/frappe/database/mariadb/database.py", line 113, in _get_connection
    return self.create_connection()
  File "/home/frappe/frappe-bench/apps/frappe/frappe/database/mariadb/database.py", line 116, in create_connection
    return pymysql.connect(**self.get_connection_settings())
  File "/home/frappe/frappe-bench/env/lib/python3.10/site-packages/pymysql/connections.py", line 358, in __init__
    self.connect()
  File "/home/frappe/frappe-bench/env/lib/python3.10/site-packages/pymysql/connections.py", line 711, in connect
    raise exc
pymysql.err.OperationalError: (2003, "Can't connect to MySQL server on '127.0.0.1' ([Errno 111] Connection refused)")

During handling of the above exception, another exception occurred:

Traceback (most recent call last):
  File "/home/frappe/frappe-bench/env/lib/python3.10/site-packages/pymysql/connections.py", line 644, in connect
    sock = socket.create_connection(
  File "/usr/lib/python3.10/socket.py", line 845, in create_connection
    raise err
  File "/usr/lib/python3.10/socket.py", line 833, in create_connection
    sock.connect(sa)
ConnectionRefusedError: [Errno 111] Connection refused

During handling of the above exception, another exception occurred:

Traceback (most recent call last):
  File "/home/frappe/frappe-bench/apps/frappe/frappe/utils/error.py", line 86, in log_error_snapshot
    log_error(title=str(exception), defer_insert=True)
  File "/home/frappe/frappe-bench/apps/frappe/frappe/utils/error.py", line 61, in log_error
    error_log = frappe.get_doc(
  File "/home/frappe/frappe-bench/apps/frappe/frappe/__init__.py", line 1329, in get_doc
    doc = frappe.model.document.get_doc(*args, **kwargs)
  File "/home/frappe/frappe-bench/apps/frappe/frappe/model/document.py", line 83, in get_doc
    controller = get_controller(doctype)
  File "/home/frappe/frappe-bench/apps/frappe/frappe/model/base_document.py", line 70, in get_controller
    site_controllers[doctype] = import_controller(doctype)
  File "/home/frappe/frappe-bench/apps/frappe/frappe/model/base_document.py", line 81, in import_controller
    doctype_info = frappe.db.get_value("DocType", doctype, fieldname="*")
  File "/home/frappe/frappe-bench/apps/frappe/frappe/database/database.py", line 519, in get_value
    result = self.get_values(
  File "/home/frappe/frappe-bench/apps/frappe/frappe/database/database.py", line 623, in get_values
    out = self._get_values_from_table(
  File "/home/frappe/frappe-bench/apps/frappe/frappe/database/database.py", line 896, in _get_values_from_table
    return query.run(as_dict=as_dict, debug=debug, update=update, run=run, pluck=pluck)
  File "/home/frappe/frappe-bench/apps/frappe/frappe/query_builder/utils.py", line 87, in execute_query
    result = frappe.db.sql(query, params, *args, **kwargs)  # nosemgrep
  File "/home/frappe/frappe-bench/apps/frappe/frappe/database/database.py", line 211, in sql
    self.connect()
  File "/home/frappe/frappe-bench/apps/frappe/frappe/database/database.py", line 117, in connect
    self._conn: "MariadbConnection" | "PostgresConnection" = self.get_connection()
  File "/home/frappe/frappe-bench/apps/frappe/frappe/database/mariadb/database.py", line 107, in get_connection
    conn = self._get_connection()
  File "/home/frappe/frappe-bench/apps/frappe/frappe/database/mariadb/database.py", line 113, in _get_connection
    return self.create_connection()
  File "/home/frappe/frappe-bench/apps/frappe/frappe/database/mariadb/database.py", line 116, in create_connection
    return pymysql.connect(**self.get_connection_settings())
  File "/home/frappe/frappe-bench/env/lib/python3.10/site-packages/pymysql/connections.py", line 358, in __init__
    self.connect()
  File "/home/frappe/frappe-bench/env/lib/python3.10/site-packages/pymysql/connections.py", line 711, in connect
    raise exc
pymysql.err.OperationalError: (2003, "Can't connect to MySQL server on '127.0.0.1' ([Errno 111] Connection refused)")
2024-07-19 12:04:18,443 ERROR frappe Could not take error snapshot: (2003, "Can't connect to MySQL server on '127.0.0.1' ([Errno 111] Connection refused)")
Site: erp.grupoatu.com
Form Dict: {}
Traceback (most recent call last):
  File "/home/frappe/frappe-bench/env/lib/python3.10/site-packages/pymysql/connections.py", line 644, in connect
    sock = socket.create_connection(
  File "/usr/lib/python3.10/socket.py", line 845, in create_connection
    raise err
  File "/usr/lib/python3.10/socket.py", line 833, in create_connection
    sock.connect(sa)
ConnectionRefusedError: [Errno 111] Connection refused

During handling of the above exception, another exception occurred:

Traceback (most recent call last):
  File "/home/frappe/frappe-bench/apps/frappe/frappe/website/serve.py", line 19, in get_response
    endpoint, renderer_instance = path_resolver.resolve()
  File "/home/frappe/frappe-bench/apps/frappe/frappe/website/path_resolver.py", line 38, in resolve
    resolve_redirect(self.path, request.query_string)
  File "/home/frappe/frappe-bench/apps/frappe/frappe/website/path_resolver.py", line 118, in resolve_redirect
    redirects += frappe.get_all("Website Route Redirect", ["source", "target"], order_by=None)
  File "/home/frappe/frappe-bench/apps/frappe/frappe/__init__.py", line 2050, in get_all
    return get_list(doctype, *args, **kwargs)
  File "/home/frappe/frappe-bench/apps/frappe/frappe/__init__.py", line 2025, in get_list
    return frappe.model.db_query.DatabaseQuery(doctype).execute(*args, **kwargs)
  File "/home/frappe/frappe-bench/apps/frappe/frappe/model/db_query.py", line 191, in execute
    result = self.build_and_run()
  File "/home/frappe/frappe-bench/apps/frappe/frappe/model/db_query.py", line 232, in build_and_run
    return frappe.db.sql(
  File "/home/frappe/frappe-bench/apps/frappe/frappe/database/database.py", line 211, in sql
    self.connect()
  File "/home/frappe/frappe-bench/apps/frappe/frappe/database/database.py", line 117, in connect
    self._conn: "MariadbConnection" | "PostgresConnection" = self.get_connection()
  File "/home/frappe/frappe-bench/apps/frappe/frappe/database/mariadb/database.py", line 107, in get_connection
    conn = self._get_connection()
  File "/home/frappe/frappe-bench/apps/frappe/frappe/database/mariadb/database.py", line 113, in _get_connection
    return self.create_connection()
  File "/home/frappe/frappe-bench/apps/frappe/frappe/database/mariadb/database.py", line 116, in create_connection
    return pymysql.connect(**self.get_connection_settings())
  File "/home/frappe/frappe-bench/env/lib/python3.10/site-packages/pymysql/connections.py", line 358, in __init__
    self.connect()
  File "/home/frappe/frappe-bench/env/lib/python3.10/site-packages/pymysql/connections.py", line 711, in connect
    raise exc
pymysql.err.OperationalError: (2003, "Can't connect to MySQL server on '127.0.0.1' ([Errno 111] Connection refused)")

During handling of the above exception, another exception occurred:

Traceback (most recent call last):
  File "/home/frappe/frappe-bench/env/lib/python3.10/site-packages/pymysql/connections.py", line 644, in connect
    sock = socket.create_connection(
  File "/usr/lib/python3.10/socket.py", line 845, in create_connection
    raise err
  File "/usr/lib/python3.10/socket.py", line 833, in create_connection
    sock.connect(sa)
ConnectionRefusedError: [Errno 111] Connection refused

During handling of the above exception, another exception occurred:

Traceback (most recent call last):
  File "/home/frappe/frappe-bench/apps/frappe/frappe/app.py", line 119, in application
    response = get_response()
  File "/home/frappe/frappe-bench/apps/frappe/frappe/website/serve.py", line 28, in get_response
    response = ErrorPage(exception=e).render()
  File "/home/frappe/frappe-bench/apps/frappe/frappe/website/page_renderers/template_page.py", line 84, in render
    html = self.get_html()
  File "/home/frappe/frappe-bench/apps/frappe/frappe/website/utils.py", line 523, in cache_html_decorator
    html = func(*args, **kwargs)
  File "/home/frappe/frappe-bench/apps/frappe/frappe/website/page_renderers/template_page.py", line 92, in get_html
    self.init_context()
  File "/home/frappe/frappe-bench/apps/frappe/frappe/website/page_renderers/error_page.py", line 14, in init_context
    super().init_context()
  File "/home/frappe/frappe-bench/apps/frappe/frappe/website/page_renderers/base_template_page.py", line 15, in init_context
    self.context.update(get_website_settings())
  File "/home/frappe/frappe-bench/apps/frappe/frappe/website/doctype/website_settings/website_settings.py", line 263, in get_website_settings
    context.boot = get_boot_data()
  File "/home/frappe/frappe-bench/apps/frappe/frappe/website/utils.py", line 179, in get_boot_data
    "user": frappe.db.get_value("User", frappe.session.user, "time_zone") or get_system_timezone(),
  File "/home/frappe/frappe-bench/apps/frappe/frappe/database/database.py", line 519, in get_value
    result = self.get_values(
  File "/home/frappe/frappe-bench/apps/frappe/frappe/database/database.py", line 623, in get_values
    out = self._get_values_from_table(
  File "/home/frappe/frappe-bench/apps/frappe/frappe/database/database.py", line 896, in _get_values_from_table
    return query.run(as_dict=as_dict, debug=debug, update=update, run=run, pluck=pluck)
  File "/home/frappe/frappe-bench/apps/frappe/frappe/query_builder/utils.py", line 87, in execute_query
    result = frappe.db.sql(query, params, *args, **kwargs)  # nosemgrep
  File "/home/frappe/frappe-bench/apps/frappe/frappe/database/database.py", line 211, in sql
    self.connect()
  File "/home/frappe/frappe-bench/apps/frappe/frappe/database/database.py", line 117, in connect
    self._conn: "MariadbConnection" | "PostgresConnection" = self.get_connection()
  File "/home/frappe/frappe-bench/apps/frappe/frappe/database/mariadb/database.py", line 107, in get_connection
    conn = self._get_connection()
  File "/home/frappe/frappe-bench/apps/frappe/frappe/database/mariadb/database.py", line 113, in _get_connection
    return self.create_connection()
  File "/home/frappe/frappe-bench/apps/frappe/frappe/database/mariadb/database.py", line 116, in create_connection
    return pymysql.connect(**self.get_connection_settings())
  File "/home/frappe/frappe-bench/env/lib/python3.10/site-packages/pymysql/connections.py", line 358, in __init__
    self.connect()
  File "/home/frappe/frappe-bench/env/lib/python3.10/site-packages/pymysql/connections.py", line 711, in connect
    raise exc
pymysql.err.OperationalError: (2003, "Can't connect to MySQL server on '127.0.0.1' ([Errno 111] Connection refused)")

During handling of the above exception, another exception occurred:

Traceback (most recent call last):
  File "/home/frappe/frappe-bench/env/lib/python3.10/site-packages/pymysql/connections.py", line 644, in connect
    sock = socket.create_connection(
  File "/usr/lib/python3.10/socket.py", line 845, in create_connection
    raise err
  File "/usr/lib/python3.10/socket.py", line 833, in create_connection
    sock.connect(sa)
ConnectionRefusedError: [Errno 111] Connection refused

During handling of the above exception, another exception occurred:

Traceback (most recent call last):
  File "/home/frappe/frappe-bench/apps/frappe/frappe/utils/error.py", line 86, in log_error_snapshot
    log_error(title=str(exception), defer_insert=True)
  File "/home/frappe/frappe-bench/apps/frappe/frappe/utils/error.py", line 61, in log_error
    error_log = frappe.get_doc(
  File "/home/frappe/frappe-bench/apps/frappe/frappe/__init__.py", line 1329, in get_doc
    doc = frappe.model.document.get_doc(*args, **kwargs)
  File "/home/frappe/frappe-bench/apps/frappe/frappe/model/document.py", line 83, in get_doc
    controller = get_controller(doctype)
  File "/home/frappe/frappe-bench/apps/frappe/frappe/model/base_document.py", line 70, in get_controller
    site_controllers[doctype] = import_controller(doctype)
  File "/home/frappe/frappe-bench/apps/frappe/frappe/model/base_document.py", line 81, in import_controller
    doctype_info = frappe.db.get_value("DocType", doctype, fieldname="*")
  File "/home/frappe/frappe-bench/apps/frappe/frappe/database/database.py", line 519, in get_value
    result = self.get_values(
  File "/home/frappe/frappe-bench/apps/frappe/frappe/database/database.py", line 623, in get_values
    out = self._get_values_from_table(
  File "/home/frappe/frappe-bench/apps/frappe/frappe/database/database.py", line 896, in _get_values_from_table
    return query.run(as_dict=as_dict, debug=debug, update=update, run=run, pluck=pluck)
  File "/home/frappe/frappe-bench/apps/frappe/frappe/query_builder/utils.py", line 87, in execute_query
    result = frappe.db.sql(query, params, *args, **kwargs)  # nosemgrep
  File "/home/frappe/frappe-bench/apps/frappe/frappe/database/database.py", line 211, in sql
    self.connect()
  File "/home/frappe/frappe-bench/apps/frappe/frappe/database/database.py", line 117, in connect
    self._conn: "MariadbConnection" | "PostgresConnection" = self.get_connection()
  File "/home/frappe/frappe-bench/apps/frappe/frappe/database/mariadb/database.py", line 107, in get_connection
    conn = self._get_connection()
  File "/home/frappe/frappe-bench/apps/frappe/frappe/database/mariadb/database.py", line 113, in _get_connection
    return self.create_connection()
  File "/home/frappe/frappe-bench/apps/frappe/frappe/database/mariadb/database.py", line 116, in create_connection
    return pymysql.connect(**self.get_connection_settings())
  File "/home/frappe/frappe-bench/env/lib/python3.10/site-packages/pymysql/connections.py", line 358, in __init__
    self.connect()
  File "/home/frappe/frappe-bench/env/lib/python3.10/site-packages/pymysql/connections.py", line 711, in connect
    raise exc
pymysql.err.OperationalError: (2003, "Can't connect to MySQL server on '127.0.0.1' ([Errno 111] Connection refused)")
2024-07-19 12:04:18,612 ERROR frappe Could not take error snapshot: (2003, "Can't connect to MySQL server on '127.0.0.1' ([Errno 111] Connection refused)")
Site: erp.grupoatu.com
Form Dict: {}
Traceback (most recent call last):
  File "/home/frappe/frappe-bench/env/lib/python3.10/site-packages/pymysql/connections.py", line 644, in connect
    sock = socket.create_connection(
  File "/usr/lib/python3.10/socket.py", line 845, in create_connection
    raise err
  File "/usr/lib/python3.10/socket.py", line 833, in create_connection
    sock.connect(sa)
ConnectionRefusedError: [Errno 111] Connection refused

During handling of the above exception, another exception occurred:

Traceback (most recent call last):
  File "/home/frappe/frappe-bench/apps/frappe/frappe/website/serve.py", line 19, in get_response
    endpoint, renderer_instance = path_resolver.resolve()
  File "/home/frappe/frappe-bench/apps/frappe/frappe/website/path_resolver.py", line 38, in resolve
    resolve_redirect(self.path, request.query_string)
  File "/home/frappe/frappe-bench/apps/frappe/frappe/website/path_resolver.py", line 118, in resolve_redirect
    redirects += frappe.get_all("Website Route Redirect", ["source", "target"], order_by=None)
  File "/home/frappe/frappe-bench/apps/frappe/frappe/__init__.py", line 2050, in get_all
    return get_list(doctype, *args, **kwargs)
  File "/home/frappe/frappe-bench/apps/frappe/frappe/__init__.py", line 2025, in get_list
    return frappe.model.db_query.DatabaseQuery(doctype).execute(*args, **kwargs)
  File "/home/frappe/frappe-bench/apps/frappe/frappe/model/db_query.py", line 191, in execute
    result = self.build_and_run()
  File "/home/frappe/frappe-bench/apps/frappe/frappe/model/db_query.py", line 232, in build_and_run
    return frappe.db.sql(
  File "/home/frappe/frappe-bench/apps/frappe/frappe/database/database.py", line 211, in sql
    self.connect()
  File "/home/frappe/frappe-bench/apps/frappe/frappe/database/database.py", line 117, in connect
    self._conn: "MariadbConnection" | "PostgresConnection" = self.get_connection()
  File "/home/frappe/frappe-bench/apps/frappe/frappe/database/mariadb/database.py", line 107, in get_connection
    conn = self._get_connection()
  File "/home/frappe/frappe-bench/apps/frappe/frappe/database/mariadb/database.py", line 113, in _get_connection
    return self.create_connection()
  File "/home/frappe/frappe-bench/apps/frappe/frappe/database/mariadb/database.py", line 116, in create_connection
    return pymysql.connect(**self.get_connection_settings())
  File "/home/frappe/frappe-bench/env/lib/python3.10/site-packages/pymysql/connections.py", line 358, in __init__
    self.connect()
  File "/home/frappe/frappe-bench/env/lib/python3.10/site-packages/pymysql/connections.py", line 711, in connect
    raise exc
pymysql.err.OperationalError: (2003, "Can't connect to MySQL server on '127.0.0.1' ([Errno 111] Connection refused)")

During handling of the above exception, another exception occurred:

Traceback (most recent call last):
  File "/home/frappe/frappe-bench/env/lib/python3.10/site-packages/pymysql/connections.py", line 644, in connect
    sock = socket.create_connection(
  File "/usr/lib/python3.10/socket.py", line 845, in create_connection
    raise err
  File "/usr/lib/python3.10/socket.py", line 833, in create_connection
    sock.connect(sa)
ConnectionRefusedError: [Errno 111] Connection refused

During handling of the above exception, another exception occurred:

Traceback (most recent call last):
  File "/home/frappe/frappe-bench/apps/frappe/frappe/app.py", line 119, in application
    response = get_response()
  File "/home/frappe/frappe-bench/apps/frappe/frappe/website/serve.py", line 28, in get_response
    response = ErrorPage(exception=e).render()
  File "/home/frappe/frappe-bench/apps/frappe/frappe/website/page_renderers/template_page.py", line 84, in render
    html = self.get_html()
  File "/home/frappe/frappe-bench/apps/frappe/frappe/website/utils.py", line 523, in cache_html_decorator
    html = func(*args, **kwargs)
  File "/home/frappe/frappe-bench/apps/frappe/frappe/website/page_renderers/template_page.py", line 92, in get_html
    self.init_context()
  File "/home/frappe/frappe-bench/apps/frappe/frappe/website/page_renderers/error_page.py", line 14, in init_context
    super().init_context()
  File "/home/frappe/frappe-bench/apps/frappe/frappe/website/page_renderers/base_template_page.py", line 15, in init_context
    self.context.update(get_website_settings())
  File "/home/frappe/frappe-bench/apps/frappe/frappe/website/doctype/website_settings/website_settings.py", line 263, in get_website_settings
    context.boot = get_boot_data()
  File "/home/frappe/frappe-bench/apps/frappe/frappe/website/utils.py", line 179, in get_boot_data
    "user": frappe.db.get_value("User", frappe.session.user, "time_zone") or get_system_timezone(),
  File "/home/frappe/frappe-bench/apps/frappe/frappe/database/database.py", line 519, in get_value
    result = self.get_values(
  File "/home/frappe/frappe-bench/apps/frappe/frappe/database/database.py", line 623, in get_values
    out = self._get_values_from_table(
  File "/home/frappe/frappe-bench/apps/frappe/frappe/database/database.py", line 896, in _get_values_from_table
    return query.run(as_dict=as_dict, debug=debug, update=update, run=run, pluck=pluck)
  File "/home/frappe/frappe-bench/apps/frappe/frappe/query_builder/utils.py", line 87, in execute_query
    result = frappe.db.sql(query, params, *args, **kwargs)  # nosemgrep
  File "/home/frappe/frappe-bench/apps/frappe/frappe/database/database.py", line 211, in sql
    self.connect()
  File "/home/frappe/frappe-bench/apps/frappe/frappe/database/database.py", line 117, in connect
    self._conn: "MariadbConnection" | "PostgresConnection" = self.get_connection()
  File "/home/frappe/frappe-bench/apps/frappe/frappe/database/mariadb/database.py", line 107, in get_connection
    conn = self._get_connection()
  File "/home/frappe/frappe-bench/apps/frappe/frappe/database/mariadb/database.py", line 113, in _get_connection
    return self.create_connection()
  File "/home/frappe/frappe-bench/apps/frappe/frappe/database/mariadb/database.py", line 116, in create_connection
    return pymysql.connect(**self.get_connection_settings())
  File "/home/frappe/frappe-bench/env/lib/python3.10/site-packages/pymysql/connections.py", line 358, in __init__
    self.connect()
  File "/home/frappe/frappe-bench/env/lib/python3.10/site-packages/pymysql/connections.py", line 711, in connect
    raise exc
pymysql.err.OperationalError: (2003, "Can't connect to MySQL server on '127.0.0.1' ([Errno 111] Connection refused)")

During handling of the above exception, another exception occurred:

Traceback (most recent call last):
  File "/home/frappe/frappe-bench/env/lib/python3.10/site-packages/pymysql/connections.py", line 644, in connect
    sock = socket.create_connection(
  File "/usr/lib/python3.10/socket.py", line 845, in create_connection
    raise err
  File "/usr/lib/python3.10/socket.py", line 833, in create_connection
    sock.connect(sa)
ConnectionRefusedError: [Errno 111] Connection refused

During handling of the above exception, another exception occurred:

Traceback (most recent call last):
  File "/home/frappe/frappe-bench/apps/frappe/frappe/utils/error.py", line 86, in log_error_snapshot
    log_error(title=str(exception), defer_insert=True)
  File "/home/frappe/frappe-bench/apps/frappe/frappe/utils/error.py", line 61, in log_error
    error_log = frappe.get_doc(
  File "/home/frappe/frappe-bench/apps/frappe/frappe/__init__.py", line 1329, in get_doc
    doc = frappe.model.document.get_doc(*args, **kwargs)
  File "/home/frappe/frappe-bench/apps/frappe/frappe/model/document.py", line 83, in get_doc
    controller = get_controller(doctype)
  File "/home/frappe/frappe-bench/apps/frappe/frappe/model/base_document.py", line 70, in get_controller
    site_controllers[doctype] = import_controller(doctype)
  File "/home/frappe/frappe-bench/apps/frappe/frappe/model/base_document.py", line 81, in import_controller
    doctype_info = frappe.db.get_value("DocType", doctype, fieldname="*")
  File "/home/frappe/frappe-bench/apps/frappe/frappe/database/database.py", line 519, in get_value
    result = self.get_values(
  File "/home/frappe/frappe-bench/apps/frappe/frappe/database/database.py", line 623, in get_values
    out = self._get_values_from_table(
  File "/home/frappe/frappe-bench/apps/frappe/frappe/database/database.py", line 896, in _get_values_from_table
    return query.run(as_dict=as_dict, debug=debug, update=update, run=run, pluck=pluck)
  File "/home/frappe/frappe-bench/apps/frappe/frappe/query_builder/utils.py", line 87, in execute_query
    result = frappe.db.sql(query, params, *args, **kwargs)  # nosemgrep
  File "/home/frappe/frappe-bench/apps/frappe/frappe/database/database.py", line 211, in sql
    self.connect()
  File "/home/frappe/frappe-bench/apps/frappe/frappe/database/database.py", line 117, in connect
    self._conn: "MariadbConnection" | "PostgresConnection" = self.get_connection()
  File "/home/frappe/frappe-bench/apps/frappe/frappe/database/mariadb/database.py", line 107, in get_connection
    conn = self._get_connection()
  File "/home/frappe/frappe-bench/apps/frappe/frappe/database/mariadb/database.py", line 113, in _get_connection
    return self.create_connection()
  File "/home/frappe/frappe-bench/apps/frappe/frappe/database/mariadb/database.py", line 116, in create_connection
    return pymysql.connect(**self.get_connection_settings())
  File "/home/frappe/frappe-bench/env/lib/python3.10/site-packages/pymysql/connections.py", line 358, in __init__
    self.connect()
  File "/home/frappe/frappe-bench/env/lib/python3.10/site-packages/pymysql/connections.py", line 711, in connect
    raise exc
pymysql.err.OperationalError: (2003, "Can't connect to MySQL server on '127.0.0.1' ([Errno 111] Connection refused)")
2024-07-19 12:04:18,792 ERROR frappe Could not take error snapshot: (2003, "Can't connect to MySQL server on '127.0.0.1' ([Errno 111] Connection refused)")
Site: erp.grupoatu.com
Form Dict: {}
Traceback (most recent call last):
  File "/home/frappe/frappe-bench/env/lib/python3.10/site-packages/pymysql/connections.py", line 644, in connect
    sock = socket.create_connection(
  File "/usr/lib/python3.10/socket.py", line 845, in create_connection
    raise err
  File "/usr/lib/python3.10/socket.py", line 833, in create_connection
    sock.connect(sa)
ConnectionRefusedError: [Errno 111] Connection refused

During handling of the above exception, another exception occurred:

Traceback (most recent call last):
  File "/home/frappe/frappe-bench/apps/frappe/frappe/website/serve.py", line 19, in get_response
    endpoint, renderer_instance = path_resolver.resolve()
  File "/home/frappe/frappe-bench/apps/frappe/frappe/website/path_resolver.py", line 38, in resolve
    resolve_redirect(self.path, request.query_string)
  File "/home/frappe/frappe-bench/apps/frappe/frappe/website/path_resolver.py", line 118, in resolve_redirect
    redirects += frappe.get_all("Website Route Redirect", ["source", "target"], order_by=None)
  File "/home/frappe/frappe-bench/apps/frappe/frappe/__init__.py", line 2050, in get_all
    return get_list(doctype, *args, **kwargs)
  File "/home/frappe/frappe-bench/apps/frappe/frappe/__init__.py", line 2025, in get_list
    return frappe.model.db_query.DatabaseQuery(doctype).execute(*args, **kwargs)
  File "/home/frappe/frappe-bench/apps/frappe/frappe/model/db_query.py", line 191, in execute
    result = self.build_and_run()
  File "/home/frappe/frappe-bench/apps/frappe/frappe/model/db_query.py", line 232, in build_and_run
    return frappe.db.sql(
  File "/home/frappe/frappe-bench/apps/frappe/frappe/database/database.py", line 211, in sql
    self.connect()
  File "/home/frappe/frappe-bench/apps/frappe/frappe/database/database.py", line 117, in connect
    self._conn: "MariadbConnection" | "PostgresConnection" = self.get_connection()
  File "/home/frappe/frappe-bench/apps/frappe/frappe/database/mariadb/database.py", line 107, in get_connection
    conn = self._get_connection()
  File "/home/frappe/frappe-bench/apps/frappe/frappe/database/mariadb/database.py", line 113, in _get_connection
    return self.create_connection()
  File "/home/frappe/frappe-bench/apps/frappe/frappe/database/mariadb/database.py", line 116, in create_connection
    return pymysql.connect(**self.get_connection_settings())
  File "/home/frappe/frappe-bench/env/lib/python3.10/site-packages/pymysql/connections.py", line 358, in __init__
    self.connect()
  File "/home/frappe/frappe-bench/env/lib/python3.10/site-packages/pymysql/connections.py", line 711, in connect
    raise exc
pymysql.err.OperationalError: (2003, "Can't connect to MySQL server on '127.0.0.1' ([Errno 111] Connection refused)")

During handling of the above exception, another exception occurred:

Traceback (most recent call last):
  File "/home/frappe/frappe-bench/env/lib/python3.10/site-packages/pymysql/connections.py", line 644, in connect
    sock = socket.create_connection(
  File "/usr/lib/python3.10/socket.py", line 845, in create_connection
    raise err
  File "/usr/lib/python3.10/socket.py", line 833, in create_connection
    sock.connect(sa)
ConnectionRefusedError: [Errno 111] Connection refused

During handling of the above exception, another exception occurred:

Traceback (most recent call last):
  File "/home/frappe/frappe-bench/apps/frappe/frappe/app.py", line 119, in application
    response = get_response()
  File "/home/frappe/frappe-bench/apps/frappe/frappe/website/serve.py", line 28, in get_response
    response = ErrorPage(exception=e).render()
  File "/home/frappe/frappe-bench/apps/frappe/frappe/website/page_renderers/template_page.py", line 84, in render
    html = self.get_html()
  File "/home/frappe/frappe-bench/apps/frappe/frappe/website/utils.py", line 523, in cache_html_decorator
    html = func(*args, **kwargs)
  File "/home/frappe/frappe-bench/apps/frappe/frappe/website/page_renderers/template_page.py", line 92, in get_html
    self.init_context()
  File "/home/frappe/frappe-bench/apps/frappe/frappe/website/page_renderers/error_page.py", line 14, in init_context
    super().init_context()
  File "/home/frappe/frappe-bench/apps/frappe/frappe/website/page_renderers/base_template_page.py", line 15, in init_context
    self.context.update(get_website_settings())
  File "/home/frappe/frappe-bench/apps/frappe/frappe/website/doctype/website_settings/website_settings.py", line 263, in get_website_settings
    context.boot = get_boot_data()
  File "/home/frappe/frappe-bench/apps/frappe/frappe/website/utils.py", line 179, in get_boot_data
    "user": frappe.db.get_value("User", frappe.session.user, "time_zone") or get_system_timezone(),
  File "/home/frappe/frappe-bench/apps/frappe/frappe/database/database.py", line 519, in get_value
    result = self.get_values(
  File "/home/frappe/frappe-bench/apps/frappe/frappe/database/database.py", line 623, in get_values
    out = self._get_values_from_table(
  File "/home/frappe/frappe-bench/apps/frappe/frappe/database/database.py", line 896, in _get_values_from_table
    return query.run(as_dict=as_dict, debug=debug, update=update, run=run, pluck=pluck)
  File "/home/frappe/frappe-bench/apps/frappe/frappe/query_builder/utils.py", line 87, in execute_query
    result = frappe.db.sql(query, params, *args, **kwargs)  # nosemgrep
  File "/home/frappe/frappe-bench/apps/frappe/frappe/database/database.py", line 211, in sql
    self.connect()
  File "/home/frappe/frappe-bench/apps/frappe/frappe/database/database.py", line 117, in connect
    self._conn: "MariadbConnection" | "PostgresConnection" = self.get_connection()
  File "/home/frappe/frappe-bench/apps/frappe/frappe/database/mariadb/database.py", line 107, in get_connection
    conn = self._get_connection()
  File "/home/frappe/frappe-bench/apps/frappe/frappe/database/mariadb/database.py", line 113, in _get_connection
    return self.create_connection()
  File "/home/frappe/frappe-bench/apps/frappe/frappe/database/mariadb/database.py", line 116, in create_connection
    return pymysql.connect(**self.get_connection_settings())
  File "/home/frappe/frappe-bench/env/lib/python3.10/site-packages/pymysql/connections.py", line 358, in __init__
    self.connect()
  File "/home/frappe/frappe-bench/env/lib/python3.10/site-packages/pymysql/connections.py", line 711, in connect
    raise exc
pymysql.err.OperationalError: (2003, "Can't connect to MySQL server on '127.0.0.1' ([Errno 111] Connection refused)")

During handling of the above exception, another exception occurred:

Traceback (most recent call last):
  File "/home/frappe/frappe-bench/env/lib/python3.10/site-packages/pymysql/connections.py", line 644, in connect
    sock = socket.create_connection(
  File "/usr/lib/python3.10/socket.py", line 845, in create_connection
    raise err
  File "/usr/lib/python3.10/socket.py", line 833, in create_connection
    sock.connect(sa)
ConnectionRefusedError: [Errno 111] Connection refused

During handling of the above exception, another exception occurred:

Traceback (most recent call last):
  File "/home/frappe/frappe-bench/apps/frappe/frappe/utils/error.py", line 86, in log_error_snapshot
    log_error(title=str(exception), defer_insert=True)
  File "/home/frappe/frappe-bench/apps/frappe/frappe/utils/error.py", line 61, in log_error
    error_log = frappe.get_doc(
  File "/home/frappe/frappe-bench/apps/frappe/frappe/__init__.py", line 1329, in get_doc
    doc = frappe.model.document.get_doc(*args, **kwargs)
  File "/home/frappe/frappe-bench/apps/frappe/frappe/model/document.py", line 83, in get_doc
    controller = get_controller(doctype)
  File "/home/frappe/frappe-bench/apps/frappe/frappe/model/base_document.py", line 70, in get_controller
    site_controllers[doctype] = import_controller(doctype)
  File "/home/frappe/frappe-bench/apps/frappe/frappe/model/base_document.py", line 81, in import_controller
    doctype_info = frappe.db.get_value("DocType", doctype, fieldname="*")
  File "/home/frappe/frappe-bench/apps/frappe/frappe/database/database.py", line 519, in get_value
    result = self.get_values(
  File "/home/frappe/frappe-bench/apps/frappe/frappe/database/database.py", line 623, in get_values
    out = self._get_values_from_table(
  File "/home/frappe/frappe-bench/apps/frappe/frappe/database/database.py", line 896, in _get_values_from_table
    return query.run(as_dict=as_dict, debug=debug, update=update, run=run, pluck=pluck)
  File "/home/frappe/frappe-bench/apps/frappe/frappe/query_builder/utils.py", line 87, in execute_query
    result = frappe.db.sql(query, params, *args, **kwargs)  # nosemgrep
  File "/home/frappe/frappe-bench/apps/frappe/frappe/database/database.py", line 211, in sql
    self.connect()
  File "/home/frappe/frappe-bench/apps/frappe/frappe/database/database.py", line 117, in connect
    self._conn: "MariadbConnection" | "PostgresConnection" = self.get_connection()
  File "/home/frappe/frappe-bench/apps/frappe/frappe/database/mariadb/database.py", line 107, in get_connection
    conn = self._get_connection()
  File "/home/frappe/frappe-bench/apps/frappe/frappe/database/mariadb/database.py", line 113, in _get_connection
    return self.create_connection()
  File "/home/frappe/frappe-bench/apps/frappe/frappe/database/mariadb/database.py", line 116, in create_connection
    return pymysql.connect(**self.get_connection_settings())
  File "/home/frappe/frappe-bench/env/lib/python3.10/site-packages/pymysql/connections.py", line 358, in __init__
    self.connect()
  File "/home/frappe/frappe-bench/env/lib/python3.10/site-packages/pymysql/connections.py", line 711, in connect
    raise exc
pymysql.err.OperationalError: (2003, "Can't connect to MySQL server on '127.0.0.1' ([Errno 111] Connection refused)")
2024-07-19 12:04:19,332 ERROR frappe Could not take error snapshot: (2003, "Can't connect to MySQL server on '127.0.0.1' ([Errno 111] Connection refused)")
Site: erp.grupoatu.com
Form Dict: {}
Traceback (most recent call last):
  File "/home/frappe/frappe-bench/env/lib/python3.10/site-packages/pymysql/connections.py", line 644, in connect
    sock = socket.create_connection(
  File "/usr/lib/python3.10/socket.py", line 845, in create_connection
    raise err
  File "/usr/lib/python3.10/socket.py", line 833, in create_connection
    sock.connect(sa)
ConnectionRefusedError: [Errno 111] Connection refused

During handling of the above exception, another exception occurred:

Traceback (most recent call last):
  File "/home/frappe/frappe-bench/apps/frappe/frappe/website/serve.py", line 19, in get_response
    endpoint, renderer_instance = path_resolver.resolve()
  File "/home/frappe/frappe-bench/apps/frappe/frappe/website/path_resolver.py", line 38, in resolve
    resolve_redirect(self.path, request.query_string)
  File "/home/frappe/frappe-bench/apps/frappe/frappe/website/path_resolver.py", line 118, in resolve_redirect
    redirects += frappe.get_all("Website Route Redirect", ["source", "target"], order_by=None)
  File "/home/frappe/frappe-bench/apps/frappe/frappe/__init__.py", line 2050, in get_all
    return get_list(doctype, *args, **kwargs)
  File "/home/frappe/frappe-bench/apps/frappe/frappe/__init__.py", line 2025, in get_list
    return frappe.model.db_query.DatabaseQuery(doctype).execute(*args, **kwargs)
  File "/home/frappe/frappe-bench/apps/frappe/frappe/model/db_query.py", line 191, in execute
    result = self.build_and_run()
  File "/home/frappe/frappe-bench/apps/frappe/frappe/model/db_query.py", line 232, in build_and_run
    return frappe.db.sql(
  File "/home/frappe/frappe-bench/apps/frappe/frappe/database/database.py", line 211, in sql
    self.connect()
  File "/home/frappe/frappe-bench/apps/frappe/frappe/database/database.py", line 117, in connect
    self._conn: "MariadbConnection" | "PostgresConnection" = self.get_connection()
  File "/home/frappe/frappe-bench/apps/frappe/frappe/database/mariadb/database.py", line 107, in get_connection
    conn = self._get_connection()
  File "/home/frappe/frappe-bench/apps/frappe/frappe/database/mariadb/database.py", line 113, in _get_connection
    return self.create_connection()
  File "/home/frappe/frappe-bench/apps/frappe/frappe/database/mariadb/database.py", line 116, in create_connection
    return pymysql.connect(**self.get_connection_settings())
  File "/home/frappe/frappe-bench/env/lib/python3.10/site-packages/pymysql/connections.py", line 358, in __init__
    self.connect()
  File "/home/frappe/frappe-bench/env/lib/python3.10/site-packages/pymysql/connections.py", line 711, in connect
    raise exc
pymysql.err.OperationalError: (2003, "Can't connect to MySQL server on '127.0.0.1' ([Errno 111] Connection refused)")

During handling of the above exception, another exception occurred:

Traceback (most recent call last):
  File "/home/frappe/frappe-bench/env/lib/python3.10/site-packages/pymysql/connections.py", line 644, in connect
    sock = socket.create_connection(
  File "/usr/lib/python3.10/socket.py", line 845, in create_connection
    raise err
  File "/usr/lib/python3.10/socket.py", line 833, in create_connection
    sock.connect(sa)
ConnectionRefusedError: [Errno 111] Connection refused

During handling of the above exception, another exception occurred:

Traceback (most recent call last):
  File "/home/frappe/frappe-bench/apps/frappe/frappe/app.py", line 119, in application
    response = get_response()
  File "/home/frappe/frappe-bench/apps/frappe/frappe/website/serve.py", line 28, in get_response
    response = ErrorPage(exception=e).render()
  File "/home/frappe/frappe-bench/apps/frappe/frappe/website/page_renderers/template_page.py", line 84, in render
    html = self.get_html()
  File "/home/frappe/frappe-bench/apps/frappe/frappe/website/utils.py", line 523, in cache_html_decorator
    html = func(*args, **kwargs)
  File "/home/frappe/frappe-bench/apps/frappe/frappe/website/page_renderers/template_page.py", line 92, in get_html
    self.init_context()
  File "/home/frappe/frappe-bench/apps/frappe/frappe/website/page_renderers/error_page.py", line 14, in init_context
    super().init_context()
  File "/home/frappe/frappe-bench/apps/frappe/frappe/website/page_renderers/base_template_page.py", line 15, in init_context
    self.context.update(get_website_settings())
  File "/home/frappe/frappe-bench/apps/frappe/frappe/website/doctype/website_settings/website_settings.py", line 263, in get_website_settings
    context.boot = get_boot_data()
  File "/home/frappe/frappe-bench/apps/frappe/frappe/website/utils.py", line 179, in get_boot_data
    "user": frappe.db.get_value("User", frappe.session.user, "time_zone") or get_system_timezone(),
  File "/home/frappe/frappe-bench/apps/frappe/frappe/database/database.py", line 519, in get_value
    result = self.get_values(
  File "/home/frappe/frappe-bench/apps/frappe/frappe/database/database.py", line 623, in get_values
    out = self._get_values_from_table(
  File "/home/frappe/frappe-bench/apps/frappe/frappe/database/database.py", line 896, in _get_values_from_table
    return query.run(as_dict=as_dict, debug=debug, update=update, run=run, pluck=pluck)
  File "/home/frappe/frappe-bench/apps/frappe/frappe/query_builder/utils.py", line 87, in execute_query
    result = frappe.db.sql(query, params, *args, **kwargs)  # nosemgrep
  File "/home/frappe/frappe-bench/apps/frappe/frappe/database/database.py", line 211, in sql
    self.connect()
  File "/home/frappe/frappe-bench/apps/frappe/frappe/database/database.py", line 117, in connect
    self._conn: "MariadbConnection" | "PostgresConnection" = self.get_connection()
  File "/home/frappe/frappe-bench/apps/frappe/frappe/database/mariadb/database.py", line 107, in get_connection
    conn = self._get_connection()
  File "/home/frappe/frappe-bench/apps/frappe/frappe/database/mariadb/database.py", line 113, in _get_connection
    return self.create_connection()
  File "/home/frappe/frappe-bench/apps/frappe/frappe/database/mariadb/database.py", line 116, in create_connection
    return pymysql.connect(**self.get_connection_settings())
  File "/home/frappe/frappe-bench/env/lib/python3.10/site-packages/pymysql/connections.py", line 358, in __init__
    self.connect()
  File "/home/frappe/frappe-bench/env/lib/python3.10/site-packages/pymysql/connections.py", line 711, in connect
    raise exc
pymysql.err.OperationalError: (2003, "Can't connect to MySQL server on '127.0.0.1' ([Errno 111] Connection refused)")

During handling of the above exception, another exception occurred:

Traceback (most recent call last):
  File "/home/frappe/frappe-bench/env/lib/python3.10/site-packages/pymysql/connections.py", line 644, in connect
    sock = socket.create_connection(
  File "/usr/lib/python3.10/socket.py", line 845, in create_connection
    raise err
  File "/usr/lib/python3.10/socket.py", line 833, in create_connection
    sock.connect(sa)
ConnectionRefusedError: [Errno 111] Connection refused

During handling of the above exception, another exception occurred:

Traceback (most recent call last):
  File "/home/frappe/frappe-bench/apps/frappe/frappe/utils/error.py", line 86, in log_error_snapshot
    log_error(title=str(exception), defer_insert=True)
  File "/home/frappe/frappe-bench/apps/frappe/frappe/utils/error.py", line 61, in log_error
    error_log = frappe.get_doc(
  File "/home/frappe/frappe-bench/apps/frappe/frappe/__init__.py", line 1329, in get_doc
    doc = frappe.model.document.get_doc(*args, **kwargs)
  File "/home/frappe/frappe-bench/apps/frappe/frappe/model/document.py", line 83, in get_doc
    controller = get_controller(doctype)
  File "/home/frappe/frappe-bench/apps/frappe/frappe/model/base_document.py", line 70, in get_controller
    site_controllers[doctype] = import_controller(doctype)
  File "/home/frappe/frappe-bench/apps/frappe/frappe/model/base_document.py", line 81, in import_controller
    doctype_info = frappe.db.get_value("DocType", doctype, fieldname="*")
  File "/home/frappe/frappe-bench/apps/frappe/frappe/database/database.py", line 519, in get_value
    result = self.get_values(
  File "/home/frappe/frappe-bench/apps/frappe/frappe/database/database.py", line 623, in get_values
    out = self._get_values_from_table(
  File "/home/frappe/frappe-bench/apps/frappe/frappe/database/database.py", line 896, in _get_values_from_table
    return query.run(as_dict=as_dict, debug=debug, update=update, run=run, pluck=pluck)
  File "/home/frappe/frappe-bench/apps/frappe/frappe/query_builder/utils.py", line 87, in execute_query
    result = frappe.db.sql(query, params, *args, **kwargs)  # nosemgrep
  File "/home/frappe/frappe-bench/apps/frappe/frappe/database/database.py", line 211, in sql
    self.connect()
  File "/home/frappe/frappe-bench/apps/frappe/frappe/database/database.py", line 117, in connect
    self._conn: "MariadbConnection" | "PostgresConnection" = self.get_connection()
  File "/home/frappe/frappe-bench/apps/frappe/frappe/database/mariadb/database.py", line 107, in get_connection
    conn = self._get_connection()
  File "/home/frappe/frappe-bench/apps/frappe/frappe/database/mariadb/database.py", line 113, in _get_connection
    return self.create_connection()
  File "/home/frappe/frappe-bench/apps/frappe/frappe/database/mariadb/database.py", line 116, in create_connection
    return pymysql.connect(**self.get_connection_settings())
  File "/home/frappe/frappe-bench/env/lib/python3.10/site-packages/pymysql/connections.py", line 358, in __init__
    self.connect()
  File "/home/frappe/frappe-bench/env/lib/python3.10/site-packages/pymysql/connections.py", line 711, in connect
    raise exc
pymysql.err.OperationalError: (2003, "Can't connect to MySQL server on '127.0.0.1' ([Errno 111] Connection refused)")
2024-07-19 12:04:20,577 ERROR frappe Could not take error snapshot: (2003, "Can't connect to MySQL server on '127.0.0.1' ([Errno 111] Connection refused)")
Site: erp.grupoatu.com
Form Dict: {}
Traceback (most recent call last):
  File "/home/frappe/frappe-bench/env/lib/python3.10/site-packages/pymysql/connections.py", line 644, in connect
    sock = socket.create_connection(
  File "/usr/lib/python3.10/socket.py", line 845, in create_connection
    raise err
  File "/usr/lib/python3.10/socket.py", line 833, in create_connection
    sock.connect(sa)
ConnectionRefusedError: [Errno 111] Connection refused

During handling of the above exception, another exception occurred:

Traceback (most recent call last):
  File "/home/frappe/frappe-bench/apps/frappe/frappe/website/serve.py", line 19, in get_response
    endpoint, renderer_instance = path_resolver.resolve()
  File "/home/frappe/frappe-bench/apps/frappe/frappe/website/path_resolver.py", line 38, in resolve
    resolve_redirect(self.path, request.query_string)
  File "/home/frappe/frappe-bench/apps/frappe/frappe/website/path_resolver.py", line 118, in resolve_redirect
    redirects += frappe.get_all("Website Route Redirect", ["source", "target"], order_by=None)
  File "/home/frappe/frappe-bench/apps/frappe/frappe/__init__.py", line 2050, in get_all
    return get_list(doctype, *args, **kwargs)
  File "/home/frappe/frappe-bench/apps/frappe/frappe/__init__.py", line 2025, in get_list
    return frappe.model.db_query.DatabaseQuery(doctype).execute(*args, **kwargs)
  File "/home/frappe/frappe-bench/apps/frappe/frappe/model/db_query.py", line 191, in execute
    result = self.build_and_run()
  File "/home/frappe/frappe-bench/apps/frappe/frappe/model/db_query.py", line 232, in build_and_run
    return frappe.db.sql(
  File "/home/frappe/frappe-bench/apps/frappe/frappe/database/database.py", line 211, in sql
    self.connect()
  File "/home/frappe/frappe-bench/apps/frappe/frappe/database/database.py", line 117, in connect
    self._conn: "MariadbConnection" | "PostgresConnection" = self.get_connection()
  File "/home/frappe/frappe-bench/apps/frappe/frappe/database/mariadb/database.py", line 107, in get_connection
    conn = self._get_connection()
  File "/home/frappe/frappe-bench/apps/frappe/frappe/database/mariadb/database.py", line 113, in _get_connection
    return self.create_connection()
  File "/home/frappe/frappe-bench/apps/frappe/frappe/database/mariadb/database.py", line 116, in create_connection
    return pymysql.connect(**self.get_connection_settings())
  File "/home/frappe/frappe-bench/env/lib/python3.10/site-packages/pymysql/connections.py", line 358, in __init__
    self.connect()
  File "/home/frappe/frappe-bench/env/lib/python3.10/site-packages/pymysql/connections.py", line 711, in connect
    raise exc
pymysql.err.OperationalError: (2003, "Can't connect to MySQL server on '127.0.0.1' ([Errno 111] Connection refused)")

During handling of the above exception, another exception occurred:

Traceback (most recent call last):
  File "/home/frappe/frappe-bench/env/lib/python3.10/site-packages/pymysql/connections.py", line 644, in connect
    sock = socket.create_connection(
  File "/usr/lib/python3.10/socket.py", line 845, in create_connection
    raise err
  File "/usr/lib/python3.10/socket.py", line 833, in create_connection
    sock.connect(sa)
ConnectionRefusedError: [Errno 111] Connection refused

During handling of the above exception, another exception occurred:

Traceback (most recent call last):
  File "/home/frappe/frappe-bench/apps/frappe/frappe/app.py", line 119, in application
    response = get_response()
  File "/home/frappe/frappe-bench/apps/frappe/frappe/website/serve.py", line 28, in get_response
    response = ErrorPage(exception=e).render()
  File "/home/frappe/frappe-bench/apps/frappe/frappe/website/page_renderers/template_page.py", line 84, in render
    html = self.get_html()
  File "/home/frappe/frappe-bench/apps/frappe/frappe/website/utils.py", line 523, in cache_html_decorator
    html = func(*args, **kwargs)
  File "/home/frappe/frappe-bench/apps/frappe/frappe/website/page_renderers/template_page.py", line 92, in get_html
    self.init_context()
  File "/home/frappe/frappe-bench/apps/frappe/frappe/website/page_renderers/error_page.py", line 14, in init_context
    super().init_context()
  File "/home/frappe/frappe-bench/apps/frappe/frappe/website/page_renderers/base_template_page.py", line 15, in init_context
    self.context.update(get_website_settings())
  File "/home/frappe/frappe-bench/apps/frappe/frappe/website/doctype/website_settings/website_settings.py", line 263, in get_website_settings
    context.boot = get_boot_data()
  File "/home/frappe/frappe-bench/apps/frappe/frappe/website/utils.py", line 179, in get_boot_data
    "user": frappe.db.get_value("User", frappe.session.user, "time_zone") or get_system_timezone(),
  File "/home/frappe/frappe-bench/apps/frappe/frappe/database/database.py", line 519, in get_value
    result = self.get_values(
  File "/home/frappe/frappe-bench/apps/frappe/frappe/database/database.py", line 623, in get_values
    out = self._get_values_from_table(
  File "/home/frappe/frappe-bench/apps/frappe/frappe/database/database.py", line 896, in _get_values_from_table
    return query.run(as_dict=as_dict, debug=debug, update=update, run=run, pluck=pluck)
  File "/home/frappe/frappe-bench/apps/frappe/frappe/query_builder/utils.py", line 87, in execute_query
    result = frappe.db.sql(query, params, *args, **kwargs)  # nosemgrep
  File "/home/frappe/frappe-bench/apps/frappe/frappe/database/database.py", line 211, in sql
    self.connect()
  File "/home/frappe/frappe-bench/apps/frappe/frappe/database/database.py", line 117, in connect
    self._conn: "MariadbConnection" | "PostgresConnection" = self.get_connection()
  File "/home/frappe/frappe-bench/apps/frappe/frappe/database/mariadb/database.py", line 107, in get_connection
    conn = self._get_connection()
  File "/home/frappe/frappe-bench/apps/frappe/frappe/database/mariadb/database.py", line 113, in _get_connection
    return self.create_connection()
  File "/home/frappe/frappe-bench/apps/frappe/frappe/database/mariadb/database.py", line 116, in create_connection
    return pymysql.connect(**self.get_connection_settings())
  File "/home/frappe/frappe-bench/env/lib/python3.10/site-packages/pymysql/connections.py", line 358, in __init__
    self.connect()
  File "/home/frappe/frappe-bench/env/lib/python3.10/site-packages/pymysql/connections.py", line 711, in connect
    raise exc
pymysql.err.OperationalError: (2003, "Can't connect to MySQL server on '127.0.0.1' ([Errno 111] Connection refused)")

During handling of the above exception, another exception occurred:

Traceback (most recent call last):
  File "/home/frappe/frappe-bench/env/lib/python3.10/site-packages/pymysql/connections.py", line 644, in connect
    sock = socket.create_connection(
  File "/usr/lib/python3.10/socket.py", line 845, in create_connection
    raise err
  File "/usr/lib/python3.10/socket.py", line 833, in create_connection
    sock.connect(sa)
ConnectionRefusedError: [Errno 111] Connection refused

During handling of the above exception, another exception occurred:

Traceback (most recent call last):
  File "/home/frappe/frappe-bench/apps/frappe/frappe/utils/error.py", line 86, in log_error_snapshot
    log_error(title=str(exception), defer_insert=True)
  File "/home/frappe/frappe-bench/apps/frappe/frappe/utils/error.py", line 61, in log_error
    error_log = frappe.get_doc(
  File "/home/frappe/frappe-bench/apps/frappe/frappe/__init__.py", line 1329, in get_doc
    doc = frappe.model.document.get_doc(*args, **kwargs)
  File "/home/frappe/frappe-bench/apps/frappe/frappe/model/document.py", line 83, in get_doc
    controller = get_controller(doctype)
  File "/home/frappe/frappe-bench/apps/frappe/frappe/model/base_document.py", line 70, in get_controller
    site_controllers[doctype] = import_controller(doctype)
  File "/home/frappe/frappe-bench/apps/frappe/frappe/model/base_document.py", line 81, in import_controller
    doctype_info = frappe.db.get_value("DocType", doctype, fieldname="*")
  File "/home/frappe/frappe-bench/apps/frappe/frappe/database/database.py", line 519, in get_value
    result = self.get_values(
  File "/home/frappe/frappe-bench/apps/frappe/frappe/database/database.py", line 623, in get_values
    out = self._get_values_from_table(
  File "/home/frappe/frappe-bench/apps/frappe/frappe/database/database.py", line 896, in _get_values_from_table
    return query.run(as_dict=as_dict, debug=debug, update=update, run=run, pluck=pluck)
  File "/home/frappe/frappe-bench/apps/frappe/frappe/query_builder/utils.py", line 87, in execute_query
    result = frappe.db.sql(query, params, *args, **kwargs)  # nosemgrep
  File "/home/frappe/frappe-bench/apps/frappe/frappe/database/database.py", line 211, in sql
    self.connect()
  File "/home/frappe/frappe-bench/apps/frappe/frappe/database/database.py", line 117, in connect
    self._conn: "MariadbConnection" | "PostgresConnection" = self.get_connection()
  File "/home/frappe/frappe-bench/apps/frappe/frappe/database/mariadb/database.py", line 107, in get_connection
    conn = self._get_connection()
  File "/home/frappe/frappe-bench/apps/frappe/frappe/database/mariadb/database.py", line 113, in _get_connection
    return self.create_connection()
  File "/home/frappe/frappe-bench/apps/frappe/frappe/database/mariadb/database.py", line 116, in create_connection
    return pymysql.connect(**self.get_connection_settings())
  File "/home/frappe/frappe-bench/env/lib/python3.10/site-packages/pymysql/connections.py", line 358, in __init__
    self.connect()
  File "/home/frappe/frappe-bench/env/lib/python3.10/site-packages/pymysql/connections.py", line 711, in connect
    raise exc
pymysql.err.OperationalError: (2003, "Can't connect to MySQL server on '127.0.0.1' ([Errno 111] Connection refused)")
