2024-07-19 12:00:42,429 ERROR frappe Could not take error snapshot: (0, '')
Site: erp.grupoatu.com
Form Dict: {'is_private': '1', 'folder': 'Home/Attachments', 'doctype': 'Room', 'docname': '300001327', 'cmd': 'upload_file'}
Traceback (most recent call last):
  File "/home/frappe/frappe-bench/apps/frappe/frappe/app.py", line 110, in application
    response = frappe.api.handle(request)
  File "/home/frappe/frappe-bench/apps/frappe/frappe/api/__init__.py", line 49, in handle
    data = endpoint(**arguments)
  File "/home/frappe/frappe-bench/apps/frappe/frappe/api/v1.py", line 36, in handle_rpc_call
    return frappe.handler.handle()
  File "/home/frappe/frappe-bench/apps/frappe/frappe/handler.py", line 49, in handle
    data = execute_cmd(cmd)
  File "/home/frappe/frappe-bench/apps/frappe/frappe/handler.py", line 85, in execute_cmd
    return frappe.call(method, **frappe.form_dict)
  File "/home/frappe/frappe-bench/apps/frappe/frappe/__init__.py", line 1761, in call
    return fn(*args, **newargs)
  File "/home/frappe/frappe-bench/apps/frappe/frappe/utils/typing_validations.py", line 31, in wrapper
    return func(*args, **kwargs)
  File "/home/frappe/frappe-bench/apps/frappe/frappe/handler.py", line 235, in upload_file
    return frappe.get_doc(
  File "/home/frappe/frappe-bench/apps/frappe/frappe/model/document.py", line 337, in save
    return self._save(*args, **kwargs)
  File "/home/frappe/frappe-bench/apps/frappe/frappe/model/document.py", line 359, in _save
    return self.insert()
  File "/home/frappe/frappe-bench/apps/frappe/frappe/model/document.py", line 285, in insert
    self.run_method("before_insert")
  File "/home/frappe/frappe-bench/apps/frappe/frappe/model/document.py", line 962, in run_method
    out = Document.hook(fn)(self, *args, **kwargs)
  File "/home/frappe/frappe-bench/apps/frappe/frappe/model/document.py", line 1322, in composer
    return composed(self, method, *args, **kwargs)
  File "/home/frappe/frappe-bench/apps/frappe/frappe/model/document.py", line 1304, in runner
    add_to_return_value(self, fn(self, *args, **kwargs))
  File "/home/frappe/frappe-bench/apps/frappe/frappe/model/document.py", line 959, in fn
    return method_object(*args, **kwargs)
  File "/home/frappe/frappe-bench/apps/frappe/frappe/core/doctype/file/file.py", line 103, in before_insert
    self.save_file(content=self.get_content())
  File "/home/frappe/frappe-bench/apps/frappe/frappe/core/doctype/file/file.py", line 638, in save_file
    duplicate_file = frappe.get_value(
  File "/home/frappe/frappe-bench/apps/frappe/frappe/__init__.py", line 2065, in get_value
    return db.get_value(*args, **kwargs)
  File "/home/frappe/frappe-bench/apps/frappe/frappe/database/database.py", line 519, in get_value
    result = self.get_values(
  File "/home/frappe/frappe-bench/apps/frappe/frappe/database/database.py", line 623, in get_values
    out = self._get_values_from_table(
  File "/home/frappe/frappe-bench/apps/frappe/frappe/database/database.py", line 896, in _get_values_from_table
    return query.run(as_dict=as_dict, debug=debug, update=update, run=run, pluck=pluck)
  File "/home/frappe/frappe-bench/apps/frappe/frappe/query_builder/utils.py", line 87, in execute_query
    result = frappe.db.sql(query, params, *args, **kwargs)  # nosemgrep
  File "/home/frappe/frappe-bench/apps/frappe/frappe/database/database.py", line 234, in sql
    self._cursor.execute(query, values)
  File "/home/frappe/frappe-bench/env/lib/python3.10/site-packages/pymysql/cursors.py", line 153, in execute
    result = self._query(query)
  File "/home/frappe/frappe-bench/env/lib/python3.10/site-packages/pymysql/cursors.py", line 322, in _query
    conn.query(q)
  File "/home/frappe/frappe-bench/env/lib/python3.10/site-packages/pymysql/connections.py", line 558, in query
    self._affected_rows = self._read_query_result(unbuffered=unbuffered)
  File "/home/frappe/frappe-bench/env/lib/python3.10/site-packages/pymysql/connections.py", line 822, in _read_query_result
    result.read()
  File "/home/frappe/frappe-bench/env/lib/python3.10/site-packages/pymysql/connections.py", line 1200, in read
    first_packet = self.connection._read_packet()
  File "/home/frappe/frappe-bench/env/lib/python3.10/site-packages/pymysql/connections.py", line 739, in _read_packet
    packet_header = self._read_bytes(4)
  File "/home/frappe/frappe-bench/env/lib/python3.10/site-packages/pymysql/connections.py", line 795, in _read_bytes
    raise err.OperationalError(
pymysql.err.OperationalError: (2013, 'Lost connection to MySQL server during query')

During handling of the above exception, another exception occurred:

Traceback (most recent call last):
  File "/home/frappe/frappe-bench/apps/frappe/frappe/utils/error.py", line 86, in log_error_snapshot
    log_error(title=str(exception), defer_insert=True)
  File "/home/frappe/frappe-bench/apps/frappe/frappe/utils/error.py", line 61, in log_error
    error_log = frappe.get_doc(
  File "/home/frappe/frappe-bench/apps/frappe/frappe/__init__.py", line 1329, in get_doc
    doc = frappe.model.document.get_doc(*args, **kwargs)
  File "/home/frappe/frappe-bench/apps/frappe/frappe/model/document.py", line 83, in get_doc
    controller = get_controller(doctype)
  File "/home/frappe/frappe-bench/apps/frappe/frappe/model/base_document.py", line 70, in get_controller
    site_controllers[doctype] = import_controller(doctype)
  File "/home/frappe/frappe-bench/apps/frappe/frappe/model/base_document.py", line 81, in import_controller
    doctype_info = frappe.db.get_value("DocType", doctype, fieldname="*")
  File "/home/frappe/frappe-bench/apps/frappe/frappe/database/database.py", line 519, in get_value
    result = self.get_values(
  File "/home/frappe/frappe-bench/apps/frappe/frappe/database/database.py", line 623, in get_values
    out = self._get_values_from_table(
  File "/home/frappe/frappe-bench/apps/frappe/frappe/database/database.py", line 896, in _get_values_from_table
    return query.run(as_dict=as_dict, debug=debug, update=update, run=run, pluck=pluck)
  File "/home/frappe/frappe-bench/apps/frappe/frappe/query_builder/utils.py", line 87, in execute_query
    result = frappe.db.sql(query, params, *args, **kwargs)  # nosemgrep
  File "/home/frappe/frappe-bench/apps/frappe/frappe/database/database.py", line 234, in sql
    self._cursor.execute(query, values)
  File "/home/frappe/frappe-bench/env/lib/python3.10/site-packages/pymysql/cursors.py", line 153, in execute
    result = self._query(query)
  File "/home/frappe/frappe-bench/env/lib/python3.10/site-packages/pymysql/cursors.py", line 322, in _query
    conn.query(q)
  File "/home/frappe/frappe-bench/env/lib/python3.10/site-packages/pymysql/connections.py", line 557, in query
    self._execute_command(COMMAND.COM_QUERY, sql)
  File "/home/frappe/frappe-bench/env/lib/python3.10/site-packages/pymysql/connections.py", line 840, in _execute_command
    raise err.InterfaceError(0, "")
pymysql.err.InterfaceError: (0, '')
2024-07-19 12:00:42,487 ERROR frappe Could not take error snapshot: (0, '')
Site: erp.grupoatu.com
Form Dict: {'is_private': '1', 'folder': 'Home/Attachments', 'doctype': 'Room', 'docname': '300001327', 'cmd': 'upload_file'}
Traceback (most recent call last):
  File "/home/frappe/frappe-bench/apps/frappe/frappe/app.py", line 110, in application
    response = frappe.api.handle(request)
  File "/home/frappe/frappe-bench/apps/frappe/frappe/api/__init__.py", line 49, in handle
    data = endpoint(**arguments)
  File "/home/frappe/frappe-bench/apps/frappe/frappe/api/v1.py", line 36, in handle_rpc_call
    return frappe.handler.handle()
  File "/home/frappe/frappe-bench/apps/frappe/frappe/handler.py", line 49, in handle
    data = execute_cmd(cmd)
  File "/home/frappe/frappe-bench/apps/frappe/frappe/handler.py", line 85, in execute_cmd
    return frappe.call(method, **frappe.form_dict)
  File "/home/frappe/frappe-bench/apps/frappe/frappe/__init__.py", line 1761, in call
    return fn(*args, **newargs)
  File "/home/frappe/frappe-bench/apps/frappe/frappe/utils/typing_validations.py", line 31, in wrapper
    return func(*args, **kwargs)
  File "/home/frappe/frappe-bench/apps/frappe/frappe/handler.py", line 235, in upload_file
    return frappe.get_doc(
  File "/home/frappe/frappe-bench/apps/frappe/frappe/model/document.py", line 337, in save
    return self._save(*args, **kwargs)
  File "/home/frappe/frappe-bench/apps/frappe/frappe/model/document.py", line 359, in _save
    return self.insert()
  File "/home/frappe/frappe-bench/apps/frappe/frappe/model/document.py", line 285, in insert
    self.run_method("before_insert")
  File "/home/frappe/frappe-bench/apps/frappe/frappe/model/document.py", line 962, in run_method
    out = Document.hook(fn)(self, *args, **kwargs)
  File "/home/frappe/frappe-bench/apps/frappe/frappe/model/document.py", line 1322, in composer
    return composed(self, method, *args, **kwargs)
  File "/home/frappe/frappe-bench/apps/frappe/frappe/model/document.py", line 1304, in runner
    add_to_return_value(self, fn(self, *args, **kwargs))
  File "/home/frappe/frappe-bench/apps/frappe/frappe/model/document.py", line 959, in fn
    return method_object(*args, **kwargs)
  File "/home/frappe/frappe-bench/apps/frappe/frappe/core/doctype/file/file.py", line 103, in before_insert
    self.save_file(content=self.get_content())
  File "/home/frappe/frappe-bench/apps/frappe/frappe/core/doctype/file/file.py", line 638, in save_file
    duplicate_file = frappe.get_value(
  File "/home/frappe/frappe-bench/apps/frappe/frappe/__init__.py", line 2065, in get_value
    return db.get_value(*args, **kwargs)
  File "/home/frappe/frappe-bench/apps/frappe/frappe/database/database.py", line 519, in get_value
    result = self.get_values(
  File "/home/frappe/frappe-bench/apps/frappe/frappe/database/database.py", line 623, in get_values
    out = self._get_values_from_table(
  File "/home/frappe/frappe-bench/apps/frappe/frappe/database/database.py", line 896, in _get_values_from_table
    return query.run(as_dict=as_dict, debug=debug, update=update, run=run, pluck=pluck)
  File "/home/frappe/frappe-bench/apps/frappe/frappe/query_builder/utils.py", line 87, in execute_query
    result = frappe.db.sql(query, params, *args, **kwargs)  # nosemgrep
  File "/home/frappe/frappe-bench/apps/frappe/frappe/database/database.py", line 234, in sql
    self._cursor.execute(query, values)
  File "/home/frappe/frappe-bench/env/lib/python3.10/site-packages/pymysql/cursors.py", line 153, in execute
    result = self._query(query)
  File "/home/frappe/frappe-bench/env/lib/python3.10/site-packages/pymysql/cursors.py", line 322, in _query
    conn.query(q)
  File "/home/frappe/frappe-bench/env/lib/python3.10/site-packages/pymysql/connections.py", line 558, in query
    self._affected_rows = self._read_query_result(unbuffered=unbuffered)
  File "/home/frappe/frappe-bench/env/lib/python3.10/site-packages/pymysql/connections.py", line 822, in _read_query_result
    result.read()
  File "/home/frappe/frappe-bench/env/lib/python3.10/site-packages/pymysql/connections.py", line 1200, in read
    first_packet = self.connection._read_packet()
  File "/home/frappe/frappe-bench/env/lib/python3.10/site-packages/pymysql/connections.py", line 739, in _read_packet
    packet_header = self._read_bytes(4)
  File "/home/frappe/frappe-bench/env/lib/python3.10/site-packages/pymysql/connections.py", line 795, in _read_bytes
    raise err.OperationalError(
pymysql.err.OperationalError: (2013, 'Lost connection to MySQL server during query')

During handling of the above exception, another exception occurred:

Traceback (most recent call last):
  File "/home/frappe/frappe-bench/apps/frappe/frappe/utils/error.py", line 86, in log_error_snapshot
    log_error(title=str(exception), defer_insert=True)
  File "/home/frappe/frappe-bench/apps/frappe/frappe/utils/error.py", line 61, in log_error
    error_log = frappe.get_doc(
  File "/home/frappe/frappe-bench/apps/frappe/frappe/__init__.py", line 1329, in get_doc
    doc = frappe.model.document.get_doc(*args, **kwargs)
  File "/home/frappe/frappe-bench/apps/frappe/frappe/model/document.py", line 83, in get_doc
    controller = get_controller(doctype)
  File "/home/frappe/frappe-bench/apps/frappe/frappe/model/base_document.py", line 70, in get_controller
    site_controllers[doctype] = import_controller(doctype)
  File "/home/frappe/frappe-bench/apps/frappe/frappe/model/base_document.py", line 81, in import_controller
    doctype_info = frappe.db.get_value("DocType", doctype, fieldname="*")
  File "/home/frappe/frappe-bench/apps/frappe/frappe/database/database.py", line 519, in get_value
    result = self.get_values(
  File "/home/frappe/frappe-bench/apps/frappe/frappe/database/database.py", line 623, in get_values
    out = self._get_values_from_table(
  File "/home/frappe/frappe-bench/apps/frappe/frappe/database/database.py", line 896, in _get_values_from_table
    return query.run(as_dict=as_dict, debug=debug, update=update, run=run, pluck=pluck)
  File "/home/frappe/frappe-bench/apps/frappe/frappe/query_builder/utils.py", line 87, in execute_query
    result = frappe.db.sql(query, params, *args, **kwargs)  # nosemgrep
  File "/home/frappe/frappe-bench/apps/frappe/frappe/database/database.py", line 234, in sql
    self._cursor.execute(query, values)
  File "/home/frappe/frappe-bench/env/lib/python3.10/site-packages/pymysql/cursors.py", line 153, in execute
    result = self._query(query)
  File "/home/frappe/frappe-bench/env/lib/python3.10/site-packages/pymysql/cursors.py", line 322, in _query
    conn.query(q)
  File "/home/frappe/frappe-bench/env/lib/python3.10/site-packages/pymysql/connections.py", line 557, in query
    self._execute_command(COMMAND.COM_QUERY, sql)
  File "/home/frappe/frappe-bench/env/lib/python3.10/site-packages/pymysql/connections.py", line 840, in _execute_command
    raise err.InterfaceError(0, "")
pymysql.err.InterfaceError: (0, '')
2024-07-19 12:00:44,528 ERROR frappe Could not take error snapshot: (2003, "Can't connect to MySQL server on '127.0.0.1' ([Errno 111] Connection refused)")
Site: erp.grupoatu.com
Form Dict: {'is_private': '1', 'folder': 'Home/Attachments', 'doctype': 'Room', 'docname': '300001327', 'optimize': 'true', 'cmd': 'upload_file'}
Traceback (most recent call last):
  File "/home/frappe/frappe-bench/env/lib/python3.10/site-packages/pymysql/connections.py", line 644, in connect
    sock = socket.create_connection(
  File "/usr/lib/python3.10/socket.py", line 845, in create_connection
    raise err
  File "/usr/lib/python3.10/socket.py", line 833, in create_connection
    sock.connect(sa)
ConnectionRefusedError: [Errno 111] Connection refused

During handling of the above exception, another exception occurred:

Traceback (most recent call last):
  File "/home/frappe/frappe-bench/apps/frappe/frappe/app.py", line 110, in application
    response = frappe.api.handle(request)
  File "/home/frappe/frappe-bench/apps/frappe/frappe/api/__init__.py", line 49, in handle
    data = endpoint(**arguments)
  File "/home/frappe/frappe-bench/apps/frappe/frappe/api/v1.py", line 36, in handle_rpc_call
    return frappe.handler.handle()
  File "/home/frappe/frappe-bench/apps/frappe/frappe/handler.py", line 49, in handle
    data = execute_cmd(cmd)
  File "/home/frappe/frappe-bench/apps/frappe/frappe/handler.py", line 85, in execute_cmd
    return frappe.call(method, **frappe.form_dict)
  File "/home/frappe/frappe-bench/apps/frappe/frappe/__init__.py", line 1761, in call
    return fn(*args, **newargs)
  File "/home/frappe/frappe-bench/apps/frappe/frappe/utils/typing_validations.py", line 31, in wrapper
    return func(*args, **kwargs)
  File "/home/frappe/frappe-bench/apps/frappe/frappe/handler.py", line 178, in upload_file
    user: "User" = frappe.get_doc("User", frappe.session.user)
  File "/home/frappe/frappe-bench/apps/frappe/frappe/__init__.py", line 1329, in get_doc
    doc = frappe.model.document.get_doc(*args, **kwargs)
  File "/home/frappe/frappe-bench/apps/frappe/frappe/model/document.py", line 85, in get_doc
    return controller(*args, **kwargs)
  File "/home/frappe/frappe-bench/apps/frappe/frappe/model/document.py", line 126, in __init__
    self.load_from_db()
  File "/home/frappe/frappe-bench/apps/frappe/frappe/model/document.py", line 167, in load_from_db
    d = frappe.db.get_value(
  File "/home/frappe/frappe-bench/apps/frappe/frappe/database/database.py", line 519, in get_value
    result = self.get_values(
  File "/home/frappe/frappe-bench/apps/frappe/frappe/database/database.py", line 623, in get_values
    out = self._get_values_from_table(
  File "/home/frappe/frappe-bench/apps/frappe/frappe/database/database.py", line 896, in _get_values_from_table
    return query.run(as_dict=as_dict, debug=debug, update=update, run=run, pluck=pluck)
  File "/home/frappe/frappe-bench/apps/frappe/frappe/query_builder/utils.py", line 87, in execute_query
    result = frappe.db.sql(query, params, *args, **kwargs)  # nosemgrep
  File "/home/frappe/frappe-bench/apps/frappe/frappe/database/database.py", line 211, in sql
    self.connect()
  File "/home/frappe/frappe-bench/apps/frappe/frappe/database/database.py", line 117, in connect
    self._conn: "MariadbConnection" | "PostgresConnection" = self.get_connection()
  File "/home/frappe/frappe-bench/apps/frappe/frappe/database/mariadb/database.py", line 107, in get_connection
    conn = self._get_connection()
  File "/home/frappe/frappe-bench/apps/frappe/frappe/database/mariadb/database.py", line 113, in _get_connection
    return self.create_connection()
  File "/home/frappe/frappe-bench/apps/frappe/frappe/database/mariadb/database.py", line 116, in create_connection
    return pymysql.connect(**self.get_connection_settings())
  File "/home/frappe/frappe-bench/env/lib/python3.10/site-packages/pymysql/connections.py", line 358, in __init__
    self.connect()
  File "/home/frappe/frappe-bench/env/lib/python3.10/site-packages/pymysql/connections.py", line 711, in connect
    raise exc
pymysql.err.OperationalError: (2003, "Can't connect to MySQL server on '127.0.0.1' ([Errno 111] Connection refused)")

During handling of the above exception, another exception occurred:

Traceback (most recent call last):
  File "/home/frappe/frappe-bench/env/lib/python3.10/site-packages/pymysql/connections.py", line 644, in connect
    sock = socket.create_connection(
  File "/usr/lib/python3.10/socket.py", line 845, in create_connection
    raise err
  File "/usr/lib/python3.10/socket.py", line 833, in create_connection
    sock.connect(sa)
ConnectionRefusedError: [Errno 111] Connection refused

During handling of the above exception, another exception occurred:

Traceback (most recent call last):
  File "/home/frappe/frappe-bench/apps/frappe/frappe/utils/error.py", line 86, in log_error_snapshot
    log_error(title=str(exception), defer_insert=True)
  File "/home/frappe/frappe-bench/apps/frappe/frappe/utils/error.py", line 61, in log_error
    error_log = frappe.get_doc(
  File "/home/frappe/frappe-bench/apps/frappe/frappe/__init__.py", line 1329, in get_doc
    doc = frappe.model.document.get_doc(*args, **kwargs)
  File "/home/frappe/frappe-bench/apps/frappe/frappe/model/document.py", line 83, in get_doc
    controller = get_controller(doctype)
  File "/home/frappe/frappe-bench/apps/frappe/frappe/model/base_document.py", line 70, in get_controller
    site_controllers[doctype] = import_controller(doctype)
  File "/home/frappe/frappe-bench/apps/frappe/frappe/model/base_document.py", line 81, in import_controller
    doctype_info = frappe.db.get_value("DocType", doctype, fieldname="*")
  File "/home/frappe/frappe-bench/apps/frappe/frappe/database/database.py", line 519, in get_value
    result = self.get_values(
  File "/home/frappe/frappe-bench/apps/frappe/frappe/database/database.py", line 623, in get_values
    out = self._get_values_from_table(
  File "/home/frappe/frappe-bench/apps/frappe/frappe/database/database.py", line 896, in _get_values_from_table
    return query.run(as_dict=as_dict, debug=debug, update=update, run=run, pluck=pluck)
  File "/home/frappe/frappe-bench/apps/frappe/frappe/query_builder/utils.py", line 87, in execute_query
    result = frappe.db.sql(query, params, *args, **kwargs)  # nosemgrep
  File "/home/frappe/frappe-bench/apps/frappe/frappe/database/database.py", line 211, in sql
    self.connect()
  File "/home/frappe/frappe-bench/apps/frappe/frappe/database/database.py", line 117, in connect
    self._conn: "MariadbConnection" | "PostgresConnection" = self.get_connection()
  File "/home/frappe/frappe-bench/apps/frappe/frappe/database/mariadb/database.py", line 107, in get_connection
    conn = self._get_connection()
  File "/home/frappe/frappe-bench/apps/frappe/frappe/database/mariadb/database.py", line 113, in _get_connection
    return self.create_connection()
  File "/home/frappe/frappe-bench/apps/frappe/frappe/database/mariadb/database.py", line 116, in create_connection
    return pymysql.connect(**self.get_connection_settings())
  File "/home/frappe/frappe-bench/env/lib/python3.10/site-packages/pymysql/connections.py", line 358, in __init__
    self.connect()
  File "/home/frappe/frappe-bench/env/lib/python3.10/site-packages/pymysql/connections.py", line 711, in connect
    raise exc
pymysql.err.OperationalError: (2003, "Can't connect to MySQL server on '127.0.0.1' ([Errno 111] Connection refused)")
2024-07-19 12:00:53,920 ERROR frappe Could not take error snapshot: (2003, "Can't connect to MySQL server on '127.0.0.1' ([Errno 111] Connection refused)")
Site: erp.grupoatu.com
Form Dict: {'doc': '{"name":"Total Outgoing Bills","owner":"Administrator","creation":"2020-07-17 11:25:34.725416","modified":"2020-07-22 13:07:19.633101","modified_by":"Administrator","docstatus":0,"idx":0,"is_standard":1,"module":"Accounts","label":"Total Outgoing Bills","type":"Document Type","function":"Sum","aggregate_function_based_on":"base_net_total","document_type":"Sales Invoice","is_public":1,"show_percentage_stats":1,"stats_time_interval":"Monthly","filters_json":"[[\\"Sales Invoice\\",\\"docstatus\\",\\"=\\",\\"1\\",false],[\\"Sales Invoice\\",\\"posting_date\\",\\"Timespan\\",\\"this year\\",false]]","doctype":"Number Card","__last_sync_on":"2024-07-19T09:09:55.185Z"}', 'filters': '[["Sales Invoice","docstatus","=","1",false],["Sales Invoice","posting_date","Timespan","this year",false]]', 'cmd': 'frappe.desk.doctype.number_card.number_card.get_result'}
Traceback (most recent call last):
  File "/home/frappe/frappe-bench/env/lib/python3.10/site-packages/pymysql/connections.py", line 644, in connect
    sock = socket.create_connection(
  File "/usr/lib/python3.10/socket.py", line 845, in create_connection
    raise err
  File "/usr/lib/python3.10/socket.py", line 833, in create_connection
    sock.connect(sa)
ConnectionRefusedError: [Errno 111] Connection refused

During handling of the above exception, another exception occurred:

Traceback (most recent call last):
  File "/home/frappe/frappe-bench/apps/frappe/frappe/app.py", line 110, in application
    response = frappe.api.handle(request)
  File "/home/frappe/frappe-bench/apps/frappe/frappe/api/__init__.py", line 49, in handle
    data = endpoint(**arguments)
  File "/home/frappe/frappe-bench/apps/frappe/frappe/api/v1.py", line 36, in handle_rpc_call
    return frappe.handler.handle()
  File "/home/frappe/frappe-bench/apps/frappe/frappe/handler.py", line 49, in handle
    data = execute_cmd(cmd)
  File "/home/frappe/frappe-bench/apps/frappe/frappe/handler.py", line 85, in execute_cmd
    return frappe.call(method, **frappe.form_dict)
  File "/home/frappe/frappe-bench/apps/frappe/frappe/__init__.py", line 1761, in call
    return fn(*args, **newargs)
  File "/home/frappe/frappe-bench/apps/frappe/frappe/utils/typing_validations.py", line 31, in wrapper
    return func(*args, **kwargs)
  File "/home/frappe/frappe-bench/apps/frappe/frappe/desk/doctype/number_card/number_card.py", line 154, in get_result
    res = frappe.get_list(
  File "/home/frappe/frappe-bench/apps/frappe/frappe/__init__.py", line 2025, in get_list
    return frappe.model.db_query.DatabaseQuery(doctype).execute(*args, **kwargs)
  File "/home/frappe/frappe-bench/apps/frappe/frappe/model/db_query.py", line 191, in execute
    result = self.build_and_run()
  File "/home/frappe/frappe-bench/apps/frappe/frappe/model/db_query.py", line 232, in build_and_run
    return frappe.db.sql(
  File "/home/frappe/frappe-bench/apps/frappe/frappe/database/database.py", line 211, in sql
    self.connect()
  File "/home/frappe/frappe-bench/apps/frappe/frappe/database/database.py", line 117, in connect
    self._conn: "MariadbConnection" | "PostgresConnection" = self.get_connection()
  File "/home/frappe/frappe-bench/apps/frappe/frappe/database/mariadb/database.py", line 107, in get_connection
    conn = self._get_connection()
  File "/home/frappe/frappe-bench/apps/frappe/frappe/database/mariadb/database.py", line 113, in _get_connection
    return self.create_connection()
  File "/home/frappe/frappe-bench/apps/frappe/frappe/database/mariadb/database.py", line 116, in create_connection
    return pymysql.connect(**self.get_connection_settings())
  File "/home/frappe/frappe-bench/env/lib/python3.10/site-packages/pymysql/connections.py", line 358, in __init__
    self.connect()
  File "/home/frappe/frappe-bench/env/lib/python3.10/site-packages/pymysql/connections.py", line 711, in connect
    raise exc
pymysql.err.OperationalError: (2003, "Can't connect to MySQL server on '127.0.0.1' ([Errno 111] Connection refused)")

During handling of the above exception, another exception occurred:

Traceback (most recent call last):
  File "/home/frappe/frappe-bench/env/lib/python3.10/site-packages/pymysql/connections.py", line 644, in connect
    sock = socket.create_connection(
  File "/usr/lib/python3.10/socket.py", line 845, in create_connection
    raise err
  File "/usr/lib/python3.10/socket.py", line 833, in create_connection
    sock.connect(sa)
ConnectionRefusedError: [Errno 111] Connection refused

During handling of the above exception, another exception occurred:

Traceback (most recent call last):
  File "/home/frappe/frappe-bench/apps/frappe/frappe/utils/error.py", line 86, in log_error_snapshot
    log_error(title=str(exception), defer_insert=True)
  File "/home/frappe/frappe-bench/apps/frappe/frappe/utils/error.py", line 61, in log_error
    error_log = frappe.get_doc(
  File "/home/frappe/frappe-bench/apps/frappe/frappe/__init__.py", line 1329, in get_doc
    doc = frappe.model.document.get_doc(*args, **kwargs)
  File "/home/frappe/frappe-bench/apps/frappe/frappe/model/document.py", line 83, in get_doc
    controller = get_controller(doctype)
  File "/home/frappe/frappe-bench/apps/frappe/frappe/model/base_document.py", line 70, in get_controller
    site_controllers[doctype] = import_controller(doctype)
  File "/home/frappe/frappe-bench/apps/frappe/frappe/model/base_document.py", line 81, in import_controller
    doctype_info = frappe.db.get_value("DocType", doctype, fieldname="*")
  File "/home/frappe/frappe-bench/apps/frappe/frappe/database/database.py", line 519, in get_value
    result = self.get_values(
  File "/home/frappe/frappe-bench/apps/frappe/frappe/database/database.py", line 623, in get_values
    out = self._get_values_from_table(
  File "/home/frappe/frappe-bench/apps/frappe/frappe/database/database.py", line 896, in _get_values_from_table
    return query.run(as_dict=as_dict, debug=debug, update=update, run=run, pluck=pluck)
  File "/home/frappe/frappe-bench/apps/frappe/frappe/query_builder/utils.py", line 87, in execute_query
    result = frappe.db.sql(query, params, *args, **kwargs)  # nosemgrep
  File "/home/frappe/frappe-bench/apps/frappe/frappe/database/database.py", line 211, in sql
    self.connect()
  File "/home/frappe/frappe-bench/apps/frappe/frappe/database/database.py", line 117, in connect
    self._conn: "MariadbConnection" | "PostgresConnection" = self.get_connection()
  File "/home/frappe/frappe-bench/apps/frappe/frappe/database/mariadb/database.py", line 107, in get_connection
    conn = self._get_connection()
  File "/home/frappe/frappe-bench/apps/frappe/frappe/database/mariadb/database.py", line 113, in _get_connection
    return self.create_connection()
  File "/home/frappe/frappe-bench/apps/frappe/frappe/database/mariadb/database.py", line 116, in create_connection
    return pymysql.connect(**self.get_connection_settings())
  File "/home/frappe/frappe-bench/env/lib/python3.10/site-packages/pymysql/connections.py", line 358, in __init__
    self.connect()
  File "/home/frappe/frappe-bench/env/lib/python3.10/site-packages/pymysql/connections.py", line 711, in connect
    raise exc
pymysql.err.OperationalError: (2003, "Can't connect to MySQL server on '127.0.0.1' ([Errno 111] Connection refused)")
2024-07-19 12:00:53,989 ERROR frappe Could not take error snapshot: (2003, "Can't connect to MySQL server on '127.0.0.1' ([Errno 111] Connection refused)")
Site: erp.grupoatu.com
Form Dict: {'report_name': 'Profit and Loss Statement', 'filters': '{"filter_based_on":"Fiscal Year","period_start_date":"2020-04-01","period_end_date":"2021-03-31","periodicity":"Yearly","include_default_book_entries":1,"company":"Grupo ATU","from_fiscal_year":"","to_fiscal_year":""}', 'ignore_prepared_report': '1', 'cmd': 'frappe.desk.query_report.run'}
Traceback (most recent call last):
  File "/home/frappe/frappe-bench/env/lib/python3.10/site-packages/pymysql/connections.py", line 644, in connect
    sock = socket.create_connection(
  File "/usr/lib/python3.10/socket.py", line 845, in create_connection
    raise err
  File "/usr/lib/python3.10/socket.py", line 833, in create_connection
    sock.connect(sa)
ConnectionRefusedError: [Errno 111] Connection refused

During handling of the above exception, another exception occurred:

Traceback (most recent call last):
  File "/home/frappe/frappe-bench/apps/frappe/frappe/app.py", line 110, in application
    response = frappe.api.handle(request)
  File "/home/frappe/frappe-bench/apps/frappe/frappe/api/__init__.py", line 49, in handle
    data = endpoint(**arguments)
  File "/home/frappe/frappe-bench/apps/frappe/frappe/api/v1.py", line 36, in handle_rpc_call
    return frappe.handler.handle()
  File "/home/frappe/frappe-bench/apps/frappe/frappe/handler.py", line 49, in handle
    data = execute_cmd(cmd)
  File "/home/frappe/frappe-bench/apps/frappe/frappe/handler.py", line 85, in execute_cmd
    return frappe.call(method, **frappe.form_dict)
  File "/home/frappe/frappe-bench/apps/frappe/frappe/__init__.py", line 1761, in call
    return fn(*args, **newargs)
  File "/home/frappe/frappe-bench/apps/frappe/frappe/utils/typing_validations.py", line 31, in wrapper
    return func(*args, **kwargs)
  File "/home/frappe/frappe-bench/apps/frappe/frappe/__init__.py", line 921, in wrapper_fn
    retval = fn(*args, **get_newargs(fn, kwargs))
  File "/home/frappe/frappe-bench/apps/frappe/frappe/desk/query_report.py", line 195, in run
    report = get_report_doc(report_name)
  File "/home/frappe/frappe-bench/apps/frappe/frappe/desk/query_report.py", line 22, in get_report_doc
    doc = frappe.get_doc("Report", report_name)
  File "/home/frappe/frappe-bench/apps/frappe/frappe/__init__.py", line 1329, in get_doc
    doc = frappe.model.document.get_doc(*args, **kwargs)
  File "/home/frappe/frappe-bench/apps/frappe/frappe/model/document.py", line 85, in get_doc
    return controller(*args, **kwargs)
  File "/home/frappe/frappe-bench/apps/frappe/frappe/model/document.py", line 126, in __init__
    self.load_from_db()
  File "/home/frappe/frappe-bench/apps/frappe/frappe/model/document.py", line 167, in load_from_db
    d = frappe.db.get_value(
  File "/home/frappe/frappe-bench/apps/frappe/frappe/database/database.py", line 519, in get_value
    result = self.get_values(
  File "/home/frappe/frappe-bench/apps/frappe/frappe/database/database.py", line 623, in get_values
    out = self._get_values_from_table(
  File "/home/frappe/frappe-bench/apps/frappe/frappe/database/database.py", line 896, in _get_values_from_table
    return query.run(as_dict=as_dict, debug=debug, update=update, run=run, pluck=pluck)
  File "/home/frappe/frappe-bench/apps/frappe/frappe/query_builder/utils.py", line 87, in execute_query
    result = frappe.db.sql(query, params, *args, **kwargs)  # nosemgrep
  File "/home/frappe/frappe-bench/apps/frappe/frappe/database/database.py", line 211, in sql
    self.connect()
  File "/home/frappe/frappe-bench/apps/frappe/frappe/database/database.py", line 117, in connect
    self._conn: "MariadbConnection" | "PostgresConnection" = self.get_connection()
  File "/home/frappe/frappe-bench/apps/frappe/frappe/database/mariadb/database.py", line 107, in get_connection
    conn = self._get_connection()
  File "/home/frappe/frappe-bench/apps/frappe/frappe/database/mariadb/database.py", line 113, in _get_connection
    return self.create_connection()
  File "/home/frappe/frappe-bench/apps/frappe/frappe/database/mariadb/database.py", line 116, in create_connection
    return pymysql.connect(**self.get_connection_settings())
  File "/home/frappe/frappe-bench/env/lib/python3.10/site-packages/pymysql/connections.py", line 358, in __init__
    self.connect()
  File "/home/frappe/frappe-bench/env/lib/python3.10/site-packages/pymysql/connections.py", line 711, in connect
    raise exc
pymysql.err.OperationalError: (2003, "Can't connect to MySQL server on '127.0.0.1' ([Errno 111] Connection refused)")

During handling of the above exception, another exception occurred:

Traceback (most recent call last):
  File "/home/frappe/frappe-bench/env/lib/python3.10/site-packages/pymysql/connections.py", line 644, in connect
    sock = socket.create_connection(
  File "/usr/lib/python3.10/socket.py", line 845, in create_connection
    raise err
  File "/usr/lib/python3.10/socket.py", line 833, in create_connection
    sock.connect(sa)
ConnectionRefusedError: [Errno 111] Connection refused

During handling of the above exception, another exception occurred:

Traceback (most recent call last):
  File "/home/frappe/frappe-bench/apps/frappe/frappe/utils/error.py", line 86, in log_error_snapshot
    log_error(title=str(exception), defer_insert=True)
  File "/home/frappe/frappe-bench/apps/frappe/frappe/utils/error.py", line 61, in log_error
    error_log = frappe.get_doc(
  File "/home/frappe/frappe-bench/apps/frappe/frappe/__init__.py", line 1329, in get_doc
    doc = frappe.model.document.get_doc(*args, **kwargs)
  File "/home/frappe/frappe-bench/apps/frappe/frappe/model/document.py", line 83, in get_doc
    controller = get_controller(doctype)
  File "/home/frappe/frappe-bench/apps/frappe/frappe/model/base_document.py", line 70, in get_controller
    site_controllers[doctype] = import_controller(doctype)
  File "/home/frappe/frappe-bench/apps/frappe/frappe/model/base_document.py", line 81, in import_controller
    doctype_info = frappe.db.get_value("DocType", doctype, fieldname="*")
  File "/home/frappe/frappe-bench/apps/frappe/frappe/database/database.py", line 519, in get_value
    result = self.get_values(
  File "/home/frappe/frappe-bench/apps/frappe/frappe/database/database.py", line 623, in get_values
    out = self._get_values_from_table(
  File "/home/frappe/frappe-bench/apps/frappe/frappe/database/database.py", line 896, in _get_values_from_table
    return query.run(as_dict=as_dict, debug=debug, update=update, run=run, pluck=pluck)
  File "/home/frappe/frappe-bench/apps/frappe/frappe/query_builder/utils.py", line 87, in execute_query
    result = frappe.db.sql(query, params, *args, **kwargs)  # nosemgrep
  File "/home/frappe/frappe-bench/apps/frappe/frappe/database/database.py", line 211, in sql
    self.connect()
  File "/home/frappe/frappe-bench/apps/frappe/frappe/database/database.py", line 117, in connect
    self._conn: "MariadbConnection" | "PostgresConnection" = self.get_connection()
  File "/home/frappe/frappe-bench/apps/frappe/frappe/database/mariadb/database.py", line 107, in get_connection
    conn = self._get_connection()
  File "/home/frappe/frappe-bench/apps/frappe/frappe/database/mariadb/database.py", line 113, in _get_connection
    return self.create_connection()
  File "/home/frappe/frappe-bench/apps/frappe/frappe/database/mariadb/database.py", line 116, in create_connection
    return pymysql.connect(**self.get_connection_settings())
  File "/home/frappe/frappe-bench/env/lib/python3.10/site-packages/pymysql/connections.py", line 358, in __init__
    self.connect()
  File "/home/frappe/frappe-bench/env/lib/python3.10/site-packages/pymysql/connections.py", line 711, in connect
    raise exc
pymysql.err.OperationalError: (2003, "Can't connect to MySQL server on '127.0.0.1' ([Errno 111] Connection refused)")
2024-07-19 12:00:53,994 ERROR frappe Could not take error snapshot: (2003, "Can't connect to MySQL server on '127.0.0.1' ([Errno 111] Connection refused)")
Site: erp.grupoatu.com
Form Dict: {'doc': '{"name":"Total Incoming Payment","owner":"Administrator","creation":"2020-07-17 11:25:34.673195","modified":"2020-07-22 13:06:20.237689","modified_by":"Administrator","docstatus":0,"idx":0,"is_standard":1,"module":"Accounts","label":"Total Incoming Payment","type":"Document Type","function":"Sum","aggregate_function_based_on":"base_received_amount","document_type":"Payment Entry","is_public":1,"show_percentage_stats":1,"stats_time_interval":"Monthly","filters_json":"[[\\"Payment Entry\\",\\"docstatus\\",\\"=\\",\\"1\\",false],[\\"Payment Entry\\",\\"posting_date\\",\\"Timespan\\",\\"this year\\",false],[\\"Payment Entry\\",\\"payment_type\\",\\"=\\",\\"Receive\\",false]]","doctype":"Number Card","__last_sync_on":"2024-07-19T09:09:55.120Z"}', 'filters': '[["Payment Entry","docstatus","=","1",false],["Payment Entry","posting_date","Timespan","this year",false],["Payment Entry","payment_type","=","Receive",false]]', 'cmd': 'frappe.desk.doctype.number_card.number_card.get_result'}
Traceback (most recent call last):
  File "/home/frappe/frappe-bench/env/lib/python3.10/site-packages/pymysql/connections.py", line 644, in connect
    sock = socket.create_connection(
  File "/usr/lib/python3.10/socket.py", line 845, in create_connection
    raise err
  File "/usr/lib/python3.10/socket.py", line 833, in create_connection
    sock.connect(sa)
ConnectionRefusedError: [Errno 111] Connection refused

During handling of the above exception, another exception occurred:

Traceback (most recent call last):
  File "/home/frappe/frappe-bench/apps/frappe/frappe/app.py", line 110, in application
    response = frappe.api.handle(request)
  File "/home/frappe/frappe-bench/apps/frappe/frappe/api/__init__.py", line 49, in handle
    data = endpoint(**arguments)
  File "/home/frappe/frappe-bench/apps/frappe/frappe/api/v1.py", line 36, in handle_rpc_call
    return frappe.handler.handle()
  File "/home/frappe/frappe-bench/apps/frappe/frappe/handler.py", line 49, in handle
    data = execute_cmd(cmd)
  File "/home/frappe/frappe-bench/apps/frappe/frappe/handler.py", line 85, in execute_cmd
    return frappe.call(method, **frappe.form_dict)
  File "/home/frappe/frappe-bench/apps/frappe/frappe/__init__.py", line 1761, in call
    return fn(*args, **newargs)
  File "/home/frappe/frappe-bench/apps/frappe/frappe/utils/typing_validations.py", line 31, in wrapper
    return func(*args, **kwargs)
  File "/home/frappe/frappe-bench/apps/frappe/frappe/desk/doctype/number_card/number_card.py", line 154, in get_result
    res = frappe.get_list(
  File "/home/frappe/frappe-bench/apps/frappe/frappe/__init__.py", line 2025, in get_list
    return frappe.model.db_query.DatabaseQuery(doctype).execute(*args, **kwargs)
  File "/home/frappe/frappe-bench/apps/frappe/frappe/model/db_query.py", line 191, in execute
    result = self.build_and_run()
  File "/home/frappe/frappe-bench/apps/frappe/frappe/model/db_query.py", line 232, in build_and_run
    return frappe.db.sql(
  File "/home/frappe/frappe-bench/apps/frappe/frappe/database/database.py", line 211, in sql
    self.connect()
  File "/home/frappe/frappe-bench/apps/frappe/frappe/database/database.py", line 117, in connect
    self._conn: "MariadbConnection" | "PostgresConnection" = self.get_connection()
  File "/home/frappe/frappe-bench/apps/frappe/frappe/database/mariadb/database.py", line 107, in get_connection
    conn = self._get_connection()
  File "/home/frappe/frappe-bench/apps/frappe/frappe/database/mariadb/database.py", line 113, in _get_connection
    return self.create_connection()
  File "/home/frappe/frappe-bench/apps/frappe/frappe/database/mariadb/database.py", line 116, in create_connection
    return pymysql.connect(**self.get_connection_settings())
  File "/home/frappe/frappe-bench/env/lib/python3.10/site-packages/pymysql/connections.py", line 358, in __init__
    self.connect()
  File "/home/frappe/frappe-bench/env/lib/python3.10/site-packages/pymysql/connections.py", line 711, in connect
    raise exc
pymysql.err.OperationalError: (2003, "Can't connect to MySQL server on '127.0.0.1' ([Errno 111] Connection refused)")

During handling of the above exception, another exception occurred:

Traceback (most recent call last):
  File "/home/frappe/frappe-bench/env/lib/python3.10/site-packages/pymysql/connections.py", line 644, in connect
    sock = socket.create_connection(
  File "/usr/lib/python3.10/socket.py", line 845, in create_connection
    raise err
  File "/usr/lib/python3.10/socket.py", line 833, in create_connection
    sock.connect(sa)
ConnectionRefusedError: [Errno 111] Connection refused

During handling of the above exception, another exception occurred:

Traceback (most recent call last):
  File "/home/frappe/frappe-bench/apps/frappe/frappe/utils/error.py", line 86, in log_error_snapshot
    log_error(title=str(exception), defer_insert=True)
  File "/home/frappe/frappe-bench/apps/frappe/frappe/utils/error.py", line 61, in log_error
    error_log = frappe.get_doc(
  File "/home/frappe/frappe-bench/apps/frappe/frappe/__init__.py", line 1329, in get_doc
    doc = frappe.model.document.get_doc(*args, **kwargs)
  File "/home/frappe/frappe-bench/apps/frappe/frappe/model/document.py", line 83, in get_doc
    controller = get_controller(doctype)
  File "/home/frappe/frappe-bench/apps/frappe/frappe/model/base_document.py", line 70, in get_controller
    site_controllers[doctype] = import_controller(doctype)
  File "/home/frappe/frappe-bench/apps/frappe/frappe/model/base_document.py", line 81, in import_controller
    doctype_info = frappe.db.get_value("DocType", doctype, fieldname="*")
  File "/home/frappe/frappe-bench/apps/frappe/frappe/database/database.py", line 519, in get_value
    result = self.get_values(
  File "/home/frappe/frappe-bench/apps/frappe/frappe/database/database.py", line 623, in get_values
    out = self._get_values_from_table(
  File "/home/frappe/frappe-bench/apps/frappe/frappe/database/database.py", line 896, in _get_values_from_table
    return query.run(as_dict=as_dict, debug=debug, update=update, run=run, pluck=pluck)
  File "/home/frappe/frappe-bench/apps/frappe/frappe/query_builder/utils.py", line 87, in execute_query
    result = frappe.db.sql(query, params, *args, **kwargs)  # nosemgrep
  File "/home/frappe/frappe-bench/apps/frappe/frappe/database/database.py", line 211, in sql
    self.connect()
  File "/home/frappe/frappe-bench/apps/frappe/frappe/database/database.py", line 117, in connect
    self._conn: "MariadbConnection" | "PostgresConnection" = self.get_connection()
  File "/home/frappe/frappe-bench/apps/frappe/frappe/database/mariadb/database.py", line 107, in get_connection
    conn = self._get_connection()
  File "/home/frappe/frappe-bench/apps/frappe/frappe/database/mariadb/database.py", line 113, in _get_connection
    return self.create_connection()
  File "/home/frappe/frappe-bench/apps/frappe/frappe/database/mariadb/database.py", line 116, in create_connection
    return pymysql.connect(**self.get_connection_settings())
  File "/home/frappe/frappe-bench/env/lib/python3.10/site-packages/pymysql/connections.py", line 358, in __init__
    self.connect()
  File "/home/frappe/frappe-bench/env/lib/python3.10/site-packages/pymysql/connections.py", line 711, in connect
    raise exc
pymysql.err.OperationalError: (2003, "Can't connect to MySQL server on '127.0.0.1' ([Errno 111] Connection refused)")
2024-07-19 12:00:55,385 ERROR frappe Could not take error snapshot: (2003, "Can't connect to MySQL server on '127.0.0.1' ([Errno 111] Connection refused)")
Site: erp.grupoatu.com
Form Dict: {'date': '2024-07-19', 'boolean': 'false', 'cmd': 'erpnext.accounts.utils.get_fiscal_year'}
Traceback (most recent call last):
  File "/home/frappe/frappe-bench/env/lib/python3.10/site-packages/pymysql/connections.py", line 644, in connect
    sock = socket.create_connection(
  File "/usr/lib/python3.10/socket.py", line 845, in create_connection
    raise err
  File "/usr/lib/python3.10/socket.py", line 833, in create_connection
    sock.connect(sa)
ConnectionRefusedError: [Errno 111] Connection refused

During handling of the above exception, another exception occurred:

Traceback (most recent call last):
  File "/home/frappe/frappe-bench/apps/frappe/frappe/app.py", line 110, in application
    response = frappe.api.handle(request)
  File "/home/frappe/frappe-bench/apps/frappe/frappe/api/__init__.py", line 49, in handle
    data = endpoint(**arguments)
  File "/home/frappe/frappe-bench/apps/frappe/frappe/api/v1.py", line 36, in handle_rpc_call
    return frappe.handler.handle()
  File "/home/frappe/frappe-bench/apps/frappe/frappe/handler.py", line 49, in handle
    data = execute_cmd(cmd)
  File "/home/frappe/frappe-bench/apps/frappe/frappe/handler.py", line 85, in execute_cmd
    return frappe.call(method, **frappe.form_dict)
  File "/home/frappe/frappe-bench/apps/frappe/frappe/__init__.py", line 1761, in call
    return fn(*args, **newargs)
  File "/home/frappe/frappe-bench/apps/frappe/frappe/utils/typing_validations.py", line 31, in wrapper
    return func(*args, **kwargs)
  File "/home/frappe/frappe-bench/apps/erpnext/erpnext/accounts/utils.py", line 61, in get_fiscal_year
    fiscal_years = get_fiscal_years(
  File "/home/frappe/frappe-bench/apps/erpnext/erpnext/accounts/utils.py", line 105, in get_fiscal_years
    fiscal_years = query.run(as_dict=True)
  File "/home/frappe/frappe-bench/apps/frappe/frappe/query_builder/utils.py", line 87, in execute_query
    result = frappe.db.sql(query, params, *args, **kwargs)  # nosemgrep
  File "/home/frappe/frappe-bench/apps/frappe/frappe/database/database.py", line 211, in sql
    self.connect()
  File "/home/frappe/frappe-bench/apps/frappe/frappe/database/database.py", line 117, in connect
    self._conn: "MariadbConnection" | "PostgresConnection" = self.get_connection()
  File "/home/frappe/frappe-bench/apps/frappe/frappe/database/mariadb/database.py", line 107, in get_connection
    conn = self._get_connection()
  File "/home/frappe/frappe-bench/apps/frappe/frappe/database/mariadb/database.py", line 113, in _get_connection
    return self.create_connection()
  File "/home/frappe/frappe-bench/apps/frappe/frappe/database/mariadb/database.py", line 116, in create_connection
    return pymysql.connect(**self.get_connection_settings())
  File "/home/frappe/frappe-bench/env/lib/python3.10/site-packages/pymysql/connections.py", line 358, in __init__
    self.connect()
  File "/home/frappe/frappe-bench/env/lib/python3.10/site-packages/pymysql/connections.py", line 711, in connect
    raise exc
pymysql.err.OperationalError: (2003, "Can't connect to MySQL server on '127.0.0.1' ([Errno 111] Connection refused)")

During handling of the above exception, another exception occurred:

Traceback (most recent call last):
  File "/home/frappe/frappe-bench/env/lib/python3.10/site-packages/pymysql/connections.py", line 644, in connect
    sock = socket.create_connection(
  File "/usr/lib/python3.10/socket.py", line 845, in create_connection
    raise err
  File "/usr/lib/python3.10/socket.py", line 833, in create_connection
    sock.connect(sa)
ConnectionRefusedError: [Errno 111] Connection refused

During handling of the above exception, another exception occurred:

Traceback (most recent call last):
  File "/home/frappe/frappe-bench/apps/frappe/frappe/utils/error.py", line 86, in log_error_snapshot
    log_error(title=str(exception), defer_insert=True)
  File "/home/frappe/frappe-bench/apps/frappe/frappe/utils/error.py", line 61, in log_error
    error_log = frappe.get_doc(
  File "/home/frappe/frappe-bench/apps/frappe/frappe/__init__.py", line 1329, in get_doc
    doc = frappe.model.document.get_doc(*args, **kwargs)
  File "/home/frappe/frappe-bench/apps/frappe/frappe/model/document.py", line 83, in get_doc
    controller = get_controller(doctype)
  File "/home/frappe/frappe-bench/apps/frappe/frappe/model/base_document.py", line 70, in get_controller
    site_controllers[doctype] = import_controller(doctype)
  File "/home/frappe/frappe-bench/apps/frappe/frappe/model/base_document.py", line 81, in import_controller
    doctype_info = frappe.db.get_value("DocType", doctype, fieldname="*")
  File "/home/frappe/frappe-bench/apps/frappe/frappe/database/database.py", line 519, in get_value
    result = self.get_values(
  File "/home/frappe/frappe-bench/apps/frappe/frappe/database/database.py", line 623, in get_values
    out = self._get_values_from_table(
  File "/home/frappe/frappe-bench/apps/frappe/frappe/database/database.py", line 896, in _get_values_from_table
    return query.run(as_dict=as_dict, debug=debug, update=update, run=run, pluck=pluck)
  File "/home/frappe/frappe-bench/apps/frappe/frappe/query_builder/utils.py", line 87, in execute_query
    result = frappe.db.sql(query, params, *args, **kwargs)  # nosemgrep
  File "/home/frappe/frappe-bench/apps/frappe/frappe/database/database.py", line 211, in sql
    self.connect()
  File "/home/frappe/frappe-bench/apps/frappe/frappe/database/database.py", line 117, in connect
    self._conn: "MariadbConnection" | "PostgresConnection" = self.get_connection()
  File "/home/frappe/frappe-bench/apps/frappe/frappe/database/mariadb/database.py", line 107, in get_connection
    conn = self._get_connection()
  File "/home/frappe/frappe-bench/apps/frappe/frappe/database/mariadb/database.py", line 113, in _get_connection
    return self.create_connection()
  File "/home/frappe/frappe-bench/apps/frappe/frappe/database/mariadb/database.py", line 116, in create_connection
    return pymysql.connect(**self.get_connection_settings())
  File "/home/frappe/frappe-bench/env/lib/python3.10/site-packages/pymysql/connections.py", line 358, in __init__
    self.connect()
  File "/home/frappe/frappe-bench/env/lib/python3.10/site-packages/pymysql/connections.py", line 711, in connect
    raise exc
pymysql.err.OperationalError: (2003, "Can't connect to MySQL server on '127.0.0.1' ([Errno 111] Connection refused)")
2024-07-19 12:00:55,451 ERROR frappe Could not take error snapshot: (2003, "Can't connect to MySQL server on '127.0.0.1' ([Errno 111] Connection refused)")
Site: erp.grupoatu.com
Form Dict: {'doctype': 'Item', 'filters': '{"disabled":0}', 'fields': '[]', 'distinct': 'false', 'cmd': 'frappe.desk.reportview.get_count'}
Traceback (most recent call last):
  File "/home/frappe/frappe-bench/env/lib/python3.10/site-packages/pymysql/connections.py", line 644, in connect
    sock = socket.create_connection(
  File "/usr/lib/python3.10/socket.py", line 845, in create_connection
    raise err
  File "/usr/lib/python3.10/socket.py", line 833, in create_connection
    sock.connect(sa)
ConnectionRefusedError: [Errno 111] Connection refused

During handling of the above exception, another exception occurred:

Traceback (most recent call last):
  File "/home/frappe/frappe-bench/apps/frappe/frappe/app.py", line 110, in application
    response = frappe.api.handle(request)
  File "/home/frappe/frappe-bench/apps/frappe/frappe/api/__init__.py", line 49, in handle
    data = endpoint(**arguments)
  File "/home/frappe/frappe-bench/apps/frappe/frappe/api/v1.py", line 36, in handle_rpc_call
    return frappe.handler.handle()
  File "/home/frappe/frappe-bench/apps/frappe/frappe/handler.py", line 49, in handle
    data = execute_cmd(cmd)
  File "/home/frappe/frappe-bench/apps/frappe/frappe/handler.py", line 85, in execute_cmd
    return frappe.call(method, **frappe.form_dict)
  File "/home/frappe/frappe-bench/apps/frappe/frappe/__init__.py", line 1761, in call
    return fn(*args, **newargs)
  File "/home/frappe/frappe-bench/apps/frappe/frappe/utils/typing_validations.py", line 31, in wrapper
    return func(*args, **kwargs)
  File "/home/frappe/frappe-bench/apps/frappe/frappe/__init__.py", line 921, in wrapper_fn
    retval = fn(*args, **get_newargs(fn, kwargs))
  File "/home/frappe/frappe-bench/apps/frappe/frappe/desk/reportview.py", line 72, in get_count
    count = execute(**args)[0].get("total_count")
  File "/home/frappe/frappe-bench/apps/frappe/frappe/desk/reportview.py", line 78, in execute
    return DatabaseQuery(doctype).execute(*args, **kwargs)
  File "/home/frappe/frappe-bench/apps/frappe/frappe/model/db_query.py", line 191, in execute
    result = self.build_and_run()
  File "/home/frappe/frappe-bench/apps/frappe/frappe/model/db_query.py", line 232, in build_and_run
    return frappe.db.sql(
  File "/home/frappe/frappe-bench/apps/frappe/frappe/database/database.py", line 211, in sql
    self.connect()
  File "/home/frappe/frappe-bench/apps/frappe/frappe/database/database.py", line 117, in connect
    self._conn: "MariadbConnection" | "PostgresConnection" = self.get_connection()
  File "/home/frappe/frappe-bench/apps/frappe/frappe/database/mariadb/database.py", line 107, in get_connection
    conn = self._get_connection()
  File "/home/frappe/frappe-bench/apps/frappe/frappe/database/mariadb/database.py", line 113, in _get_connection
    return self.create_connection()
  File "/home/frappe/frappe-bench/apps/frappe/frappe/database/mariadb/database.py", line 116, in create_connection
    return pymysql.connect(**self.get_connection_settings())
  File "/home/frappe/frappe-bench/env/lib/python3.10/site-packages/pymysql/connections.py", line 358, in __init__
    self.connect()
  File "/home/frappe/frappe-bench/env/lib/python3.10/site-packages/pymysql/connections.py", line 711, in connect
    raise exc
pymysql.err.OperationalError: (2003, "Can't connect to MySQL server on '127.0.0.1' ([Errno 111] Connection refused)")

During handling of the above exception, another exception occurred:

Traceback (most recent call last):
  File "/home/frappe/frappe-bench/env/lib/python3.10/site-packages/pymysql/connections.py", line 644, in connect
    sock = socket.create_connection(
  File "/usr/lib/python3.10/socket.py", line 845, in create_connection
    raise err
  File "/usr/lib/python3.10/socket.py", line 833, in create_connection
    sock.connect(sa)
ConnectionRefusedError: [Errno 111] Connection refused

During handling of the above exception, another exception occurred:

Traceback (most recent call last):
  File "/home/frappe/frappe-bench/apps/frappe/frappe/utils/error.py", line 86, in log_error_snapshot
    log_error(title=str(exception), defer_insert=True)
  File "/home/frappe/frappe-bench/apps/frappe/frappe/utils/error.py", line 61, in log_error
    error_log = frappe.get_doc(
  File "/home/frappe/frappe-bench/apps/frappe/frappe/__init__.py", line 1329, in get_doc
    doc = frappe.model.document.get_doc(*args, **kwargs)
  File "/home/frappe/frappe-bench/apps/frappe/frappe/model/document.py", line 83, in get_doc
    controller = get_controller(doctype)
  File "/home/frappe/frappe-bench/apps/frappe/frappe/model/base_document.py", line 70, in get_controller
    site_controllers[doctype] = import_controller(doctype)
  File "/home/frappe/frappe-bench/apps/frappe/frappe/model/base_document.py", line 81, in import_controller
    doctype_info = frappe.db.get_value("DocType", doctype, fieldname="*")
  File "/home/frappe/frappe-bench/apps/frappe/frappe/database/database.py", line 519, in get_value
    result = self.get_values(
  File "/home/frappe/frappe-bench/apps/frappe/frappe/database/database.py", line 623, in get_values
    out = self._get_values_from_table(
  File "/home/frappe/frappe-bench/apps/frappe/frappe/database/database.py", line 896, in _get_values_from_table
    return query.run(as_dict=as_dict, debug=debug, update=update, run=run, pluck=pluck)
  File "/home/frappe/frappe-bench/apps/frappe/frappe/query_builder/utils.py", line 87, in execute_query
    result = frappe.db.sql(query, params, *args, **kwargs)  # nosemgrep
  File "/home/frappe/frappe-bench/apps/frappe/frappe/database/database.py", line 211, in sql
    self.connect()
  File "/home/frappe/frappe-bench/apps/frappe/frappe/database/database.py", line 117, in connect
    self._conn: "MariadbConnection" | "PostgresConnection" = self.get_connection()
  File "/home/frappe/frappe-bench/apps/frappe/frappe/database/mariadb/database.py", line 107, in get_connection
    conn = self._get_connection()
  File "/home/frappe/frappe-bench/apps/frappe/frappe/database/mariadb/database.py", line 113, in _get_connection
    return self.create_connection()
  File "/home/frappe/frappe-bench/apps/frappe/frappe/database/mariadb/database.py", line 116, in create_connection
    return pymysql.connect(**self.get_connection_settings())
  File "/home/frappe/frappe-bench/env/lib/python3.10/site-packages/pymysql/connections.py", line 358, in __init__
    self.connect()
  File "/home/frappe/frappe-bench/env/lib/python3.10/site-packages/pymysql/connections.py", line 711, in connect
    raise exc
pymysql.err.OperationalError: (2003, "Can't connect to MySQL server on '127.0.0.1' ([Errno 111] Connection refused)")
2024-07-19 12:00:59,234 ERROR frappe Could not take error snapshot: (2003, "Can't connect to MySQL server on '127.0.0.1' ([Errno 111] Connection refused)")
Site: erp.grupoatu.com
Form Dict: {'with_cost_center_and_project': 'true', 'cmd': 'erpnext.accounts.doctype.accounting_dimension.accounting_dimension.get_dimensions'}
Traceback (most recent call last):
  File "/home/frappe/frappe-bench/env/lib/python3.10/site-packages/pymysql/connections.py", line 644, in connect
    sock = socket.create_connection(
  File "/usr/lib/python3.10/socket.py", line 845, in create_connection
    raise err
  File "/usr/lib/python3.10/socket.py", line 833, in create_connection
    sock.connect(sa)
ConnectionRefusedError: [Errno 111] Connection refused

During handling of the above exception, another exception occurred:

Traceback (most recent call last):
  File "/home/frappe/frappe-bench/apps/frappe/frappe/app.py", line 110, in application
    response = frappe.api.handle(request)
  File "/home/frappe/frappe-bench/apps/frappe/frappe/api/__init__.py", line 49, in handle
    data = endpoint(**arguments)
  File "/home/frappe/frappe-bench/apps/frappe/frappe/api/v1.py", line 36, in handle_rpc_call
    return frappe.handler.handle()
  File "/home/frappe/frappe-bench/apps/frappe/frappe/handler.py", line 49, in handle
    data = execute_cmd(cmd)
  File "/home/frappe/frappe-bench/apps/frappe/frappe/handler.py", line 85, in execute_cmd
    return frappe.call(method, **frappe.form_dict)
  File "/home/frappe/frappe-bench/apps/frappe/frappe/__init__.py", line 1761, in call
    return fn(*args, **newargs)
  File "/home/frappe/frappe-bench/apps/frappe/frappe/utils/typing_validations.py", line 31, in wrapper
    return func(*args, **kwargs)
  File "/home/frappe/frappe-bench/apps/erpnext/erpnext/accounts/doctype/accounting_dimension/accounting_dimension.py", line 287, in get_dimensions
    frappe.qb.from_(p).select(p.label, p.fieldname, p.document_type).where(p.disabled == 0).run(as_dict=1)
  File "/home/frappe/frappe-bench/apps/frappe/frappe/query_builder/utils.py", line 87, in execute_query
    result = frappe.db.sql(query, params, *args, **kwargs)  # nosemgrep
  File "/home/frappe/frappe-bench/apps/frappe/frappe/database/database.py", line 211, in sql
    self.connect()
  File "/home/frappe/frappe-bench/apps/frappe/frappe/database/database.py", line 117, in connect
    self._conn: "MariadbConnection" | "PostgresConnection" = self.get_connection()
  File "/home/frappe/frappe-bench/apps/frappe/frappe/database/mariadb/database.py", line 107, in get_connection
    conn = self._get_connection()
  File "/home/frappe/frappe-bench/apps/frappe/frappe/database/mariadb/database.py", line 113, in _get_connection
    return self.create_connection()
  File "/home/frappe/frappe-bench/apps/frappe/frappe/database/mariadb/database.py", line 116, in create_connection
    return pymysql.connect(**self.get_connection_settings())
  File "/home/frappe/frappe-bench/env/lib/python3.10/site-packages/pymysql/connections.py", line 358, in __init__
    self.connect()
  File "/home/frappe/frappe-bench/env/lib/python3.10/site-packages/pymysql/connections.py", line 711, in connect
    raise exc
pymysql.err.OperationalError: (2003, "Can't connect to MySQL server on '127.0.0.1' ([Errno 111] Connection refused)")

During handling of the above exception, another exception occurred:

Traceback (most recent call last):
  File "/home/frappe/frappe-bench/env/lib/python3.10/site-packages/pymysql/connections.py", line 644, in connect
    sock = socket.create_connection(
  File "/usr/lib/python3.10/socket.py", line 845, in create_connection
    raise err
  File "/usr/lib/python3.10/socket.py", line 833, in create_connection
    sock.connect(sa)
ConnectionRefusedError: [Errno 111] Connection refused

During handling of the above exception, another exception occurred:

Traceback (most recent call last):
  File "/home/frappe/frappe-bench/apps/frappe/frappe/utils/error.py", line 86, in log_error_snapshot
    log_error(title=str(exception), defer_insert=True)
  File "/home/frappe/frappe-bench/apps/frappe/frappe/utils/error.py", line 61, in log_error
    error_log = frappe.get_doc(
  File "/home/frappe/frappe-bench/apps/frappe/frappe/__init__.py", line 1329, in get_doc
    doc = frappe.model.document.get_doc(*args, **kwargs)
  File "/home/frappe/frappe-bench/apps/frappe/frappe/model/document.py", line 83, in get_doc
    controller = get_controller(doctype)
  File "/home/frappe/frappe-bench/apps/frappe/frappe/model/base_document.py", line 70, in get_controller
    site_controllers[doctype] = import_controller(doctype)
  File "/home/frappe/frappe-bench/apps/frappe/frappe/model/base_document.py", line 81, in import_controller
    doctype_info = frappe.db.get_value("DocType", doctype, fieldname="*")
  File "/home/frappe/frappe-bench/apps/frappe/frappe/database/database.py", line 519, in get_value
    result = self.get_values(
  File "/home/frappe/frappe-bench/apps/frappe/frappe/database/database.py", line 623, in get_values
    out = self._get_values_from_table(
  File "/home/frappe/frappe-bench/apps/frappe/frappe/database/database.py", line 896, in _get_values_from_table
    return query.run(as_dict=as_dict, debug=debug, update=update, run=run, pluck=pluck)
  File "/home/frappe/frappe-bench/apps/frappe/frappe/query_builder/utils.py", line 87, in execute_query
    result = frappe.db.sql(query, params, *args, **kwargs)  # nosemgrep
  File "/home/frappe/frappe-bench/apps/frappe/frappe/database/database.py", line 211, in sql
    self.connect()
  File "/home/frappe/frappe-bench/apps/frappe/frappe/database/database.py", line 117, in connect
    self._conn: "MariadbConnection" | "PostgresConnection" = self.get_connection()
  File "/home/frappe/frappe-bench/apps/frappe/frappe/database/mariadb/database.py", line 107, in get_connection
    conn = self._get_connection()
  File "/home/frappe/frappe-bench/apps/frappe/frappe/database/mariadb/database.py", line 113, in _get_connection
    return self.create_connection()
  File "/home/frappe/frappe-bench/apps/frappe/frappe/database/mariadb/database.py", line 116, in create_connection
    return pymysql.connect(**self.get_connection_settings())
  File "/home/frappe/frappe-bench/env/lib/python3.10/site-packages/pymysql/connections.py", line 358, in __init__
    self.connect()
  File "/home/frappe/frappe-bench/env/lib/python3.10/site-packages/pymysql/connections.py", line 711, in connect
    raise exc
pymysql.err.OperationalError: (2003, "Can't connect to MySQL server on '127.0.0.1' ([Errno 111] Connection refused)")
2024-07-19 12:01:04,238 ERROR frappe Could not take error snapshot: (2003, "Can't connect to MySQL server on '127.0.0.1' ([Errno 111] Connection refused)")
Site: erp.grupoatu.com
Form Dict: {'txt': '', 'doctype': 'Customer', 'ignore_user_permissions': '0', 'reference_doctype': 'Sales Invoice', 'page_length': '10', 'cmd': 'frappe.desk.search.search_link'}
Traceback (most recent call last):
  File "/home/frappe/frappe-bench/env/lib/python3.10/site-packages/pymysql/connections.py", line 644, in connect
    sock = socket.create_connection(
  File "/usr/lib/python3.10/socket.py", line 845, in create_connection
    raise err
  File "/usr/lib/python3.10/socket.py", line 833, in create_connection
    sock.connect(sa)
ConnectionRefusedError: [Errno 111] Connection refused

During handling of the above exception, another exception occurred:

Traceback (most recent call last):
  File "/home/frappe/frappe-bench/apps/frappe/frappe/app.py", line 110, in application
    response = frappe.api.handle(request)
  File "/home/frappe/frappe-bench/apps/frappe/frappe/api/__init__.py", line 49, in handle
    data = endpoint(**arguments)
  File "/home/frappe/frappe-bench/apps/frappe/frappe/api/v1.py", line 36, in handle_rpc_call
    return frappe.handler.handle()
  File "/home/frappe/frappe-bench/apps/frappe/frappe/handler.py", line 49, in handle
    data = execute_cmd(cmd)
  File "/home/frappe/frappe-bench/apps/frappe/frappe/handler.py", line 85, in execute_cmd
    return frappe.call(method, **frappe.form_dict)
  File "/home/frappe/frappe-bench/apps/frappe/frappe/__init__.py", line 1761, in call
    return fn(*args, **newargs)
  File "/home/frappe/frappe-bench/apps/frappe/frappe/utils/typing_validations.py", line 31, in wrapper
    return func(*args, **kwargs)
  File "/home/frappe/frappe-bench/apps/frappe/frappe/desk/search.py", line 47, in search_link
    results = search_widget(
  File "/home/frappe/frappe-bench/apps/frappe/frappe/utils/typing_validations.py", line 31, in wrapper
    return func(*args, **kwargs)
  File "/home/frappe/frappe-bench/apps/frappe/frappe/desk/search.py", line 193, in search_widget
    values = frappe.get_list(
  File "/home/frappe/frappe-bench/apps/frappe/frappe/__init__.py", line 2025, in get_list
    return frappe.model.db_query.DatabaseQuery(doctype).execute(*args, **kwargs)
  File "/home/frappe/frappe-bench/apps/frappe/frappe/model/db_query.py", line 167, in execute
    if is_virtual_doctype(self.doctype):
  File "/home/frappe/frappe-bench/apps/frappe/frappe/utils/caching.py", line 119, in site_cache_wrapper
    _SITE_CACHE[func_key][frappe.local.site][func_call_key] = func(*args, **kwargs)
  File "/home/frappe/frappe-bench/apps/frappe/frappe/model/utils/__init__.py", line 133, in is_virtual_doctype
    return frappe.db.get_value("DocType", doctype, "is_virtual")
  File "/home/frappe/frappe-bench/apps/frappe/frappe/database/database.py", line 519, in get_value
    result = self.get_values(
  File "/home/frappe/frappe-bench/apps/frappe/frappe/database/database.py", line 623, in get_values
    out = self._get_values_from_table(
  File "/home/frappe/frappe-bench/apps/frappe/frappe/database/database.py", line 896, in _get_values_from_table
    return query.run(as_dict=as_dict, debug=debug, update=update, run=run, pluck=pluck)
  File "/home/frappe/frappe-bench/apps/frappe/frappe/query_builder/utils.py", line 87, in execute_query
    result = frappe.db.sql(query, params, *args, **kwargs)  # nosemgrep
  File "/home/frappe/frappe-bench/apps/frappe/frappe/database/database.py", line 211, in sql
    self.connect()
  File "/home/frappe/frappe-bench/apps/frappe/frappe/database/database.py", line 117, in connect
    self._conn: "MariadbConnection" | "PostgresConnection" = self.get_connection()
  File "/home/frappe/frappe-bench/apps/frappe/frappe/database/mariadb/database.py", line 107, in get_connection
    conn = self._get_connection()
  File "/home/frappe/frappe-bench/apps/frappe/frappe/database/mariadb/database.py", line 113, in _get_connection
    return self.create_connection()
  File "/home/frappe/frappe-bench/apps/frappe/frappe/database/mariadb/database.py", line 116, in create_connection
    return pymysql.connect(**self.get_connection_settings())
  File "/home/frappe/frappe-bench/env/lib/python3.10/site-packages/pymysql/connections.py", line 358, in __init__
    self.connect()
  File "/home/frappe/frappe-bench/env/lib/python3.10/site-packages/pymysql/connections.py", line 711, in connect
    raise exc
pymysql.err.OperationalError: (2003, "Can't connect to MySQL server on '127.0.0.1' ([Errno 111] Connection refused)")

During handling of the above exception, another exception occurred:

Traceback (most recent call last):
  File "/home/frappe/frappe-bench/env/lib/python3.10/site-packages/pymysql/connections.py", line 644, in connect
    sock = socket.create_connection(
  File "/usr/lib/python3.10/socket.py", line 845, in create_connection
    raise err
  File "/usr/lib/python3.10/socket.py", line 833, in create_connection
    sock.connect(sa)
ConnectionRefusedError: [Errno 111] Connection refused

During handling of the above exception, another exception occurred:

Traceback (most recent call last):
  File "/home/frappe/frappe-bench/apps/frappe/frappe/utils/error.py", line 86, in log_error_snapshot
    log_error(title=str(exception), defer_insert=True)
  File "/home/frappe/frappe-bench/apps/frappe/frappe/utils/error.py", line 61, in log_error
    error_log = frappe.get_doc(
  File "/home/frappe/frappe-bench/apps/frappe/frappe/__init__.py", line 1329, in get_doc
    doc = frappe.model.document.get_doc(*args, **kwargs)
  File "/home/frappe/frappe-bench/apps/frappe/frappe/model/document.py", line 83, in get_doc
    controller = get_controller(doctype)
  File "/home/frappe/frappe-bench/apps/frappe/frappe/model/base_document.py", line 70, in get_controller
    site_controllers[doctype] = import_controller(doctype)
  File "/home/frappe/frappe-bench/apps/frappe/frappe/model/base_document.py", line 81, in import_controller
    doctype_info = frappe.db.get_value("DocType", doctype, fieldname="*")
  File "/home/frappe/frappe-bench/apps/frappe/frappe/database/database.py", line 519, in get_value
    result = self.get_values(
  File "/home/frappe/frappe-bench/apps/frappe/frappe/database/database.py", line 623, in get_values
    out = self._get_values_from_table(
  File "/home/frappe/frappe-bench/apps/frappe/frappe/database/database.py", line 896, in _get_values_from_table
    return query.run(as_dict=as_dict, debug=debug, update=update, run=run, pluck=pluck)
  File "/home/frappe/frappe-bench/apps/frappe/frappe/query_builder/utils.py", line 87, in execute_query
    result = frappe.db.sql(query, params, *args, **kwargs)  # nosemgrep
  File "/home/frappe/frappe-bench/apps/frappe/frappe/database/database.py", line 211, in sql
    self.connect()
  File "/home/frappe/frappe-bench/apps/frappe/frappe/database/database.py", line 117, in connect
    self._conn: "MariadbConnection" | "PostgresConnection" = self.get_connection()
  File "/home/frappe/frappe-bench/apps/frappe/frappe/database/mariadb/database.py", line 107, in get_connection
    conn = self._get_connection()
  File "/home/frappe/frappe-bench/apps/frappe/frappe/database/mariadb/database.py", line 113, in _get_connection
    return self.create_connection()
  File "/home/frappe/frappe-bench/apps/frappe/frappe/database/mariadb/database.py", line 116, in create_connection
    return pymysql.connect(**self.get_connection_settings())
  File "/home/frappe/frappe-bench/env/lib/python3.10/site-packages/pymysql/connections.py", line 358, in __init__
    self.connect()
  File "/home/frappe/frappe-bench/env/lib/python3.10/site-packages/pymysql/connections.py", line 711, in connect
    raise exc
pymysql.err.OperationalError: (2003, "Can't connect to MySQL server on '127.0.0.1' ([Errno 111] Connection refused)")
2024-07-19 12:01:49,948 ERROR frappe Could not take error snapshot: (2003, "Can't connect to MySQL server on '127.0.0.1' ([Errno 111] Connection refused)")
Site: erp.grupoatu.com
Form Dict: {'doctype': 'Account', 'fields': '["`tabAccount`.`name`","`tabAccount`.`owner`","`tabAccount`.`creation`","`tabAccount`.`modified`","`tabAccount`.`modified_by`","`tabAccount`.`_user_tags`","`tabAccount`.`_comments`","`tabAccount`.`_assign`","`tabAccount`.`_liked_by`","`tabAccount`.`docstatus`","`tabAccount`.`idx`","`tabAccount`.`root_type`","`tabAccount`.`account_type`","`tabAccount`.`disabled`"]', 'filters': '[["Account","name","like","%luisa%"]]', 'order_by': '`tabAccount`.`name` asc', 'start': '0', 'page_length': '500', 'view': 'List', 'group_by': '', 'with_comment_count': '1', 'cmd': 'frappe.desk.reportview.get'}
Traceback (most recent call last):
  File "/home/frappe/frappe-bench/env/lib/python3.10/site-packages/pymysql/connections.py", line 644, in connect
    sock = socket.create_connection(
  File "/usr/lib/python3.10/socket.py", line 845, in create_connection
    raise err
  File "/usr/lib/python3.10/socket.py", line 833, in create_connection
    sock.connect(sa)
ConnectionRefusedError: [Errno 111] Connection refused

During handling of the above exception, another exception occurred:

Traceback (most recent call last):
  File "/home/frappe/frappe-bench/apps/frappe/frappe/app.py", line 110, in application
    response = frappe.api.handle(request)
  File "/home/frappe/frappe-bench/apps/frappe/frappe/api/__init__.py", line 49, in handle
    data = endpoint(**arguments)
  File "/home/frappe/frappe-bench/apps/frappe/frappe/api/v1.py", line 36, in handle_rpc_call
    return frappe.handler.handle()
  File "/home/frappe/frappe-bench/apps/frappe/frappe/handler.py", line 49, in handle
    data = execute_cmd(cmd)
  File "/home/frappe/frappe-bench/apps/frappe/frappe/handler.py", line 85, in execute_cmd
    return frappe.call(method, **frappe.form_dict)
  File "/home/frappe/frappe-bench/apps/frappe/frappe/__init__.py", line 1761, in call
    return fn(*args, **newargs)
  File "/home/frappe/frappe-bench/apps/frappe/frappe/utils/typing_validations.py", line 31, in wrapper
    return func(*args, **kwargs)
  File "/home/frappe/frappe-bench/apps/frappe/frappe/__init__.py", line 921, in wrapper_fn
    retval = fn(*args, **get_newargs(fn, kwargs))
  File "/home/frappe/frappe-bench/apps/frappe/frappe/desk/reportview.py", line 32, in get
    data = compress(execute(**args), args=args)
  File "/home/frappe/frappe-bench/apps/frappe/frappe/desk/reportview.py", line 78, in execute
    return DatabaseQuery(doctype).execute(*args, **kwargs)
  File "/home/frappe/frappe-bench/apps/frappe/frappe/model/db_query.py", line 191, in execute
    result = self.build_and_run()
  File "/home/frappe/frappe-bench/apps/frappe/frappe/model/db_query.py", line 232, in build_and_run
    return frappe.db.sql(
  File "/home/frappe/frappe-bench/apps/frappe/frappe/database/database.py", line 211, in sql
    self.connect()
  File "/home/frappe/frappe-bench/apps/frappe/frappe/database/database.py", line 117, in connect
    self._conn: "MariadbConnection" | "PostgresConnection" = self.get_connection()
  File "/home/frappe/frappe-bench/apps/frappe/frappe/database/mariadb/database.py", line 107, in get_connection
    conn = self._get_connection()
  File "/home/frappe/frappe-bench/apps/frappe/frappe/database/mariadb/database.py", line 113, in _get_connection
    return self.create_connection()
  File "/home/frappe/frappe-bench/apps/frappe/frappe/database/mariadb/database.py", line 116, in create_connection
    return pymysql.connect(**self.get_connection_settings())
  File "/home/frappe/frappe-bench/env/lib/python3.10/site-packages/pymysql/connections.py", line 358, in __init__
    self.connect()
  File "/home/frappe/frappe-bench/env/lib/python3.10/site-packages/pymysql/connections.py", line 711, in connect
    raise exc
pymysql.err.OperationalError: (2003, "Can't connect to MySQL server on '127.0.0.1' ([Errno 111] Connection refused)")

During handling of the above exception, another exception occurred:

Traceback (most recent call last):
  File "/home/frappe/frappe-bench/env/lib/python3.10/site-packages/pymysql/connections.py", line 644, in connect
    sock = socket.create_connection(
  File "/usr/lib/python3.10/socket.py", line 845, in create_connection
    raise err
  File "/usr/lib/python3.10/socket.py", line 833, in create_connection
    sock.connect(sa)
ConnectionRefusedError: [Errno 111] Connection refused

During handling of the above exception, another exception occurred:

Traceback (most recent call last):
  File "/home/frappe/frappe-bench/apps/frappe/frappe/utils/error.py", line 86, in log_error_snapshot
    log_error(title=str(exception), defer_insert=True)
  File "/home/frappe/frappe-bench/apps/frappe/frappe/utils/error.py", line 61, in log_error
    error_log = frappe.get_doc(
  File "/home/frappe/frappe-bench/apps/frappe/frappe/__init__.py", line 1329, in get_doc
    doc = frappe.model.document.get_doc(*args, **kwargs)
  File "/home/frappe/frappe-bench/apps/frappe/frappe/model/document.py", line 83, in get_doc
    controller = get_controller(doctype)
  File "/home/frappe/frappe-bench/apps/frappe/frappe/model/base_document.py", line 70, in get_controller
    site_controllers[doctype] = import_controller(doctype)
  File "/home/frappe/frappe-bench/apps/frappe/frappe/model/base_document.py", line 81, in import_controller
    doctype_info = frappe.db.get_value("DocType", doctype, fieldname="*")
  File "/home/frappe/frappe-bench/apps/frappe/frappe/database/database.py", line 519, in get_value
    result = self.get_values(
  File "/home/frappe/frappe-bench/apps/frappe/frappe/database/database.py", line 623, in get_values
    out = self._get_values_from_table(
  File "/home/frappe/frappe-bench/apps/frappe/frappe/database/database.py", line 896, in _get_values_from_table
    return query.run(as_dict=as_dict, debug=debug, update=update, run=run, pluck=pluck)
  File "/home/frappe/frappe-bench/apps/frappe/frappe/query_builder/utils.py", line 87, in execute_query
    result = frappe.db.sql(query, params, *args, **kwargs)  # nosemgrep
  File "/home/frappe/frappe-bench/apps/frappe/frappe/database/database.py", line 211, in sql
    self.connect()
  File "/home/frappe/frappe-bench/apps/frappe/frappe/database/database.py", line 117, in connect
    self._conn: "MariadbConnection" | "PostgresConnection" = self.get_connection()
  File "/home/frappe/frappe-bench/apps/frappe/frappe/database/mariadb/database.py", line 107, in get_connection
    conn = self._get_connection()
  File "/home/frappe/frappe-bench/apps/frappe/frappe/database/mariadb/database.py", line 113, in _get_connection
    return self.create_connection()
  File "/home/frappe/frappe-bench/apps/frappe/frappe/database/mariadb/database.py", line 116, in create_connection
    return pymysql.connect(**self.get_connection_settings())
  File "/home/frappe/frappe-bench/env/lib/python3.10/site-packages/pymysql/connections.py", line 358, in __init__
    self.connect()
  File "/home/frappe/frappe-bench/env/lib/python3.10/site-packages/pymysql/connections.py", line 711, in connect
    raise exc
pymysql.err.OperationalError: (2003, "Can't connect to MySQL server on '127.0.0.1' ([Errno 111] Connection refused)")
2024-07-19 12:01:59,485 ERROR frappe Could not take error snapshot: (2003, "Can't connect to MySQL server on '127.0.0.1' ([Errno 111] Connection refused)")
Site: erp.grupoatu.com
Form Dict: {}
Traceback (most recent call last):
  File "/home/frappe/frappe-bench/env/lib/python3.10/site-packages/pymysql/connections.py", line 644, in connect
    sock = socket.create_connection(
  File "/usr/lib/python3.10/socket.py", line 845, in create_connection
    raise err
  File "/usr/lib/python3.10/socket.py", line 833, in create_connection
    sock.connect(sa)
ConnectionRefusedError: [Errno 111] Connection refused

During handling of the above exception, another exception occurred:

Traceback (most recent call last):
  File "/home/frappe/frappe-bench/apps/frappe/frappe/website/serve.py", line 19, in get_response
    endpoint, renderer_instance = path_resolver.resolve()
  File "/home/frappe/frappe-bench/apps/frappe/frappe/website/path_resolver.py", line 38, in resolve
    resolve_redirect(self.path, request.query_string)
  File "/home/frappe/frappe-bench/apps/frappe/frappe/website/path_resolver.py", line 118, in resolve_redirect
    redirects += frappe.get_all("Website Route Redirect", ["source", "target"], order_by=None)
  File "/home/frappe/frappe-bench/apps/frappe/frappe/__init__.py", line 2050, in get_all
    return get_list(doctype, *args, **kwargs)
  File "/home/frappe/frappe-bench/apps/frappe/frappe/__init__.py", line 2025, in get_list
    return frappe.model.db_query.DatabaseQuery(doctype).execute(*args, **kwargs)
  File "/home/frappe/frappe-bench/apps/frappe/frappe/model/db_query.py", line 191, in execute
    result = self.build_and_run()
  File "/home/frappe/frappe-bench/apps/frappe/frappe/model/db_query.py", line 232, in build_and_run
    return frappe.db.sql(
  File "/home/frappe/frappe-bench/apps/frappe/frappe/database/database.py", line 211, in sql
    self.connect()
  File "/home/frappe/frappe-bench/apps/frappe/frappe/database/database.py", line 117, in connect
    self._conn: "MariadbConnection" | "PostgresConnection" = self.get_connection()
  File "/home/frappe/frappe-bench/apps/frappe/frappe/database/mariadb/database.py", line 107, in get_connection
    conn = self._get_connection()
  File "/home/frappe/frappe-bench/apps/frappe/frappe/database/mariadb/database.py", line 113, in _get_connection
    return self.create_connection()
  File "/home/frappe/frappe-bench/apps/frappe/frappe/database/mariadb/database.py", line 116, in create_connection
    return pymysql.connect(**self.get_connection_settings())
  File "/home/frappe/frappe-bench/env/lib/python3.10/site-packages/pymysql/connections.py", line 358, in __init__
    self.connect()
  File "/home/frappe/frappe-bench/env/lib/python3.10/site-packages/pymysql/connections.py", line 711, in connect
    raise exc
pymysql.err.OperationalError: (2003, "Can't connect to MySQL server on '127.0.0.1' ([Errno 111] Connection refused)")

During handling of the above exception, another exception occurred:

Traceback (most recent call last):
  File "/home/frappe/frappe-bench/env/lib/python3.10/site-packages/pymysql/connections.py", line 644, in connect
    sock = socket.create_connection(
  File "/usr/lib/python3.10/socket.py", line 845, in create_connection
    raise err
  File "/usr/lib/python3.10/socket.py", line 833, in create_connection
    sock.connect(sa)
ConnectionRefusedError: [Errno 111] Connection refused

During handling of the above exception, another exception occurred:

Traceback (most recent call last):
  File "/home/frappe/frappe-bench/apps/frappe/frappe/app.py", line 119, in application
    response = get_response()
  File "/home/frappe/frappe-bench/apps/frappe/frappe/website/serve.py", line 28, in get_response
    response = ErrorPage(exception=e).render()
  File "/home/frappe/frappe-bench/apps/frappe/frappe/website/page_renderers/template_page.py", line 84, in render
    html = self.get_html()
  File "/home/frappe/frappe-bench/apps/frappe/frappe/website/utils.py", line 523, in cache_html_decorator
    html = func(*args, **kwargs)
  File "/home/frappe/frappe-bench/apps/frappe/frappe/website/page_renderers/template_page.py", line 92, in get_html
    self.init_context()
  File "/home/frappe/frappe-bench/apps/frappe/frappe/website/page_renderers/error_page.py", line 14, in init_context
    super().init_context()
  File "/home/frappe/frappe-bench/apps/frappe/frappe/website/page_renderers/base_template_page.py", line 15, in init_context
    self.context.update(get_website_settings())
  File "/home/frappe/frappe-bench/apps/frappe/frappe/website/doctype/website_settings/website_settings.py", line 263, in get_website_settings
    context.boot = get_boot_data()
  File "/home/frappe/frappe-bench/apps/frappe/frappe/website/utils.py", line 179, in get_boot_data
    "user": frappe.db.get_value("User", frappe.session.user, "time_zone") or get_system_timezone(),
  File "/home/frappe/frappe-bench/apps/frappe/frappe/database/database.py", line 519, in get_value
    result = self.get_values(
  File "/home/frappe/frappe-bench/apps/frappe/frappe/database/database.py", line 623, in get_values
    out = self._get_values_from_table(
  File "/home/frappe/frappe-bench/apps/frappe/frappe/database/database.py", line 896, in _get_values_from_table
    return query.run(as_dict=as_dict, debug=debug, update=update, run=run, pluck=pluck)
  File "/home/frappe/frappe-bench/apps/frappe/frappe/query_builder/utils.py", line 87, in execute_query
    result = frappe.db.sql(query, params, *args, **kwargs)  # nosemgrep
  File "/home/frappe/frappe-bench/apps/frappe/frappe/database/database.py", line 211, in sql
    self.connect()
  File "/home/frappe/frappe-bench/apps/frappe/frappe/database/database.py", line 117, in connect
    self._conn: "MariadbConnection" | "PostgresConnection" = self.get_connection()
  File "/home/frappe/frappe-bench/apps/frappe/frappe/database/mariadb/database.py", line 107, in get_connection
    conn = self._get_connection()
  File "/home/frappe/frappe-bench/apps/frappe/frappe/database/mariadb/database.py", line 113, in _get_connection
    return self.create_connection()
  File "/home/frappe/frappe-bench/apps/frappe/frappe/database/mariadb/database.py", line 116, in create_connection
    return pymysql.connect(**self.get_connection_settings())
  File "/home/frappe/frappe-bench/env/lib/python3.10/site-packages/pymysql/connections.py", line 358, in __init__
    self.connect()
  File "/home/frappe/frappe-bench/env/lib/python3.10/site-packages/pymysql/connections.py", line 711, in connect
    raise exc
pymysql.err.OperationalError: (2003, "Can't connect to MySQL server on '127.0.0.1' ([Errno 111] Connection refused)")

During handling of the above exception, another exception occurred:

Traceback (most recent call last):
  File "/home/frappe/frappe-bench/env/lib/python3.10/site-packages/pymysql/connections.py", line 644, in connect
    sock = socket.create_connection(
  File "/usr/lib/python3.10/socket.py", line 845, in create_connection
    raise err
  File "/usr/lib/python3.10/socket.py", line 833, in create_connection
    sock.connect(sa)
ConnectionRefusedError: [Errno 111] Connection refused

During handling of the above exception, another exception occurred:

Traceback (most recent call last):
  File "/home/frappe/frappe-bench/apps/frappe/frappe/utils/error.py", line 86, in log_error_snapshot
    log_error(title=str(exception), defer_insert=True)
  File "/home/frappe/frappe-bench/apps/frappe/frappe/utils/error.py", line 61, in log_error
    error_log = frappe.get_doc(
  File "/home/frappe/frappe-bench/apps/frappe/frappe/__init__.py", line 1329, in get_doc
    doc = frappe.model.document.get_doc(*args, **kwargs)
  File "/home/frappe/frappe-bench/apps/frappe/frappe/model/document.py", line 83, in get_doc
    controller = get_controller(doctype)
  File "/home/frappe/frappe-bench/apps/frappe/frappe/model/base_document.py", line 70, in get_controller
    site_controllers[doctype] = import_controller(doctype)
  File "/home/frappe/frappe-bench/apps/frappe/frappe/model/base_document.py", line 81, in import_controller
    doctype_info = frappe.db.get_value("DocType", doctype, fieldname="*")
  File "/home/frappe/frappe-bench/apps/frappe/frappe/database/database.py", line 519, in get_value
    result = self.get_values(
  File "/home/frappe/frappe-bench/apps/frappe/frappe/database/database.py", line 623, in get_values
    out = self._get_values_from_table(
  File "/home/frappe/frappe-bench/apps/frappe/frappe/database/database.py", line 896, in _get_values_from_table
    return query.run(as_dict=as_dict, debug=debug, update=update, run=run, pluck=pluck)
  File "/home/frappe/frappe-bench/apps/frappe/frappe/query_builder/utils.py", line 87, in execute_query
    result = frappe.db.sql(query, params, *args, **kwargs)  # nosemgrep
  File "/home/frappe/frappe-bench/apps/frappe/frappe/database/database.py", line 211, in sql
    self.connect()
  File "/home/frappe/frappe-bench/apps/frappe/frappe/database/database.py", line 117, in connect
    self._conn: "MariadbConnection" | "PostgresConnection" = self.get_connection()
  File "/home/frappe/frappe-bench/apps/frappe/frappe/database/mariadb/database.py", line 107, in get_connection
    conn = self._get_connection()
  File "/home/frappe/frappe-bench/apps/frappe/frappe/database/mariadb/database.py", line 113, in _get_connection
    return self.create_connection()
  File "/home/frappe/frappe-bench/apps/frappe/frappe/database/mariadb/database.py", line 116, in create_connection
    return pymysql.connect(**self.get_connection_settings())
  File "/home/frappe/frappe-bench/env/lib/python3.10/site-packages/pymysql/connections.py", line 358, in __init__
    self.connect()
  File "/home/frappe/frappe-bench/env/lib/python3.10/site-packages/pymysql/connections.py", line 711, in connect
    raise exc
pymysql.err.OperationalError: (2003, "Can't connect to MySQL server on '127.0.0.1' ([Errno 111] Connection refused)")
2024-07-19 12:02:04,103 ERROR frappe Could not take error snapshot: (2003, "Can't connect to MySQL server on '127.0.0.1' ([Errno 111] Connection refused)")
Site: erp.grupoatu.com
Form Dict: {'txt': 'TORRENOVA TORREVIEJA, ', 'doctype': 'Supplier', 'ignore_user_permissions': '0', 'reference_doctype': 'Room', 'page_length': '10', 'cmd': 'frappe.desk.search.search_link'}
Traceback (most recent call last):
  File "/home/frappe/frappe-bench/env/lib/python3.10/site-packages/pymysql/connections.py", line 644, in connect
    sock = socket.create_connection(
  File "/usr/lib/python3.10/socket.py", line 845, in create_connection
    raise err
  File "/usr/lib/python3.10/socket.py", line 833, in create_connection
    sock.connect(sa)
ConnectionRefusedError: [Errno 111] Connection refused

During handling of the above exception, another exception occurred:

Traceback (most recent call last):
  File "/home/frappe/frappe-bench/apps/frappe/frappe/app.py", line 110, in application
    response = frappe.api.handle(request)
  File "/home/frappe/frappe-bench/apps/frappe/frappe/api/__init__.py", line 49, in handle
    data = endpoint(**arguments)
  File "/home/frappe/frappe-bench/apps/frappe/frappe/api/v1.py", line 36, in handle_rpc_call
    return frappe.handler.handle()
  File "/home/frappe/frappe-bench/apps/frappe/frappe/handler.py", line 49, in handle
    data = execute_cmd(cmd)
  File "/home/frappe/frappe-bench/apps/frappe/frappe/handler.py", line 85, in execute_cmd
    return frappe.call(method, **frappe.form_dict)
  File "/home/frappe/frappe-bench/apps/frappe/frappe/__init__.py", line 1761, in call
    return fn(*args, **newargs)
  File "/home/frappe/frappe-bench/apps/frappe/frappe/utils/typing_validations.py", line 31, in wrapper
    return func(*args, **kwargs)
  File "/home/frappe/frappe-bench/apps/frappe/frappe/desk/search.py", line 47, in search_link
    results = search_widget(
  File "/home/frappe/frappe-bench/apps/frappe/frappe/utils/typing_validations.py", line 31, in wrapper
    return func(*args, **kwargs)
  File "/home/frappe/frappe-bench/apps/frappe/frappe/desk/search.py", line 193, in search_widget
    values = frappe.get_list(
  File "/home/frappe/frappe-bench/apps/frappe/frappe/__init__.py", line 2025, in get_list
    return frappe.model.db_query.DatabaseQuery(doctype).execute(*args, **kwargs)
  File "/home/frappe/frappe-bench/apps/frappe/frappe/model/db_query.py", line 191, in execute
    result = self.build_and_run()
  File "/home/frappe/frappe-bench/apps/frappe/frappe/model/db_query.py", line 232, in build_and_run
    return frappe.db.sql(
  File "/home/frappe/frappe-bench/apps/frappe/frappe/database/database.py", line 211, in sql
    self.connect()
  File "/home/frappe/frappe-bench/apps/frappe/frappe/database/database.py", line 117, in connect
    self._conn: "MariadbConnection" | "PostgresConnection" = self.get_connection()
  File "/home/frappe/frappe-bench/apps/frappe/frappe/database/mariadb/database.py", line 107, in get_connection
    conn = self._get_connection()
  File "/home/frappe/frappe-bench/apps/frappe/frappe/database/mariadb/database.py", line 113, in _get_connection
    return self.create_connection()
  File "/home/frappe/frappe-bench/apps/frappe/frappe/database/mariadb/database.py", line 116, in create_connection
    return pymysql.connect(**self.get_connection_settings())
  File "/home/frappe/frappe-bench/env/lib/python3.10/site-packages/pymysql/connections.py", line 358, in __init__
    self.connect()
  File "/home/frappe/frappe-bench/env/lib/python3.10/site-packages/pymysql/connections.py", line 711, in connect
    raise exc
pymysql.err.OperationalError: (2003, "Can't connect to MySQL server on '127.0.0.1' ([Errno 111] Connection refused)")

During handling of the above exception, another exception occurred:

Traceback (most recent call last):
  File "/home/frappe/frappe-bench/env/lib/python3.10/site-packages/pymysql/connections.py", line 644, in connect
    sock = socket.create_connection(
  File "/usr/lib/python3.10/socket.py", line 845, in create_connection
    raise err
  File "/usr/lib/python3.10/socket.py", line 833, in create_connection
    sock.connect(sa)
ConnectionRefusedError: [Errno 111] Connection refused

During handling of the above exception, another exception occurred:

Traceback (most recent call last):
  File "/home/frappe/frappe-bench/apps/frappe/frappe/utils/error.py", line 86, in log_error_snapshot
    log_error(title=str(exception), defer_insert=True)
  File "/home/frappe/frappe-bench/apps/frappe/frappe/utils/error.py", line 61, in log_error
    error_log = frappe.get_doc(
  File "/home/frappe/frappe-bench/apps/frappe/frappe/__init__.py", line 1329, in get_doc
    doc = frappe.model.document.get_doc(*args, **kwargs)
  File "/home/frappe/frappe-bench/apps/frappe/frappe/model/document.py", line 83, in get_doc
    controller = get_controller(doctype)
  File "/home/frappe/frappe-bench/apps/frappe/frappe/model/base_document.py", line 70, in get_controller
    site_controllers[doctype] = import_controller(doctype)
  File "/home/frappe/frappe-bench/apps/frappe/frappe/model/base_document.py", line 81, in import_controller
    doctype_info = frappe.db.get_value("DocType", doctype, fieldname="*")
  File "/home/frappe/frappe-bench/apps/frappe/frappe/database/database.py", line 519, in get_value
    result = self.get_values(
  File "/home/frappe/frappe-bench/apps/frappe/frappe/database/database.py", line 623, in get_values
    out = self._get_values_from_table(
  File "/home/frappe/frappe-bench/apps/frappe/frappe/database/database.py", line 896, in _get_values_from_table
    return query.run(as_dict=as_dict, debug=debug, update=update, run=run, pluck=pluck)
  File "/home/frappe/frappe-bench/apps/frappe/frappe/query_builder/utils.py", line 87, in execute_query
    result = frappe.db.sql(query, params, *args, **kwargs)  # nosemgrep
  File "/home/frappe/frappe-bench/apps/frappe/frappe/database/database.py", line 211, in sql
    self.connect()
  File "/home/frappe/frappe-bench/apps/frappe/frappe/database/database.py", line 117, in connect
    self._conn: "MariadbConnection" | "PostgresConnection" = self.get_connection()
  File "/home/frappe/frappe-bench/apps/frappe/frappe/database/mariadb/database.py", line 107, in get_connection
    conn = self._get_connection()
  File "/home/frappe/frappe-bench/apps/frappe/frappe/database/mariadb/database.py", line 113, in _get_connection
    return self.create_connection()
  File "/home/frappe/frappe-bench/apps/frappe/frappe/database/mariadb/database.py", line 116, in create_connection
    return pymysql.connect(**self.get_connection_settings())
  File "/home/frappe/frappe-bench/env/lib/python3.10/site-packages/pymysql/connections.py", line 358, in __init__
    self.connect()
  File "/home/frappe/frappe-bench/env/lib/python3.10/site-packages/pymysql/connections.py", line 711, in connect
    raise exc
pymysql.err.OperationalError: (2003, "Can't connect to MySQL server on '127.0.0.1' ([Errno 111] Connection refused)")
