2024-07-25 10:42:00,510 ERROR frappe New Exception collected in error log
Site: erp.grupoatu.com
Form Dict: {'doctype': 'Course', 'name': 'Este curso de prueba', 'items': '["Program","Course Enrollment","Course Schedule","Student Group","Assessment Plan","Assessment Result"]', 'cmd': 'frappe.desk.notifications.get_open_count'}
2024-07-25 14:48:35,789 ERROR frappe New Exception collected in error log
Site: erp.grupoatu.com
Form Dict: {'doctype': 'Course', 'name': 'Este curso de prueba', 'items': '["Program","Course Enrollment","Course Schedule","Student Group","Assessment Plan","Assessment Result"]', 'cmd': 'frappe.desk.notifications.get_open_count'}
2024-07-26 07:42:06,828 ERROR frappe New Exception collected in error log
Site: erp.grupoatu.com
Form Dict: {'course': 'CUR-2024-00158', 'cmd': 'education.education.doctype.course.course.get_programs_without_course'}
2024-07-26 07:49:23,844 ERROR frappe New Exception collected in error log
Site: erp.grupoatu.com
Form Dict: {'doctype': 'Course', 'name': 'CUR-2024-01407', 'items': '["Program","Course Enrollment","Course Schedule","Student Group","Assessment Plan","Assessment Result"]', 'cmd': 'frappe.desk.notifications.get_open_count'}
2024-07-26 07:49:23,852 ERROR frappe New Exception collected in error log
Site: erp.grupoatu.com
Form Dict: {'doctype': 'Course', 'name': 'CUR-2024-01407', 'items': '["Program","Course Enrollment","Course Schedule","Student Group","Assessment Plan","Assessment Result"]', 'cmd': 'frappe.desk.notifications.get_open_count'}
2024-07-26 07:49:23,854 ERROR frappe New Exception collected in error log
Site: erp.grupoatu.com
Form Dict: {'doctype': 'Course', 'name': 'CUR-2024-01407', 'items': '["Program","Course Enrollment","Course Schedule","Student Group","Assessment Plan","Assessment Result"]', 'cmd': 'frappe.desk.notifications.get_open_count'}
2024-07-26 07:49:23,956 ERROR frappe New Exception collected in error log
Site: erp.grupoatu.com
Form Dict: {'doctype': 'Course', 'name': 'CUR-2024-01407', 'items': '["Program","Course Enrollment","Course Schedule","Student Group","Assessment Plan","Assessment Result"]', 'cmd': 'frappe.desk.notifications.get_open_count'}
2024-07-26 07:49:23,987 ERROR frappe New Exception collected in error log
Site: erp.grupoatu.com
Form Dict: {'doctype': 'Course', 'name': 'CUR-2024-01407', 'items': '["Program","Course Enrollment","Course Schedule","Student Group","Assessment Plan","Assessment Result"]', 'cmd': 'frappe.desk.notifications.get_open_count'}
2024-07-26 07:49:42,377 ERROR frappe New Exception collected in error log
Site: erp.grupoatu.com
Form Dict: {'doctype': 'Course', 'name': 'CUR-2024-01407', 'items': '["Program","Course Enrollment","Course Schedule","Student Group","Assessment Plan","Assessment Result"]', 'cmd': 'frappe.desk.notifications.get_open_count'}
2024-07-26 08:04:48,867 ERROR frappe New Exception collected in error log
Site: erp.grupoatu.com
Form Dict: {'doctype': 'Course', 'name': 'Este curso de prueba', 'items': '["Program","Course Enrollment","Course Schedule","Student Group","Assessment Plan","Assessment Result"]', 'cmd': 'frappe.desk.notifications.get_open_count'}
2024-07-26 08:13:18,739 ERROR frappe New Exception collected in error log
Site: erp.grupoatu.com
Form Dict: {'doctype': 'Course', 'name': 'CUR-2024-01350', 'items': '["Program","Course Enrollment","Course Schedule","Student Group","Assessment Plan","Assessment Result"]', 'cmd': 'frappe.desk.notifications.get_open_count'}
2024-07-26 08:46:42,462 ERROR frappe New Exception collected in error log
Site: erp.grupoatu.com
Form Dict: {'doctype': 'Course', 'name': 'CUR-2024-01417', 'items': '["Program","Course Enrollment","Course Schedule","Student Group","Assessment Plan","Assessment Result"]', 'cmd': 'frappe.desk.notifications.get_open_count'}
2024-07-26 08:46:47,893 ERROR frappe New Exception collected in error log
Site: erp.grupoatu.com
Form Dict: {'course': 'CUR-2024-01417', 'cmd': 'education.education.doctype.course.course.get_programs_without_course'}
2024-07-26 10:15:32,172 ERROR frappe New Exception collected in error log
Site: erp.grupoatu.com
Form Dict: {'cmd': 'filtrar_empleado'}
2024-07-26 10:45:36,637 ERROR frappe New Exception collected in error log
Site: erp.grupoatu.com
Form Dict: {'cmd': 'restringir_empleados'}
2024-07-26 17:54:10,410 ERROR frappe Could not take error snapshot: (1146, "Table '_098c566c1373ba13.tabSingles' doesn't exist")
Site: erp.grupoatu.com
Form Dict: {'name': 'user-profile'}
Traceback (most recent call last):
  File "/home/frappe/frappe-bench/apps/frappe/frappe/app.py", line 95, in application
    init_request(request)
  File "/home/frappe/frappe-bench/apps/frappe/frappe/app.py", line 191, in init_request
    frappe.local.http_request = HTTPRequest()
  File "/home/frappe/frappe-bench/apps/frappe/frappe/auth.py", line 42, in __init__
    self.set_session()
  File "/home/frappe/frappe-bench/apps/frappe/frappe/auth.py", line 76, in set_session
    frappe.local.login_manager = LoginManager()
  File "/home/frappe/frappe-bench/apps/frappe/frappe/auth.py", line 118, in __init__
    self.make_session(resume=True)
  File "/home/frappe/frappe-bench/apps/frappe/frappe/auth.py", line 204, in make_session
    frappe.local.session_obj = Session(
  File "/home/frappe/frappe-bench/apps/frappe/frappe/sessions.py", line 209, in __init__
    self.resume()
  File "/home/frappe/frappe-bench/apps/frappe/frappe/sessions.py", line 272, in resume
    data = self.get_session_record()
  File "/home/frappe/frappe-bench/apps/frappe/frappe/sessions.py", line 289, in get_session_record
    r = self.get_session_data()
  File "/home/frappe/frappe-bench/apps/frappe/frappe/sessions.py", line 305, in get_session_data
    data = self.get_session_data_from_db()
  File "/home/frappe/frappe-bench/apps/frappe/frappe/sessions.py", line 334, in get_session_data_from_db
    ).run()
  File "/home/frappe/frappe-bench/apps/frappe/frappe/query_builder/utils.py", line 87, in execute_query
    result = frappe.db.sql(query, params, *args, **kwargs)  # nosemgrep
  File "/home/frappe/frappe-bench/apps/frappe/frappe/database/database.py", line 234, in sql
    self._cursor.execute(query, values)
  File "/home/frappe/frappe-bench/env/lib/python3.10/site-packages/pymysql/cursors.py", line 153, in execute
    result = self._query(query)
  File "/home/frappe/frappe-bench/env/lib/python3.10/site-packages/pymysql/cursors.py", line 322, in _query
    conn.query(q)
  File "/home/frappe/frappe-bench/env/lib/python3.10/site-packages/pymysql/connections.py", line 558, in query
    self._affected_rows = self._read_query_result(unbuffered=unbuffered)
  File "/home/frappe/frappe-bench/env/lib/python3.10/site-packages/pymysql/connections.py", line 822, in _read_query_result
    result.read()
  File "/home/frappe/frappe-bench/env/lib/python3.10/site-packages/pymysql/connections.py", line 1200, in read
    first_packet = self.connection._read_packet()
  File "/home/frappe/frappe-bench/env/lib/python3.10/site-packages/pymysql/connections.py", line 772, in _read_packet
    packet.raise_for_error()
  File "/home/frappe/frappe-bench/env/lib/python3.10/site-packages/pymysql/protocol.py", line 221, in raise_for_error
    err.raise_mysql_exception(self._data)
  File "/home/frappe/frappe-bench/env/lib/python3.10/site-packages/pymysql/err.py", line 143, in raise_mysql_exception
    raise errorclass(errno, errval)
pymysql.err.ProgrammingError: (1146, "Table '_098c566c1373ba13.tabSessions' doesn't exist")

During handling of the above exception, another exception occurred:

Traceback (most recent call last):
  File "/home/frappe/frappe-bench/apps/frappe/frappe/database/database.py", line 623, in get_values
    out = self._get_values_from_table(
  File "/home/frappe/frappe-bench/apps/frappe/frappe/database/database.py", line 896, in _get_values_from_table
    return query.run(as_dict=as_dict, debug=debug, update=update, run=run, pluck=pluck)
  File "/home/frappe/frappe-bench/apps/frappe/frappe/query_builder/utils.py", line 87, in execute_query
    result = frappe.db.sql(query, params, *args, **kwargs)  # nosemgrep
  File "/home/frappe/frappe-bench/apps/frappe/frappe/database/database.py", line 234, in sql
    self._cursor.execute(query, values)
  File "/home/frappe/frappe-bench/env/lib/python3.10/site-packages/pymysql/cursors.py", line 153, in execute
    result = self._query(query)
  File "/home/frappe/frappe-bench/env/lib/python3.10/site-packages/pymysql/cursors.py", line 322, in _query
    conn.query(q)
  File "/home/frappe/frappe-bench/env/lib/python3.10/site-packages/pymysql/connections.py", line 558, in query
    self._affected_rows = self._read_query_result(unbuffered=unbuffered)
  File "/home/frappe/frappe-bench/env/lib/python3.10/site-packages/pymysql/connections.py", line 822, in _read_query_result
    result.read()
  File "/home/frappe/frappe-bench/env/lib/python3.10/site-packages/pymysql/connections.py", line 1200, in read
    first_packet = self.connection._read_packet()
  File "/home/frappe/frappe-bench/env/lib/python3.10/site-packages/pymysql/connections.py", line 772, in _read_packet
    packet.raise_for_error()
  File "/home/frappe/frappe-bench/env/lib/python3.10/site-packages/pymysql/protocol.py", line 221, in raise_for_error
    err.raise_mysql_exception(self._data)
  File "/home/frappe/frappe-bench/env/lib/python3.10/site-packages/pymysql/err.py", line 143, in raise_mysql_exception
    raise errorclass(errno, errval)
pymysql.err.ProgrammingError: (1146, "Table '_098c566c1373ba13.tabDocType' doesn't exist")

During handling of the above exception, another exception occurred:

Traceback (most recent call last):
  File "/home/frappe/frappe-bench/apps/frappe/frappe/utils/error.py", line 86, in log_error_snapshot
    log_error(title=str(exception), defer_insert=True)
  File "/home/frappe/frappe-bench/apps/frappe/frappe/utils/error.py", line 61, in log_error
    error_log = frappe.get_doc(
  File "/home/frappe/frappe-bench/apps/frappe/frappe/__init__.py", line 1329, in get_doc
    doc = frappe.model.document.get_doc(*args, **kwargs)
  File "/home/frappe/frappe-bench/apps/frappe/frappe/model/document.py", line 83, in get_doc
    controller = get_controller(doctype)
  File "/home/frappe/frappe-bench/apps/frappe/frappe/model/base_document.py", line 70, in get_controller
    site_controllers[doctype] = import_controller(doctype)
  File "/home/frappe/frappe-bench/apps/frappe/frappe/model/base_document.py", line 81, in import_controller
    doctype_info = frappe.db.get_value("DocType", doctype, fieldname="*")
  File "/home/frappe/frappe-bench/apps/frappe/frappe/database/database.py", line 519, in get_value
    result = self.get_values(
  File "/home/frappe/frappe-bench/apps/frappe/frappe/database/database.py", line 648, in get_values
    out = self.get_values_from_single(
  File "/home/frappe/frappe-bench/apps/frappe/frappe/database/database.py", line 685, in get_values_from_single
    values = self.get_singles_dict(doctype)
  File "/home/frappe/frappe-bench/apps/frappe/frappe/database/database.py", line 733, in get_singles_dict
    queried_result = frappe.qb.get_query(
  File "/home/frappe/frappe-bench/apps/frappe/frappe/query_builder/utils.py", line 87, in execute_query
    result = frappe.db.sql(query, params, *args, **kwargs)  # nosemgrep
  File "/home/frappe/frappe-bench/apps/frappe/frappe/database/database.py", line 234, in sql
    self._cursor.execute(query, values)
  File "/home/frappe/frappe-bench/env/lib/python3.10/site-packages/pymysql/cursors.py", line 153, in execute
    result = self._query(query)
  File "/home/frappe/frappe-bench/env/lib/python3.10/site-packages/pymysql/cursors.py", line 322, in _query
    conn.query(q)
  File "/home/frappe/frappe-bench/env/lib/python3.10/site-packages/pymysql/connections.py", line 558, in query
    self._affected_rows = self._read_query_result(unbuffered=unbuffered)
  File "/home/frappe/frappe-bench/env/lib/python3.10/site-packages/pymysql/connections.py", line 822, in _read_query_result
    result.read()
  File "/home/frappe/frappe-bench/env/lib/python3.10/site-packages/pymysql/connections.py", line 1200, in read
    first_packet = self.connection._read_packet()
  File "/home/frappe/frappe-bench/env/lib/python3.10/site-packages/pymysql/connections.py", line 772, in _read_packet
    packet.raise_for_error()
  File "/home/frappe/frappe-bench/env/lib/python3.10/site-packages/pymysql/protocol.py", line 221, in raise_for_error
    err.raise_mysql_exception(self._data)
  File "/home/frappe/frappe-bench/env/lib/python3.10/site-packages/pymysql/err.py", line 143, in raise_mysql_exception
    raise errorclass(errno, errval)
pymysql.err.ProgrammingError: (1146, "Table '_098c566c1373ba13.tabSingles' doesn't exist")
2024-07-26 17:54:14,840 ERROR frappe Could not take error snapshot: (1146, "Table '_098c566c1373ba13.tabSingles' doesn't exist")
Site: erp.grupoatu.com
Form Dict: {}
Traceback (most recent call last):
  File "/home/frappe/frappe-bench/apps/frappe/frappe/database/database.py", line 623, in get_values
    out = self._get_values_from_table(
  File "/home/frappe/frappe-bench/apps/frappe/frappe/database/database.py", line 896, in _get_values_from_table
    return query.run(as_dict=as_dict, debug=debug, update=update, run=run, pluck=pluck)
  File "/home/frappe/frappe-bench/apps/frappe/frappe/query_builder/utils.py", line 87, in execute_query
    result = frappe.db.sql(query, params, *args, **kwargs)  # nosemgrep
  File "/home/frappe/frappe-bench/apps/frappe/frappe/database/database.py", line 234, in sql
    self._cursor.execute(query, values)
  File "/home/frappe/frappe-bench/env/lib/python3.10/site-packages/pymysql/cursors.py", line 153, in execute
    result = self._query(query)
  File "/home/frappe/frappe-bench/env/lib/python3.10/site-packages/pymysql/cursors.py", line 322, in _query
    conn.query(q)
  File "/home/frappe/frappe-bench/env/lib/python3.10/site-packages/pymysql/connections.py", line 558, in query
    self._affected_rows = self._read_query_result(unbuffered=unbuffered)
  File "/home/frappe/frappe-bench/env/lib/python3.10/site-packages/pymysql/connections.py", line 822, in _read_query_result
    result.read()
  File "/home/frappe/frappe-bench/env/lib/python3.10/site-packages/pymysql/connections.py", line 1200, in read
    first_packet = self.connection._read_packet()
  File "/home/frappe/frappe-bench/env/lib/python3.10/site-packages/pymysql/connections.py", line 772, in _read_packet
    packet.raise_for_error()
  File "/home/frappe/frappe-bench/env/lib/python3.10/site-packages/pymysql/protocol.py", line 221, in raise_for_error
    err.raise_mysql_exception(self._data)
  File "/home/frappe/frappe-bench/env/lib/python3.10/site-packages/pymysql/err.py", line 143, in raise_mysql_exception
    raise errorclass(errno, errval)
pymysql.err.ProgrammingError: (1146, "Table '_098c566c1373ba13.tabDocType' doesn't exist")

During handling of the above exception, another exception occurred:

Traceback (most recent call last):
  File "/home/frappe/frappe-bench/apps/frappe/frappe/website/serve.py", line 19, in get_response
    endpoint, renderer_instance = path_resolver.resolve()
  File "/home/frappe/frappe-bench/apps/frappe/frappe/website/path_resolver.py", line 38, in resolve
    resolve_redirect(self.path, request.query_string)
  File "/home/frappe/frappe-bench/apps/frappe/frappe/website/path_resolver.py", line 118, in resolve_redirect
    redirects += frappe.get_all("Website Route Redirect", ["source", "target"], order_by=None)
  File "/home/frappe/frappe-bench/apps/frappe/frappe/__init__.py", line 2050, in get_all
    return get_list(doctype, *args, **kwargs)
  File "/home/frappe/frappe-bench/apps/frappe/frappe/__init__.py", line 2025, in get_list
    return frappe.model.db_query.DatabaseQuery(doctype).execute(*args, **kwargs)
  File "/home/frappe/frappe-bench/apps/frappe/frappe/model/db_query.py", line 167, in execute
    if is_virtual_doctype(self.doctype):
  File "/home/frappe/frappe-bench/apps/frappe/frappe/utils/caching.py", line 119, in site_cache_wrapper
    _SITE_CACHE[func_key][frappe.local.site][func_call_key] = func(*args, **kwargs)
  File "/home/frappe/frappe-bench/apps/frappe/frappe/model/utils/__init__.py", line 133, in is_virtual_doctype
    return frappe.db.get_value("DocType", doctype, "is_virtual")
  File "/home/frappe/frappe-bench/apps/frappe/frappe/database/database.py", line 519, in get_value
    result = self.get_values(
  File "/home/frappe/frappe-bench/apps/frappe/frappe/database/database.py", line 648, in get_values
    out = self.get_values_from_single(
  File "/home/frappe/frappe-bench/apps/frappe/frappe/database/database.py", line 698, in get_values_from_single
    r = frappe.qb.get_query(
  File "/home/frappe/frappe-bench/apps/frappe/frappe/query_builder/utils.py", line 87, in execute_query
    result = frappe.db.sql(query, params, *args, **kwargs)  # nosemgrep
  File "/home/frappe/frappe-bench/apps/frappe/frappe/database/database.py", line 234, in sql
    self._cursor.execute(query, values)
  File "/home/frappe/frappe-bench/env/lib/python3.10/site-packages/pymysql/cursors.py", line 153, in execute
    result = self._query(query)
  File "/home/frappe/frappe-bench/env/lib/python3.10/site-packages/pymysql/cursors.py", line 322, in _query
    conn.query(q)
  File "/home/frappe/frappe-bench/env/lib/python3.10/site-packages/pymysql/connections.py", line 558, in query
    self._affected_rows = self._read_query_result(unbuffered=unbuffered)
  File "/home/frappe/frappe-bench/env/lib/python3.10/site-packages/pymysql/connections.py", line 822, in _read_query_result
    result.read()
  File "/home/frappe/frappe-bench/env/lib/python3.10/site-packages/pymysql/connections.py", line 1200, in read
    first_packet = self.connection._read_packet()
  File "/home/frappe/frappe-bench/env/lib/python3.10/site-packages/pymysql/connections.py", line 772, in _read_packet
    packet.raise_for_error()
  File "/home/frappe/frappe-bench/env/lib/python3.10/site-packages/pymysql/protocol.py", line 221, in raise_for_error
    err.raise_mysql_exception(self._data)
  File "/home/frappe/frappe-bench/env/lib/python3.10/site-packages/pymysql/err.py", line 143, in raise_mysql_exception
    raise errorclass(errno, errval)
pymysql.err.ProgrammingError: (1146, "Table '_098c566c1373ba13.tabSingles' doesn't exist")

During handling of the above exception, another exception occurred:

Traceback (most recent call last):
  File "/home/frappe/frappe-bench/apps/frappe/frappe/database/database.py", line 623, in get_values
    out = self._get_values_from_table(
  File "/home/frappe/frappe-bench/apps/frappe/frappe/database/database.py", line 896, in _get_values_from_table
    return query.run(as_dict=as_dict, debug=debug, update=update, run=run, pluck=pluck)
  File "/home/frappe/frappe-bench/apps/frappe/frappe/query_builder/utils.py", line 87, in execute_query
    result = frappe.db.sql(query, params, *args, **kwargs)  # nosemgrep
  File "/home/frappe/frappe-bench/apps/frappe/frappe/database/database.py", line 234, in sql
    self._cursor.execute(query, values)
  File "/home/frappe/frappe-bench/env/lib/python3.10/site-packages/pymysql/cursors.py", line 153, in execute
    result = self._query(query)
  File "/home/frappe/frappe-bench/env/lib/python3.10/site-packages/pymysql/cursors.py", line 322, in _query
    conn.query(q)
  File "/home/frappe/frappe-bench/env/lib/python3.10/site-packages/pymysql/connections.py", line 558, in query
    self._affected_rows = self._read_query_result(unbuffered=unbuffered)
  File "/home/frappe/frappe-bench/env/lib/python3.10/site-packages/pymysql/connections.py", line 822, in _read_query_result
    result.read()
  File "/home/frappe/frappe-bench/env/lib/python3.10/site-packages/pymysql/connections.py", line 1200, in read
    first_packet = self.connection._read_packet()
  File "/home/frappe/frappe-bench/env/lib/python3.10/site-packages/pymysql/connections.py", line 772, in _read_packet
    packet.raise_for_error()
  File "/home/frappe/frappe-bench/env/lib/python3.10/site-packages/pymysql/protocol.py", line 221, in raise_for_error
    err.raise_mysql_exception(self._data)
  File "/home/frappe/frappe-bench/env/lib/python3.10/site-packages/pymysql/err.py", line 143, in raise_mysql_exception
    raise errorclass(errno, errval)
pymysql.err.ProgrammingError: (1146, "Table '_098c566c1373ba13.tabUser' doesn't exist")

During handling of the above exception, another exception occurred:

Traceback (most recent call last):
  File "/home/frappe/frappe-bench/apps/frappe/frappe/app.py", line 119, in application
    response = get_response()
  File "/home/frappe/frappe-bench/apps/frappe/frappe/website/serve.py", line 28, in get_response
    response = ErrorPage(exception=e).render()
  File "/home/frappe/frappe-bench/apps/frappe/frappe/website/page_renderers/template_page.py", line 84, in render
    html = self.get_html()
  File "/home/frappe/frappe-bench/apps/frappe/frappe/website/utils.py", line 523, in cache_html_decorator
    html = func(*args, **kwargs)
  File "/home/frappe/frappe-bench/apps/frappe/frappe/website/page_renderers/template_page.py", line 92, in get_html
    self.init_context()
  File "/home/frappe/frappe-bench/apps/frappe/frappe/website/page_renderers/error_page.py", line 14, in init_context
    super().init_context()
  File "/home/frappe/frappe-bench/apps/frappe/frappe/website/page_renderers/base_template_page.py", line 15, in init_context
    self.context.update(get_website_settings())
  File "/home/frappe/frappe-bench/apps/frappe/frappe/website/doctype/website_settings/website_settings.py", line 263, in get_website_settings
    context.boot = get_boot_data()
  File "/home/frappe/frappe-bench/apps/frappe/frappe/website/utils.py", line 179, in get_boot_data
    "user": frappe.db.get_value("User", frappe.session.user, "time_zone") or get_system_timezone(),
  File "/home/frappe/frappe-bench/apps/frappe/frappe/database/database.py", line 519, in get_value
    result = self.get_values(
  File "/home/frappe/frappe-bench/apps/frappe/frappe/database/database.py", line 648, in get_values
    out = self.get_values_from_single(
  File "/home/frappe/frappe-bench/apps/frappe/frappe/database/database.py", line 698, in get_values_from_single
    r = frappe.qb.get_query(
  File "/home/frappe/frappe-bench/apps/frappe/frappe/query_builder/utils.py", line 87, in execute_query
    result = frappe.db.sql(query, params, *args, **kwargs)  # nosemgrep
  File "/home/frappe/frappe-bench/apps/frappe/frappe/database/database.py", line 234, in sql
    self._cursor.execute(query, values)
  File "/home/frappe/frappe-bench/env/lib/python3.10/site-packages/pymysql/cursors.py", line 153, in execute
    result = self._query(query)
  File "/home/frappe/frappe-bench/env/lib/python3.10/site-packages/pymysql/cursors.py", line 322, in _query
    conn.query(q)
  File "/home/frappe/frappe-bench/env/lib/python3.10/site-packages/pymysql/connections.py", line 558, in query
    self._affected_rows = self._read_query_result(unbuffered=unbuffered)
  File "/home/frappe/frappe-bench/env/lib/python3.10/site-packages/pymysql/connections.py", line 822, in _read_query_result
    result.read()
  File "/home/frappe/frappe-bench/env/lib/python3.10/site-packages/pymysql/connections.py", line 1200, in read
    first_packet = self.connection._read_packet()
  File "/home/frappe/frappe-bench/env/lib/python3.10/site-packages/pymysql/connections.py", line 772, in _read_packet
    packet.raise_for_error()
  File "/home/frappe/frappe-bench/env/lib/python3.10/site-packages/pymysql/protocol.py", line 221, in raise_for_error
    err.raise_mysql_exception(self._data)
  File "/home/frappe/frappe-bench/env/lib/python3.10/site-packages/pymysql/err.py", line 143, in raise_mysql_exception
    raise errorclass(errno, errval)
pymysql.err.ProgrammingError: (1146, "Table '_098c566c1373ba13.tabSingles' doesn't exist")

During handling of the above exception, another exception occurred:

Traceback (most recent call last):
  File "/home/frappe/frappe-bench/apps/frappe/frappe/database/database.py", line 623, in get_values
    out = self._get_values_from_table(
  File "/home/frappe/frappe-bench/apps/frappe/frappe/database/database.py", line 896, in _get_values_from_table
    return query.run(as_dict=as_dict, debug=debug, update=update, run=run, pluck=pluck)
  File "/home/frappe/frappe-bench/apps/frappe/frappe/query_builder/utils.py", line 87, in execute_query
    result = frappe.db.sql(query, params, *args, **kwargs)  # nosemgrep
  File "/home/frappe/frappe-bench/apps/frappe/frappe/database/database.py", line 234, in sql
    self._cursor.execute(query, values)
  File "/home/frappe/frappe-bench/env/lib/python3.10/site-packages/pymysql/cursors.py", line 153, in execute
    result = self._query(query)
  File "/home/frappe/frappe-bench/env/lib/python3.10/site-packages/pymysql/cursors.py", line 322, in _query
    conn.query(q)
  File "/home/frappe/frappe-bench/env/lib/python3.10/site-packages/pymysql/connections.py", line 558, in query
    self._affected_rows = self._read_query_result(unbuffered=unbuffered)
  File "/home/frappe/frappe-bench/env/lib/python3.10/site-packages/pymysql/connections.py", line 822, in _read_query_result
    result.read()
  File "/home/frappe/frappe-bench/env/lib/python3.10/site-packages/pymysql/connections.py", line 1200, in read
    first_packet = self.connection._read_packet()
  File "/home/frappe/frappe-bench/env/lib/python3.10/site-packages/pymysql/connections.py", line 772, in _read_packet
    packet.raise_for_error()
  File "/home/frappe/frappe-bench/env/lib/python3.10/site-packages/pymysql/protocol.py", line 221, in raise_for_error
    err.raise_mysql_exception(self._data)
  File "/home/frappe/frappe-bench/env/lib/python3.10/site-packages/pymysql/err.py", line 143, in raise_mysql_exception
    raise errorclass(errno, errval)
pymysql.err.ProgrammingError: (1146, "Table '_098c566c1373ba13.tabDocType' doesn't exist")

During handling of the above exception, another exception occurred:

Traceback (most recent call last):
  File "/home/frappe/frappe-bench/apps/frappe/frappe/utils/error.py", line 86, in log_error_snapshot
    log_error(title=str(exception), defer_insert=True)
  File "/home/frappe/frappe-bench/apps/frappe/frappe/utils/error.py", line 61, in log_error
    error_log = frappe.get_doc(
  File "/home/frappe/frappe-bench/apps/frappe/frappe/__init__.py", line 1329, in get_doc
    doc = frappe.model.document.get_doc(*args, **kwargs)
  File "/home/frappe/frappe-bench/apps/frappe/frappe/model/document.py", line 83, in get_doc
    controller = get_controller(doctype)
  File "/home/frappe/frappe-bench/apps/frappe/frappe/model/base_document.py", line 70, in get_controller
    site_controllers[doctype] = import_controller(doctype)
  File "/home/frappe/frappe-bench/apps/frappe/frappe/model/base_document.py", line 81, in import_controller
    doctype_info = frappe.db.get_value("DocType", doctype, fieldname="*")
  File "/home/frappe/frappe-bench/apps/frappe/frappe/database/database.py", line 519, in get_value
    result = self.get_values(
  File "/home/frappe/frappe-bench/apps/frappe/frappe/database/database.py", line 648, in get_values
    out = self.get_values_from_single(
  File "/home/frappe/frappe-bench/apps/frappe/frappe/database/database.py", line 685, in get_values_from_single
    values = self.get_singles_dict(doctype)
  File "/home/frappe/frappe-bench/apps/frappe/frappe/database/database.py", line 733, in get_singles_dict
    queried_result = frappe.qb.get_query(
  File "/home/frappe/frappe-bench/apps/frappe/frappe/query_builder/utils.py", line 87, in execute_query
    result = frappe.db.sql(query, params, *args, **kwargs)  # nosemgrep
  File "/home/frappe/frappe-bench/apps/frappe/frappe/database/database.py", line 234, in sql
    self._cursor.execute(query, values)
  File "/home/frappe/frappe-bench/env/lib/python3.10/site-packages/pymysql/cursors.py", line 153, in execute
    result = self._query(query)
  File "/home/frappe/frappe-bench/env/lib/python3.10/site-packages/pymysql/cursors.py", line 322, in _query
    conn.query(q)
  File "/home/frappe/frappe-bench/env/lib/python3.10/site-packages/pymysql/connections.py", line 558, in query
    self._affected_rows = self._read_query_result(unbuffered=unbuffered)
  File "/home/frappe/frappe-bench/env/lib/python3.10/site-packages/pymysql/connections.py", line 822, in _read_query_result
    result.read()
  File "/home/frappe/frappe-bench/env/lib/python3.10/site-packages/pymysql/connections.py", line 1200, in read
    first_packet = self.connection._read_packet()
  File "/home/frappe/frappe-bench/env/lib/python3.10/site-packages/pymysql/connections.py", line 772, in _read_packet
    packet.raise_for_error()
  File "/home/frappe/frappe-bench/env/lib/python3.10/site-packages/pymysql/protocol.py", line 221, in raise_for_error
    err.raise_mysql_exception(self._data)
  File "/home/frappe/frappe-bench/env/lib/python3.10/site-packages/pymysql/err.py", line 143, in raise_mysql_exception
    raise errorclass(errno, errval)
pymysql.err.ProgrammingError: (1146, "Table '_098c566c1373ba13.tabSingles' doesn't exist")
2024-07-26 17:54:15,170 ERROR frappe Could not take error snapshot: (1146, "Table '_098c566c1373ba13.tabSingles' doesn't exist")
Site: erp.grupoatu.com
Form Dict: {}
Traceback (most recent call last):
  File "/home/frappe/frappe-bench/apps/frappe/frappe/database/database.py", line 623, in get_values
    out = self._get_values_from_table(
  File "/home/frappe/frappe-bench/apps/frappe/frappe/database/database.py", line 896, in _get_values_from_table
    return query.run(as_dict=as_dict, debug=debug, update=update, run=run, pluck=pluck)
  File "/home/frappe/frappe-bench/apps/frappe/frappe/query_builder/utils.py", line 87, in execute_query
    result = frappe.db.sql(query, params, *args, **kwargs)  # nosemgrep
  File "/home/frappe/frappe-bench/apps/frappe/frappe/database/database.py", line 234, in sql
    self._cursor.execute(query, values)
  File "/home/frappe/frappe-bench/env/lib/python3.10/site-packages/pymysql/cursors.py", line 153, in execute
    result = self._query(query)
  File "/home/frappe/frappe-bench/env/lib/python3.10/site-packages/pymysql/cursors.py", line 322, in _query
    conn.query(q)
  File "/home/frappe/frappe-bench/env/lib/python3.10/site-packages/pymysql/connections.py", line 558, in query
    self._affected_rows = self._read_query_result(unbuffered=unbuffered)
  File "/home/frappe/frappe-bench/env/lib/python3.10/site-packages/pymysql/connections.py", line 822, in _read_query_result
    result.read()
  File "/home/frappe/frappe-bench/env/lib/python3.10/site-packages/pymysql/connections.py", line 1200, in read
    first_packet = self.connection._read_packet()
  File "/home/frappe/frappe-bench/env/lib/python3.10/site-packages/pymysql/connections.py", line 772, in _read_packet
    packet.raise_for_error()
  File "/home/frappe/frappe-bench/env/lib/python3.10/site-packages/pymysql/protocol.py", line 221, in raise_for_error
    err.raise_mysql_exception(self._data)
  File "/home/frappe/frappe-bench/env/lib/python3.10/site-packages/pymysql/err.py", line 143, in raise_mysql_exception
    raise errorclass(errno, errval)
pymysql.err.ProgrammingError: (1146, "Table '_098c566c1373ba13.tabDocType' doesn't exist")

During handling of the above exception, another exception occurred:

Traceback (most recent call last):
  File "/home/frappe/frappe-bench/apps/frappe/frappe/website/serve.py", line 19, in get_response
    endpoint, renderer_instance = path_resolver.resolve()
  File "/home/frappe/frappe-bench/apps/frappe/frappe/website/path_resolver.py", line 38, in resolve
    resolve_redirect(self.path, request.query_string)
  File "/home/frappe/frappe-bench/apps/frappe/frappe/website/path_resolver.py", line 118, in resolve_redirect
    redirects += frappe.get_all("Website Route Redirect", ["source", "target"], order_by=None)
  File "/home/frappe/frappe-bench/apps/frappe/frappe/__init__.py", line 2050, in get_all
    return get_list(doctype, *args, **kwargs)
  File "/home/frappe/frappe-bench/apps/frappe/frappe/__init__.py", line 2025, in get_list
    return frappe.model.db_query.DatabaseQuery(doctype).execute(*args, **kwargs)
  File "/home/frappe/frappe-bench/apps/frappe/frappe/model/db_query.py", line 167, in execute
    if is_virtual_doctype(self.doctype):
  File "/home/frappe/frappe-bench/apps/frappe/frappe/utils/caching.py", line 119, in site_cache_wrapper
    _SITE_CACHE[func_key][frappe.local.site][func_call_key] = func(*args, **kwargs)
  File "/home/frappe/frappe-bench/apps/frappe/frappe/model/utils/__init__.py", line 133, in is_virtual_doctype
    return frappe.db.get_value("DocType", doctype, "is_virtual")
  File "/home/frappe/frappe-bench/apps/frappe/frappe/database/database.py", line 519, in get_value
    result = self.get_values(
  File "/home/frappe/frappe-bench/apps/frappe/frappe/database/database.py", line 648, in get_values
    out = self.get_values_from_single(
  File "/home/frappe/frappe-bench/apps/frappe/frappe/database/database.py", line 698, in get_values_from_single
    r = frappe.qb.get_query(
  File "/home/frappe/frappe-bench/apps/frappe/frappe/query_builder/utils.py", line 87, in execute_query
    result = frappe.db.sql(query, params, *args, **kwargs)  # nosemgrep
  File "/home/frappe/frappe-bench/apps/frappe/frappe/database/database.py", line 234, in sql
    self._cursor.execute(query, values)
  File "/home/frappe/frappe-bench/env/lib/python3.10/site-packages/pymysql/cursors.py", line 153, in execute
    result = self._query(query)
  File "/home/frappe/frappe-bench/env/lib/python3.10/site-packages/pymysql/cursors.py", line 322, in _query
    conn.query(q)
  File "/home/frappe/frappe-bench/env/lib/python3.10/site-packages/pymysql/connections.py", line 558, in query
    self._affected_rows = self._read_query_result(unbuffered=unbuffered)
  File "/home/frappe/frappe-bench/env/lib/python3.10/site-packages/pymysql/connections.py", line 822, in _read_query_result
    result.read()
  File "/home/frappe/frappe-bench/env/lib/python3.10/site-packages/pymysql/connections.py", line 1200, in read
    first_packet = self.connection._read_packet()
  File "/home/frappe/frappe-bench/env/lib/python3.10/site-packages/pymysql/connections.py", line 772, in _read_packet
    packet.raise_for_error()
  File "/home/frappe/frappe-bench/env/lib/python3.10/site-packages/pymysql/protocol.py", line 221, in raise_for_error
    err.raise_mysql_exception(self._data)
  File "/home/frappe/frappe-bench/env/lib/python3.10/site-packages/pymysql/err.py", line 143, in raise_mysql_exception
    raise errorclass(errno, errval)
pymysql.err.ProgrammingError: (1146, "Table '_098c566c1373ba13.tabSingles' doesn't exist")

During handling of the above exception, another exception occurred:

Traceback (most recent call last):
  File "/home/frappe/frappe-bench/apps/frappe/frappe/database/database.py", line 623, in get_values
    out = self._get_values_from_table(
  File "/home/frappe/frappe-bench/apps/frappe/frappe/database/database.py", line 896, in _get_values_from_table
    return query.run(as_dict=as_dict, debug=debug, update=update, run=run, pluck=pluck)
  File "/home/frappe/frappe-bench/apps/frappe/frappe/query_builder/utils.py", line 87, in execute_query
    result = frappe.db.sql(query, params, *args, **kwargs)  # nosemgrep
  File "/home/frappe/frappe-bench/apps/frappe/frappe/database/database.py", line 234, in sql
    self._cursor.execute(query, values)
  File "/home/frappe/frappe-bench/env/lib/python3.10/site-packages/pymysql/cursors.py", line 153, in execute
    result = self._query(query)
  File "/home/frappe/frappe-bench/env/lib/python3.10/site-packages/pymysql/cursors.py", line 322, in _query
    conn.query(q)
  File "/home/frappe/frappe-bench/env/lib/python3.10/site-packages/pymysql/connections.py", line 558, in query
    self._affected_rows = self._read_query_result(unbuffered=unbuffered)
  File "/home/frappe/frappe-bench/env/lib/python3.10/site-packages/pymysql/connections.py", line 822, in _read_query_result
    result.read()
  File "/home/frappe/frappe-bench/env/lib/python3.10/site-packages/pymysql/connections.py", line 1200, in read
    first_packet = self.connection._read_packet()
  File "/home/frappe/frappe-bench/env/lib/python3.10/site-packages/pymysql/connections.py", line 772, in _read_packet
    packet.raise_for_error()
  File "/home/frappe/frappe-bench/env/lib/python3.10/site-packages/pymysql/protocol.py", line 221, in raise_for_error
    err.raise_mysql_exception(self._data)
  File "/home/frappe/frappe-bench/env/lib/python3.10/site-packages/pymysql/err.py", line 143, in raise_mysql_exception
    raise errorclass(errno, errval)
pymysql.err.ProgrammingError: (1146, "Table '_098c566c1373ba13.tabUser' doesn't exist")

During handling of the above exception, another exception occurred:

Traceback (most recent call last):
  File "/home/frappe/frappe-bench/apps/frappe/frappe/app.py", line 119, in application
    response = get_response()
  File "/home/frappe/frappe-bench/apps/frappe/frappe/website/serve.py", line 28, in get_response
    response = ErrorPage(exception=e).render()
  File "/home/frappe/frappe-bench/apps/frappe/frappe/website/page_renderers/template_page.py", line 84, in render
    html = self.get_html()
  File "/home/frappe/frappe-bench/apps/frappe/frappe/website/utils.py", line 523, in cache_html_decorator
    html = func(*args, **kwargs)
  File "/home/frappe/frappe-bench/apps/frappe/frappe/website/page_renderers/template_page.py", line 92, in get_html
    self.init_context()
  File "/home/frappe/frappe-bench/apps/frappe/frappe/website/page_renderers/error_page.py", line 14, in init_context
    super().init_context()
  File "/home/frappe/frappe-bench/apps/frappe/frappe/website/page_renderers/base_template_page.py", line 15, in init_context
    self.context.update(get_website_settings())
  File "/home/frappe/frappe-bench/apps/frappe/frappe/website/doctype/website_settings/website_settings.py", line 263, in get_website_settings
    context.boot = get_boot_data()
  File "/home/frappe/frappe-bench/apps/frappe/frappe/website/utils.py", line 179, in get_boot_data
    "user": frappe.db.get_value("User", frappe.session.user, "time_zone") or get_system_timezone(),
  File "/home/frappe/frappe-bench/apps/frappe/frappe/database/database.py", line 519, in get_value
    result = self.get_values(
  File "/home/frappe/frappe-bench/apps/frappe/frappe/database/database.py", line 648, in get_values
    out = self.get_values_from_single(
  File "/home/frappe/frappe-bench/apps/frappe/frappe/database/database.py", line 698, in get_values_from_single
    r = frappe.qb.get_query(
  File "/home/frappe/frappe-bench/apps/frappe/frappe/query_builder/utils.py", line 87, in execute_query
    result = frappe.db.sql(query, params, *args, **kwargs)  # nosemgrep
  File "/home/frappe/frappe-bench/apps/frappe/frappe/database/database.py", line 234, in sql
    self._cursor.execute(query, values)
  File "/home/frappe/frappe-bench/env/lib/python3.10/site-packages/pymysql/cursors.py", line 153, in execute
    result = self._query(query)
  File "/home/frappe/frappe-bench/env/lib/python3.10/site-packages/pymysql/cursors.py", line 322, in _query
    conn.query(q)
  File "/home/frappe/frappe-bench/env/lib/python3.10/site-packages/pymysql/connections.py", line 558, in query
    self._affected_rows = self._read_query_result(unbuffered=unbuffered)
  File "/home/frappe/frappe-bench/env/lib/python3.10/site-packages/pymysql/connections.py", line 822, in _read_query_result
    result.read()
  File "/home/frappe/frappe-bench/env/lib/python3.10/site-packages/pymysql/connections.py", line 1200, in read
    first_packet = self.connection._read_packet()
  File "/home/frappe/frappe-bench/env/lib/python3.10/site-packages/pymysql/connections.py", line 772, in _read_packet
    packet.raise_for_error()
  File "/home/frappe/frappe-bench/env/lib/python3.10/site-packages/pymysql/protocol.py", line 221, in raise_for_error
    err.raise_mysql_exception(self._data)
  File "/home/frappe/frappe-bench/env/lib/python3.10/site-packages/pymysql/err.py", line 143, in raise_mysql_exception
    raise errorclass(errno, errval)
pymysql.err.ProgrammingError: (1146, "Table '_098c566c1373ba13.tabSingles' doesn't exist")

During handling of the above exception, another exception occurred:

Traceback (most recent call last):
  File "/home/frappe/frappe-bench/apps/frappe/frappe/database/database.py", line 623, in get_values
    out = self._get_values_from_table(
  File "/home/frappe/frappe-bench/apps/frappe/frappe/database/database.py", line 896, in _get_values_from_table
    return query.run(as_dict=as_dict, debug=debug, update=update, run=run, pluck=pluck)
  File "/home/frappe/frappe-bench/apps/frappe/frappe/query_builder/utils.py", line 87, in execute_query
    result = frappe.db.sql(query, params, *args, **kwargs)  # nosemgrep
  File "/home/frappe/frappe-bench/apps/frappe/frappe/database/database.py", line 234, in sql
    self._cursor.execute(query, values)
  File "/home/frappe/frappe-bench/env/lib/python3.10/site-packages/pymysql/cursors.py", line 153, in execute
    result = self._query(query)
  File "/home/frappe/frappe-bench/env/lib/python3.10/site-packages/pymysql/cursors.py", line 322, in _query
    conn.query(q)
  File "/home/frappe/frappe-bench/env/lib/python3.10/site-packages/pymysql/connections.py", line 558, in query
    self._affected_rows = self._read_query_result(unbuffered=unbuffered)
  File "/home/frappe/frappe-bench/env/lib/python3.10/site-packages/pymysql/connections.py", line 822, in _read_query_result
    result.read()
  File "/home/frappe/frappe-bench/env/lib/python3.10/site-packages/pymysql/connections.py", line 1200, in read
    first_packet = self.connection._read_packet()
  File "/home/frappe/frappe-bench/env/lib/python3.10/site-packages/pymysql/connections.py", line 772, in _read_packet
    packet.raise_for_error()
  File "/home/frappe/frappe-bench/env/lib/python3.10/site-packages/pymysql/protocol.py", line 221, in raise_for_error
    err.raise_mysql_exception(self._data)
  File "/home/frappe/frappe-bench/env/lib/python3.10/site-packages/pymysql/err.py", line 143, in raise_mysql_exception
    raise errorclass(errno, errval)
pymysql.err.ProgrammingError: (1146, "Table '_098c566c1373ba13.tabDocType' doesn't exist")

During handling of the above exception, another exception occurred:

Traceback (most recent call last):
  File "/home/frappe/frappe-bench/apps/frappe/frappe/utils/error.py", line 86, in log_error_snapshot
    log_error(title=str(exception), defer_insert=True)
  File "/home/frappe/frappe-bench/apps/frappe/frappe/utils/error.py", line 61, in log_error
    error_log = frappe.get_doc(
  File "/home/frappe/frappe-bench/apps/frappe/frappe/__init__.py", line 1329, in get_doc
    doc = frappe.model.document.get_doc(*args, **kwargs)
  File "/home/frappe/frappe-bench/apps/frappe/frappe/model/document.py", line 83, in get_doc
    controller = get_controller(doctype)
  File "/home/frappe/frappe-bench/apps/frappe/frappe/model/base_document.py", line 70, in get_controller
    site_controllers[doctype] = import_controller(doctype)
  File "/home/frappe/frappe-bench/apps/frappe/frappe/model/base_document.py", line 81, in import_controller
    doctype_info = frappe.db.get_value("DocType", doctype, fieldname="*")
  File "/home/frappe/frappe-bench/apps/frappe/frappe/database/database.py", line 519, in get_value
    result = self.get_values(
  File "/home/frappe/frappe-bench/apps/frappe/frappe/database/database.py", line 648, in get_values
    out = self.get_values_from_single(
  File "/home/frappe/frappe-bench/apps/frappe/frappe/database/database.py", line 685, in get_values_from_single
    values = self.get_singles_dict(doctype)
  File "/home/frappe/frappe-bench/apps/frappe/frappe/database/database.py", line 733, in get_singles_dict
    queried_result = frappe.qb.get_query(
  File "/home/frappe/frappe-bench/apps/frappe/frappe/query_builder/utils.py", line 87, in execute_query
    result = frappe.db.sql(query, params, *args, **kwargs)  # nosemgrep
  File "/home/frappe/frappe-bench/apps/frappe/frappe/database/database.py", line 234, in sql
    self._cursor.execute(query, values)
  File "/home/frappe/frappe-bench/env/lib/python3.10/site-packages/pymysql/cursors.py", line 153, in execute
    result = self._query(query)
  File "/home/frappe/frappe-bench/env/lib/python3.10/site-packages/pymysql/cursors.py", line 322, in _query
    conn.query(q)
  File "/home/frappe/frappe-bench/env/lib/python3.10/site-packages/pymysql/connections.py", line 558, in query
    self._affected_rows = self._read_query_result(unbuffered=unbuffered)
  File "/home/frappe/frappe-bench/env/lib/python3.10/site-packages/pymysql/connections.py", line 822, in _read_query_result
    result.read()
  File "/home/frappe/frappe-bench/env/lib/python3.10/site-packages/pymysql/connections.py", line 1200, in read
    first_packet = self.connection._read_packet()
  File "/home/frappe/frappe-bench/env/lib/python3.10/site-packages/pymysql/connections.py", line 772, in _read_packet
    packet.raise_for_error()
  File "/home/frappe/frappe-bench/env/lib/python3.10/site-packages/pymysql/protocol.py", line 221, in raise_for_error
    err.raise_mysql_exception(self._data)
  File "/home/frappe/frappe-bench/env/lib/python3.10/site-packages/pymysql/err.py", line 143, in raise_mysql_exception
    raise errorclass(errno, errval)
pymysql.err.ProgrammingError: (1146, "Table '_098c566c1373ba13.tabSingles' doesn't exist")
