2024-07-18 11:45:55,678 ERROR frappe Could not take error snapshot: (2003, "Can't connect to MySQL server on '127.0.0.1' ([Errno 111] Connection refused)")
Site: erp.grupoatu.com
Form Dict: {'customer': 'SILVIA GOMEZ GARCIA'}
Traceback (most recent call last):
  File "/home/frappe/frappe-bench/env/lib/python3.10/site-packages/pymysql/connections.py", line 644, in connect
    sock = socket.create_connection(
  File "/usr/lib/python3.10/socket.py", line 845, in create_connection
    raise err
  File "/usr/lib/python3.10/socket.py", line 833, in create_connection
    sock.connect(sa)
ConnectionRefusedError: [Errno 111] Connection refused

During handling of the above exception, another exception occurred:

Traceback (most recent call last):
  File "/home/frappe/frappe-bench/apps/frappe/frappe/website/serve.py", line 19, in get_response
    endpoint, renderer_instance = path_resolver.resolve()
  File "/home/frappe/frappe-bench/apps/frappe/frappe/website/path_resolver.py", line 38, in resolve
    resolve_redirect(self.path, request.query_string)
  File "/home/frappe/frappe-bench/apps/frappe/frappe/website/path_resolver.py", line 118, in resolve_redirect
    redirects += frappe.get_all("Website Route Redirect", ["source", "target"], order_by=None)
  File "/home/frappe/frappe-bench/apps/frappe/frappe/__init__.py", line 2050, in get_all
    return get_list(doctype, *args, **kwargs)
  File "/home/frappe/frappe-bench/apps/frappe/frappe/__init__.py", line 2025, in get_list
    return frappe.model.db_query.DatabaseQuery(doctype).execute(*args, **kwargs)
  File "/home/frappe/frappe-bench/apps/frappe/frappe/model/db_query.py", line 167, in execute
    if is_virtual_doctype(self.doctype):
  File "/home/frappe/frappe-bench/apps/frappe/frappe/utils/caching.py", line 119, in site_cache_wrapper
    _SITE_CACHE[func_key][frappe.local.site][func_call_key] = func(*args, **kwargs)
  File "/home/frappe/frappe-bench/apps/frappe/frappe/model/utils/__init__.py", line 133, in is_virtual_doctype
    return frappe.db.get_value("DocType", doctype, "is_virtual")
  File "/home/frappe/frappe-bench/apps/frappe/frappe/database/database.py", line 519, in get_value
    result = self.get_values(
  File "/home/frappe/frappe-bench/apps/frappe/frappe/database/database.py", line 623, in get_values
    out = self._get_values_from_table(
  File "/home/frappe/frappe-bench/apps/frappe/frappe/database/database.py", line 896, in _get_values_from_table
    return query.run(as_dict=as_dict, debug=debug, update=update, run=run, pluck=pluck)
  File "/home/frappe/frappe-bench/apps/frappe/frappe/query_builder/utils.py", line 87, in execute_query
    result = frappe.db.sql(query, params, *args, **kwargs)  # nosemgrep
  File "/home/frappe/frappe-bench/apps/frappe/frappe/database/database.py", line 211, in sql
    self.connect()
  File "/home/frappe/frappe-bench/apps/frappe/frappe/database/database.py", line 117, in connect
    self._conn: "MariadbConnection" | "PostgresConnection" = self.get_connection()
  File "/home/frappe/frappe-bench/apps/frappe/frappe/database/mariadb/database.py", line 107, in get_connection
    conn = self._get_connection()
  File "/home/frappe/frappe-bench/apps/frappe/frappe/database/mariadb/database.py", line 113, in _get_connection
    return self.create_connection()
  File "/home/frappe/frappe-bench/apps/frappe/frappe/database/mariadb/database.py", line 116, in create_connection
    return pymysql.connect(**self.get_connection_settings())
  File "/home/frappe/frappe-bench/env/lib/python3.10/site-packages/pymysql/connections.py", line 358, in __init__
    self.connect()
  File "/home/frappe/frappe-bench/env/lib/python3.10/site-packages/pymysql/connections.py", line 711, in connect
    raise exc
pymysql.err.OperationalError: (2003, "Can't connect to MySQL server on '127.0.0.1' ([Errno 111] Connection refused)")

During handling of the above exception, another exception occurred:

Traceback (most recent call last):
  File "/home/frappe/frappe-bench/env/lib/python3.10/site-packages/pymysql/connections.py", line 644, in connect
    sock = socket.create_connection(
  File "/usr/lib/python3.10/socket.py", line 845, in create_connection
    raise err
  File "/usr/lib/python3.10/socket.py", line 833, in create_connection
    sock.connect(sa)
ConnectionRefusedError: [Errno 111] Connection refused

During handling of the above exception, another exception occurred:

Traceback (most recent call last):
  File "/home/frappe/frappe-bench/apps/frappe/frappe/app.py", line 119, in application
    response = get_response()
  File "/home/frappe/frappe-bench/apps/frappe/frappe/website/serve.py", line 28, in get_response
    response = ErrorPage(exception=e).render()
  File "/home/frappe/frappe-bench/apps/frappe/frappe/website/page_renderers/template_page.py", line 84, in render
    html = self.get_html()
  File "/home/frappe/frappe-bench/apps/frappe/frappe/website/utils.py", line 523, in cache_html_decorator
    html = func(*args, **kwargs)
  File "/home/frappe/frappe-bench/apps/frappe/frappe/website/page_renderers/template_page.py", line 92, in get_html
    self.init_context()
  File "/home/frappe/frappe-bench/apps/frappe/frappe/website/page_renderers/error_page.py", line 14, in init_context
    super().init_context()
  File "/home/frappe/frappe-bench/apps/frappe/frappe/website/page_renderers/base_template_page.py", line 15, in init_context
    self.context.update(get_website_settings())
  File "/home/frappe/frappe-bench/apps/frappe/frappe/website/doctype/website_settings/website_settings.py", line 263, in get_website_settings
    context.boot = get_boot_data()
  File "/home/frappe/frappe-bench/apps/frappe/frappe/website/utils.py", line 179, in get_boot_data
    "user": frappe.db.get_value("User", frappe.session.user, "time_zone") or get_system_timezone(),
  File "/home/frappe/frappe-bench/apps/frappe/frappe/database/database.py", line 519, in get_value
    result = self.get_values(
  File "/home/frappe/frappe-bench/apps/frappe/frappe/database/database.py", line 623, in get_values
    out = self._get_values_from_table(
  File "/home/frappe/frappe-bench/apps/frappe/frappe/database/database.py", line 896, in _get_values_from_table
    return query.run(as_dict=as_dict, debug=debug, update=update, run=run, pluck=pluck)
  File "/home/frappe/frappe-bench/apps/frappe/frappe/query_builder/utils.py", line 87, in execute_query
    result = frappe.db.sql(query, params, *args, **kwargs)  # nosemgrep
  File "/home/frappe/frappe-bench/apps/frappe/frappe/database/database.py", line 211, in sql
    self.connect()
  File "/home/frappe/frappe-bench/apps/frappe/frappe/database/database.py", line 117, in connect
    self._conn: "MariadbConnection" | "PostgresConnection" = self.get_connection()
  File "/home/frappe/frappe-bench/apps/frappe/frappe/database/mariadb/database.py", line 107, in get_connection
    conn = self._get_connection()
  File "/home/frappe/frappe-bench/apps/frappe/frappe/database/mariadb/database.py", line 113, in _get_connection
    return self.create_connection()
  File "/home/frappe/frappe-bench/apps/frappe/frappe/database/mariadb/database.py", line 116, in create_connection
    return pymysql.connect(**self.get_connection_settings())
  File "/home/frappe/frappe-bench/env/lib/python3.10/site-packages/pymysql/connections.py", line 358, in __init__
    self.connect()
  File "/home/frappe/frappe-bench/env/lib/python3.10/site-packages/pymysql/connections.py", line 711, in connect
    raise exc
pymysql.err.OperationalError: (2003, "Can't connect to MySQL server on '127.0.0.1' ([Errno 111] Connection refused)")

During handling of the above exception, another exception occurred:

Traceback (most recent call last):
  File "/home/frappe/frappe-bench/env/lib/python3.10/site-packages/pymysql/connections.py", line 644, in connect
    sock = socket.create_connection(
  File "/usr/lib/python3.10/socket.py", line 845, in create_connection
    raise err
  File "/usr/lib/python3.10/socket.py", line 833, in create_connection
    sock.connect(sa)
ConnectionRefusedError: [Errno 111] Connection refused

During handling of the above exception, another exception occurred:

Traceback (most recent call last):
  File "/home/frappe/frappe-bench/apps/frappe/frappe/utils/error.py", line 86, in log_error_snapshot
    log_error(title=str(exception), defer_insert=True)
  File "/home/frappe/frappe-bench/apps/frappe/frappe/utils/error.py", line 61, in log_error
    error_log = frappe.get_doc(
  File "/home/frappe/frappe-bench/apps/frappe/frappe/__init__.py", line 1329, in get_doc
    doc = frappe.model.document.get_doc(*args, **kwargs)
  File "/home/frappe/frappe-bench/apps/frappe/frappe/model/document.py", line 83, in get_doc
    controller = get_controller(doctype)
  File "/home/frappe/frappe-bench/apps/frappe/frappe/model/base_document.py", line 70, in get_controller
    site_controllers[doctype] = import_controller(doctype)
  File "/home/frappe/frappe-bench/apps/frappe/frappe/model/base_document.py", line 81, in import_controller
    doctype_info = frappe.db.get_value("DocType", doctype, fieldname="*")
  File "/home/frappe/frappe-bench/apps/frappe/frappe/database/database.py", line 519, in get_value
    result = self.get_values(
  File "/home/frappe/frappe-bench/apps/frappe/frappe/database/database.py", line 623, in get_values
    out = self._get_values_from_table(
  File "/home/frappe/frappe-bench/apps/frappe/frappe/database/database.py", line 896, in _get_values_from_table
    return query.run(as_dict=as_dict, debug=debug, update=update, run=run, pluck=pluck)
  File "/home/frappe/frappe-bench/apps/frappe/frappe/query_builder/utils.py", line 87, in execute_query
    result = frappe.db.sql(query, params, *args, **kwargs)  # nosemgrep
  File "/home/frappe/frappe-bench/apps/frappe/frappe/database/database.py", line 211, in sql
    self.connect()
  File "/home/frappe/frappe-bench/apps/frappe/frappe/database/database.py", line 117, in connect
    self._conn: "MariadbConnection" | "PostgresConnection" = self.get_connection()
  File "/home/frappe/frappe-bench/apps/frappe/frappe/database/mariadb/database.py", line 107, in get_connection
    conn = self._get_connection()
  File "/home/frappe/frappe-bench/apps/frappe/frappe/database/mariadb/database.py", line 113, in _get_connection
    return self.create_connection()
  File "/home/frappe/frappe-bench/apps/frappe/frappe/database/mariadb/database.py", line 116, in create_connection
    return pymysql.connect(**self.get_connection_settings())
  File "/home/frappe/frappe-bench/env/lib/python3.10/site-packages/pymysql/connections.py", line 358, in __init__
    self.connect()
  File "/home/frappe/frappe-bench/env/lib/python3.10/site-packages/pymysql/connections.py", line 711, in connect
    raise exc
pymysql.err.OperationalError: (2003, "Can't connect to MySQL server on '127.0.0.1' ([Errno 111] Connection refused)")
2024-07-18 11:45:55,764 ERROR frappe Could not take error snapshot: (2003, "Can't connect to MySQL server on '127.0.0.1' ([Errno 111] Connection refused)")
Site: erp.grupoatu.com
Form Dict: {}
Traceback (most recent call last):
  File "/home/frappe/frappe-bench/env/lib/python3.10/site-packages/pymysql/connections.py", line 644, in connect
    sock = socket.create_connection(
  File "/usr/lib/python3.10/socket.py", line 845, in create_connection
    raise err
  File "/usr/lib/python3.10/socket.py", line 833, in create_connection
    sock.connect(sa)
ConnectionRefusedError: [Errno 111] Connection refused

During handling of the above exception, another exception occurred:

Traceback (most recent call last):
  File "/home/frappe/frappe-bench/apps/frappe/frappe/website/serve.py", line 19, in get_response
    endpoint, renderer_instance = path_resolver.resolve()
  File "/home/frappe/frappe-bench/apps/frappe/frappe/website/path_resolver.py", line 38, in resolve
    resolve_redirect(self.path, request.query_string)
  File "/home/frappe/frappe-bench/apps/frappe/frappe/website/path_resolver.py", line 118, in resolve_redirect
    redirects += frappe.get_all("Website Route Redirect", ["source", "target"], order_by=None)
  File "/home/frappe/frappe-bench/apps/frappe/frappe/__init__.py", line 2050, in get_all
    return get_list(doctype, *args, **kwargs)
  File "/home/frappe/frappe-bench/apps/frappe/frappe/__init__.py", line 2025, in get_list
    return frappe.model.db_query.DatabaseQuery(doctype).execute(*args, **kwargs)
  File "/home/frappe/frappe-bench/apps/frappe/frappe/model/db_query.py", line 167, in execute
    if is_virtual_doctype(self.doctype):
  File "/home/frappe/frappe-bench/apps/frappe/frappe/utils/caching.py", line 119, in site_cache_wrapper
    _SITE_CACHE[func_key][frappe.local.site][func_call_key] = func(*args, **kwargs)
  File "/home/frappe/frappe-bench/apps/frappe/frappe/model/utils/__init__.py", line 133, in is_virtual_doctype
    return frappe.db.get_value("DocType", doctype, "is_virtual")
  File "/home/frappe/frappe-bench/apps/frappe/frappe/database/database.py", line 519, in get_value
    result = self.get_values(
  File "/home/frappe/frappe-bench/apps/frappe/frappe/database/database.py", line 623, in get_values
    out = self._get_values_from_table(
  File "/home/frappe/frappe-bench/apps/frappe/frappe/database/database.py", line 896, in _get_values_from_table
    return query.run(as_dict=as_dict, debug=debug, update=update, run=run, pluck=pluck)
  File "/home/frappe/frappe-bench/apps/frappe/frappe/query_builder/utils.py", line 87, in execute_query
    result = frappe.db.sql(query, params, *args, **kwargs)  # nosemgrep
  File "/home/frappe/frappe-bench/apps/frappe/frappe/database/database.py", line 211, in sql
    self.connect()
  File "/home/frappe/frappe-bench/apps/frappe/frappe/database/database.py", line 117, in connect
    self._conn: "MariadbConnection" | "PostgresConnection" = self.get_connection()
  File "/home/frappe/frappe-bench/apps/frappe/frappe/database/mariadb/database.py", line 107, in get_connection
    conn = self._get_connection()
  File "/home/frappe/frappe-bench/apps/frappe/frappe/database/mariadb/database.py", line 113, in _get_connection
    return self.create_connection()
  File "/home/frappe/frappe-bench/apps/frappe/frappe/database/mariadb/database.py", line 116, in create_connection
    return pymysql.connect(**self.get_connection_settings())
  File "/home/frappe/frappe-bench/env/lib/python3.10/site-packages/pymysql/connections.py", line 358, in __init__
    self.connect()
  File "/home/frappe/frappe-bench/env/lib/python3.10/site-packages/pymysql/connections.py", line 711, in connect
    raise exc
pymysql.err.OperationalError: (2003, "Can't connect to MySQL server on '127.0.0.1' ([Errno 111] Connection refused)")

During handling of the above exception, another exception occurred:

Traceback (most recent call last):
  File "/home/frappe/frappe-bench/env/lib/python3.10/site-packages/pymysql/connections.py", line 644, in connect
    sock = socket.create_connection(
  File "/usr/lib/python3.10/socket.py", line 845, in create_connection
    raise err
  File "/usr/lib/python3.10/socket.py", line 833, in create_connection
    sock.connect(sa)
ConnectionRefusedError: [Errno 111] Connection refused

During handling of the above exception, another exception occurred:

Traceback (most recent call last):
  File "/home/frappe/frappe-bench/apps/frappe/frappe/app.py", line 119, in application
    response = get_response()
  File "/home/frappe/frappe-bench/apps/frappe/frappe/website/serve.py", line 28, in get_response
    response = ErrorPage(exception=e).render()
  File "/home/frappe/frappe-bench/apps/frappe/frappe/website/page_renderers/template_page.py", line 84, in render
    html = self.get_html()
  File "/home/frappe/frappe-bench/apps/frappe/frappe/website/utils.py", line 523, in cache_html_decorator
    html = func(*args, **kwargs)
  File "/home/frappe/frappe-bench/apps/frappe/frappe/website/page_renderers/template_page.py", line 92, in get_html
    self.init_context()
  File "/home/frappe/frappe-bench/apps/frappe/frappe/website/page_renderers/error_page.py", line 14, in init_context
    super().init_context()
  File "/home/frappe/frappe-bench/apps/frappe/frappe/website/page_renderers/base_template_page.py", line 15, in init_context
    self.context.update(get_website_settings())
  File "/home/frappe/frappe-bench/apps/frappe/frappe/website/doctype/website_settings/website_settings.py", line 263, in get_website_settings
    context.boot = get_boot_data()
  File "/home/frappe/frappe-bench/apps/frappe/frappe/website/utils.py", line 179, in get_boot_data
    "user": frappe.db.get_value("User", frappe.session.user, "time_zone") or get_system_timezone(),
  File "/home/frappe/frappe-bench/apps/frappe/frappe/database/database.py", line 519, in get_value
    result = self.get_values(
  File "/home/frappe/frappe-bench/apps/frappe/frappe/database/database.py", line 623, in get_values
    out = self._get_values_from_table(
  File "/home/frappe/frappe-bench/apps/frappe/frappe/database/database.py", line 896, in _get_values_from_table
    return query.run(as_dict=as_dict, debug=debug, update=update, run=run, pluck=pluck)
  File "/home/frappe/frappe-bench/apps/frappe/frappe/query_builder/utils.py", line 87, in execute_query
    result = frappe.db.sql(query, params, *args, **kwargs)  # nosemgrep
  File "/home/frappe/frappe-bench/apps/frappe/frappe/database/database.py", line 211, in sql
    self.connect()
  File "/home/frappe/frappe-bench/apps/frappe/frappe/database/database.py", line 117, in connect
    self._conn: "MariadbConnection" | "PostgresConnection" = self.get_connection()
  File "/home/frappe/frappe-bench/apps/frappe/frappe/database/mariadb/database.py", line 107, in get_connection
    conn = self._get_connection()
  File "/home/frappe/frappe-bench/apps/frappe/frappe/database/mariadb/database.py", line 113, in _get_connection
    return self.create_connection()
  File "/home/frappe/frappe-bench/apps/frappe/frappe/database/mariadb/database.py", line 116, in create_connection
    return pymysql.connect(**self.get_connection_settings())
  File "/home/frappe/frappe-bench/env/lib/python3.10/site-packages/pymysql/connections.py", line 358, in __init__
    self.connect()
  File "/home/frappe/frappe-bench/env/lib/python3.10/site-packages/pymysql/connections.py", line 711, in connect
    raise exc
pymysql.err.OperationalError: (2003, "Can't connect to MySQL server on '127.0.0.1' ([Errno 111] Connection refused)")

During handling of the above exception, another exception occurred:

Traceback (most recent call last):
  File "/home/frappe/frappe-bench/env/lib/python3.10/site-packages/pymysql/connections.py", line 644, in connect
    sock = socket.create_connection(
  File "/usr/lib/python3.10/socket.py", line 845, in create_connection
    raise err
  File "/usr/lib/python3.10/socket.py", line 833, in create_connection
    sock.connect(sa)
ConnectionRefusedError: [Errno 111] Connection refused

During handling of the above exception, another exception occurred:

Traceback (most recent call last):
  File "/home/frappe/frappe-bench/apps/frappe/frappe/utils/error.py", line 86, in log_error_snapshot
    log_error(title=str(exception), defer_insert=True)
  File "/home/frappe/frappe-bench/apps/frappe/frappe/utils/error.py", line 61, in log_error
    error_log = frappe.get_doc(
  File "/home/frappe/frappe-bench/apps/frappe/frappe/__init__.py", line 1329, in get_doc
    doc = frappe.model.document.get_doc(*args, **kwargs)
  File "/home/frappe/frappe-bench/apps/frappe/frappe/model/document.py", line 83, in get_doc
    controller = get_controller(doctype)
  File "/home/frappe/frappe-bench/apps/frappe/frappe/model/base_document.py", line 70, in get_controller
    site_controllers[doctype] = import_controller(doctype)
  File "/home/frappe/frappe-bench/apps/frappe/frappe/model/base_document.py", line 81, in import_controller
    doctype_info = frappe.db.get_value("DocType", doctype, fieldname="*")
  File "/home/frappe/frappe-bench/apps/frappe/frappe/database/database.py", line 519, in get_value
    result = self.get_values(
  File "/home/frappe/frappe-bench/apps/frappe/frappe/database/database.py", line 623, in get_values
    out = self._get_values_from_table(
  File "/home/frappe/frappe-bench/apps/frappe/frappe/database/database.py", line 896, in _get_values_from_table
    return query.run(as_dict=as_dict, debug=debug, update=update, run=run, pluck=pluck)
  File "/home/frappe/frappe-bench/apps/frappe/frappe/query_builder/utils.py", line 87, in execute_query
    result = frappe.db.sql(query, params, *args, **kwargs)  # nosemgrep
  File "/home/frappe/frappe-bench/apps/frappe/frappe/database/database.py", line 211, in sql
    self.connect()
  File "/home/frappe/frappe-bench/apps/frappe/frappe/database/database.py", line 117, in connect
    self._conn: "MariadbConnection" | "PostgresConnection" = self.get_connection()
  File "/home/frappe/frappe-bench/apps/frappe/frappe/database/mariadb/database.py", line 107, in get_connection
    conn = self._get_connection()
  File "/home/frappe/frappe-bench/apps/frappe/frappe/database/mariadb/database.py", line 113, in _get_connection
    return self.create_connection()
  File "/home/frappe/frappe-bench/apps/frappe/frappe/database/mariadb/database.py", line 116, in create_connection
    return pymysql.connect(**self.get_connection_settings())
  File "/home/frappe/frappe-bench/env/lib/python3.10/site-packages/pymysql/connections.py", line 358, in __init__
    self.connect()
  File "/home/frappe/frappe-bench/env/lib/python3.10/site-packages/pymysql/connections.py", line 711, in connect
    raise exc
pymysql.err.OperationalError: (2003, "Can't connect to MySQL server on '127.0.0.1' ([Errno 111] Connection refused)")
2024-07-18 11:45:59,414 ERROR frappe Could not take error snapshot: (2003, "Can't connect to MySQL server on '127.0.0.1' ([Errno 111] Connection refused)")
Site: erp.grupoatu.com
Form Dict: {'doctype': 'Issue', 'fields': '["`tabIssue`.`name`","`tabIssue`.`owner`","`tabIssue`.`creation`","`tabIssue`.`modified`","`tabIssue`.`modified_by`","`tabIssue`.`_user_tags`","`tabIssue`.`_comments`","`tabIssue`.`_assign`","`tabIssue`.`_liked_by`","`tabIssue`.`docstatus`","`tabIssue`.`idx`","`tabIssue`.`raised_by`","`tabIssue`.`status`","`tabIssue`.`priority`","`tabIssue`.`subject`","`tabIssue`.`_seen`"]', 'filters': '[["Issue","status","in",["Abierto","Leído","Respondido",null]],["Issue","issue_type","!=","Incidencias Cursos"]]', 'order_by': '`tabIssue`.`modified` desc', 'start': '0', 'page_length': '20', 'view': 'List', 'group_by': '', 'with_comment_count': '1', 'cmd': 'frappe.desk.reportview.get'}
Traceback (most recent call last):
  File "/home/frappe/frappe-bench/env/lib/python3.10/site-packages/pymysql/connections.py", line 644, in connect
    sock = socket.create_connection(
  File "/usr/lib/python3.10/socket.py", line 845, in create_connection
    raise err
  File "/usr/lib/python3.10/socket.py", line 833, in create_connection
    sock.connect(sa)
ConnectionRefusedError: [Errno 111] Connection refused

During handling of the above exception, another exception occurred:

Traceback (most recent call last):
  File "/home/frappe/frappe-bench/apps/frappe/frappe/app.py", line 110, in application
    response = frappe.api.handle(request)
  File "/home/frappe/frappe-bench/apps/frappe/frappe/api/__init__.py", line 49, in handle
    data = endpoint(**arguments)
  File "/home/frappe/frappe-bench/apps/frappe/frappe/api/v1.py", line 36, in handle_rpc_call
    return frappe.handler.handle()
  File "/home/frappe/frappe-bench/apps/frappe/frappe/handler.py", line 49, in handle
    data = execute_cmd(cmd)
  File "/home/frappe/frappe-bench/apps/frappe/frappe/handler.py", line 85, in execute_cmd
    return frappe.call(method, **frappe.form_dict)
  File "/home/frappe/frappe-bench/apps/frappe/frappe/__init__.py", line 1761, in call
    return fn(*args, **newargs)
  File "/home/frappe/frappe-bench/apps/frappe/frappe/utils/typing_validations.py", line 31, in wrapper
    return func(*args, **kwargs)
  File "/home/frappe/frappe-bench/apps/frappe/frappe/__init__.py", line 921, in wrapper_fn
    retval = fn(*args, **get_newargs(fn, kwargs))
  File "/home/frappe/frappe-bench/apps/frappe/frappe/desk/reportview.py", line 28, in get
    if is_virtual_doctype(args.doctype):
  File "/home/frappe/frappe-bench/apps/frappe/frappe/utils/caching.py", line 119, in site_cache_wrapper
    _SITE_CACHE[func_key][frappe.local.site][func_call_key] = func(*args, **kwargs)
  File "/home/frappe/frappe-bench/apps/frappe/frappe/model/utils/__init__.py", line 133, in is_virtual_doctype
    return frappe.db.get_value("DocType", doctype, "is_virtual")
  File "/home/frappe/frappe-bench/apps/frappe/frappe/database/database.py", line 519, in get_value
    result = self.get_values(
  File "/home/frappe/frappe-bench/apps/frappe/frappe/database/database.py", line 623, in get_values
    out = self._get_values_from_table(
  File "/home/frappe/frappe-bench/apps/frappe/frappe/database/database.py", line 896, in _get_values_from_table
    return query.run(as_dict=as_dict, debug=debug, update=update, run=run, pluck=pluck)
  File "/home/frappe/frappe-bench/apps/frappe/frappe/query_builder/utils.py", line 87, in execute_query
    result = frappe.db.sql(query, params, *args, **kwargs)  # nosemgrep
  File "/home/frappe/frappe-bench/apps/frappe/frappe/database/database.py", line 211, in sql
    self.connect()
  File "/home/frappe/frappe-bench/apps/frappe/frappe/database/database.py", line 117, in connect
    self._conn: "MariadbConnection" | "PostgresConnection" = self.get_connection()
  File "/home/frappe/frappe-bench/apps/frappe/frappe/database/mariadb/database.py", line 107, in get_connection
    conn = self._get_connection()
  File "/home/frappe/frappe-bench/apps/frappe/frappe/database/mariadb/database.py", line 113, in _get_connection
    return self.create_connection()
  File "/home/frappe/frappe-bench/apps/frappe/frappe/database/mariadb/database.py", line 116, in create_connection
    return pymysql.connect(**self.get_connection_settings())
  File "/home/frappe/frappe-bench/env/lib/python3.10/site-packages/pymysql/connections.py", line 358, in __init__
    self.connect()
  File "/home/frappe/frappe-bench/env/lib/python3.10/site-packages/pymysql/connections.py", line 711, in connect
    raise exc
pymysql.err.OperationalError: (2003, "Can't connect to MySQL server on '127.0.0.1' ([Errno 111] Connection refused)")

During handling of the above exception, another exception occurred:

Traceback (most recent call last):
  File "/home/frappe/frappe-bench/env/lib/python3.10/site-packages/pymysql/connections.py", line 644, in connect
    sock = socket.create_connection(
  File "/usr/lib/python3.10/socket.py", line 845, in create_connection
    raise err
  File "/usr/lib/python3.10/socket.py", line 833, in create_connection
    sock.connect(sa)
ConnectionRefusedError: [Errno 111] Connection refused

During handling of the above exception, another exception occurred:

Traceback (most recent call last):
  File "/home/frappe/frappe-bench/apps/frappe/frappe/utils/error.py", line 86, in log_error_snapshot
    log_error(title=str(exception), defer_insert=True)
  File "/home/frappe/frappe-bench/apps/frappe/frappe/utils/error.py", line 61, in log_error
    error_log = frappe.get_doc(
  File "/home/frappe/frappe-bench/apps/frappe/frappe/__init__.py", line 1329, in get_doc
    doc = frappe.model.document.get_doc(*args, **kwargs)
  File "/home/frappe/frappe-bench/apps/frappe/frappe/model/document.py", line 83, in get_doc
    controller = get_controller(doctype)
  File "/home/frappe/frappe-bench/apps/frappe/frappe/model/base_document.py", line 70, in get_controller
    site_controllers[doctype] = import_controller(doctype)
  File "/home/frappe/frappe-bench/apps/frappe/frappe/model/base_document.py", line 81, in import_controller
    doctype_info = frappe.db.get_value("DocType", doctype, fieldname="*")
  File "/home/frappe/frappe-bench/apps/frappe/frappe/database/database.py", line 519, in get_value
    result = self.get_values(
  File "/home/frappe/frappe-bench/apps/frappe/frappe/database/database.py", line 623, in get_values
    out = self._get_values_from_table(
  File "/home/frappe/frappe-bench/apps/frappe/frappe/database/database.py", line 896, in _get_values_from_table
    return query.run(as_dict=as_dict, debug=debug, update=update, run=run, pluck=pluck)
  File "/home/frappe/frappe-bench/apps/frappe/frappe/query_builder/utils.py", line 87, in execute_query
    result = frappe.db.sql(query, params, *args, **kwargs)  # nosemgrep
  File "/home/frappe/frappe-bench/apps/frappe/frappe/database/database.py", line 211, in sql
    self.connect()
  File "/home/frappe/frappe-bench/apps/frappe/frappe/database/database.py", line 117, in connect
    self._conn: "MariadbConnection" | "PostgresConnection" = self.get_connection()
  File "/home/frappe/frappe-bench/apps/frappe/frappe/database/mariadb/database.py", line 107, in get_connection
    conn = self._get_connection()
  File "/home/frappe/frappe-bench/apps/frappe/frappe/database/mariadb/database.py", line 113, in _get_connection
    return self.create_connection()
  File "/home/frappe/frappe-bench/apps/frappe/frappe/database/mariadb/database.py", line 116, in create_connection
    return pymysql.connect(**self.get_connection_settings())
  File "/home/frappe/frappe-bench/env/lib/python3.10/site-packages/pymysql/connections.py", line 358, in __init__
    self.connect()
  File "/home/frappe/frappe-bench/env/lib/python3.10/site-packages/pymysql/connections.py", line 711, in connect
    raise exc
pymysql.err.OperationalError: (2003, "Can't connect to MySQL server on '127.0.0.1' ([Errno 111] Connection refused)")
2024-07-18 11:46:01,398 ERROR frappe Could not take error snapshot: (2003, "Can't connect to MySQL server on '127.0.0.1' ([Errno 111] Connection refused)")
Site: erp.grupoatu.com
Form Dict: {}
Traceback (most recent call last):
  File "/home/frappe/frappe-bench/env/lib/python3.10/site-packages/pymysql/connections.py", line 644, in connect
    sock = socket.create_connection(
  File "/usr/lib/python3.10/socket.py", line 845, in create_connection
    raise err
  File "/usr/lib/python3.10/socket.py", line 833, in create_connection
    sock.connect(sa)
ConnectionRefusedError: [Errno 111] Connection refused

During handling of the above exception, another exception occurred:

Traceback (most recent call last):
  File "/home/frappe/frappe-bench/apps/frappe/frappe/website/serve.py", line 19, in get_response
    endpoint, renderer_instance = path_resolver.resolve()
  File "/home/frappe/frappe-bench/apps/frappe/frappe/website/path_resolver.py", line 38, in resolve
    resolve_redirect(self.path, request.query_string)
  File "/home/frappe/frappe-bench/apps/frappe/frappe/website/path_resolver.py", line 118, in resolve_redirect
    redirects += frappe.get_all("Website Route Redirect", ["source", "target"], order_by=None)
  File "/home/frappe/frappe-bench/apps/frappe/frappe/__init__.py", line 2050, in get_all
    return get_list(doctype, *args, **kwargs)
  File "/home/frappe/frappe-bench/apps/frappe/frappe/__init__.py", line 2025, in get_list
    return frappe.model.db_query.DatabaseQuery(doctype).execute(*args, **kwargs)
  File "/home/frappe/frappe-bench/apps/frappe/frappe/model/db_query.py", line 167, in execute
    if is_virtual_doctype(self.doctype):
  File "/home/frappe/frappe-bench/apps/frappe/frappe/utils/caching.py", line 119, in site_cache_wrapper
    _SITE_CACHE[func_key][frappe.local.site][func_call_key] = func(*args, **kwargs)
  File "/home/frappe/frappe-bench/apps/frappe/frappe/model/utils/__init__.py", line 133, in is_virtual_doctype
    return frappe.db.get_value("DocType", doctype, "is_virtual")
  File "/home/frappe/frappe-bench/apps/frappe/frappe/database/database.py", line 519, in get_value
    result = self.get_values(
  File "/home/frappe/frappe-bench/apps/frappe/frappe/database/database.py", line 623, in get_values
    out = self._get_values_from_table(
  File "/home/frappe/frappe-bench/apps/frappe/frappe/database/database.py", line 896, in _get_values_from_table
    return query.run(as_dict=as_dict, debug=debug, update=update, run=run, pluck=pluck)
  File "/home/frappe/frappe-bench/apps/frappe/frappe/query_builder/utils.py", line 87, in execute_query
    result = frappe.db.sql(query, params, *args, **kwargs)  # nosemgrep
  File "/home/frappe/frappe-bench/apps/frappe/frappe/database/database.py", line 211, in sql
    self.connect()
  File "/home/frappe/frappe-bench/apps/frappe/frappe/database/database.py", line 117, in connect
    self._conn: "MariadbConnection" | "PostgresConnection" = self.get_connection()
  File "/home/frappe/frappe-bench/apps/frappe/frappe/database/mariadb/database.py", line 107, in get_connection
    conn = self._get_connection()
  File "/home/frappe/frappe-bench/apps/frappe/frappe/database/mariadb/database.py", line 113, in _get_connection
    return self.create_connection()
  File "/home/frappe/frappe-bench/apps/frappe/frappe/database/mariadb/database.py", line 116, in create_connection
    return pymysql.connect(**self.get_connection_settings())
  File "/home/frappe/frappe-bench/env/lib/python3.10/site-packages/pymysql/connections.py", line 358, in __init__
    self.connect()
  File "/home/frappe/frappe-bench/env/lib/python3.10/site-packages/pymysql/connections.py", line 711, in connect
    raise exc
pymysql.err.OperationalError: (2003, "Can't connect to MySQL server on '127.0.0.1' ([Errno 111] Connection refused)")

During handling of the above exception, another exception occurred:

Traceback (most recent call last):
  File "/home/frappe/frappe-bench/env/lib/python3.10/site-packages/pymysql/connections.py", line 644, in connect
    sock = socket.create_connection(
  File "/usr/lib/python3.10/socket.py", line 845, in create_connection
    raise err
  File "/usr/lib/python3.10/socket.py", line 833, in create_connection
    sock.connect(sa)
ConnectionRefusedError: [Errno 111] Connection refused

During handling of the above exception, another exception occurred:

Traceback (most recent call last):
  File "/home/frappe/frappe-bench/apps/frappe/frappe/app.py", line 119, in application
    response = get_response()
  File "/home/frappe/frappe-bench/apps/frappe/frappe/website/serve.py", line 28, in get_response
    response = ErrorPage(exception=e).render()
  File "/home/frappe/frappe-bench/apps/frappe/frappe/website/page_renderers/template_page.py", line 84, in render
    html = self.get_html()
  File "/home/frappe/frappe-bench/apps/frappe/frappe/website/utils.py", line 523, in cache_html_decorator
    html = func(*args, **kwargs)
  File "/home/frappe/frappe-bench/apps/frappe/frappe/website/page_renderers/template_page.py", line 92, in get_html
    self.init_context()
  File "/home/frappe/frappe-bench/apps/frappe/frappe/website/page_renderers/error_page.py", line 14, in init_context
    super().init_context()
  File "/home/frappe/frappe-bench/apps/frappe/frappe/website/page_renderers/base_template_page.py", line 15, in init_context
    self.context.update(get_website_settings())
  File "/home/frappe/frappe-bench/apps/frappe/frappe/website/doctype/website_settings/website_settings.py", line 263, in get_website_settings
    context.boot = get_boot_data()
  File "/home/frappe/frappe-bench/apps/frappe/frappe/website/utils.py", line 179, in get_boot_data
    "user": frappe.db.get_value("User", frappe.session.user, "time_zone") or get_system_timezone(),
  File "/home/frappe/frappe-bench/apps/frappe/frappe/database/database.py", line 519, in get_value
    result = self.get_values(
  File "/home/frappe/frappe-bench/apps/frappe/frappe/database/database.py", line 623, in get_values
    out = self._get_values_from_table(
  File "/home/frappe/frappe-bench/apps/frappe/frappe/database/database.py", line 896, in _get_values_from_table
    return query.run(as_dict=as_dict, debug=debug, update=update, run=run, pluck=pluck)
  File "/home/frappe/frappe-bench/apps/frappe/frappe/query_builder/utils.py", line 87, in execute_query
    result = frappe.db.sql(query, params, *args, **kwargs)  # nosemgrep
  File "/home/frappe/frappe-bench/apps/frappe/frappe/database/database.py", line 211, in sql
    self.connect()
  File "/home/frappe/frappe-bench/apps/frappe/frappe/database/database.py", line 117, in connect
    self._conn: "MariadbConnection" | "PostgresConnection" = self.get_connection()
  File "/home/frappe/frappe-bench/apps/frappe/frappe/database/mariadb/database.py", line 107, in get_connection
    conn = self._get_connection()
  File "/home/frappe/frappe-bench/apps/frappe/frappe/database/mariadb/database.py", line 113, in _get_connection
    return self.create_connection()
  File "/home/frappe/frappe-bench/apps/frappe/frappe/database/mariadb/database.py", line 116, in create_connection
    return pymysql.connect(**self.get_connection_settings())
  File "/home/frappe/frappe-bench/env/lib/python3.10/site-packages/pymysql/connections.py", line 358, in __init__
    self.connect()
  File "/home/frappe/frappe-bench/env/lib/python3.10/site-packages/pymysql/connections.py", line 711, in connect
    raise exc
pymysql.err.OperationalError: (2003, "Can't connect to MySQL server on '127.0.0.1' ([Errno 111] Connection refused)")

During handling of the above exception, another exception occurred:

Traceback (most recent call last):
  File "/home/frappe/frappe-bench/env/lib/python3.10/site-packages/pymysql/connections.py", line 644, in connect
    sock = socket.create_connection(
  File "/usr/lib/python3.10/socket.py", line 845, in create_connection
    raise err
  File "/usr/lib/python3.10/socket.py", line 833, in create_connection
    sock.connect(sa)
ConnectionRefusedError: [Errno 111] Connection refused

During handling of the above exception, another exception occurred:

Traceback (most recent call last):
  File "/home/frappe/frappe-bench/apps/frappe/frappe/utils/error.py", line 86, in log_error_snapshot
    log_error(title=str(exception), defer_insert=True)
  File "/home/frappe/frappe-bench/apps/frappe/frappe/utils/error.py", line 61, in log_error
    error_log = frappe.get_doc(
  File "/home/frappe/frappe-bench/apps/frappe/frappe/__init__.py", line 1329, in get_doc
    doc = frappe.model.document.get_doc(*args, **kwargs)
  File "/home/frappe/frappe-bench/apps/frappe/frappe/model/document.py", line 83, in get_doc
    controller = get_controller(doctype)
  File "/home/frappe/frappe-bench/apps/frappe/frappe/model/base_document.py", line 70, in get_controller
    site_controllers[doctype] = import_controller(doctype)
  File "/home/frappe/frappe-bench/apps/frappe/frappe/model/base_document.py", line 81, in import_controller
    doctype_info = frappe.db.get_value("DocType", doctype, fieldname="*")
  File "/home/frappe/frappe-bench/apps/frappe/frappe/database/database.py", line 519, in get_value
    result = self.get_values(
  File "/home/frappe/frappe-bench/apps/frappe/frappe/database/database.py", line 623, in get_values
    out = self._get_values_from_table(
  File "/home/frappe/frappe-bench/apps/frappe/frappe/database/database.py", line 896, in _get_values_from_table
    return query.run(as_dict=as_dict, debug=debug, update=update, run=run, pluck=pluck)
  File "/home/frappe/frappe-bench/apps/frappe/frappe/query_builder/utils.py", line 87, in execute_query
    result = frappe.db.sql(query, params, *args, **kwargs)  # nosemgrep
  File "/home/frappe/frappe-bench/apps/frappe/frappe/database/database.py", line 211, in sql
    self.connect()
  File "/home/frappe/frappe-bench/apps/frappe/frappe/database/database.py", line 117, in connect
    self._conn: "MariadbConnection" | "PostgresConnection" = self.get_connection()
  File "/home/frappe/frappe-bench/apps/frappe/frappe/database/mariadb/database.py", line 107, in get_connection
    conn = self._get_connection()
  File "/home/frappe/frappe-bench/apps/frappe/frappe/database/mariadb/database.py", line 113, in _get_connection
    return self.create_connection()
  File "/home/frappe/frappe-bench/apps/frappe/frappe/database/mariadb/database.py", line 116, in create_connection
    return pymysql.connect(**self.get_connection_settings())
  File "/home/frappe/frappe-bench/env/lib/python3.10/site-packages/pymysql/connections.py", line 358, in __init__
    self.connect()
  File "/home/frappe/frappe-bench/env/lib/python3.10/site-packages/pymysql/connections.py", line 711, in connect
    raise exc
pymysql.err.OperationalError: (2003, "Can't connect to MySQL server on '127.0.0.1' ([Errno 111] Connection refused)")
2024-07-18 11:46:01,495 ERROR frappe Could not take error snapshot: (2003, "Can't connect to MySQL server on '127.0.0.1' ([Errno 111] Connection refused)")
Site: erp.grupoatu.com
Form Dict: {}
Traceback (most recent call last):
  File "/home/frappe/frappe-bench/env/lib/python3.10/site-packages/pymysql/connections.py", line 644, in connect
    sock = socket.create_connection(
  File "/usr/lib/python3.10/socket.py", line 845, in create_connection
    raise err
  File "/usr/lib/python3.10/socket.py", line 833, in create_connection
    sock.connect(sa)
ConnectionRefusedError: [Errno 111] Connection refused

During handling of the above exception, another exception occurred:

Traceback (most recent call last):
  File "/home/frappe/frappe-bench/apps/frappe/frappe/website/serve.py", line 19, in get_response
    endpoint, renderer_instance = path_resolver.resolve()
  File "/home/frappe/frappe-bench/apps/frappe/frappe/website/path_resolver.py", line 38, in resolve
    resolve_redirect(self.path, request.query_string)
  File "/home/frappe/frappe-bench/apps/frappe/frappe/website/path_resolver.py", line 118, in resolve_redirect
    redirects += frappe.get_all("Website Route Redirect", ["source", "target"], order_by=None)
  File "/home/frappe/frappe-bench/apps/frappe/frappe/__init__.py", line 2050, in get_all
    return get_list(doctype, *args, **kwargs)
  File "/home/frappe/frappe-bench/apps/frappe/frappe/__init__.py", line 2025, in get_list
    return frappe.model.db_query.DatabaseQuery(doctype).execute(*args, **kwargs)
  File "/home/frappe/frappe-bench/apps/frappe/frappe/model/db_query.py", line 167, in execute
    if is_virtual_doctype(self.doctype):
  File "/home/frappe/frappe-bench/apps/frappe/frappe/utils/caching.py", line 119, in site_cache_wrapper
    _SITE_CACHE[func_key][frappe.local.site][func_call_key] = func(*args, **kwargs)
  File "/home/frappe/frappe-bench/apps/frappe/frappe/model/utils/__init__.py", line 133, in is_virtual_doctype
    return frappe.db.get_value("DocType", doctype, "is_virtual")
  File "/home/frappe/frappe-bench/apps/frappe/frappe/database/database.py", line 519, in get_value
    result = self.get_values(
  File "/home/frappe/frappe-bench/apps/frappe/frappe/database/database.py", line 623, in get_values
    out = self._get_values_from_table(
  File "/home/frappe/frappe-bench/apps/frappe/frappe/database/database.py", line 896, in _get_values_from_table
    return query.run(as_dict=as_dict, debug=debug, update=update, run=run, pluck=pluck)
  File "/home/frappe/frappe-bench/apps/frappe/frappe/query_builder/utils.py", line 87, in execute_query
    result = frappe.db.sql(query, params, *args, **kwargs)  # nosemgrep
  File "/home/frappe/frappe-bench/apps/frappe/frappe/database/database.py", line 211, in sql
    self.connect()
  File "/home/frappe/frappe-bench/apps/frappe/frappe/database/database.py", line 117, in connect
    self._conn: "MariadbConnection" | "PostgresConnection" = self.get_connection()
  File "/home/frappe/frappe-bench/apps/frappe/frappe/database/mariadb/database.py", line 107, in get_connection
    conn = self._get_connection()
  File "/home/frappe/frappe-bench/apps/frappe/frappe/database/mariadb/database.py", line 113, in _get_connection
    return self.create_connection()
  File "/home/frappe/frappe-bench/apps/frappe/frappe/database/mariadb/database.py", line 116, in create_connection
    return pymysql.connect(**self.get_connection_settings())
  File "/home/frappe/frappe-bench/env/lib/python3.10/site-packages/pymysql/connections.py", line 358, in __init__
    self.connect()
  File "/home/frappe/frappe-bench/env/lib/python3.10/site-packages/pymysql/connections.py", line 711, in connect
    raise exc
pymysql.err.OperationalError: (2003, "Can't connect to MySQL server on '127.0.0.1' ([Errno 111] Connection refused)")

During handling of the above exception, another exception occurred:

Traceback (most recent call last):
  File "/home/frappe/frappe-bench/env/lib/python3.10/site-packages/pymysql/connections.py", line 644, in connect
    sock = socket.create_connection(
  File "/usr/lib/python3.10/socket.py", line 845, in create_connection
    raise err
  File "/usr/lib/python3.10/socket.py", line 833, in create_connection
    sock.connect(sa)
ConnectionRefusedError: [Errno 111] Connection refused

During handling of the above exception, another exception occurred:

Traceback (most recent call last):
  File "/home/frappe/frappe-bench/apps/frappe/frappe/app.py", line 119, in application
    response = get_response()
  File "/home/frappe/frappe-bench/apps/frappe/frappe/website/serve.py", line 28, in get_response
    response = ErrorPage(exception=e).render()
  File "/home/frappe/frappe-bench/apps/frappe/frappe/website/page_renderers/template_page.py", line 84, in render
    html = self.get_html()
  File "/home/frappe/frappe-bench/apps/frappe/frappe/website/utils.py", line 523, in cache_html_decorator
    html = func(*args, **kwargs)
  File "/home/frappe/frappe-bench/apps/frappe/frappe/website/page_renderers/template_page.py", line 92, in get_html
    self.init_context()
  File "/home/frappe/frappe-bench/apps/frappe/frappe/website/page_renderers/error_page.py", line 14, in init_context
    super().init_context()
  File "/home/frappe/frappe-bench/apps/frappe/frappe/website/page_renderers/base_template_page.py", line 15, in init_context
    self.context.update(get_website_settings())
  File "/home/frappe/frappe-bench/apps/frappe/frappe/website/doctype/website_settings/website_settings.py", line 263, in get_website_settings
    context.boot = get_boot_data()
  File "/home/frappe/frappe-bench/apps/frappe/frappe/website/utils.py", line 179, in get_boot_data
    "user": frappe.db.get_value("User", frappe.session.user, "time_zone") or get_system_timezone(),
  File "/home/frappe/frappe-bench/apps/frappe/frappe/database/database.py", line 519, in get_value
    result = self.get_values(
  File "/home/frappe/frappe-bench/apps/frappe/frappe/database/database.py", line 623, in get_values
    out = self._get_values_from_table(
  File "/home/frappe/frappe-bench/apps/frappe/frappe/database/database.py", line 896, in _get_values_from_table
    return query.run(as_dict=as_dict, debug=debug, update=update, run=run, pluck=pluck)
  File "/home/frappe/frappe-bench/apps/frappe/frappe/query_builder/utils.py", line 87, in execute_query
    result = frappe.db.sql(query, params, *args, **kwargs)  # nosemgrep
  File "/home/frappe/frappe-bench/apps/frappe/frappe/database/database.py", line 211, in sql
    self.connect()
  File "/home/frappe/frappe-bench/apps/frappe/frappe/database/database.py", line 117, in connect
    self._conn: "MariadbConnection" | "PostgresConnection" = self.get_connection()
  File "/home/frappe/frappe-bench/apps/frappe/frappe/database/mariadb/database.py", line 107, in get_connection
    conn = self._get_connection()
  File "/home/frappe/frappe-bench/apps/frappe/frappe/database/mariadb/database.py", line 113, in _get_connection
    return self.create_connection()
  File "/home/frappe/frappe-bench/apps/frappe/frappe/database/mariadb/database.py", line 116, in create_connection
    return pymysql.connect(**self.get_connection_settings())
  File "/home/frappe/frappe-bench/env/lib/python3.10/site-packages/pymysql/connections.py", line 358, in __init__
    self.connect()
  File "/home/frappe/frappe-bench/env/lib/python3.10/site-packages/pymysql/connections.py", line 711, in connect
    raise exc
pymysql.err.OperationalError: (2003, "Can't connect to MySQL server on '127.0.0.1' ([Errno 111] Connection refused)")

During handling of the above exception, another exception occurred:

Traceback (most recent call last):
  File "/home/frappe/frappe-bench/env/lib/python3.10/site-packages/pymysql/connections.py", line 644, in connect
    sock = socket.create_connection(
  File "/usr/lib/python3.10/socket.py", line 845, in create_connection
    raise err
  File "/usr/lib/python3.10/socket.py", line 833, in create_connection
    sock.connect(sa)
ConnectionRefusedError: [Errno 111] Connection refused

During handling of the above exception, another exception occurred:

Traceback (most recent call last):
  File "/home/frappe/frappe-bench/apps/frappe/frappe/utils/error.py", line 86, in log_error_snapshot
    log_error(title=str(exception), defer_insert=True)
  File "/home/frappe/frappe-bench/apps/frappe/frappe/utils/error.py", line 61, in log_error
    error_log = frappe.get_doc(
  File "/home/frappe/frappe-bench/apps/frappe/frappe/__init__.py", line 1329, in get_doc
    doc = frappe.model.document.get_doc(*args, **kwargs)
  File "/home/frappe/frappe-bench/apps/frappe/frappe/model/document.py", line 83, in get_doc
    controller = get_controller(doctype)
  File "/home/frappe/frappe-bench/apps/frappe/frappe/model/base_document.py", line 70, in get_controller
    site_controllers[doctype] = import_controller(doctype)
  File "/home/frappe/frappe-bench/apps/frappe/frappe/model/base_document.py", line 81, in import_controller
    doctype_info = frappe.db.get_value("DocType", doctype, fieldname="*")
  File "/home/frappe/frappe-bench/apps/frappe/frappe/database/database.py", line 519, in get_value
    result = self.get_values(
  File "/home/frappe/frappe-bench/apps/frappe/frappe/database/database.py", line 623, in get_values
    out = self._get_values_from_table(
  File "/home/frappe/frappe-bench/apps/frappe/frappe/database/database.py", line 896, in _get_values_from_table
    return query.run(as_dict=as_dict, debug=debug, update=update, run=run, pluck=pluck)
  File "/home/frappe/frappe-bench/apps/frappe/frappe/query_builder/utils.py", line 87, in execute_query
    result = frappe.db.sql(query, params, *args, **kwargs)  # nosemgrep
  File "/home/frappe/frappe-bench/apps/frappe/frappe/database/database.py", line 211, in sql
    self.connect()
  File "/home/frappe/frappe-bench/apps/frappe/frappe/database/database.py", line 117, in connect
    self._conn: "MariadbConnection" | "PostgresConnection" = self.get_connection()
  File "/home/frappe/frappe-bench/apps/frappe/frappe/database/mariadb/database.py", line 107, in get_connection
    conn = self._get_connection()
  File "/home/frappe/frappe-bench/apps/frappe/frappe/database/mariadb/database.py", line 113, in _get_connection
    return self.create_connection()
  File "/home/frappe/frappe-bench/apps/frappe/frappe/database/mariadb/database.py", line 116, in create_connection
    return pymysql.connect(**self.get_connection_settings())
  File "/home/frappe/frappe-bench/env/lib/python3.10/site-packages/pymysql/connections.py", line 358, in __init__
    self.connect()
  File "/home/frappe/frappe-bench/env/lib/python3.10/site-packages/pymysql/connections.py", line 711, in connect
    raise exc
pymysql.err.OperationalError: (2003, "Can't connect to MySQL server on '127.0.0.1' ([Errno 111] Connection refused)")
2024-07-18 11:46:07,948 ERROR frappe Could not take error snapshot: (2003, "Can't connect to MySQL server on '127.0.0.1' ([Errno 111] Connection refused)")
Site: erp.grupoatu.com
Form Dict: {'cmd': 'frappe.sessions.clear'}
Traceback (most recent call last):
  File "/home/frappe/frappe-bench/env/lib/python3.10/site-packages/pymysql/connections.py", line 644, in connect
    sock = socket.create_connection(
  File "/usr/lib/python3.10/socket.py", line 845, in create_connection
    raise err
  File "/usr/lib/python3.10/socket.py", line 833, in create_connection
    sock.connect(sa)
ConnectionRefusedError: [Errno 111] Connection refused

During handling of the above exception, another exception occurred:

Traceback (most recent call last):
  File "/home/frappe/frappe-bench/apps/frappe/frappe/app.py", line 110, in application
    response = frappe.api.handle(request)
  File "/home/frappe/frappe-bench/apps/frappe/frappe/api/__init__.py", line 49, in handle
    data = endpoint(**arguments)
  File "/home/frappe/frappe-bench/apps/frappe/frappe/api/v1.py", line 36, in handle_rpc_call
    return frappe.handler.handle()
  File "/home/frappe/frappe-bench/apps/frappe/frappe/handler.py", line 49, in handle
    data = execute_cmd(cmd)
  File "/home/frappe/frappe-bench/apps/frappe/frappe/handler.py", line 85, in execute_cmd
    return frappe.call(method, **frappe.form_dict)
  File "/home/frappe/frappe-bench/apps/frappe/frappe/__init__.py", line 1761, in call
    return fn(*args, **newargs)
  File "/home/frappe/frappe-bench/apps/frappe/frappe/utils/typing_validations.py", line 31, in wrapper
    return func(*args, **kwargs)
  File "/home/frappe/frappe-bench/apps/frappe/frappe/sessions.py", line 28, in clear
    frappe.local.session_obj.update(force=True)
  File "/home/frappe/frappe-bench/apps/frappe/frappe/sessions.py", line 378, in update
    ).run()
  File "/home/frappe/frappe-bench/apps/frappe/frappe/query_builder/utils.py", line 87, in execute_query
    result = frappe.db.sql(query, params, *args, **kwargs)  # nosemgrep
  File "/home/frappe/frappe-bench/apps/frappe/frappe/database/database.py", line 211, in sql
    self.connect()
  File "/home/frappe/frappe-bench/apps/frappe/frappe/database/database.py", line 117, in connect
    self._conn: "MariadbConnection" | "PostgresConnection" = self.get_connection()
  File "/home/frappe/frappe-bench/apps/frappe/frappe/database/mariadb/database.py", line 107, in get_connection
    conn = self._get_connection()
  File "/home/frappe/frappe-bench/apps/frappe/frappe/database/mariadb/database.py", line 113, in _get_connection
    return self.create_connection()
  File "/home/frappe/frappe-bench/apps/frappe/frappe/database/mariadb/database.py", line 116, in create_connection
    return pymysql.connect(**self.get_connection_settings())
  File "/home/frappe/frappe-bench/env/lib/python3.10/site-packages/pymysql/connections.py", line 358, in __init__
    self.connect()
  File "/home/frappe/frappe-bench/env/lib/python3.10/site-packages/pymysql/connections.py", line 711, in connect
    raise exc
pymysql.err.OperationalError: (2003, "Can't connect to MySQL server on '127.0.0.1' ([Errno 111] Connection refused)")

During handling of the above exception, another exception occurred:

Traceback (most recent call last):
  File "/home/frappe/frappe-bench/env/lib/python3.10/site-packages/pymysql/connections.py", line 644, in connect
    sock = socket.create_connection(
  File "/usr/lib/python3.10/socket.py", line 845, in create_connection
    raise err
  File "/usr/lib/python3.10/socket.py", line 833, in create_connection
    sock.connect(sa)
ConnectionRefusedError: [Errno 111] Connection refused

During handling of the above exception, another exception occurred:

Traceback (most recent call last):
  File "/home/frappe/frappe-bench/apps/frappe/frappe/utils/error.py", line 86, in log_error_snapshot
    log_error(title=str(exception), defer_insert=True)
  File "/home/frappe/frappe-bench/apps/frappe/frappe/utils/error.py", line 61, in log_error
    error_log = frappe.get_doc(
  File "/home/frappe/frappe-bench/apps/frappe/frappe/__init__.py", line 1329, in get_doc
    doc = frappe.model.document.get_doc(*args, **kwargs)
  File "/home/frappe/frappe-bench/apps/frappe/frappe/model/document.py", line 83, in get_doc
    controller = get_controller(doctype)
  File "/home/frappe/frappe-bench/apps/frappe/frappe/model/base_document.py", line 70, in get_controller
    site_controllers[doctype] = import_controller(doctype)
  File "/home/frappe/frappe-bench/apps/frappe/frappe/model/base_document.py", line 81, in import_controller
    doctype_info = frappe.db.get_value("DocType", doctype, fieldname="*")
  File "/home/frappe/frappe-bench/apps/frappe/frappe/database/database.py", line 519, in get_value
    result = self.get_values(
  File "/home/frappe/frappe-bench/apps/frappe/frappe/database/database.py", line 623, in get_values
    out = self._get_values_from_table(
  File "/home/frappe/frappe-bench/apps/frappe/frappe/database/database.py", line 896, in _get_values_from_table
    return query.run(as_dict=as_dict, debug=debug, update=update, run=run, pluck=pluck)
  File "/home/frappe/frappe-bench/apps/frappe/frappe/query_builder/utils.py", line 87, in execute_query
    result = frappe.db.sql(query, params, *args, **kwargs)  # nosemgrep
  File "/home/frappe/frappe-bench/apps/frappe/frappe/database/database.py", line 211, in sql
    self.connect()
  File "/home/frappe/frappe-bench/apps/frappe/frappe/database/database.py", line 117, in connect
    self._conn: "MariadbConnection" | "PostgresConnection" = self.get_connection()
  File "/home/frappe/frappe-bench/apps/frappe/frappe/database/mariadb/database.py", line 107, in get_connection
    conn = self._get_connection()
  File "/home/frappe/frappe-bench/apps/frappe/frappe/database/mariadb/database.py", line 113, in _get_connection
    return self.create_connection()
  File "/home/frappe/frappe-bench/apps/frappe/frappe/database/mariadb/database.py", line 116, in create_connection
    return pymysql.connect(**self.get_connection_settings())
  File "/home/frappe/frappe-bench/env/lib/python3.10/site-packages/pymysql/connections.py", line 358, in __init__
    self.connect()
  File "/home/frappe/frappe-bench/env/lib/python3.10/site-packages/pymysql/connections.py", line 711, in connect
    raise exc
pymysql.err.OperationalError: (2003, "Can't connect to MySQL server on '127.0.0.1' ([Errno 111] Connection refused)")
2024-07-18 11:46:17,180 ERROR frappe Could not take error snapshot: (2003, "Can't connect to MySQL server on '127.0.0.1' ([Errno 111] Connection refused)")
Site: erp.grupoatu.com
Form Dict: {'doctype': 'User', 'txt': 'charo', 'filters': '{"user_type":"System User","enabled":1}', 'cmd': 'frappe.desk.search.search_link'}
Traceback (most recent call last):
  File "/home/frappe/frappe-bench/env/lib/python3.10/site-packages/pymysql/connections.py", line 644, in connect
    sock = socket.create_connection(
  File "/usr/lib/python3.10/socket.py", line 845, in create_connection
    raise err
  File "/usr/lib/python3.10/socket.py", line 833, in create_connection
    sock.connect(sa)
ConnectionRefusedError: [Errno 111] Connection refused

During handling of the above exception, another exception occurred:

Traceback (most recent call last):
  File "/home/frappe/frappe-bench/apps/frappe/frappe/app.py", line 110, in application
    response = frappe.api.handle(request)
  File "/home/frappe/frappe-bench/apps/frappe/frappe/api/__init__.py", line 49, in handle
    data = endpoint(**arguments)
  File "/home/frappe/frappe-bench/apps/frappe/frappe/api/v1.py", line 36, in handle_rpc_call
    return frappe.handler.handle()
  File "/home/frappe/frappe-bench/apps/frappe/frappe/handler.py", line 49, in handle
    data = execute_cmd(cmd)
  File "/home/frappe/frappe-bench/apps/frappe/frappe/handler.py", line 85, in execute_cmd
    return frappe.call(method, **frappe.form_dict)
  File "/home/frappe/frappe-bench/apps/frappe/frappe/__init__.py", line 1761, in call
    return fn(*args, **newargs)
  File "/home/frappe/frappe-bench/apps/frappe/frappe/utils/typing_validations.py", line 31, in wrapper
    return func(*args, **kwargs)
  File "/home/frappe/frappe-bench/apps/frappe/frappe/desk/search.py", line 47, in search_link
    results = search_widget(
  File "/home/frappe/frappe-bench/apps/frappe/frappe/utils/typing_validations.py", line 31, in wrapper
    return func(*args, **kwargs)
  File "/home/frappe/frappe-bench/apps/frappe/frappe/desk/search.py", line 94, in search_widget
    return frappe.call(
  File "/home/frappe/frappe-bench/apps/frappe/frappe/__init__.py", line 1761, in call
    return fn(*args, **newargs)
  File "/home/frappe/frappe-bench/apps/frappe/frappe/utils/typing_validations.py", line 31, in wrapper
    return func(*args, **kwargs)
  File "/home/frappe/frappe-bench/apps/frappe/frappe/__init__.py", line 2513, in wrapper
    if kwargs["doctype"] and not db.exists("DocType", kwargs["doctype"]):
  File "/home/frappe/frappe-bench/apps/frappe/frappe/database/database.py", line 1130, in exists
    return self.get_value(dt, dn, ignore=True, cache=cache, order_by=None)
  File "/home/frappe/frappe-bench/apps/frappe/frappe/database/database.py", line 519, in get_value
    result = self.get_values(
  File "/home/frappe/frappe-bench/apps/frappe/frappe/database/database.py", line 623, in get_values
    out = self._get_values_from_table(
  File "/home/frappe/frappe-bench/apps/frappe/frappe/database/database.py", line 896, in _get_values_from_table
    return query.run(as_dict=as_dict, debug=debug, update=update, run=run, pluck=pluck)
  File "/home/frappe/frappe-bench/apps/frappe/frappe/query_builder/utils.py", line 87, in execute_query
    result = frappe.db.sql(query, params, *args, **kwargs)  # nosemgrep
  File "/home/frappe/frappe-bench/apps/frappe/frappe/database/database.py", line 211, in sql
    self.connect()
  File "/home/frappe/frappe-bench/apps/frappe/frappe/database/database.py", line 117, in connect
    self._conn: "MariadbConnection" | "PostgresConnection" = self.get_connection()
  File "/home/frappe/frappe-bench/apps/frappe/frappe/database/mariadb/database.py", line 107, in get_connection
    conn = self._get_connection()
  File "/home/frappe/frappe-bench/apps/frappe/frappe/database/mariadb/database.py", line 113, in _get_connection
    return self.create_connection()
  File "/home/frappe/frappe-bench/apps/frappe/frappe/database/mariadb/database.py", line 116, in create_connection
    return pymysql.connect(**self.get_connection_settings())
  File "/home/frappe/frappe-bench/env/lib/python3.10/site-packages/pymysql/connections.py", line 358, in __init__
    self.connect()
  File "/home/frappe/frappe-bench/env/lib/python3.10/site-packages/pymysql/connections.py", line 711, in connect
    raise exc
pymysql.err.OperationalError: (2003, "Can't connect to MySQL server on '127.0.0.1' ([Errno 111] Connection refused)")

During handling of the above exception, another exception occurred:

Traceback (most recent call last):
  File "/home/frappe/frappe-bench/env/lib/python3.10/site-packages/pymysql/connections.py", line 644, in connect
    sock = socket.create_connection(
  File "/usr/lib/python3.10/socket.py", line 845, in create_connection
    raise err
  File "/usr/lib/python3.10/socket.py", line 833, in create_connection
    sock.connect(sa)
ConnectionRefusedError: [Errno 111] Connection refused

During handling of the above exception, another exception occurred:

Traceback (most recent call last):
  File "/home/frappe/frappe-bench/apps/frappe/frappe/utils/error.py", line 86, in log_error_snapshot
    log_error(title=str(exception), defer_insert=True)
  File "/home/frappe/frappe-bench/apps/frappe/frappe/utils/error.py", line 61, in log_error
    error_log = frappe.get_doc(
  File "/home/frappe/frappe-bench/apps/frappe/frappe/__init__.py", line 1329, in get_doc
    doc = frappe.model.document.get_doc(*args, **kwargs)
  File "/home/frappe/frappe-bench/apps/frappe/frappe/model/document.py", line 83, in get_doc
    controller = get_controller(doctype)
  File "/home/frappe/frappe-bench/apps/frappe/frappe/model/base_document.py", line 70, in get_controller
    site_controllers[doctype] = import_controller(doctype)
  File "/home/frappe/frappe-bench/apps/frappe/frappe/model/base_document.py", line 81, in import_controller
    doctype_info = frappe.db.get_value("DocType", doctype, fieldname="*")
  File "/home/frappe/frappe-bench/apps/frappe/frappe/database/database.py", line 519, in get_value
    result = self.get_values(
  File "/home/frappe/frappe-bench/apps/frappe/frappe/database/database.py", line 623, in get_values
    out = self._get_values_from_table(
  File "/home/frappe/frappe-bench/apps/frappe/frappe/database/database.py", line 896, in _get_values_from_table
    return query.run(as_dict=as_dict, debug=debug, update=update, run=run, pluck=pluck)
  File "/home/frappe/frappe-bench/apps/frappe/frappe/query_builder/utils.py", line 87, in execute_query
    result = frappe.db.sql(query, params, *args, **kwargs)  # nosemgrep
  File "/home/frappe/frappe-bench/apps/frappe/frappe/database/database.py", line 211, in sql
    self.connect()
  File "/home/frappe/frappe-bench/apps/frappe/frappe/database/database.py", line 117, in connect
    self._conn: "MariadbConnection" | "PostgresConnection" = self.get_connection()
  File "/home/frappe/frappe-bench/apps/frappe/frappe/database/mariadb/database.py", line 107, in get_connection
    conn = self._get_connection()
  File "/home/frappe/frappe-bench/apps/frappe/frappe/database/mariadb/database.py", line 113, in _get_connection
    return self.create_connection()
  File "/home/frappe/frappe-bench/apps/frappe/frappe/database/mariadb/database.py", line 116, in create_connection
    return pymysql.connect(**self.get_connection_settings())
  File "/home/frappe/frappe-bench/env/lib/python3.10/site-packages/pymysql/connections.py", line 358, in __init__
    self.connect()
  File "/home/frappe/frappe-bench/env/lib/python3.10/site-packages/pymysql/connections.py", line 711, in connect
    raise exc
pymysql.err.OperationalError: (2003, "Can't connect to MySQL server on '127.0.0.1' ([Errno 111] Connection refused)")
2024-07-18 11:46:34,570 ERROR frappe Could not take error snapshot: (2003, "Can't connect to MySQL server on '127.0.0.1' ([Errno 111] Connection refused)")
Site: erp.grupoatu.com
Form Dict: {}
Traceback (most recent call last):
  File "/home/frappe/frappe-bench/env/lib/python3.10/site-packages/pymysql/connections.py", line 644, in connect
    sock = socket.create_connection(
  File "/usr/lib/python3.10/socket.py", line 845, in create_connection
    raise err
  File "/usr/lib/python3.10/socket.py", line 833, in create_connection
    sock.connect(sa)
ConnectionRefusedError: [Errno 111] Connection refused

During handling of the above exception, another exception occurred:

Traceback (most recent call last):
  File "/home/frappe/frappe-bench/apps/frappe/frappe/app.py", line 95, in application
    init_request(request)
  File "/home/frappe/frappe-bench/apps/frappe/frappe/app.py", line 191, in init_request
    frappe.local.http_request = HTTPRequest()
  File "/home/frappe/frappe-bench/apps/frappe/frappe/auth.py", line 42, in __init__
    self.set_session()
  File "/home/frappe/frappe-bench/apps/frappe/frappe/auth.py", line 76, in set_session
    frappe.local.login_manager = LoginManager()
  File "/home/frappe/frappe-bench/apps/frappe/frappe/auth.py", line 118, in __init__
    self.make_session(resume=True)
  File "/home/frappe/frappe-bench/apps/frappe/frappe/auth.py", line 204, in make_session
    frappe.local.session_obj = Session(
  File "/home/frappe/frappe-bench/apps/frappe/frappe/sessions.py", line 209, in __init__
    self.resume()
  File "/home/frappe/frappe-bench/apps/frappe/frappe/sessions.py", line 272, in resume
    data = self.get_session_record()
  File "/home/frappe/frappe-bench/apps/frappe/frappe/sessions.py", line 289, in get_session_record
    r = self.get_session_data()
  File "/home/frappe/frappe-bench/apps/frappe/frappe/sessions.py", line 305, in get_session_data
    data = self.get_session_data_from_db()
  File "/home/frappe/frappe-bench/apps/frappe/frappe/sessions.py", line 334, in get_session_data_from_db
    ).run()
  File "/home/frappe/frappe-bench/apps/frappe/frappe/query_builder/utils.py", line 87, in execute_query
    result = frappe.db.sql(query, params, *args, **kwargs)  # nosemgrep
  File "/home/frappe/frappe-bench/apps/frappe/frappe/database/database.py", line 211, in sql
    self.connect()
  File "/home/frappe/frappe-bench/apps/frappe/frappe/database/database.py", line 117, in connect
    self._conn: "MariadbConnection" | "PostgresConnection" = self.get_connection()
  File "/home/frappe/frappe-bench/apps/frappe/frappe/database/mariadb/database.py", line 107, in get_connection
    conn = self._get_connection()
  File "/home/frappe/frappe-bench/apps/frappe/frappe/database/mariadb/database.py", line 113, in _get_connection
    return self.create_connection()
  File "/home/frappe/frappe-bench/apps/frappe/frappe/database/mariadb/database.py", line 116, in create_connection
    return pymysql.connect(**self.get_connection_settings())
  File "/home/frappe/frappe-bench/env/lib/python3.10/site-packages/pymysql/connections.py", line 358, in __init__
    self.connect()
  File "/home/frappe/frappe-bench/env/lib/python3.10/site-packages/pymysql/connections.py", line 711, in connect
    raise exc
pymysql.err.OperationalError: (2003, "Can't connect to MySQL server on '127.0.0.1' ([Errno 111] Connection refused)")

During handling of the above exception, another exception occurred:

Traceback (most recent call last):
  File "/home/frappe/frappe-bench/env/lib/python3.10/site-packages/pymysql/connections.py", line 644, in connect
    sock = socket.create_connection(
  File "/usr/lib/python3.10/socket.py", line 845, in create_connection
    raise err
  File "/usr/lib/python3.10/socket.py", line 833, in create_connection
    sock.connect(sa)
ConnectionRefusedError: [Errno 111] Connection refused

During handling of the above exception, another exception occurred:

Traceback (most recent call last):
  File "/home/frappe/frappe-bench/apps/frappe/frappe/utils/error.py", line 86, in log_error_snapshot
    log_error(title=str(exception), defer_insert=True)
  File "/home/frappe/frappe-bench/apps/frappe/frappe/utils/error.py", line 61, in log_error
    error_log = frappe.get_doc(
  File "/home/frappe/frappe-bench/apps/frappe/frappe/__init__.py", line 1329, in get_doc
    doc = frappe.model.document.get_doc(*args, **kwargs)
  File "/home/frappe/frappe-bench/apps/frappe/frappe/model/document.py", line 83, in get_doc
    controller = get_controller(doctype)
  File "/home/frappe/frappe-bench/apps/frappe/frappe/model/base_document.py", line 70, in get_controller
    site_controllers[doctype] = import_controller(doctype)
  File "/home/frappe/frappe-bench/apps/frappe/frappe/model/base_document.py", line 81, in import_controller
    doctype_info = frappe.db.get_value("DocType", doctype, fieldname="*")
  File "/home/frappe/frappe-bench/apps/frappe/frappe/database/database.py", line 519, in get_value
    result = self.get_values(
  File "/home/frappe/frappe-bench/apps/frappe/frappe/database/database.py", line 623, in get_values
    out = self._get_values_from_table(
  File "/home/frappe/frappe-bench/apps/frappe/frappe/database/database.py", line 896, in _get_values_from_table
    return query.run(as_dict=as_dict, debug=debug, update=update, run=run, pluck=pluck)
  File "/home/frappe/frappe-bench/apps/frappe/frappe/query_builder/utils.py", line 87, in execute_query
    result = frappe.db.sql(query, params, *args, **kwargs)  # nosemgrep
  File "/home/frappe/frappe-bench/apps/frappe/frappe/database/database.py", line 211, in sql
    self.connect()
  File "/home/frappe/frappe-bench/apps/frappe/frappe/database/database.py", line 117, in connect
    self._conn: "MariadbConnection" | "PostgresConnection" = self.get_connection()
  File "/home/frappe/frappe-bench/apps/frappe/frappe/database/mariadb/database.py", line 107, in get_connection
    conn = self._get_connection()
  File "/home/frappe/frappe-bench/apps/frappe/frappe/database/mariadb/database.py", line 113, in _get_connection
    return self.create_connection()
  File "/home/frappe/frappe-bench/apps/frappe/frappe/database/mariadb/database.py", line 116, in create_connection
    return pymysql.connect(**self.get_connection_settings())
  File "/home/frappe/frappe-bench/env/lib/python3.10/site-packages/pymysql/connections.py", line 358, in __init__
    self.connect()
  File "/home/frappe/frappe-bench/env/lib/python3.10/site-packages/pymysql/connections.py", line 711, in connect
    raise exc
pymysql.err.OperationalError: (2003, "Can't connect to MySQL server on '127.0.0.1' ([Errno 111] Connection refused)")
2024-07-18 11:46:34,682 ERROR frappe Could not take error snapshot: (2003, "Can't connect to MySQL server on '127.0.0.1' ([Errno 111] Connection refused)")
Site: erp.grupoatu.com
Form Dict: {}
Traceback (most recent call last):
  File "/home/frappe/frappe-bench/env/lib/python3.10/site-packages/pymysql/connections.py", line 644, in connect
    sock = socket.create_connection(
  File "/usr/lib/python3.10/socket.py", line 845, in create_connection
    raise err
  File "/usr/lib/python3.10/socket.py", line 833, in create_connection
    sock.connect(sa)
ConnectionRefusedError: [Errno 111] Connection refused

During handling of the above exception, another exception occurred:

Traceback (most recent call last):
  File "/home/frappe/frappe-bench/apps/frappe/frappe/app.py", line 95, in application
    init_request(request)
  File "/home/frappe/frappe-bench/apps/frappe/frappe/app.py", line 191, in init_request
    frappe.local.http_request = HTTPRequest()
  File "/home/frappe/frappe-bench/apps/frappe/frappe/auth.py", line 42, in __init__
    self.set_session()
  File "/home/frappe/frappe-bench/apps/frappe/frappe/auth.py", line 76, in set_session
    frappe.local.login_manager = LoginManager()
  File "/home/frappe/frappe-bench/apps/frappe/frappe/auth.py", line 118, in __init__
    self.make_session(resume=True)
  File "/home/frappe/frappe-bench/apps/frappe/frappe/auth.py", line 204, in make_session
    frappe.local.session_obj = Session(
  File "/home/frappe/frappe-bench/apps/frappe/frappe/sessions.py", line 209, in __init__
    self.resume()
  File "/home/frappe/frappe-bench/apps/frappe/frappe/sessions.py", line 272, in resume
    data = self.get_session_record()
  File "/home/frappe/frappe-bench/apps/frappe/frappe/sessions.py", line 289, in get_session_record
    r = self.get_session_data()
  File "/home/frappe/frappe-bench/apps/frappe/frappe/sessions.py", line 305, in get_session_data
    data = self.get_session_data_from_db()
  File "/home/frappe/frappe-bench/apps/frappe/frappe/sessions.py", line 334, in get_session_data_from_db
    ).run()
  File "/home/frappe/frappe-bench/apps/frappe/frappe/query_builder/utils.py", line 87, in execute_query
    result = frappe.db.sql(query, params, *args, **kwargs)  # nosemgrep
  File "/home/frappe/frappe-bench/apps/frappe/frappe/database/database.py", line 211, in sql
    self.connect()
  File "/home/frappe/frappe-bench/apps/frappe/frappe/database/database.py", line 117, in connect
    self._conn: "MariadbConnection" | "PostgresConnection" = self.get_connection()
  File "/home/frappe/frappe-bench/apps/frappe/frappe/database/mariadb/database.py", line 107, in get_connection
    conn = self._get_connection()
  File "/home/frappe/frappe-bench/apps/frappe/frappe/database/mariadb/database.py", line 113, in _get_connection
    return self.create_connection()
  File "/home/frappe/frappe-bench/apps/frappe/frappe/database/mariadb/database.py", line 116, in create_connection
    return pymysql.connect(**self.get_connection_settings())
  File "/home/frappe/frappe-bench/env/lib/python3.10/site-packages/pymysql/connections.py", line 358, in __init__
    self.connect()
  File "/home/frappe/frappe-bench/env/lib/python3.10/site-packages/pymysql/connections.py", line 711, in connect
    raise exc
pymysql.err.OperationalError: (2003, "Can't connect to MySQL server on '127.0.0.1' ([Errno 111] Connection refused)")

During handling of the above exception, another exception occurred:

Traceback (most recent call last):
  File "/home/frappe/frappe-bench/env/lib/python3.10/site-packages/pymysql/connections.py", line 644, in connect
    sock = socket.create_connection(
  File "/usr/lib/python3.10/socket.py", line 845, in create_connection
    raise err
  File "/usr/lib/python3.10/socket.py", line 833, in create_connection
    sock.connect(sa)
ConnectionRefusedError: [Errno 111] Connection refused

During handling of the above exception, another exception occurred:

Traceback (most recent call last):
  File "/home/frappe/frappe-bench/apps/frappe/frappe/utils/error.py", line 86, in log_error_snapshot
    log_error(title=str(exception), defer_insert=True)
  File "/home/frappe/frappe-bench/apps/frappe/frappe/utils/error.py", line 61, in log_error
    error_log = frappe.get_doc(
  File "/home/frappe/frappe-bench/apps/frappe/frappe/__init__.py", line 1329, in get_doc
    doc = frappe.model.document.get_doc(*args, **kwargs)
  File "/home/frappe/frappe-bench/apps/frappe/frappe/model/document.py", line 83, in get_doc
    controller = get_controller(doctype)
  File "/home/frappe/frappe-bench/apps/frappe/frappe/model/base_document.py", line 70, in get_controller
    site_controllers[doctype] = import_controller(doctype)
  File "/home/frappe/frappe-bench/apps/frappe/frappe/model/base_document.py", line 81, in import_controller
    doctype_info = frappe.db.get_value("DocType", doctype, fieldname="*")
  File "/home/frappe/frappe-bench/apps/frappe/frappe/database/database.py", line 519, in get_value
    result = self.get_values(
  File "/home/frappe/frappe-bench/apps/frappe/frappe/database/database.py", line 623, in get_values
    out = self._get_values_from_table(
  File "/home/frappe/frappe-bench/apps/frappe/frappe/database/database.py", line 896, in _get_values_from_table
    return query.run(as_dict=as_dict, debug=debug, update=update, run=run, pluck=pluck)
  File "/home/frappe/frappe-bench/apps/frappe/frappe/query_builder/utils.py", line 87, in execute_query
    result = frappe.db.sql(query, params, *args, **kwargs)  # nosemgrep
  File "/home/frappe/frappe-bench/apps/frappe/frappe/database/database.py", line 211, in sql
    self.connect()
  File "/home/frappe/frappe-bench/apps/frappe/frappe/database/database.py", line 117, in connect
    self._conn: "MariadbConnection" | "PostgresConnection" = self.get_connection()
  File "/home/frappe/frappe-bench/apps/frappe/frappe/database/mariadb/database.py", line 107, in get_connection
    conn = self._get_connection()
  File "/home/frappe/frappe-bench/apps/frappe/frappe/database/mariadb/database.py", line 113, in _get_connection
    return self.create_connection()
  File "/home/frappe/frappe-bench/apps/frappe/frappe/database/mariadb/database.py", line 116, in create_connection
    return pymysql.connect(**self.get_connection_settings())
  File "/home/frappe/frappe-bench/env/lib/python3.10/site-packages/pymysql/connections.py", line 358, in __init__
    self.connect()
  File "/home/frappe/frappe-bench/env/lib/python3.10/site-packages/pymysql/connections.py", line 711, in connect
    raise exc
pymysql.err.OperationalError: (2003, "Can't connect to MySQL server on '127.0.0.1' ([Errno 111] Connection refused)")
2024-07-18 12:30:25,655 ERROR frappe New Exception collected in error log
Site: erp.grupoatu.com
Form Dict: {'doctype': 'Course', 'name': 'CUR-2024-01416', 'items': '["Program","Course Enrollment","Course Schedule","Student Group","Assessment Plan","Assessment Result"]', 'cmd': 'frappe.desk.notifications.get_open_count'}
2024-07-18 12:30:25,657 ERROR frappe New Exception collected in error log
Site: erp.grupoatu.com
Form Dict: {'doctype': 'Course', 'name': 'CUR-2024-01416', 'items': '["Program","Course Enrollment","Course Schedule","Student Group","Assessment Plan","Assessment Result"]', 'cmd': 'frappe.desk.notifications.get_open_count'}
2024-07-18 13:01:37,224 ERROR frappe New Exception collected in error log
Site: erp.grupoatu.com
Form Dict: {'cmd': 'frappe.utils.print_format.download_multi_pdf_async'}
2024-07-18 13:10:00,885 ERROR frappe New Exception collected in error log
Site: erp.grupoatu.com
Form Dict: {'doctype': 'Sales Invoice', 'name': ['ASF/O/2400012'], 'print_format': 'Standard', 'lang': 'es', 'cmd': 'frappe.utils.print_format.download_multi_pdf_async'}
2024-07-18 13:10:15,635 ERROR frappe New Exception collected in error log
Site: erp.grupoatu.com
Form Dict: {'doctype': 'Sales Invoice', 'name': 'ASF/O/2400012', 'print_format': 'Standard', 'lang': 'es', 'cmd': 'frappe.utils.print_format.download_multi_pdf_async'}
2024-07-18 13:11:14,131 ERROR frappe New Exception collected in error log
Site: erp.grupoatu.com
Form Dict: {'doctype': 'Sales Invoice', 'name': ['ASF/O/2400012'], 'print_format': 'Standard', 'lang': 'es', 'cmd': 'frappe.utils.print_format.download_multi_pdf_async'}
2024-07-18 16:29:05,503 ERROR frappe New Exception collected in error log
Site: erp.grupoatu.com
Form Dict: {'doctype': 'Course', 'name': 'Este curso de prueba', 'items': '["Program","Course Enrollment","Course Schedule","Student Group","Assessment Plan","Assessment Result"]', 'cmd': 'frappe.desk.notifications.get_open_count'}
2024-07-18 16:29:05,597 ERROR frappe New Exception collected in error log
Site: erp.grupoatu.com
Form Dict: {'doctype': 'Course', 'name': 'Este curso de prueba', 'items': '["Program","Course Enrollment","Course Schedule","Student Group","Assessment Plan","Assessment Result"]', 'cmd': 'frappe.desk.notifications.get_open_count'}
2024-07-19 01:07:59,372 ERROR frappe New Exception collected in error log
Site: erp.grupoatu.com
Form Dict: {'doctype': 'Sales Invoice', 'name': 'BATU/V/2400003', 'cmd': 'frappe.desk.form.save.cancel'}
2024-07-19 01:08:07,925 ERROR frappe New Exception collected in error log
Site: erp.grupoatu.com
Form Dict: {'doctype': 'Sales Invoice', 'name': 'BATU/V/2400003', 'cmd': 'frappe.desk.form.save.cancel'}
2024-07-19 01:08:23,220 ERROR frappe New Exception collected in error log
Site: erp.grupoatu.com
Form Dict: {'doctype': 'Sales Invoice', 'name': 'BATU/V/2400003', 'cmd': 'frappe.desk.form.save.cancel'}
2024-07-19 08:15:54,957 ERROR frappe New Exception collected in error log
Site: erp.grupoatu.com
Form Dict: {'doctype': 'Sales Invoice', 'name': 'BATU/V/2400003', 'cmd': 'frappe.desk.form.save.cancel'}
2024-07-19 08:17:31,741 ERROR frappe New Exception collected in error log
Site: erp.grupoatu.com
Form Dict: {'doctype': 'Sales Invoice', 'name': 'BATU/V/2400003', 'cmd': 'frappe.desk.form.save.cancel'}
2024-07-19 08:28:08,072 ERROR frappe New Exception collected in error log
Site: erp.grupoatu.com
Form Dict: {'doctype': 'Sales Invoice', 'name': 'BATU/V/2400003', 'cmd': 'frappe.desk.form.save.cancel'}
2024-07-19 10:49:52,584 ERROR frappe New Exception collected in error log
Site: erp.grupoatu.com
Form Dict: {'doctype': 'Course Schedule', 'start': '2024-07-01 00:00:00', 'end': '2024-08-12 00:00:00', 'filters': '[]', 'field_map': '{"start":"from_time","end":"to_time","id":"name","title":"course","allDay":"allDay"}', 'cmd': 'education.education.api.get_course_schedule_events'}
2024-07-19 12:00:42,281 ERROR frappe Could not take error snapshot: (2003, "Can't connect to MySQL server on '127.0.0.1' ([Errno 111] Connection refused)")
Site: erp.grupoatu.com
Form Dict: {'doctype': 'Room', 'name': '300001327', 'cmd': 'frappe.desk.form.load.get_docinfo'}
Traceback (most recent call last):
  File "/home/frappe/frappe-bench/env/lib/python3.10/site-packages/pymysql/connections.py", line 779, in _read_bytes
    data = self._rfile.read(num_bytes)
  File "/usr/lib/python3.10/socket.py", line 705, in readinto
    return self._sock.recv_into(b)
ConnectionResetError: [Errno 104] Connection reset by peer

During handling of the above exception, another exception occurred:

Traceback (most recent call last):
  File "/home/frappe/frappe-bench/apps/frappe/frappe/app.py", line 110, in application
    response = frappe.api.handle(request)
  File "/home/frappe/frappe-bench/apps/frappe/frappe/api/__init__.py", line 49, in handle
    data = endpoint(**arguments)
  File "/home/frappe/frappe-bench/apps/frappe/frappe/api/v1.py", line 36, in handle_rpc_call
    return frappe.handler.handle()
  File "/home/frappe/frappe-bench/apps/frappe/frappe/handler.py", line 49, in handle
    data = execute_cmd(cmd)
  File "/home/frappe/frappe-bench/apps/frappe/frappe/handler.py", line 85, in execute_cmd
    return frappe.call(method, **frappe.form_dict)
  File "/home/frappe/frappe-bench/apps/frappe/frappe/__init__.py", line 1761, in call
    return fn(*args, **newargs)
  File "/home/frappe/frappe-bench/apps/frappe/frappe/utils/typing_validations.py", line 31, in wrapper
    return func(*args, **kwargs)
  File "/home/frappe/frappe-bench/apps/frappe/frappe/desk/form/load.py", line 97, in get_docinfo
    doc = frappe.get_doc(doctype, name)
  File "/home/frappe/frappe-bench/apps/frappe/frappe/__init__.py", line 1329, in get_doc
    doc = frappe.model.document.get_doc(*args, **kwargs)
  File "/home/frappe/frappe-bench/apps/frappe/frappe/model/document.py", line 85, in get_doc
    return controller(*args, **kwargs)
  File "/home/frappe/frappe-bench/apps/frappe/frappe/model/document.py", line 126, in __init__
    self.load_from_db()
  File "/home/frappe/frappe-bench/apps/frappe/frappe/model/document.py", line 167, in load_from_db
    d = frappe.db.get_value(
  File "/home/frappe/frappe-bench/apps/frappe/frappe/database/database.py", line 519, in get_value
    result = self.get_values(
  File "/home/frappe/frappe-bench/apps/frappe/frappe/database/database.py", line 623, in get_values
    out = self._get_values_from_table(
  File "/home/frappe/frappe-bench/apps/frappe/frappe/database/database.py", line 896, in _get_values_from_table
    return query.run(as_dict=as_dict, debug=debug, update=update, run=run, pluck=pluck)
  File "/home/frappe/frappe-bench/apps/frappe/frappe/query_builder/utils.py", line 87, in execute_query
    result = frappe.db.sql(query, params, *args, **kwargs)  # nosemgrep
  File "/home/frappe/frappe-bench/apps/frappe/frappe/database/database.py", line 211, in sql
    self.connect()
  File "/home/frappe/frappe-bench/apps/frappe/frappe/database/database.py", line 117, in connect
    self._conn: "MariadbConnection" | "PostgresConnection" = self.get_connection()
  File "/home/frappe/frappe-bench/apps/frappe/frappe/database/mariadb/database.py", line 107, in get_connection
    conn = self._get_connection()
  File "/home/frappe/frappe-bench/apps/frappe/frappe/database/mariadb/database.py", line 113, in _get_connection
    return self.create_connection()
  File "/home/frappe/frappe-bench/apps/frappe/frappe/database/mariadb/database.py", line 116, in create_connection
    return pymysql.connect(**self.get_connection_settings())
  File "/home/frappe/frappe-bench/env/lib/python3.10/site-packages/pymysql/connections.py", line 358, in __init__
    self.connect()
  File "/home/frappe/frappe-bench/env/lib/python3.10/site-packages/pymysql/connections.py", line 663, in connect
    self._get_server_information()
  File "/home/frappe/frappe-bench/env/lib/python3.10/site-packages/pymysql/connections.py", line 1099, in _get_server_information
    packet = self._read_packet()
  File "/home/frappe/frappe-bench/env/lib/python3.10/site-packages/pymysql/connections.py", line 739, in _read_packet
    packet_header = self._read_bytes(4)
  File "/home/frappe/frappe-bench/env/lib/python3.10/site-packages/pymysql/connections.py", line 785, in _read_bytes
    raise err.OperationalError(
pymysql.err.OperationalError: (2013, 'Lost connection to MySQL server during query ([Errno 104] Connection reset by peer)')

During handling of the above exception, another exception occurred:

Traceback (most recent call last):
  File "/home/frappe/frappe-bench/env/lib/python3.10/site-packages/pymysql/connections.py", line 644, in connect
    sock = socket.create_connection(
  File "/usr/lib/python3.10/socket.py", line 845, in create_connection
    raise err
  File "/usr/lib/python3.10/socket.py", line 833, in create_connection
    sock.connect(sa)
ConnectionRefusedError: [Errno 111] Connection refused

During handling of the above exception, another exception occurred:

Traceback (most recent call last):
  File "/home/frappe/frappe-bench/apps/frappe/frappe/utils/error.py", line 86, in log_error_snapshot
    log_error(title=str(exception), defer_insert=True)
  File "/home/frappe/frappe-bench/apps/frappe/frappe/utils/error.py", line 61, in log_error
    error_log = frappe.get_doc(
  File "/home/frappe/frappe-bench/apps/frappe/frappe/__init__.py", line 1329, in get_doc
    doc = frappe.model.document.get_doc(*args, **kwargs)
  File "/home/frappe/frappe-bench/apps/frappe/frappe/model/document.py", line 83, in get_doc
    controller = get_controller(doctype)
  File "/home/frappe/frappe-bench/apps/frappe/frappe/model/base_document.py", line 70, in get_controller
    site_controllers[doctype] = import_controller(doctype)
  File "/home/frappe/frappe-bench/apps/frappe/frappe/model/base_document.py", line 81, in import_controller
    doctype_info = frappe.db.get_value("DocType", doctype, fieldname="*")
  File "/home/frappe/frappe-bench/apps/frappe/frappe/database/database.py", line 519, in get_value
    result = self.get_values(
  File "/home/frappe/frappe-bench/apps/frappe/frappe/database/database.py", line 623, in get_values
    out = self._get_values_from_table(
  File "/home/frappe/frappe-bench/apps/frappe/frappe/database/database.py", line 896, in _get_values_from_table
    return query.run(as_dict=as_dict, debug=debug, update=update, run=run, pluck=pluck)
  File "/home/frappe/frappe-bench/apps/frappe/frappe/query_builder/utils.py", line 87, in execute_query
    result = frappe.db.sql(query, params, *args, **kwargs)  # nosemgrep
  File "/home/frappe/frappe-bench/apps/frappe/frappe/database/database.py", line 211, in sql
    self.connect()
  File "/home/frappe/frappe-bench/apps/frappe/frappe/database/database.py", line 117, in connect
    self._conn: "MariadbConnection" | "PostgresConnection" = self.get_connection()
  File "/home/frappe/frappe-bench/apps/frappe/frappe/database/mariadb/database.py", line 107, in get_connection
    conn = self._get_connection()
  File "/home/frappe/frappe-bench/apps/frappe/frappe/database/mariadb/database.py", line 113, in _get_connection
    return self.create_connection()
  File "/home/frappe/frappe-bench/apps/frappe/frappe/database/mariadb/database.py", line 116, in create_connection
    return pymysql.connect(**self.get_connection_settings())
  File "/home/frappe/frappe-bench/env/lib/python3.10/site-packages/pymysql/connections.py", line 358, in __init__
    self.connect()
  File "/home/frappe/frappe-bench/env/lib/python3.10/site-packages/pymysql/connections.py", line 711, in connect
    raise exc
pymysql.err.OperationalError: (2003, "Can't connect to MySQL server on '127.0.0.1' ([Errno 111] Connection refused)")
2024-07-19 12:00:42,282 ERROR frappe Could not take error snapshot: (2003, "Can't connect to MySQL server on '127.0.0.1' ([Errno 111] Connection refused)")
Site: erp.grupoatu.com
Form Dict: {'is_private': '1', 'folder': 'Home/Attachments', 'doctype': 'Room', 'docname': '300001327', 'cmd': 'upload_file'}
Traceback (most recent call last):
  File "/home/frappe/frappe-bench/env/lib/python3.10/site-packages/pymysql/connections.py", line 779, in _read_bytes
    data = self._rfile.read(num_bytes)
  File "/usr/lib/python3.10/socket.py", line 705, in readinto
    return self._sock.recv_into(b)
ConnectionResetError: [Errno 104] Connection reset by peer

During handling of the above exception, another exception occurred:

Traceback (most recent call last):
  File "/home/frappe/frappe-bench/apps/frappe/frappe/app.py", line 110, in application
    response = frappe.api.handle(request)
  File "/home/frappe/frappe-bench/apps/frappe/frappe/api/__init__.py", line 49, in handle
    data = endpoint(**arguments)
  File "/home/frappe/frappe-bench/apps/frappe/frappe/api/v1.py", line 36, in handle_rpc_call
    return frappe.handler.handle()
  File "/home/frappe/frappe-bench/apps/frappe/frappe/handler.py", line 49, in handle
    data = execute_cmd(cmd)
  File "/home/frappe/frappe-bench/apps/frappe/frappe/handler.py", line 85, in execute_cmd
    return frappe.call(method, **frappe.form_dict)
  File "/home/frappe/frappe-bench/apps/frappe/frappe/__init__.py", line 1761, in call
    return fn(*args, **newargs)
  File "/home/frappe/frappe-bench/apps/frappe/frappe/utils/typing_validations.py", line 31, in wrapper
    return func(*args, **kwargs)
  File "/home/frappe/frappe-bench/apps/frappe/frappe/handler.py", line 178, in upload_file
    user: "User" = frappe.get_doc("User", frappe.session.user)
  File "/home/frappe/frappe-bench/apps/frappe/frappe/__init__.py", line 1329, in get_doc
    doc = frappe.model.document.get_doc(*args, **kwargs)
  File "/home/frappe/frappe-bench/apps/frappe/frappe/model/document.py", line 85, in get_doc
    return controller(*args, **kwargs)
  File "/home/frappe/frappe-bench/apps/frappe/frappe/model/document.py", line 126, in __init__
    self.load_from_db()
  File "/home/frappe/frappe-bench/apps/frappe/frappe/model/document.py", line 167, in load_from_db
    d = frappe.db.get_value(
  File "/home/frappe/frappe-bench/apps/frappe/frappe/database/database.py", line 519, in get_value
    result = self.get_values(
  File "/home/frappe/frappe-bench/apps/frappe/frappe/database/database.py", line 623, in get_values
    out = self._get_values_from_table(
  File "/home/frappe/frappe-bench/apps/frappe/frappe/database/database.py", line 896, in _get_values_from_table
    return query.run(as_dict=as_dict, debug=debug, update=update, run=run, pluck=pluck)
  File "/home/frappe/frappe-bench/apps/frappe/frappe/query_builder/utils.py", line 87, in execute_query
    result = frappe.db.sql(query, params, *args, **kwargs)  # nosemgrep
  File "/home/frappe/frappe-bench/apps/frappe/frappe/database/database.py", line 211, in sql
    self.connect()
  File "/home/frappe/frappe-bench/apps/frappe/frappe/database/database.py", line 117, in connect
    self._conn: "MariadbConnection" | "PostgresConnection" = self.get_connection()
  File "/home/frappe/frappe-bench/apps/frappe/frappe/database/mariadb/database.py", line 107, in get_connection
    conn = self._get_connection()
  File "/home/frappe/frappe-bench/apps/frappe/frappe/database/mariadb/database.py", line 113, in _get_connection
    return self.create_connection()
  File "/home/frappe/frappe-bench/apps/frappe/frappe/database/mariadb/database.py", line 116, in create_connection
    return pymysql.connect(**self.get_connection_settings())
  File "/home/frappe/frappe-bench/env/lib/python3.10/site-packages/pymysql/connections.py", line 358, in __init__
    self.connect()
  File "/home/frappe/frappe-bench/env/lib/python3.10/site-packages/pymysql/connections.py", line 663, in connect
    self._get_server_information()
  File "/home/frappe/frappe-bench/env/lib/python3.10/site-packages/pymysql/connections.py", line 1099, in _get_server_information
    packet = self._read_packet()
  File "/home/frappe/frappe-bench/env/lib/python3.10/site-packages/pymysql/connections.py", line 739, in _read_packet
    packet_header = self._read_bytes(4)
  File "/home/frappe/frappe-bench/env/lib/python3.10/site-packages/pymysql/connections.py", line 785, in _read_bytes
    raise err.OperationalError(
pymysql.err.OperationalError: (2013, 'Lost connection to MySQL server during query ([Errno 104] Connection reset by peer)')

During handling of the above exception, another exception occurred:

Traceback (most recent call last):
  File "/home/frappe/frappe-bench/env/lib/python3.10/site-packages/pymysql/connections.py", line 644, in connect
    sock = socket.create_connection(
  File "/usr/lib/python3.10/socket.py", line 845, in create_connection
    raise err
  File "/usr/lib/python3.10/socket.py", line 833, in create_connection
    sock.connect(sa)
ConnectionRefusedError: [Errno 111] Connection refused

During handling of the above exception, another exception occurred:

Traceback (most recent call last):
  File "/home/frappe/frappe-bench/apps/frappe/frappe/utils/error.py", line 86, in log_error_snapshot
    log_error(title=str(exception), defer_insert=True)
  File "/home/frappe/frappe-bench/apps/frappe/frappe/utils/error.py", line 61, in log_error
    error_log = frappe.get_doc(
  File "/home/frappe/frappe-bench/apps/frappe/frappe/__init__.py", line 1329, in get_doc
    doc = frappe.model.document.get_doc(*args, **kwargs)
  File "/home/frappe/frappe-bench/apps/frappe/frappe/model/document.py", line 83, in get_doc
    controller = get_controller(doctype)
  File "/home/frappe/frappe-bench/apps/frappe/frappe/model/base_document.py", line 70, in get_controller
    site_controllers[doctype] = import_controller(doctype)
  File "/home/frappe/frappe-bench/apps/frappe/frappe/model/base_document.py", line 81, in import_controller
    doctype_info = frappe.db.get_value("DocType", doctype, fieldname="*")
  File "/home/frappe/frappe-bench/apps/frappe/frappe/database/database.py", line 519, in get_value
    result = self.get_values(
  File "/home/frappe/frappe-bench/apps/frappe/frappe/database/database.py", line 623, in get_values
    out = self._get_values_from_table(
  File "/home/frappe/frappe-bench/apps/frappe/frappe/database/database.py", line 896, in _get_values_from_table
    return query.run(as_dict=as_dict, debug=debug, update=update, run=run, pluck=pluck)
  File "/home/frappe/frappe-bench/apps/frappe/frappe/query_builder/utils.py", line 87, in execute_query
    result = frappe.db.sql(query, params, *args, **kwargs)  # nosemgrep
  File "/home/frappe/frappe-bench/apps/frappe/frappe/database/database.py", line 211, in sql
    self.connect()
  File "/home/frappe/frappe-bench/apps/frappe/frappe/database/database.py", line 117, in connect
    self._conn: "MariadbConnection" | "PostgresConnection" = self.get_connection()
  File "/home/frappe/frappe-bench/apps/frappe/frappe/database/mariadb/database.py", line 107, in get_connection
    conn = self._get_connection()
  File "/home/frappe/frappe-bench/apps/frappe/frappe/database/mariadb/database.py", line 113, in _get_connection
    return self.create_connection()
  File "/home/frappe/frappe-bench/apps/frappe/frappe/database/mariadb/database.py", line 116, in create_connection
    return pymysql.connect(**self.get_connection_settings())
  File "/home/frappe/frappe-bench/env/lib/python3.10/site-packages/pymysql/connections.py", line 358, in __init__
    self.connect()
  File "/home/frappe/frappe-bench/env/lib/python3.10/site-packages/pymysql/connections.py", line 711, in connect
    raise exc
pymysql.err.OperationalError: (2003, "Can't connect to MySQL server on '127.0.0.1' ([Errno 111] Connection refused)")
