2024-11-22 10:40:24,777 ERROR frappe Failed to capture exception
Site: erp.grupoatu.com
Form Dict: {'filters': "{'lead_id':'CRM-LEAD-2024-77041'}", 'limit_page_length': 20}
Traceback (most recent call last):
  File "/home/frappe/frappe-bench/env/lib/python3.10/site-packages/werkzeug/wrappers/request.py", line 611, in get_json
    rv = self.json_module.loads(data)
  File "/usr/lib/python3.10/json/__init__.py", line 346, in loads
    return _default_decoder.decode(s)
  File "/usr/lib/python3.10/json/decoder.py", line 337, in decode
    obj, end = self.raw_decode(s, idx=_w(s, 0).end())
  File "/usr/lib/python3.10/json/decoder.py", line 355, in raw_decode
    raise JSONDecodeError("Expecting value", s, err.value) from None
json.decoder.JSONDecodeError: Expecting value: line 1 column 1 (char 0)

During handling of the above exception, another exception occurred:

Traceback (most recent call last):
  File "/home/frappe/frappe-bench/apps/frappe/frappe/utils/sentry.py", line 121, in capture_exception
    scope.set_context("JSON Body", frappe.request.json)
  File "/home/frappe/frappe-bench/env/lib/python3.10/site-packages/werkzeug/wrappers/request.py", line 558, in json
    return self.get_json()
  File "/home/frappe/frappe-bench/env/lib/python3.10/site-packages/werkzeug/wrappers/request.py", line 620, in get_json
    rv = self.on_json_loading_failed(e)
  File "/home/frappe/frappe-bench/env/lib/python3.10/site-packages/werkzeug/wrappers/request.py", line 645, in on_json_loading_failed
    raise BadRequest(f"Failed to decode JSON object: {e}")
werkzeug.exceptions.BadRequest: 400 Bad Request: Failed to decode JSON object: Expecting value: line 1 column 1 (char 0)
2024-11-22 10:40:24,781 ERROR frappe New Exception collected in error log
Site: erp.grupoatu.com
Form Dict: {'filters': "{'lead_id':'CRM-LEAD-2024-77041'}", 'limit_page_length': 20}
2024-11-22 10:53:46,570 ERROR frappe Failed to capture exception
Site: erp.grupoatu.com
Form Dict: {'filters': "{'lead_id':'CRM-LEAD-2024-21950'}", 'limit_page_length': 20}
Traceback (most recent call last):
  File "/home/frappe/frappe-bench/env/lib/python3.10/site-packages/werkzeug/wrappers/request.py", line 611, in get_json
    rv = self.json_module.loads(data)
  File "/usr/lib/python3.10/json/__init__.py", line 346, in loads
    return _default_decoder.decode(s)
  File "/usr/lib/python3.10/json/decoder.py", line 337, in decode
    obj, end = self.raw_decode(s, idx=_w(s, 0).end())
  File "/usr/lib/python3.10/json/decoder.py", line 355, in raw_decode
    raise JSONDecodeError("Expecting value", s, err.value) from None
json.decoder.JSONDecodeError: Expecting value: line 1 column 1 (char 0)

During handling of the above exception, another exception occurred:

Traceback (most recent call last):
  File "/home/frappe/frappe-bench/apps/frappe/frappe/utils/sentry.py", line 121, in capture_exception
    scope.set_context("JSON Body", frappe.request.json)
  File "/home/frappe/frappe-bench/env/lib/python3.10/site-packages/werkzeug/wrappers/request.py", line 558, in json
    return self.get_json()
  File "/home/frappe/frappe-bench/env/lib/python3.10/site-packages/werkzeug/wrappers/request.py", line 620, in get_json
    rv = self.on_json_loading_failed(e)
  File "/home/frappe/frappe-bench/env/lib/python3.10/site-packages/werkzeug/wrappers/request.py", line 645, in on_json_loading_failed
    raise BadRequest(f"Failed to decode JSON object: {e}")
werkzeug.exceptions.BadRequest: 400 Bad Request: Failed to decode JSON object: Expecting value: line 1 column 1 (char 0)
2024-11-22 10:53:46,572 ERROR frappe New Exception collected in error log
Site: erp.grupoatu.com
Form Dict: {'filters': "{'lead_id':'CRM-LEAD-2024-21950'}", 'limit_page_length': 20}
2024-11-22 11:03:44,023 ERROR frappe Failed to capture exception
Site: erp.grupoatu.com
Form Dict: {'filters': "{'lead_id':'CRM-LEAD-2024-77082'}", 'limit_page_length': 20}
Traceback (most recent call last):
  File "/home/frappe/frappe-bench/env/lib/python3.10/site-packages/werkzeug/wrappers/request.py", line 611, in get_json
    rv = self.json_module.loads(data)
  File "/usr/lib/python3.10/json/__init__.py", line 346, in loads
    return _default_decoder.decode(s)
  File "/usr/lib/python3.10/json/decoder.py", line 337, in decode
    obj, end = self.raw_decode(s, idx=_w(s, 0).end())
  File "/usr/lib/python3.10/json/decoder.py", line 355, in raw_decode
    raise JSONDecodeError("Expecting value", s, err.value) from None
json.decoder.JSONDecodeError: Expecting value: line 1 column 1 (char 0)

During handling of the above exception, another exception occurred:

Traceback (most recent call last):
  File "/home/frappe/frappe-bench/apps/frappe/frappe/utils/sentry.py", line 121, in capture_exception
    scope.set_context("JSON Body", frappe.request.json)
  File "/home/frappe/frappe-bench/env/lib/python3.10/site-packages/werkzeug/wrappers/request.py", line 558, in json
    return self.get_json()
  File "/home/frappe/frappe-bench/env/lib/python3.10/site-packages/werkzeug/wrappers/request.py", line 620, in get_json
    rv = self.on_json_loading_failed(e)
  File "/home/frappe/frappe-bench/env/lib/python3.10/site-packages/werkzeug/wrappers/request.py", line 645, in on_json_loading_failed
    raise BadRequest(f"Failed to decode JSON object: {e}")
werkzeug.exceptions.BadRequest: 400 Bad Request: Failed to decode JSON object: Expecting value: line 1 column 1 (char 0)
2024-11-22 11:03:44,025 ERROR frappe New Exception collected in error log
Site: erp.grupoatu.com
Form Dict: {'filters': "{'lead_id':'CRM-LEAD-2024-77082'}", 'limit_page_length': 20}
2024-11-22 11:36:50,909 ERROR frappe Failed to capture exception
Site: erp.grupoatu.com
Form Dict: {'filters': "{'lead_id':'CRM-LEAD-2024-77105'}", 'limit_page_length': 20}
Traceback (most recent call last):
  File "/home/frappe/frappe-bench/env/lib/python3.10/site-packages/werkzeug/wrappers/request.py", line 611, in get_json
    rv = self.json_module.loads(data)
  File "/usr/lib/python3.10/json/__init__.py", line 346, in loads
    return _default_decoder.decode(s)
  File "/usr/lib/python3.10/json/decoder.py", line 337, in decode
    obj, end = self.raw_decode(s, idx=_w(s, 0).end())
  File "/usr/lib/python3.10/json/decoder.py", line 355, in raw_decode
    raise JSONDecodeError("Expecting value", s, err.value) from None
json.decoder.JSONDecodeError: Expecting value: line 1 column 1 (char 0)

During handling of the above exception, another exception occurred:

Traceback (most recent call last):
  File "/home/frappe/frappe-bench/apps/frappe/frappe/utils/sentry.py", line 121, in capture_exception
    scope.set_context("JSON Body", frappe.request.json)
  File "/home/frappe/frappe-bench/env/lib/python3.10/site-packages/werkzeug/wrappers/request.py", line 558, in json
    return self.get_json()
  File "/home/frappe/frappe-bench/env/lib/python3.10/site-packages/werkzeug/wrappers/request.py", line 620, in get_json
    rv = self.on_json_loading_failed(e)
  File "/home/frappe/frappe-bench/env/lib/python3.10/site-packages/werkzeug/wrappers/request.py", line 645, in on_json_loading_failed
    raise BadRequest(f"Failed to decode JSON object: {e}")
werkzeug.exceptions.BadRequest: 400 Bad Request: Failed to decode JSON object: Expecting value: line 1 column 1 (char 0)
2024-11-22 11:36:50,911 ERROR frappe New Exception collected in error log
Site: erp.grupoatu.com
Form Dict: {'filters': "{'lead_id':'CRM-LEAD-2024-77105'}", 'limit_page_length': 20}
2024-11-22 11:56:08,686 ERROR frappe Failed to capture exception
Site: erp.grupoatu.com
Form Dict: {'filters': "{'lead_id':'CRM-LEAD-2024-77114'}", 'limit_page_length': 20}
Traceback (most recent call last):
  File "/home/frappe/frappe-bench/env/lib/python3.10/site-packages/werkzeug/wrappers/request.py", line 611, in get_json
    rv = self.json_module.loads(data)
  File "/usr/lib/python3.10/json/__init__.py", line 346, in loads
    return _default_decoder.decode(s)
  File "/usr/lib/python3.10/json/decoder.py", line 337, in decode
    obj, end = self.raw_decode(s, idx=_w(s, 0).end())
  File "/usr/lib/python3.10/json/decoder.py", line 355, in raw_decode
    raise JSONDecodeError("Expecting value", s, err.value) from None
json.decoder.JSONDecodeError: Expecting value: line 1 column 1 (char 0)

During handling of the above exception, another exception occurred:

Traceback (most recent call last):
  File "/home/frappe/frappe-bench/apps/frappe/frappe/utils/sentry.py", line 121, in capture_exception
    scope.set_context("JSON Body", frappe.request.json)
  File "/home/frappe/frappe-bench/env/lib/python3.10/site-packages/werkzeug/wrappers/request.py", line 558, in json
    return self.get_json()
  File "/home/frappe/frappe-bench/env/lib/python3.10/site-packages/werkzeug/wrappers/request.py", line 620, in get_json
    rv = self.on_json_loading_failed(e)
  File "/home/frappe/frappe-bench/env/lib/python3.10/site-packages/werkzeug/wrappers/request.py", line 645, in on_json_loading_failed
    raise BadRequest(f"Failed to decode JSON object: {e}")
werkzeug.exceptions.BadRequest: 400 Bad Request: Failed to decode JSON object: Expecting value: line 1 column 1 (char 0)
2024-11-22 11:56:08,687 ERROR frappe New Exception collected in error log
Site: erp.grupoatu.com
Form Dict: {'filters': "{'lead_id':'CRM-LEAD-2024-77114'}", 'limit_page_length': 20}
2024-11-22 12:13:30,648 ERROR frappe Failed to capture exception
Site: erp.grupoatu.com
Form Dict: {'filters': "{'lead_id':'CRM-LEAD-2024-02592'}", 'limit_page_length': 20}
Traceback (most recent call last):
  File "/home/frappe/frappe-bench/env/lib/python3.10/site-packages/werkzeug/wrappers/request.py", line 611, in get_json
    rv = self.json_module.loads(data)
  File "/usr/lib/python3.10/json/__init__.py", line 346, in loads
    return _default_decoder.decode(s)
  File "/usr/lib/python3.10/json/decoder.py", line 337, in decode
    obj, end = self.raw_decode(s, idx=_w(s, 0).end())
  File "/usr/lib/python3.10/json/decoder.py", line 355, in raw_decode
    raise JSONDecodeError("Expecting value", s, err.value) from None
json.decoder.JSONDecodeError: Expecting value: line 1 column 1 (char 0)

During handling of the above exception, another exception occurred:

Traceback (most recent call last):
  File "/home/frappe/frappe-bench/apps/frappe/frappe/utils/sentry.py", line 121, in capture_exception
    scope.set_context("JSON Body", frappe.request.json)
  File "/home/frappe/frappe-bench/env/lib/python3.10/site-packages/werkzeug/wrappers/request.py", line 558, in json
    return self.get_json()
  File "/home/frappe/frappe-bench/env/lib/python3.10/site-packages/werkzeug/wrappers/request.py", line 620, in get_json
    rv = self.on_json_loading_failed(e)
  File "/home/frappe/frappe-bench/env/lib/python3.10/site-packages/werkzeug/wrappers/request.py", line 645, in on_json_loading_failed
    raise BadRequest(f"Failed to decode JSON object: {e}")
werkzeug.exceptions.BadRequest: 400 Bad Request: Failed to decode JSON object: Expecting value: line 1 column 1 (char 0)
2024-11-22 12:13:30,649 ERROR frappe New Exception collected in error log
Site: erp.grupoatu.com
Form Dict: {'filters': "{'lead_id':'CRM-LEAD-2024-02592'}", 'limit_page_length': 20}
2024-11-22 13:28:27,244 ERROR frappe Failed to capture exception
Site: erp.grupoatu.com
Form Dict: {'filters': "{'lead_id':'CRM-LEAD-2024-73516'}", 'limit_page_length': 20}
Traceback (most recent call last):
  File "/home/frappe/frappe-bench/env/lib/python3.10/site-packages/werkzeug/wrappers/request.py", line 611, in get_json
    rv = self.json_module.loads(data)
  File "/usr/lib/python3.10/json/__init__.py", line 346, in loads
    return _default_decoder.decode(s)
  File "/usr/lib/python3.10/json/decoder.py", line 337, in decode
    obj, end = self.raw_decode(s, idx=_w(s, 0).end())
  File "/usr/lib/python3.10/json/decoder.py", line 355, in raw_decode
    raise JSONDecodeError("Expecting value", s, err.value) from None
json.decoder.JSONDecodeError: Expecting value: line 1 column 1 (char 0)

During handling of the above exception, another exception occurred:

Traceback (most recent call last):
  File "/home/frappe/frappe-bench/apps/frappe/frappe/utils/sentry.py", line 121, in capture_exception
    scope.set_context("JSON Body", frappe.request.json)
  File "/home/frappe/frappe-bench/env/lib/python3.10/site-packages/werkzeug/wrappers/request.py", line 558, in json
    return self.get_json()
  File "/home/frappe/frappe-bench/env/lib/python3.10/site-packages/werkzeug/wrappers/request.py", line 620, in get_json
    rv = self.on_json_loading_failed(e)
  File "/home/frappe/frappe-bench/env/lib/python3.10/site-packages/werkzeug/wrappers/request.py", line 645, in on_json_loading_failed
    raise BadRequest(f"Failed to decode JSON object: {e}")
werkzeug.exceptions.BadRequest: 400 Bad Request: Failed to decode JSON object: Expecting value: line 1 column 1 (char 0)
2024-11-22 13:28:27,246 ERROR frappe New Exception collected in error log
Site: erp.grupoatu.com
Form Dict: {'filters': "{'lead_id':'CRM-LEAD-2024-73516'}", 'limit_page_length': 20}
2024-11-22 13:28:27,424 ERROR frappe Failed to capture exception
Site: erp.grupoatu.com
Form Dict: {'filters': "{'lead_id':'CRM-LEAD-2024-73516'}", 'limit_page_length': 20}
Traceback (most recent call last):
  File "/home/frappe/frappe-bench/env/lib/python3.10/site-packages/werkzeug/wrappers/request.py", line 611, in get_json
    rv = self.json_module.loads(data)
  File "/usr/lib/python3.10/json/__init__.py", line 346, in loads
    return _default_decoder.decode(s)
  File "/usr/lib/python3.10/json/decoder.py", line 337, in decode
    obj, end = self.raw_decode(s, idx=_w(s, 0).end())
  File "/usr/lib/python3.10/json/decoder.py", line 355, in raw_decode
    raise JSONDecodeError("Expecting value", s, err.value) from None
json.decoder.JSONDecodeError: Expecting value: line 1 column 1 (char 0)

During handling of the above exception, another exception occurred:

Traceback (most recent call last):
  File "/home/frappe/frappe-bench/apps/frappe/frappe/utils/sentry.py", line 121, in capture_exception
    scope.set_context("JSON Body", frappe.request.json)
  File "/home/frappe/frappe-bench/env/lib/python3.10/site-packages/werkzeug/wrappers/request.py", line 558, in json
    return self.get_json()
  File "/home/frappe/frappe-bench/env/lib/python3.10/site-packages/werkzeug/wrappers/request.py", line 620, in get_json
    rv = self.on_json_loading_failed(e)
  File "/home/frappe/frappe-bench/env/lib/python3.10/site-packages/werkzeug/wrappers/request.py", line 645, in on_json_loading_failed
    raise BadRequest(f"Failed to decode JSON object: {e}")
werkzeug.exceptions.BadRequest: 400 Bad Request: Failed to decode JSON object: Expecting value: line 1 column 1 (char 0)
2024-11-22 13:28:27,425 ERROR frappe New Exception collected in error log
Site: erp.grupoatu.com
Form Dict: {'filters': "{'lead_id':'CRM-LEAD-2024-73516'}", 'limit_page_length': 20}
2024-11-22 13:28:27,616 ERROR frappe Failed to capture exception
Site: erp.grupoatu.com
Form Dict: {'filters': "{'lead_id':'CRM-LEAD-2024-73516'}", 'limit_page_length': 20}
Traceback (most recent call last):
  File "/home/frappe/frappe-bench/env/lib/python3.10/site-packages/werkzeug/wrappers/request.py", line 611, in get_json
    rv = self.json_module.loads(data)
  File "/usr/lib/python3.10/json/__init__.py", line 346, in loads
    return _default_decoder.decode(s)
  File "/usr/lib/python3.10/json/decoder.py", line 337, in decode
    obj, end = self.raw_decode(s, idx=_w(s, 0).end())
  File "/usr/lib/python3.10/json/decoder.py", line 355, in raw_decode
    raise JSONDecodeError("Expecting value", s, err.value) from None
json.decoder.JSONDecodeError: Expecting value: line 1 column 1 (char 0)

During handling of the above exception, another exception occurred:

Traceback (most recent call last):
  File "/home/frappe/frappe-bench/apps/frappe/frappe/utils/sentry.py", line 121, in capture_exception
    scope.set_context("JSON Body", frappe.request.json)
  File "/home/frappe/frappe-bench/env/lib/python3.10/site-packages/werkzeug/wrappers/request.py", line 558, in json
    return self.get_json()
  File "/home/frappe/frappe-bench/env/lib/python3.10/site-packages/werkzeug/wrappers/request.py", line 620, in get_json
    rv = self.on_json_loading_failed(e)
  File "/home/frappe/frappe-bench/env/lib/python3.10/site-packages/werkzeug/wrappers/request.py", line 645, in on_json_loading_failed
    raise BadRequest(f"Failed to decode JSON object: {e}")
werkzeug.exceptions.BadRequest: 400 Bad Request: Failed to decode JSON object: Expecting value: line 1 column 1 (char 0)
2024-11-22 13:28:27,618 ERROR frappe New Exception collected in error log
Site: erp.grupoatu.com
Form Dict: {'filters': "{'lead_id':'CRM-LEAD-2024-73516'}", 'limit_page_length': 20}
2024-11-22 13:28:27,837 ERROR frappe Failed to capture exception
Site: erp.grupoatu.com
Form Dict: {'filters': "{'lead_id':'CRM-LEAD-2024-73516'}", 'limit_page_length': 20}
Traceback (most recent call last):
  File "/home/frappe/frappe-bench/env/lib/python3.10/site-packages/werkzeug/wrappers/request.py", line 611, in get_json
    rv = self.json_module.loads(data)
  File "/usr/lib/python3.10/json/__init__.py", line 346, in loads
    return _default_decoder.decode(s)
  File "/usr/lib/python3.10/json/decoder.py", line 337, in decode
    obj, end = self.raw_decode(s, idx=_w(s, 0).end())
  File "/usr/lib/python3.10/json/decoder.py", line 355, in raw_decode
    raise JSONDecodeError("Expecting value", s, err.value) from None
json.decoder.JSONDecodeError: Expecting value: line 1 column 1 (char 0)

During handling of the above exception, another exception occurred:

Traceback (most recent call last):
  File "/home/frappe/frappe-bench/apps/frappe/frappe/utils/sentry.py", line 121, in capture_exception
    scope.set_context("JSON Body", frappe.request.json)
  File "/home/frappe/frappe-bench/env/lib/python3.10/site-packages/werkzeug/wrappers/request.py", line 558, in json
    return self.get_json()
  File "/home/frappe/frappe-bench/env/lib/python3.10/site-packages/werkzeug/wrappers/request.py", line 620, in get_json
    rv = self.on_json_loading_failed(e)
  File "/home/frappe/frappe-bench/env/lib/python3.10/site-packages/werkzeug/wrappers/request.py", line 645, in on_json_loading_failed
    raise BadRequest(f"Failed to decode JSON object: {e}")
werkzeug.exceptions.BadRequest: 400 Bad Request: Failed to decode JSON object: Expecting value: line 1 column 1 (char 0)
2024-11-22 13:28:27,839 ERROR frappe New Exception collected in error log
Site: erp.grupoatu.com
Form Dict: {'filters': "{'lead_id':'CRM-LEAD-2024-73516'}", 'limit_page_length': 20}
2024-11-22 13:28:28,053 ERROR frappe Failed to capture exception
Site: erp.grupoatu.com
Form Dict: {'filters': "{'lead_id':'CRM-LEAD-2024-73516'}", 'limit_page_length': 20}
Traceback (most recent call last):
  File "/home/frappe/frappe-bench/env/lib/python3.10/site-packages/werkzeug/wrappers/request.py", line 611, in get_json
    rv = self.json_module.loads(data)
  File "/usr/lib/python3.10/json/__init__.py", line 346, in loads
    return _default_decoder.decode(s)
  File "/usr/lib/python3.10/json/decoder.py", line 337, in decode
    obj, end = self.raw_decode(s, idx=_w(s, 0).end())
  File "/usr/lib/python3.10/json/decoder.py", line 355, in raw_decode
    raise JSONDecodeError("Expecting value", s, err.value) from None
json.decoder.JSONDecodeError: Expecting value: line 1 column 1 (char 0)

During handling of the above exception, another exception occurred:

Traceback (most recent call last):
  File "/home/frappe/frappe-bench/apps/frappe/frappe/utils/sentry.py", line 121, in capture_exception
    scope.set_context("JSON Body", frappe.request.json)
  File "/home/frappe/frappe-bench/env/lib/python3.10/site-packages/werkzeug/wrappers/request.py", line 558, in json
    return self.get_json()
  File "/home/frappe/frappe-bench/env/lib/python3.10/site-packages/werkzeug/wrappers/request.py", line 620, in get_json
    rv = self.on_json_loading_failed(e)
  File "/home/frappe/frappe-bench/env/lib/python3.10/site-packages/werkzeug/wrappers/request.py", line 645, in on_json_loading_failed
    raise BadRequest(f"Failed to decode JSON object: {e}")
werkzeug.exceptions.BadRequest: 400 Bad Request: Failed to decode JSON object: Expecting value: line 1 column 1 (char 0)
2024-11-22 13:28:28,055 ERROR frappe New Exception collected in error log
Site: erp.grupoatu.com
Form Dict: {'filters': "{'lead_id':'CRM-LEAD-2024-73516'}", 'limit_page_length': 20}
2024-11-22 13:28:28,251 ERROR frappe Failed to capture exception
Site: erp.grupoatu.com
Form Dict: {'filters': "{'lead_id':'CRM-LEAD-2024-73516'}", 'limit_page_length': 20}
Traceback (most recent call last):
  File "/home/frappe/frappe-bench/env/lib/python3.10/site-packages/werkzeug/wrappers/request.py", line 611, in get_json
    rv = self.json_module.loads(data)
  File "/usr/lib/python3.10/json/__init__.py", line 346, in loads
    return _default_decoder.decode(s)
  File "/usr/lib/python3.10/json/decoder.py", line 337, in decode
    obj, end = self.raw_decode(s, idx=_w(s, 0).end())
  File "/usr/lib/python3.10/json/decoder.py", line 355, in raw_decode
    raise JSONDecodeError("Expecting value", s, err.value) from None
json.decoder.JSONDecodeError: Expecting value: line 1 column 1 (char 0)

During handling of the above exception, another exception occurred:

Traceback (most recent call last):
  File "/home/frappe/frappe-bench/apps/frappe/frappe/utils/sentry.py", line 121, in capture_exception
    scope.set_context("JSON Body", frappe.request.json)
  File "/home/frappe/frappe-bench/env/lib/python3.10/site-packages/werkzeug/wrappers/request.py", line 558, in json
    return self.get_json()
  File "/home/frappe/frappe-bench/env/lib/python3.10/site-packages/werkzeug/wrappers/request.py", line 620, in get_json
    rv = self.on_json_loading_failed(e)
  File "/home/frappe/frappe-bench/env/lib/python3.10/site-packages/werkzeug/wrappers/request.py", line 645, in on_json_loading_failed
    raise BadRequest(f"Failed to decode JSON object: {e}")
werkzeug.exceptions.BadRequest: 400 Bad Request: Failed to decode JSON object: Expecting value: line 1 column 1 (char 0)
2024-11-22 13:28:28,253 ERROR frappe New Exception collected in error log
Site: erp.grupoatu.com
Form Dict: {'filters': "{'lead_id':'CRM-LEAD-2024-73516'}", 'limit_page_length': 20}
2024-11-25 07:11:13,086 ERROR frappe Failed to capture exception
Site: erp.grupoatu.com
Form Dict: {'filters': "{'lead_id':'CRM-LEAD-2024-04048'}", 'limit_page_length': 20}
Traceback (most recent call last):
  File "/home/frappe/frappe-bench/env/lib/python3.10/site-packages/werkzeug/wrappers/request.py", line 611, in get_json
    rv = self.json_module.loads(data)
  File "/usr/lib/python3.10/json/__init__.py", line 346, in loads
    return _default_decoder.decode(s)
  File "/usr/lib/python3.10/json/decoder.py", line 337, in decode
    obj, end = self.raw_decode(s, idx=_w(s, 0).end())
  File "/usr/lib/python3.10/json/decoder.py", line 355, in raw_decode
    raise JSONDecodeError("Expecting value", s, err.value) from None
json.decoder.JSONDecodeError: Expecting value: line 1 column 1 (char 0)

During handling of the above exception, another exception occurred:

Traceback (most recent call last):
  File "/home/frappe/frappe-bench/apps/frappe/frappe/utils/sentry.py", line 121, in capture_exception
    scope.set_context("JSON Body", frappe.request.json)
  File "/home/frappe/frappe-bench/env/lib/python3.10/site-packages/werkzeug/wrappers/request.py", line 558, in json
    return self.get_json()
  File "/home/frappe/frappe-bench/env/lib/python3.10/site-packages/werkzeug/wrappers/request.py", line 620, in get_json
    rv = self.on_json_loading_failed(e)
  File "/home/frappe/frappe-bench/env/lib/python3.10/site-packages/werkzeug/wrappers/request.py", line 645, in on_json_loading_failed
    raise BadRequest(f"Failed to decode JSON object: {e}")
werkzeug.exceptions.BadRequest: 400 Bad Request: Failed to decode JSON object: Expecting value: line 1 column 1 (char 0)
2024-11-25 07:11:13,088 ERROR frappe New Exception collected in error log
Site: erp.grupoatu.com
Form Dict: {'filters': "{'lead_id':'CRM-LEAD-2024-04048'}", 'limit_page_length': 20}
2024-11-25 08:02:12,634 ERROR frappe Failed to capture exception
Site: erp.grupoatu.com
Form Dict: {'filters': "{'lead_id':'CRM-LEAD-2024-77050'}", 'limit_page_length': 20}
Traceback (most recent call last):
  File "/home/frappe/frappe-bench/env/lib/python3.10/site-packages/werkzeug/wrappers/request.py", line 611, in get_json
    rv = self.json_module.loads(data)
  File "/usr/lib/python3.10/json/__init__.py", line 346, in loads
    return _default_decoder.decode(s)
  File "/usr/lib/python3.10/json/decoder.py", line 337, in decode
    obj, end = self.raw_decode(s, idx=_w(s, 0).end())
  File "/usr/lib/python3.10/json/decoder.py", line 355, in raw_decode
    raise JSONDecodeError("Expecting value", s, err.value) from None
json.decoder.JSONDecodeError: Expecting value: line 1 column 1 (char 0)

During handling of the above exception, another exception occurred:

Traceback (most recent call last):
  File "/home/frappe/frappe-bench/apps/frappe/frappe/utils/sentry.py", line 121, in capture_exception
    scope.set_context("JSON Body", frappe.request.json)
  File "/home/frappe/frappe-bench/env/lib/python3.10/site-packages/werkzeug/wrappers/request.py", line 558, in json
    return self.get_json()
  File "/home/frappe/frappe-bench/env/lib/python3.10/site-packages/werkzeug/wrappers/request.py", line 620, in get_json
    rv = self.on_json_loading_failed(e)
  File "/home/frappe/frappe-bench/env/lib/python3.10/site-packages/werkzeug/wrappers/request.py", line 645, in on_json_loading_failed
    raise BadRequest(f"Failed to decode JSON object: {e}")
werkzeug.exceptions.BadRequest: 400 Bad Request: Failed to decode JSON object: Expecting value: line 1 column 1 (char 0)
2024-11-25 08:02:12,636 ERROR frappe New Exception collected in error log
Site: erp.grupoatu.com
Form Dict: {'filters': "{'lead_id':'CRM-LEAD-2024-77050'}", 'limit_page_length': 20}
2024-11-25 08:14:17,689 ERROR frappe Failed to capture exception
Site: erp.grupoatu.com
Form Dict: {'filters': "{'lead_id':'CRM-LEAD-2024-76710'}", 'limit_page_length': 20}
Traceback (most recent call last):
  File "/home/frappe/frappe-bench/env/lib/python3.10/site-packages/werkzeug/wrappers/request.py", line 611, in get_json
    rv = self.json_module.loads(data)
  File "/usr/lib/python3.10/json/__init__.py", line 346, in loads
    return _default_decoder.decode(s)
  File "/usr/lib/python3.10/json/decoder.py", line 337, in decode
    obj, end = self.raw_decode(s, idx=_w(s, 0).end())
  File "/usr/lib/python3.10/json/decoder.py", line 355, in raw_decode
    raise JSONDecodeError("Expecting value", s, err.value) from None
json.decoder.JSONDecodeError: Expecting value: line 1 column 1 (char 0)

During handling of the above exception, another exception occurred:

Traceback (most recent call last):
  File "/home/frappe/frappe-bench/apps/frappe/frappe/utils/sentry.py", line 121, in capture_exception
    scope.set_context("JSON Body", frappe.request.json)
  File "/home/frappe/frappe-bench/env/lib/python3.10/site-packages/werkzeug/wrappers/request.py", line 558, in json
    return self.get_json()
  File "/home/frappe/frappe-bench/env/lib/python3.10/site-packages/werkzeug/wrappers/request.py", line 620, in get_json
    rv = self.on_json_loading_failed(e)
  File "/home/frappe/frappe-bench/env/lib/python3.10/site-packages/werkzeug/wrappers/request.py", line 645, in on_json_loading_failed
    raise BadRequest(f"Failed to decode JSON object: {e}")
werkzeug.exceptions.BadRequest: 400 Bad Request: Failed to decode JSON object: Expecting value: line 1 column 1 (char 0)
2024-11-25 08:14:17,692 ERROR frappe New Exception collected in error log
Site: erp.grupoatu.com
Form Dict: {'filters': "{'lead_id':'CRM-LEAD-2024-76710'}", 'limit_page_length': 20}
2024-11-25 10:46:25,027 ERROR frappe New Exception collected in error log
Site: erp.grupoatu.com
Form Dict: {'doc': '{"name":"HR-ANX-2024-0000170-3","owner":"Administrator","creation":"2024-11-25 11:46:14.883165","modified":"2024-11-25 11:46:18.908590","modified_by":"Administrator","docstatus":0,"idx":0,"workflow_state":"Solicitado","company":"Academia Técnica Universitaria SL","employee":"02323232F","custom_tipo_de_contrato":"Indefinido ordinario","tipo_actualizacion":"Llamamiento","custom_estado_de_tramitacion":"Solicitado","designation":"Derecho","custom_provincia":"Burgos","start_date":"2024-11-25","status":"Esperando Respuesta","fecha_validacion":"2024-11-25","job_offer":"HR-OFF-2024-01513","custom_necesaria_confirmacion_de_baja":"No","custom_nombre_del_empleado":"Prueba Test dos","custom_dninie":"02323232F","custom_solicitante_de_empleo":"prueba2@prueba.com","custom_discapacidad":0,"custom_correo":"prueba2@prueba.com","custom_movil":"666666666","custom_seg_social":"2323232444","custom_nacimiento":"2024-07-22","custom_firmado":0,"custom_firmar":0,"custom_comun":0,"custom_iban":"edfrghtdgs31245","objeto":"res","amended_from":"HR-ANX-2024-0000170-2","applicant_name":"Prueba Test dos","dni":"02323232F","validator_email":"ana@sbm.es","validated_by":"ana@sbm.es","owner_email":"xappiens@xappiens.com","custom_solicited_by":"Administrator","custom_email_solicited":"xappiens@xappiens.com","doctype":"Modificaciones RRHH","offer_terms":[],"registro_horas":[],"__last_sync_on":"2024-11-25T10:46:22.171Z"}', 'action': 'Tramitar', 'cmd': 'frappe.model.workflow.apply_workflow'}
2024-11-25 12:12:15,406 ERROR frappe New Exception collected in error log
Site: erp.grupoatu.com
Form Dict: {'fid': '234288fa30', 'dt': 'Student Applicant', 'dn': 'EDU-APP-2024-06909', 'cmd': 'frappe.desk.form.utils.remove_attach'}
2024-11-25 12:44:46,319 ERROR frappe Failed to capture exception
Site: erp.grupoatu.com
Form Dict: {'filters': "{'lead_id':'CRM-LEAD-2024-77087'}", 'limit_page_length': 20}
Traceback (most recent call last):
  File "/home/frappe/frappe-bench/env/lib/python3.10/site-packages/werkzeug/wrappers/request.py", line 611, in get_json
    rv = self.json_module.loads(data)
  File "/usr/lib/python3.10/json/__init__.py", line 346, in loads
    return _default_decoder.decode(s)
  File "/usr/lib/python3.10/json/decoder.py", line 337, in decode
    obj, end = self.raw_decode(s, idx=_w(s, 0).end())
  File "/usr/lib/python3.10/json/decoder.py", line 355, in raw_decode
    raise JSONDecodeError("Expecting value", s, err.value) from None
json.decoder.JSONDecodeError: Expecting value: line 1 column 1 (char 0)

During handling of the above exception, another exception occurred:

Traceback (most recent call last):
  File "/home/frappe/frappe-bench/apps/frappe/frappe/utils/sentry.py", line 121, in capture_exception
    scope.set_context("JSON Body", frappe.request.json)
  File "/home/frappe/frappe-bench/env/lib/python3.10/site-packages/werkzeug/wrappers/request.py", line 558, in json
    return self.get_json()
  File "/home/frappe/frappe-bench/env/lib/python3.10/site-packages/werkzeug/wrappers/request.py", line 620, in get_json
    rv = self.on_json_loading_failed(e)
  File "/home/frappe/frappe-bench/env/lib/python3.10/site-packages/werkzeug/wrappers/request.py", line 645, in on_json_loading_failed
    raise BadRequest(f"Failed to decode JSON object: {e}")
werkzeug.exceptions.BadRequest: 400 Bad Request: Failed to decode JSON object: Expecting value: line 1 column 1 (char 0)
2024-11-25 12:44:46,321 ERROR frappe New Exception collected in error log
Site: erp.grupoatu.com
Form Dict: {'filters': "{'lead_id':'CRM-LEAD-2024-77087'}", 'limit_page_length': 20}
2024-11-26 07:07:09,232 ERROR frappe New Exception collected in error log
Site: erp.grupoatu.com
Form Dict: {'doctype': 'Sales Invoice', 'name': 'TBC/V/2400223', 'format': 'BATU - Factura Venta Fecha', 'letterhead': 'TAKIN', 'cmd': 'integracion.integracion.custom_pdf_make.custom_download_and_attach_pdf'}
2024-11-26 07:13:22,166 ERROR frappe New Exception collected in error log
Site: erp.grupoatu.com
Form Dict: {'doctype': 'Sales Invoice', 'name': 'TBC/V/2400224', 'format': 'BATU - Factura Venta Fecha', 'letterhead': 'TAKIN', 'cmd': 'integracion.integracion.custom_pdf_make.custom_download_and_attach_pdf'}
2024-11-26 07:19:08,495 ERROR frappe New Exception collected in error log
Site: erp.grupoatu.com
Form Dict: {'doctype': 'Sales Invoice', 'name': 'TBC/V/2400225', 'format': 'BATU - Factura Venta Fecha', 'letterhead': 'TAKIN', 'cmd': 'integracion.integracion.custom_pdf_make.custom_download_and_attach_pdf'}
2024-11-26 07:33:07,212 ERROR frappe New Exception collected in error log
Site: erp.grupoatu.com
Form Dict: {'doctype': 'Sales Invoice', 'name': 'TBC/V/2400224-1', 'format': 'BATU - Factura Venta Fecha', 'letterhead': 'TAKIN', 'cmd': 'integracion.integracion.custom_pdf_make.custom_download_and_attach_pdf'}
2024-11-26 08:22:26,088 ERROR frappe Failed to capture exception
Site: erp.grupoatu.com
Form Dict: {'filters': "{'lead_id':'CRM-LEAD-2024-73486'}", 'limit_page_length': 20}
Traceback (most recent call last):
  File "/home/frappe/frappe-bench/env/lib/python3.10/site-packages/werkzeug/wrappers/request.py", line 611, in get_json
    rv = self.json_module.loads(data)
  File "/usr/lib/python3.10/json/__init__.py", line 346, in loads
    return _default_decoder.decode(s)
  File "/usr/lib/python3.10/json/decoder.py", line 337, in decode
    obj, end = self.raw_decode(s, idx=_w(s, 0).end())
  File "/usr/lib/python3.10/json/decoder.py", line 355, in raw_decode
    raise JSONDecodeError("Expecting value", s, err.value) from None
json.decoder.JSONDecodeError: Expecting value: line 1 column 1 (char 0)

During handling of the above exception, another exception occurred:

Traceback (most recent call last):
  File "/home/frappe/frappe-bench/apps/frappe/frappe/utils/sentry.py", line 121, in capture_exception
    scope.set_context("JSON Body", frappe.request.json)
  File "/home/frappe/frappe-bench/env/lib/python3.10/site-packages/werkzeug/wrappers/request.py", line 558, in json
    return self.get_json()
  File "/home/frappe/frappe-bench/env/lib/python3.10/site-packages/werkzeug/wrappers/request.py", line 620, in get_json
    rv = self.on_json_loading_failed(e)
  File "/home/frappe/frappe-bench/env/lib/python3.10/site-packages/werkzeug/wrappers/request.py", line 645, in on_json_loading_failed
    raise BadRequest(f"Failed to decode JSON object: {e}")
werkzeug.exceptions.BadRequest: 400 Bad Request: Failed to decode JSON object: Expecting value: line 1 column 1 (char 0)
2024-11-26 08:22:26,089 ERROR frappe New Exception collected in error log
Site: erp.grupoatu.com
Form Dict: {'filters': "{'lead_id':'CRM-LEAD-2024-73486'}", 'limit_page_length': 20}
2024-11-26 08:22:26,259 ERROR frappe Failed to capture exception
Site: erp.grupoatu.com
Form Dict: {'filters': "{'lead_id':'CRM-LEAD-2024-73486'}", 'limit_page_length': 20}
Traceback (most recent call last):
  File "/home/frappe/frappe-bench/env/lib/python3.10/site-packages/werkzeug/wrappers/request.py", line 611, in get_json
    rv = self.json_module.loads(data)
  File "/usr/lib/python3.10/json/__init__.py", line 346, in loads
    return _default_decoder.decode(s)
  File "/usr/lib/python3.10/json/decoder.py", line 337, in decode
    obj, end = self.raw_decode(s, idx=_w(s, 0).end())
  File "/usr/lib/python3.10/json/decoder.py", line 355, in raw_decode
    raise JSONDecodeError("Expecting value", s, err.value) from None
json.decoder.JSONDecodeError: Expecting value: line 1 column 1 (char 0)

During handling of the above exception, another exception occurred:

Traceback (most recent call last):
  File "/home/frappe/frappe-bench/apps/frappe/frappe/utils/sentry.py", line 121, in capture_exception
    scope.set_context("JSON Body", frappe.request.json)
  File "/home/frappe/frappe-bench/env/lib/python3.10/site-packages/werkzeug/wrappers/request.py", line 558, in json
    return self.get_json()
  File "/home/frappe/frappe-bench/env/lib/python3.10/site-packages/werkzeug/wrappers/request.py", line 620, in get_json
    rv = self.on_json_loading_failed(e)
  File "/home/frappe/frappe-bench/env/lib/python3.10/site-packages/werkzeug/wrappers/request.py", line 645, in on_json_loading_failed
    raise BadRequest(f"Failed to decode JSON object: {e}")
werkzeug.exceptions.BadRequest: 400 Bad Request: Failed to decode JSON object: Expecting value: line 1 column 1 (char 0)
2024-11-26 08:22:26,260 ERROR frappe New Exception collected in error log
Site: erp.grupoatu.com
Form Dict: {'filters': "{'lead_id':'CRM-LEAD-2024-73486'}", 'limit_page_length': 20}
2024-11-26 08:22:26,560 ERROR frappe Failed to capture exception
Site: erp.grupoatu.com
Form Dict: {'filters': "{'lead_id':'CRM-LEAD-2024-73486'}", 'limit_page_length': 20}
Traceback (most recent call last):
  File "/home/frappe/frappe-bench/env/lib/python3.10/site-packages/werkzeug/wrappers/request.py", line 611, in get_json
    rv = self.json_module.loads(data)
  File "/usr/lib/python3.10/json/__init__.py", line 346, in loads
    return _default_decoder.decode(s)
  File "/usr/lib/python3.10/json/decoder.py", line 337, in decode
    obj, end = self.raw_decode(s, idx=_w(s, 0).end())
  File "/usr/lib/python3.10/json/decoder.py", line 355, in raw_decode
    raise JSONDecodeError("Expecting value", s, err.value) from None
json.decoder.JSONDecodeError: Expecting value: line 1 column 1 (char 0)

During handling of the above exception, another exception occurred:

Traceback (most recent call last):
  File "/home/frappe/frappe-bench/apps/frappe/frappe/utils/sentry.py", line 121, in capture_exception
    scope.set_context("JSON Body", frappe.request.json)
  File "/home/frappe/frappe-bench/env/lib/python3.10/site-packages/werkzeug/wrappers/request.py", line 558, in json
    return self.get_json()
  File "/home/frappe/frappe-bench/env/lib/python3.10/site-packages/werkzeug/wrappers/request.py", line 620, in get_json
    rv = self.on_json_loading_failed(e)
  File "/home/frappe/frappe-bench/env/lib/python3.10/site-packages/werkzeug/wrappers/request.py", line 645, in on_json_loading_failed
    raise BadRequest(f"Failed to decode JSON object: {e}")
werkzeug.exceptions.BadRequest: 400 Bad Request: Failed to decode JSON object: Expecting value: line 1 column 1 (char 0)
2024-11-26 08:22:26,561 ERROR frappe New Exception collected in error log
Site: erp.grupoatu.com
Form Dict: {'filters': "{'lead_id':'CRM-LEAD-2024-73486'}", 'limit_page_length': 20}
2024-11-26 08:22:26,811 ERROR frappe Failed to capture exception
Site: erp.grupoatu.com
Form Dict: {'filters': "{'lead_id':'CRM-LEAD-2024-73486'}", 'limit_page_length': 20}
Traceback (most recent call last):
  File "/home/frappe/frappe-bench/env/lib/python3.10/site-packages/werkzeug/wrappers/request.py", line 611, in get_json
    rv = self.json_module.loads(data)
  File "/usr/lib/python3.10/json/__init__.py", line 346, in loads
    return _default_decoder.decode(s)
  File "/usr/lib/python3.10/json/decoder.py", line 337, in decode
    obj, end = self.raw_decode(s, idx=_w(s, 0).end())
  File "/usr/lib/python3.10/json/decoder.py", line 355, in raw_decode
    raise JSONDecodeError("Expecting value", s, err.value) from None
json.decoder.JSONDecodeError: Expecting value: line 1 column 1 (char 0)

During handling of the above exception, another exception occurred:

Traceback (most recent call last):
  File "/home/frappe/frappe-bench/apps/frappe/frappe/utils/sentry.py", line 121, in capture_exception
    scope.set_context("JSON Body", frappe.request.json)
  File "/home/frappe/frappe-bench/env/lib/python3.10/site-packages/werkzeug/wrappers/request.py", line 558, in json
    return self.get_json()
  File "/home/frappe/frappe-bench/env/lib/python3.10/site-packages/werkzeug/wrappers/request.py", line 620, in get_json
    rv = self.on_json_loading_failed(e)
  File "/home/frappe/frappe-bench/env/lib/python3.10/site-packages/werkzeug/wrappers/request.py", line 645, in on_json_loading_failed
    raise BadRequest(f"Failed to decode JSON object: {e}")
werkzeug.exceptions.BadRequest: 400 Bad Request: Failed to decode JSON object: Expecting value: line 1 column 1 (char 0)
2024-11-26 08:22:26,812 ERROR frappe New Exception collected in error log
Site: erp.grupoatu.com
Form Dict: {'filters': "{'lead_id':'CRM-LEAD-2024-73486'}", 'limit_page_length': 20}
2024-11-26 08:22:27,068 ERROR frappe Failed to capture exception
Site: erp.grupoatu.com
Form Dict: {'filters': "{'lead_id':'CRM-LEAD-2024-73486'}", 'limit_page_length': 20}
Traceback (most recent call last):
  File "/home/frappe/frappe-bench/env/lib/python3.10/site-packages/werkzeug/wrappers/request.py", line 611, in get_json
    rv = self.json_module.loads(data)
  File "/usr/lib/python3.10/json/__init__.py", line 346, in loads
    return _default_decoder.decode(s)
  File "/usr/lib/python3.10/json/decoder.py", line 337, in decode
    obj, end = self.raw_decode(s, idx=_w(s, 0).end())
  File "/usr/lib/python3.10/json/decoder.py", line 355, in raw_decode
    raise JSONDecodeError("Expecting value", s, err.value) from None
json.decoder.JSONDecodeError: Expecting value: line 1 column 1 (char 0)

During handling of the above exception, another exception occurred:

Traceback (most recent call last):
  File "/home/frappe/frappe-bench/apps/frappe/frappe/utils/sentry.py", line 121, in capture_exception
    scope.set_context("JSON Body", frappe.request.json)
  File "/home/frappe/frappe-bench/env/lib/python3.10/site-packages/werkzeug/wrappers/request.py", line 558, in json
    return self.get_json()
  File "/home/frappe/frappe-bench/env/lib/python3.10/site-packages/werkzeug/wrappers/request.py", line 620, in get_json
    rv = self.on_json_loading_failed(e)
  File "/home/frappe/frappe-bench/env/lib/python3.10/site-packages/werkzeug/wrappers/request.py", line 645, in on_json_loading_failed
    raise BadRequest(f"Failed to decode JSON object: {e}")
werkzeug.exceptions.BadRequest: 400 Bad Request: Failed to decode JSON object: Expecting value: line 1 column 1 (char 0)
2024-11-26 08:22:27,070 ERROR frappe New Exception collected in error log
Site: erp.grupoatu.com
Form Dict: {'filters': "{'lead_id':'CRM-LEAD-2024-73486'}", 'limit_page_length': 20}
2024-11-26 08:22:27,323 ERROR frappe Failed to capture exception
Site: erp.grupoatu.com
Form Dict: {'filters': "{'lead_id':'CRM-LEAD-2024-73486'}", 'limit_page_length': 20}
Traceback (most recent call last):
  File "/home/frappe/frappe-bench/env/lib/python3.10/site-packages/werkzeug/wrappers/request.py", line 611, in get_json
    rv = self.json_module.loads(data)
  File "/usr/lib/python3.10/json/__init__.py", line 346, in loads
    return _default_decoder.decode(s)
  File "/usr/lib/python3.10/json/decoder.py", line 337, in decode
    obj, end = self.raw_decode(s, idx=_w(s, 0).end())
  File "/usr/lib/python3.10/json/decoder.py", line 355, in raw_decode
    raise JSONDecodeError("Expecting value", s, err.value) from None
json.decoder.JSONDecodeError: Expecting value: line 1 column 1 (char 0)

During handling of the above exception, another exception occurred:

Traceback (most recent call last):
  File "/home/frappe/frappe-bench/apps/frappe/frappe/utils/sentry.py", line 121, in capture_exception
    scope.set_context("JSON Body", frappe.request.json)
  File "/home/frappe/frappe-bench/env/lib/python3.10/site-packages/werkzeug/wrappers/request.py", line 558, in json
    return self.get_json()
  File "/home/frappe/frappe-bench/env/lib/python3.10/site-packages/werkzeug/wrappers/request.py", line 620, in get_json
    rv = self.on_json_loading_failed(e)
  File "/home/frappe/frappe-bench/env/lib/python3.10/site-packages/werkzeug/wrappers/request.py", line 645, in on_json_loading_failed
    raise BadRequest(f"Failed to decode JSON object: {e}")
werkzeug.exceptions.BadRequest: 400 Bad Request: Failed to decode JSON object: Expecting value: line 1 column 1 (char 0)
2024-11-26 08:22:27,326 ERROR frappe New Exception collected in error log
Site: erp.grupoatu.com
Form Dict: {'filters': "{'lead_id':'CRM-LEAD-2024-73486'}", 'limit_page_length': 20}
2024-11-26 10:00:07,326 ERROR frappe Failed to capture exception
Site: erp.grupoatu.com
Form Dict: {'filters': "{'lead_id':'CRM-LEAD-2024-76112'}", 'limit_page_length': 20}
Traceback (most recent call last):
  File "/home/frappe/frappe-bench/env/lib/python3.10/site-packages/werkzeug/wrappers/request.py", line 611, in get_json
    rv = self.json_module.loads(data)
  File "/usr/lib/python3.10/json/__init__.py", line 346, in loads
    return _default_decoder.decode(s)
  File "/usr/lib/python3.10/json/decoder.py", line 337, in decode
    obj, end = self.raw_decode(s, idx=_w(s, 0).end())
  File "/usr/lib/python3.10/json/decoder.py", line 355, in raw_decode
    raise JSONDecodeError("Expecting value", s, err.value) from None
json.decoder.JSONDecodeError: Expecting value: line 1 column 1 (char 0)

During handling of the above exception, another exception occurred:

Traceback (most recent call last):
  File "/home/frappe/frappe-bench/apps/frappe/frappe/utils/sentry.py", line 121, in capture_exception
    scope.set_context("JSON Body", frappe.request.json)
  File "/home/frappe/frappe-bench/env/lib/python3.10/site-packages/werkzeug/wrappers/request.py", line 558, in json
    return self.get_json()
  File "/home/frappe/frappe-bench/env/lib/python3.10/site-packages/werkzeug/wrappers/request.py", line 620, in get_json
    rv = self.on_json_loading_failed(e)
  File "/home/frappe/frappe-bench/env/lib/python3.10/site-packages/werkzeug/wrappers/request.py", line 645, in on_json_loading_failed
    raise BadRequest(f"Failed to decode JSON object: {e}")
werkzeug.exceptions.BadRequest: 400 Bad Request: Failed to decode JSON object: Expecting value: line 1 column 1 (char 0)
2024-11-26 10:00:07,328 ERROR frappe New Exception collected in error log
Site: erp.grupoatu.com
Form Dict: {'filters': "{'lead_id':'CRM-LEAD-2024-76112'}", 'limit_page_length': 20}
2024-11-26 11:20:34,064 ERROR frappe New Exception collected in error log
Site: erp.grupoatu.com
Form Dict: {'format': 'PDF', 'filters': '{"company":"Burgos atu SL","filter_based_on":"Date Range","period_start_date":"2024-01-01","period_end_date":"2024-06-30","from_fiscal_year":"2024","to_fiscal_year":"2024","periodicity":"Yearly","cost_center":[],"project":[],"selected_view":"Report","accumulated_values":1,"include_default_book_entries":1}', 'cmd': 'integracion.utils.export_balance_sheet.export_balance_sheet'}
2024-11-26 11:21:35,376 ERROR frappe New Exception collected in error log
Site: erp.grupoatu.com
Form Dict: {'format': 'PDF', 'filters': '{"company":"Burgos atu SL","filter_based_on":"Date Range","period_start_date":"2024-01-01","period_end_date":"2024-06-30","from_fiscal_year":"2024","to_fiscal_year":"2024","periodicity":"Yearly","cost_center":[],"project":[],"selected_view":"Report","accumulated_values":1,"include_default_book_entries":1}', 'cmd': 'integracion.utils.export_balance_sheet.export_balance_sheet'}
2024-11-26 11:28:51,110 ERROR frappe Failed to capture exception
Site: erp.grupoatu.com
Form Dict: {'filters': "{'lead_id':'CRM-LEAD-2024-77608'}", 'limit_page_length': 20}
Traceback (most recent call last):
  File "/home/frappe/frappe-bench/env/lib/python3.10/site-packages/werkzeug/wrappers/request.py", line 611, in get_json
    rv = self.json_module.loads(data)
  File "/usr/lib/python3.10/json/__init__.py", line 346, in loads
    return _default_decoder.decode(s)
  File "/usr/lib/python3.10/json/decoder.py", line 337, in decode
    obj, end = self.raw_decode(s, idx=_w(s, 0).end())
  File "/usr/lib/python3.10/json/decoder.py", line 355, in raw_decode
    raise JSONDecodeError("Expecting value", s, err.value) from None
json.decoder.JSONDecodeError: Expecting value: line 1 column 1 (char 0)

During handling of the above exception, another exception occurred:

Traceback (most recent call last):
  File "/home/frappe/frappe-bench/apps/frappe/frappe/utils/sentry.py", line 121, in capture_exception
    scope.set_context("JSON Body", frappe.request.json)
  File "/home/frappe/frappe-bench/env/lib/python3.10/site-packages/werkzeug/wrappers/request.py", line 558, in json
    return self.get_json()
  File "/home/frappe/frappe-bench/env/lib/python3.10/site-packages/werkzeug/wrappers/request.py", line 620, in get_json
    rv = self.on_json_loading_failed(e)
  File "/home/frappe/frappe-bench/env/lib/python3.10/site-packages/werkzeug/wrappers/request.py", line 645, in on_json_loading_failed
    raise BadRequest(f"Failed to decode JSON object: {e}")
werkzeug.exceptions.BadRequest: 400 Bad Request: Failed to decode JSON object: Expecting value: line 1 column 1 (char 0)
2024-11-26 11:28:51,112 ERROR frappe New Exception collected in error log
Site: erp.grupoatu.com
Form Dict: {'filters': "{'lead_id':'CRM-LEAD-2024-77608'}", 'limit_page_length': 20}
2024-11-26 11:32:00,751 ERROR frappe Failed to capture exception
Site: erp.grupoatu.com
Form Dict: {'filters': "{'lead_id':'CRM-LEAD-2024-77609'}", 'limit_page_length': 20}
Traceback (most recent call last):
  File "/home/frappe/frappe-bench/env/lib/python3.10/site-packages/werkzeug/wrappers/request.py", line 611, in get_json
    rv = self.json_module.loads(data)
  File "/usr/lib/python3.10/json/__init__.py", line 346, in loads
    return _default_decoder.decode(s)
  File "/usr/lib/python3.10/json/decoder.py", line 337, in decode
    obj, end = self.raw_decode(s, idx=_w(s, 0).end())
  File "/usr/lib/python3.10/json/decoder.py", line 355, in raw_decode
    raise JSONDecodeError("Expecting value", s, err.value) from None
json.decoder.JSONDecodeError: Expecting value: line 1 column 1 (char 0)

During handling of the above exception, another exception occurred:

Traceback (most recent call last):
  File "/home/frappe/frappe-bench/apps/frappe/frappe/utils/sentry.py", line 121, in capture_exception
    scope.set_context("JSON Body", frappe.request.json)
  File "/home/frappe/frappe-bench/env/lib/python3.10/site-packages/werkzeug/wrappers/request.py", line 558, in json
    return self.get_json()
  File "/home/frappe/frappe-bench/env/lib/python3.10/site-packages/werkzeug/wrappers/request.py", line 620, in get_json
    rv = self.on_json_loading_failed(e)
  File "/home/frappe/frappe-bench/env/lib/python3.10/site-packages/werkzeug/wrappers/request.py", line 645, in on_json_loading_failed
    raise BadRequest(f"Failed to decode JSON object: {e}")
werkzeug.exceptions.BadRequest: 400 Bad Request: Failed to decode JSON object: Expecting value: line 1 column 1 (char 0)
2024-11-26 11:32:00,753 ERROR frappe New Exception collected in error log
Site: erp.grupoatu.com
Form Dict: {'filters': "{'lead_id':'CRM-LEAD-2024-77609'}", 'limit_page_length': 20}
2024-11-26 11:34:37,214 ERROR frappe Failed to capture exception
Site: erp.grupoatu.com
Form Dict: {'filters': "{'lead_id':'CRM-LEAD-2024-77612'}", 'limit_page_length': 20}
Traceback (most recent call last):
  File "/home/frappe/frappe-bench/env/lib/python3.10/site-packages/werkzeug/wrappers/request.py", line 611, in get_json
    rv = self.json_module.loads(data)
  File "/usr/lib/python3.10/json/__init__.py", line 346, in loads
    return _default_decoder.decode(s)
  File "/usr/lib/python3.10/json/decoder.py", line 337, in decode
    obj, end = self.raw_decode(s, idx=_w(s, 0).end())
  File "/usr/lib/python3.10/json/decoder.py", line 355, in raw_decode
    raise JSONDecodeError("Expecting value", s, err.value) from None
json.decoder.JSONDecodeError: Expecting value: line 1 column 1 (char 0)

During handling of the above exception, another exception occurred:

Traceback (most recent call last):
  File "/home/frappe/frappe-bench/apps/frappe/frappe/utils/sentry.py", line 121, in capture_exception
    scope.set_context("JSON Body", frappe.request.json)
  File "/home/frappe/frappe-bench/env/lib/python3.10/site-packages/werkzeug/wrappers/request.py", line 558, in json
    return self.get_json()
  File "/home/frappe/frappe-bench/env/lib/python3.10/site-packages/werkzeug/wrappers/request.py", line 620, in get_json
    rv = self.on_json_loading_failed(e)
  File "/home/frappe/frappe-bench/env/lib/python3.10/site-packages/werkzeug/wrappers/request.py", line 645, in on_json_loading_failed
    raise BadRequest(f"Failed to decode JSON object: {e}")
werkzeug.exceptions.BadRequest: 400 Bad Request: Failed to decode JSON object: Expecting value: line 1 column 1 (char 0)
2024-11-26 11:34:37,216 ERROR frappe New Exception collected in error log
Site: erp.grupoatu.com
Form Dict: {'filters': "{'lead_id':'CRM-LEAD-2024-77612'}", 'limit_page_length': 20}
2024-11-26 11:41:31,155 ERROR frappe Failed to capture exception
Site: erp.grupoatu.com
Form Dict: {'filters': "{'lead_id':'CRM-LEAD-2024-77614'}", 'limit_page_length': 20}
Traceback (most recent call last):
  File "/home/frappe/frappe-bench/env/lib/python3.10/site-packages/werkzeug/wrappers/request.py", line 611, in get_json
    rv = self.json_module.loads(data)
  File "/usr/lib/python3.10/json/__init__.py", line 346, in loads
    return _default_decoder.decode(s)
  File "/usr/lib/python3.10/json/decoder.py", line 337, in decode
    obj, end = self.raw_decode(s, idx=_w(s, 0).end())
  File "/usr/lib/python3.10/json/decoder.py", line 355, in raw_decode
    raise JSONDecodeError("Expecting value", s, err.value) from None
json.decoder.JSONDecodeError: Expecting value: line 1 column 1 (char 0)

During handling of the above exception, another exception occurred:

Traceback (most recent call last):
  File "/home/frappe/frappe-bench/apps/frappe/frappe/utils/sentry.py", line 121, in capture_exception
    scope.set_context("JSON Body", frappe.request.json)
  File "/home/frappe/frappe-bench/env/lib/python3.10/site-packages/werkzeug/wrappers/request.py", line 558, in json
    return self.get_json()
  File "/home/frappe/frappe-bench/env/lib/python3.10/site-packages/werkzeug/wrappers/request.py", line 620, in get_json
    rv = self.on_json_loading_failed(e)
  File "/home/frappe/frappe-bench/env/lib/python3.10/site-packages/werkzeug/wrappers/request.py", line 645, in on_json_loading_failed
    raise BadRequest(f"Failed to decode JSON object: {e}")
werkzeug.exceptions.BadRequest: 400 Bad Request: Failed to decode JSON object: Expecting value: line 1 column 1 (char 0)
2024-11-26 11:41:31,156 ERROR frappe New Exception collected in error log
Site: erp.grupoatu.com
Form Dict: {'filters': "{'lead_id':'CRM-LEAD-2024-77614'}", 'limit_page_length': 20}
2024-11-26 11:41:33,803 ERROR frappe Failed to capture exception
Site: erp.grupoatu.com
Form Dict: {'filters': "{'lead_id':'CRM-LEAD-2024-77614'}", 'limit_page_length': 20}
Traceback (most recent call last):
  File "/home/frappe/frappe-bench/env/lib/python3.10/site-packages/werkzeug/wrappers/request.py", line 611, in get_json
    rv = self.json_module.loads(data)
  File "/usr/lib/python3.10/json/__init__.py", line 346, in loads
    return _default_decoder.decode(s)
  File "/usr/lib/python3.10/json/decoder.py", line 337, in decode
    obj, end = self.raw_decode(s, idx=_w(s, 0).end())
  File "/usr/lib/python3.10/json/decoder.py", line 355, in raw_decode
    raise JSONDecodeError("Expecting value", s, err.value) from None
json.decoder.JSONDecodeError: Expecting value: line 1 column 1 (char 0)

During handling of the above exception, another exception occurred:

Traceback (most recent call last):
  File "/home/frappe/frappe-bench/apps/frappe/frappe/utils/sentry.py", line 121, in capture_exception
    scope.set_context("JSON Body", frappe.request.json)
  File "/home/frappe/frappe-bench/env/lib/python3.10/site-packages/werkzeug/wrappers/request.py", line 558, in json
    return self.get_json()
  File "/home/frappe/frappe-bench/env/lib/python3.10/site-packages/werkzeug/wrappers/request.py", line 620, in get_json
    rv = self.on_json_loading_failed(e)
  File "/home/frappe/frappe-bench/env/lib/python3.10/site-packages/werkzeug/wrappers/request.py", line 645, in on_json_loading_failed
    raise BadRequest(f"Failed to decode JSON object: {e}")
werkzeug.exceptions.BadRequest: 400 Bad Request: Failed to decode JSON object: Expecting value: line 1 column 1 (char 0)
2024-11-26 11:41:33,804 ERROR frappe New Exception collected in error log
Site: erp.grupoatu.com
Form Dict: {'filters': "{'lead_id':'CRM-LEAD-2024-77614'}", 'limit_page_length': 20}
2024-11-26 11:56:11,546 ERROR frappe New Exception collected in error log
Site: erp.grupoatu.com
Form Dict: {'format': 'PDF', 'filters': '{"company":"Burgos atu SL","filter_based_on":"Date Range","period_start_date":"2024-01-01","period_end_date":"2024-06-30","from_fiscal_year":"2024","to_fiscal_year":"2024","periodicity":"Yearly","cost_center":[],"project":[],"selected_view":"Report","accumulated_values":1,"include_default_book_entries":1}', 'cmd': 'integracion.utils.export_balance_sheet.export_balance_sheet'}
2024-11-26 13:05:39,491 ERROR frappe New Exception collected in error log
Site: erp.grupoatu.com
Form Dict: {'filters': '', 'cmd': 'integracion.get_prom_reconciled_transaction'}
2024-11-26 21:34:24,356 ERROR frappe New Exception collected in error log
Site: erp.grupoatu.com
Form Dict: {'format': 'PDF', 'filters': '{"company":"Burgos atu SL","filter_based_on":"Date Range","period_start_date":"2024-01-01","period_end_date":"2024-06-30","from_fiscal_year":"2024","to_fiscal_year":"2024","periodicity":"Yearly","cost_center":[],"project":[],"selected_view":"Report","accumulated_values":1,"include_default_book_entries":1}', 'cmd': 'integracion.utils.export_balance_sheet.export_balance_sheet'}
2024-11-26 21:35:34,258 ERROR frappe New Exception collected in error log
Site: erp.grupoatu.com
Form Dict: {'format': 'PDF', 'filters': '{"company":"Burgos atu SL","filter_based_on":"Date Range","period_start_date":"2024-01-01","period_end_date":"2024-06-30","from_fiscal_year":"2024","to_fiscal_year":"2024","periodicity":"Yearly","cost_center":[],"project":[],"selected_view":"Report","accumulated_values":1,"include_default_book_entries":1}', 'cmd': 'integracion.utils.export_balance_sheet.export_balance_sheet'}
2024-11-26 22:45:00,097 ERROR frappe New Exception collected in error log
Site: erp.grupoatu.com
Form Dict: {'format': 'PDF', 'filters': '{"company":"Burgos atu SL","filter_based_on":"Date Range","period_start_date":"2024-01-01","period_end_date":"2024-06-30","from_fiscal_year":"2024","to_fiscal_year":"2024","periodicity":"Yearly","cost_center":[],"project":[],"selected_view":"Report","accumulated_values":1,"include_default_book_entries":1}', 'cmd': 'integracion.utils.export_balance_sheet.export_balance_sheet'}
2024-11-27 01:00:47,279 ERROR frappe New Exception collected in error log
Site: erp.grupoatu.com
Form Dict: {'format': 'PDF', 'filters': '{"company":"Burgos atu SL","filter_based_on":"Date Range","period_start_date":"2024-01-01","period_end_date":"2024-06-30","from_fiscal_year":"2024","to_fiscal_year":"2024","periodicity":"Yearly","cost_center":[],"project":[],"selected_view":"Report","accumulated_values":1,"include_default_book_entries":1}', 'cmd': 'integracion.utils.export_balance_sheet.export_balance_sheet'}
2024-11-27 01:00:59,912 ERROR frappe New Exception collected in error log
Site: erp.grupoatu.com
Form Dict: {'format': 'PDF', 'filters': '{"company":"Burgos atu SL","filter_based_on":"Date Range","period_start_date":"2024-01-01","period_end_date":"2024-12-31","from_fiscal_year":"2024","to_fiscal_year":"2024","periodicity":"Yearly","cost_center":[],"project":[],"selected_view":"Report","accumulated_values":1,"include_default_book_entries":1}', 'cmd': 'integracion.utils.export_balance_sheet.export_balance_sheet'}
2024-11-27 01:03:01,063 ERROR frappe New Exception collected in error log
Site: erp.grupoatu.com
Form Dict: {'format': 'PDF', 'filters': '{"company":"Burgos atu SL","filter_based_on":"Date Range","period_start_date":"2024-01-01","period_end_date":"2024-12-31","from_fiscal_year":"2024","to_fiscal_year":"2024","periodicity":"Yearly","cost_center":[],"project":[],"selected_view":"Report","accumulated_values":1,"include_default_book_entries":1}', 'cmd': 'integracion.utils.export_balance_sheet.export_balance_sheet'}
2024-11-27 01:04:01,395 ERROR frappe New Exception collected in error log
Site: erp.grupoatu.com
Form Dict: {'format': 'PDF', 'filters': '{"company":"Burgos atu SL","filter_based_on":"Date Range","period_start_date":"2024-01-01","period_end_date":"2024-12-31","from_fiscal_year":"2024","to_fiscal_year":"2024","periodicity":"Yearly","cost_center":[],"project":[],"selected_view":"Report","accumulated_values":1,"include_default_book_entries":1}', 'cmd': 'integracion.utils.export_balance_sheet.export_balance_sheet'}
2024-11-27 01:05:44,617 ERROR frappe New Exception collected in error log
Site: erp.grupoatu.com
Form Dict: {'format': 'PDF', 'filters': '{"company":"Burgos atu SL","filter_based_on":"Date Range","period_start_date":"2024-01-01","period_end_date":"2024-12-31","from_fiscal_year":"2024","to_fiscal_year":"2024","periodicity":"Yearly","cost_center":[],"project":[],"selected_view":"Report","accumulated_values":1,"include_default_book_entries":1}', 'cmd': 'integracion.utils.export_balance_sheet.export_balance_sheet'}
2024-11-27 01:06:34,287 ERROR frappe New Exception collected in error log
Site: erp.grupoatu.com
Form Dict: {'format': 'PDF', 'filters': '{"company":"Burgos atu SL","filter_based_on":"Date Range","period_start_date":"2024-01-01","period_end_date":"2024-12-31","from_fiscal_year":"2024","to_fiscal_year":"2024","periodicity":"Yearly","cost_center":[],"project":[],"selected_view":"Report","accumulated_values":1,"include_default_book_entries":1}', 'cmd': 'integracion.utils.export_balance_sheet.export_balance_sheet'}
2024-11-27 01:32:53,147 ERROR frappe New Exception collected in error log
Site: erp.grupoatu.com
Form Dict: {'format': 'PDF', 'filters': '{"company":"Burgos atu SL","filter_based_on":"Date Range","period_start_date":"2024-01-01","period_end_date":"2024-06-30","from_fiscal_year":"2024","to_fiscal_year":"2024","periodicity":"Yearly","cost_center":[],"project":[],"selected_view":"Report","accumulated_values":1,"include_default_book_entries":1}', 'cmd': 'integracion.utils.export_balance_sheet.export_balance_sheet'}
2024-11-27 03:33:17,120 ERROR frappe New Exception collected in error log
Site: erp.grupoatu.com
Form Dict: {'format': 'PDF', 'filters': '{"company":"Burgos atu SL","filter_based_on":"Date Range","period_start_date":"2024-01-01","period_end_date":"2024-06-30","from_fiscal_year":"2024","to_fiscal_year":"2024","periodicity":"Yearly","cost_center":[],"project":[],"selected_view":"Report","accumulated_values":1,"include_default_book_entries":1}', 'cmd': 'integracion.utils.export_balance_sheet.export_balance_sheet'}
2024-11-27 03:34:07,707 ERROR frappe New Exception collected in error log
Site: erp.grupoatu.com
Form Dict: {'format': 'PDF', 'filters': '{"company":"Burgos atu SL","filter_based_on":"Date Range","period_start_date":"2024-01-01","period_end_date":"2024-06-30","from_fiscal_year":"2024","to_fiscal_year":"2024","periodicity":"Yearly","cost_center":[],"project":[],"selected_view":"Report","accumulated_values":1,"include_default_book_entries":1}', 'cmd': 'integracion.utils.export_balance_sheet.export_balance_sheet'}
2024-11-27 03:36:51,579 ERROR frappe New Exception collected in error log
Site: erp.grupoatu.com
Form Dict: {'format': 'PDF', 'filters': '{"company":"Burgos atu SL","filter_based_on":"Date Range","period_start_date":"2024-01-01","period_end_date":"2024-06-30","from_fiscal_year":"2024","to_fiscal_year":"2024","periodicity":"Yearly","cost_center":[],"project":[],"selected_view":"Report","accumulated_values":1,"include_default_book_entries":1}', 'cmd': 'integracion.utils.export_balance_sheet.export_balance_sheet'}
2024-11-27 03:49:39,702 ERROR frappe New Exception collected in error log
Site: erp.grupoatu.com
Form Dict: {'format': 'PDF', 'filters': '{"company":"Burgos atu SL","filter_based_on":"Date Range","period_start_date":"2024-01-01","period_end_date":"2024-06-30","from_fiscal_year":"2024","to_fiscal_year":"2024","periodicity":"Yearly","cost_center":[],"project":[],"selected_view":"Report","accumulated_values":1,"include_default_book_entries":1}', 'cmd': 'integracion.utils.export_balance_sheet.export_balance_sheet'}
2024-11-27 03:56:19,095 ERROR frappe New Exception collected in error log
Site: erp.grupoatu.com
Form Dict: {'format': 'PDF', 'filters': '{"company":"Burgos atu SL","filter_based_on":"Date Range","period_start_date":"2024-01-01","period_end_date":"2024-06-30","from_fiscal_year":"2024","to_fiscal_year":"2024","periodicity":"Yearly","cost_center":[],"project":[],"selected_view":"Report","accumulated_values":1,"include_default_book_entries":1}', 'cmd': 'integracion.utils.export_balance_sheet.export_balance_sheet'}
2024-11-27 03:59:08,542 ERROR frappe New Exception collected in error log
Site: erp.grupoatu.com
Form Dict: {'format': 'PDF', 'filters': '{"company":"Burgos atu SL","filter_based_on":"Date Range","period_start_date":"2024-01-01","period_end_date":"2024-06-30","from_fiscal_year":"2024","to_fiscal_year":"2024","periodicity":"Yearly","cost_center":[],"project":[],"selected_view":"Report","accumulated_values":1,"include_default_book_entries":1}', 'cmd': 'integracion.utils.export_balance_sheet.export_balance_sheet'}
2024-11-27 04:10:47,592 ERROR frappe New Exception collected in error log
Site: erp.grupoatu.com
Form Dict: {'format': 'PDF', 'filters': '{"company":"Burgos atu SL","filter_based_on":"Date Range","period_start_date":"2024-01-01","period_end_date":"2024-06-30","from_fiscal_year":"2024","to_fiscal_year":"2024","periodicity":"Yearly","cost_center":[],"project":[],"selected_view":"Report","accumulated_values":1,"include_default_book_entries":1}', 'cmd': 'integracion.utils.export_balance_sheet.export_balance_sheet'}
2024-11-27 04:13:24,144 ERROR frappe New Exception collected in error log
Site: erp.grupoatu.com
Form Dict: {'format': 'PDF', 'filters': '{"company":"Burgos atu SL","filter_based_on":"Date Range","period_start_date":"2024-01-01","period_end_date":"2024-06-30","from_fiscal_year":"2024","to_fiscal_year":"2024","periodicity":"Yearly","cost_center":[],"project":[],"selected_view":"Report","accumulated_values":1,"include_default_book_entries":1}', 'cmd': 'integracion.utils.export_balance_sheet.export_balance_sheet'}
2024-11-27 04:38:20,022 ERROR frappe New Exception collected in error log
Site: erp.grupoatu.com
Form Dict: {'format': 'PDF', 'filters': '{"company":"Burgos atu SL","filter_based_on":"Date Range","period_start_date":"2024-01-01","period_end_date":"2024-06-30","from_fiscal_year":"2024","to_fiscal_year":"2024","periodicity":"Yearly","cost_center":[],"project":[],"selected_view":"Report","accumulated_values":1,"include_default_book_entries":1}', 'cmd': 'integracion.utils.export_balance_sheet.export_balance_sheet'}
2024-11-27 04:51:31,298 ERROR frappe New Exception collected in error log
Site: erp.grupoatu.com
Form Dict: {'format': 'PDF', 'filters': '{"company":"Burgos atu SL","filter_based_on":"Date Range","period_start_date":"2024-01-01","period_end_date":"2024-06-30","from_fiscal_year":"2024","to_fiscal_year":"2024","periodicity":"Yearly","cost_center":[],"project":[],"selected_view":"Report","accumulated_values":1,"include_default_book_entries":1}', 'cmd': 'integracion.utils.export_balance_sheet.export_balance_sheet'}
2024-11-27 04:51:42,243 ERROR frappe New Exception collected in error log
Site: erp.grupoatu.com
Form Dict: {'format': 'PDF', 'filters': '{"company":"Burgos atu SL","filter_based_on":"Date Range","period_start_date":"2024-01-01","period_end_date":"2024-12-31","from_fiscal_year":"2024","to_fiscal_year":"2024","periodicity":"Yearly","cost_center":[],"project":[],"selected_view":"Report","accumulated_values":1,"include_default_book_entries":1}', 'cmd': 'integracion.utils.export_balance_sheet.export_balance_sheet'}
2024-11-27 04:52:00,508 ERROR frappe New Exception collected in error log
Site: erp.grupoatu.com
Form Dict: {'format': 'PDF', 'filters': '{"company":"Burgos atu SL","filter_based_on":"Date Range","period_start_date":"2024-01-01","period_end_date":"2024-12-31","from_fiscal_year":"2024","to_fiscal_year":"2024","periodicity":"Yearly","cost_center":[],"project":[],"selected_view":"Report","accumulated_values":1,"include_default_book_entries":1}', 'cmd': 'integracion.utils.export_balance_sheet.export_balance_sheet'}
2024-11-27 06:12:35,977 ERROR frappe Failed to capture exception
Site: erp.grupoatu.com
Form Dict: {'filters': "{'lead_id':'CRM-LEAD-2024-73486'}", 'limit_page_length': 20}
Traceback (most recent call last):
  File "/home/frappe/frappe-bench/env/lib/python3.10/site-packages/werkzeug/wrappers/request.py", line 611, in get_json
    rv = self.json_module.loads(data)
  File "/usr/lib/python3.10/json/__init__.py", line 346, in loads
    return _default_decoder.decode(s)
  File "/usr/lib/python3.10/json/decoder.py", line 337, in decode
    obj, end = self.raw_decode(s, idx=_w(s, 0).end())
  File "/usr/lib/python3.10/json/decoder.py", line 355, in raw_decode
    raise JSONDecodeError("Expecting value", s, err.value) from None
json.decoder.JSONDecodeError: Expecting value: line 1 column 1 (char 0)

During handling of the above exception, another exception occurred:

Traceback (most recent call last):
  File "/home/frappe/frappe-bench/apps/frappe/frappe/utils/sentry.py", line 121, in capture_exception
    scope.set_context("JSON Body", frappe.request.json)
  File "/home/frappe/frappe-bench/env/lib/python3.10/site-packages/werkzeug/wrappers/request.py", line 558, in json
    return self.get_json()
  File "/home/frappe/frappe-bench/env/lib/python3.10/site-packages/werkzeug/wrappers/request.py", line 620, in get_json
    rv = self.on_json_loading_failed(e)
  File "/home/frappe/frappe-bench/env/lib/python3.10/site-packages/werkzeug/wrappers/request.py", line 645, in on_json_loading_failed
    raise BadRequest(f"Failed to decode JSON object: {e}")
werkzeug.exceptions.BadRequest: 400 Bad Request: Failed to decode JSON object: Expecting value: line 1 column 1 (char 0)
2024-11-27 06:12:35,980 ERROR frappe New Exception collected in error log
Site: erp.grupoatu.com
Form Dict: {'filters': "{'lead_id':'CRM-LEAD-2024-73486'}", 'limit_page_length': 20}
2024-11-27 06:12:36,150 ERROR frappe Failed to capture exception
Site: erp.grupoatu.com
Form Dict: {'filters': "{'lead_id':'CRM-LEAD-2024-73486'}", 'limit_page_length': 20}
Traceback (most recent call last):
  File "/home/frappe/frappe-bench/env/lib/python3.10/site-packages/werkzeug/wrappers/request.py", line 611, in get_json
    rv = self.json_module.loads(data)
  File "/usr/lib/python3.10/json/__init__.py", line 346, in loads
    return _default_decoder.decode(s)
  File "/usr/lib/python3.10/json/decoder.py", line 337, in decode
    obj, end = self.raw_decode(s, idx=_w(s, 0).end())
  File "/usr/lib/python3.10/json/decoder.py", line 355, in raw_decode
    raise JSONDecodeError("Expecting value", s, err.value) from None
json.decoder.JSONDecodeError: Expecting value: line 1 column 1 (char 0)

During handling of the above exception, another exception occurred:

Traceback (most recent call last):
  File "/home/frappe/frappe-bench/apps/frappe/frappe/utils/sentry.py", line 121, in capture_exception
    scope.set_context("JSON Body", frappe.request.json)
  File "/home/frappe/frappe-bench/env/lib/python3.10/site-packages/werkzeug/wrappers/request.py", line 558, in json
    return self.get_json()
  File "/home/frappe/frappe-bench/env/lib/python3.10/site-packages/werkzeug/wrappers/request.py", line 620, in get_json
    rv = self.on_json_loading_failed(e)
  File "/home/frappe/frappe-bench/env/lib/python3.10/site-packages/werkzeug/wrappers/request.py", line 645, in on_json_loading_failed
    raise BadRequest(f"Failed to decode JSON object: {e}")
werkzeug.exceptions.BadRequest: 400 Bad Request: Failed to decode JSON object: Expecting value: line 1 column 1 (char 0)
2024-11-27 06:12:36,151 ERROR frappe New Exception collected in error log
Site: erp.grupoatu.com
Form Dict: {'filters': "{'lead_id':'CRM-LEAD-2024-73486'}", 'limit_page_length': 20}
2024-11-27 06:12:36,483 ERROR frappe Failed to capture exception
Site: erp.grupoatu.com
Form Dict: {'filters': "{'lead_id':'CRM-LEAD-2024-73486'}", 'limit_page_length': 20}
Traceback (most recent call last):
  File "/home/frappe/frappe-bench/env/lib/python3.10/site-packages/werkzeug/wrappers/request.py", line 611, in get_json
    rv = self.json_module.loads(data)
  File "/usr/lib/python3.10/json/__init__.py", line 346, in loads
    return _default_decoder.decode(s)
  File "/usr/lib/python3.10/json/decoder.py", line 337, in decode
    obj, end = self.raw_decode(s, idx=_w(s, 0).end())
  File "/usr/lib/python3.10/json/decoder.py", line 355, in raw_decode
    raise JSONDecodeError("Expecting value", s, err.value) from None
json.decoder.JSONDecodeError: Expecting value: line 1 column 1 (char 0)

During handling of the above exception, another exception occurred:

Traceback (most recent call last):
  File "/home/frappe/frappe-bench/apps/frappe/frappe/utils/sentry.py", line 121, in capture_exception
    scope.set_context("JSON Body", frappe.request.json)
  File "/home/frappe/frappe-bench/env/lib/python3.10/site-packages/werkzeug/wrappers/request.py", line 558, in json
    return self.get_json()
  File "/home/frappe/frappe-bench/env/lib/python3.10/site-packages/werkzeug/wrappers/request.py", line 620, in get_json
    rv = self.on_json_loading_failed(e)
  File "/home/frappe/frappe-bench/env/lib/python3.10/site-packages/werkzeug/wrappers/request.py", line 645, in on_json_loading_failed
    raise BadRequest(f"Failed to decode JSON object: {e}")
werkzeug.exceptions.BadRequest: 400 Bad Request: Failed to decode JSON object: Expecting value: line 1 column 1 (char 0)
2024-11-27 06:12:36,485 ERROR frappe New Exception collected in error log
Site: erp.grupoatu.com
Form Dict: {'filters': "{'lead_id':'CRM-LEAD-2024-73486'}", 'limit_page_length': 20}
2024-11-27 06:12:36,820 ERROR frappe Failed to capture exception
Site: erp.grupoatu.com
Form Dict: {'filters': "{'lead_id':'CRM-LEAD-2024-73486'}", 'limit_page_length': 20}
Traceback (most recent call last):
  File "/home/frappe/frappe-bench/env/lib/python3.10/site-packages/werkzeug/wrappers/request.py", line 611, in get_json
    rv = self.json_module.loads(data)
  File "/usr/lib/python3.10/json/__init__.py", line 346, in loads
    return _default_decoder.decode(s)
  File "/usr/lib/python3.10/json/decoder.py", line 337, in decode
    obj, end = self.raw_decode(s, idx=_w(s, 0).end())
  File "/usr/lib/python3.10/json/decoder.py", line 355, in raw_decode
    raise JSONDecodeError("Expecting value", s, err.value) from None
json.decoder.JSONDecodeError: Expecting value: line 1 column 1 (char 0)

During handling of the above exception, another exception occurred:

Traceback (most recent call last):
  File "/home/frappe/frappe-bench/apps/frappe/frappe/utils/sentry.py", line 121, in capture_exception
    scope.set_context("JSON Body", frappe.request.json)
  File "/home/frappe/frappe-bench/env/lib/python3.10/site-packages/werkzeug/wrappers/request.py", line 558, in json
    return self.get_json()
  File "/home/frappe/frappe-bench/env/lib/python3.10/site-packages/werkzeug/wrappers/request.py", line 620, in get_json
    rv = self.on_json_loading_failed(e)
  File "/home/frappe/frappe-bench/env/lib/python3.10/site-packages/werkzeug/wrappers/request.py", line 645, in on_json_loading_failed
    raise BadRequest(f"Failed to decode JSON object: {e}")
werkzeug.exceptions.BadRequest: 400 Bad Request: Failed to decode JSON object: Expecting value: line 1 column 1 (char 0)
2024-11-27 06:12:36,821 ERROR frappe New Exception collected in error log
Site: erp.grupoatu.com
Form Dict: {'filters': "{'lead_id':'CRM-LEAD-2024-73486'}", 'limit_page_length': 20}
2024-11-27 06:12:37,008 ERROR frappe Failed to capture exception
Site: erp.grupoatu.com
Form Dict: {'filters': "{'lead_id':'CRM-LEAD-2024-73486'}", 'limit_page_length': 20}
Traceback (most recent call last):
  File "/home/frappe/frappe-bench/env/lib/python3.10/site-packages/werkzeug/wrappers/request.py", line 611, in get_json
    rv = self.json_module.loads(data)
  File "/usr/lib/python3.10/json/__init__.py", line 346, in loads
    return _default_decoder.decode(s)
  File "/usr/lib/python3.10/json/decoder.py", line 337, in decode
    obj, end = self.raw_decode(s, idx=_w(s, 0).end())
  File "/usr/lib/python3.10/json/decoder.py", line 355, in raw_decode
    raise JSONDecodeError("Expecting value", s, err.value) from None
json.decoder.JSONDecodeError: Expecting value: line 1 column 1 (char 0)

During handling of the above exception, another exception occurred:

Traceback (most recent call last):
  File "/home/frappe/frappe-bench/apps/frappe/frappe/utils/sentry.py", line 121, in capture_exception
    scope.set_context("JSON Body", frappe.request.json)
  File "/home/frappe/frappe-bench/env/lib/python3.10/site-packages/werkzeug/wrappers/request.py", line 558, in json
    return self.get_json()
  File "/home/frappe/frappe-bench/env/lib/python3.10/site-packages/werkzeug/wrappers/request.py", line 620, in get_json
    rv = self.on_json_loading_failed(e)
  File "/home/frappe/frappe-bench/env/lib/python3.10/site-packages/werkzeug/wrappers/request.py", line 645, in on_json_loading_failed
    raise BadRequest(f"Failed to decode JSON object: {e}")
werkzeug.exceptions.BadRequest: 400 Bad Request: Failed to decode JSON object: Expecting value: line 1 column 1 (char 0)
2024-11-27 06:12:37,009 ERROR frappe New Exception collected in error log
Site: erp.grupoatu.com
Form Dict: {'filters': "{'lead_id':'CRM-LEAD-2024-73486'}", 'limit_page_length': 20}
2024-11-27 06:12:37,256 ERROR frappe Failed to capture exception
Site: erp.grupoatu.com
Form Dict: {'filters': "{'lead_id':'CRM-LEAD-2024-73486'}", 'limit_page_length': 20}
Traceback (most recent call last):
  File "/home/frappe/frappe-bench/env/lib/python3.10/site-packages/werkzeug/wrappers/request.py", line 611, in get_json
    rv = self.json_module.loads(data)
  File "/usr/lib/python3.10/json/__init__.py", line 346, in loads
    return _default_decoder.decode(s)
  File "/usr/lib/python3.10/json/decoder.py", line 337, in decode
    obj, end = self.raw_decode(s, idx=_w(s, 0).end())
  File "/usr/lib/python3.10/json/decoder.py", line 355, in raw_decode
    raise JSONDecodeError("Expecting value", s, err.value) from None
json.decoder.JSONDecodeError: Expecting value: line 1 column 1 (char 0)

During handling of the above exception, another exception occurred:

Traceback (most recent call last):
  File "/home/frappe/frappe-bench/apps/frappe/frappe/utils/sentry.py", line 121, in capture_exception
    scope.set_context("JSON Body", frappe.request.json)
  File "/home/frappe/frappe-bench/env/lib/python3.10/site-packages/werkzeug/wrappers/request.py", line 558, in json
    return self.get_json()
  File "/home/frappe/frappe-bench/env/lib/python3.10/site-packages/werkzeug/wrappers/request.py", line 620, in get_json
    rv = self.on_json_loading_failed(e)
  File "/home/frappe/frappe-bench/env/lib/python3.10/site-packages/werkzeug/wrappers/request.py", line 645, in on_json_loading_failed
    raise BadRequest(f"Failed to decode JSON object: {e}")
werkzeug.exceptions.BadRequest: 400 Bad Request: Failed to decode JSON object: Expecting value: line 1 column 1 (char 0)
2024-11-27 06:12:37,258 ERROR frappe New Exception collected in error log
Site: erp.grupoatu.com
Form Dict: {'filters': "{'lead_id':'CRM-LEAD-2024-73486'}", 'limit_page_length': 20}
2024-11-27 07:45:18,871 ERROR frappe Failed to capture exception
Site: erp.grupoatu.com
Form Dict: {'filters': "{'lead_id':'CRMLead(CRM-LEAD-2024-73486)'}", 'limit_page_length': 20}
Traceback (most recent call last):
  File "/home/frappe/frappe-bench/env/lib/python3.10/site-packages/werkzeug/wrappers/request.py", line 611, in get_json
    rv = self.json_module.loads(data)
  File "/usr/lib/python3.10/json/__init__.py", line 346, in loads
    return _default_decoder.decode(s)
  File "/usr/lib/python3.10/json/decoder.py", line 337, in decode
    obj, end = self.raw_decode(s, idx=_w(s, 0).end())
  File "/usr/lib/python3.10/json/decoder.py", line 355, in raw_decode
    raise JSONDecodeError("Expecting value", s, err.value) from None
json.decoder.JSONDecodeError: Expecting value: line 1 column 1 (char 0)

During handling of the above exception, another exception occurred:

Traceback (most recent call last):
  File "/home/frappe/frappe-bench/apps/frappe/frappe/utils/sentry.py", line 121, in capture_exception
    scope.set_context("JSON Body", frappe.request.json)
  File "/home/frappe/frappe-bench/env/lib/python3.10/site-packages/werkzeug/wrappers/request.py", line 558, in json
    return self.get_json()
  File "/home/frappe/frappe-bench/env/lib/python3.10/site-packages/werkzeug/wrappers/request.py", line 620, in get_json
    rv = self.on_json_loading_failed(e)
  File "/home/frappe/frappe-bench/env/lib/python3.10/site-packages/werkzeug/wrappers/request.py", line 645, in on_json_loading_failed
    raise BadRequest(f"Failed to decode JSON object: {e}")
werkzeug.exceptions.BadRequest: 400 Bad Request: Failed to decode JSON object: Expecting value: line 1 column 1 (char 0)
2024-11-27 07:45:18,873 ERROR frappe New Exception collected in error log
Site: erp.grupoatu.com
Form Dict: {'filters': "{'lead_id':'CRMLead(CRM-LEAD-2024-73486)'}", 'limit_page_length': 20}
2024-11-27 07:45:19,078 ERROR frappe Failed to capture exception
Site: erp.grupoatu.com
Form Dict: {'filters': "{'lead_id':'CRMLead(CRM-LEAD-2024-73486)'}", 'limit_page_length': 20}
Traceback (most recent call last):
  File "/home/frappe/frappe-bench/env/lib/python3.10/site-packages/werkzeug/wrappers/request.py", line 611, in get_json
    rv = self.json_module.loads(data)
  File "/usr/lib/python3.10/json/__init__.py", line 346, in loads
    return _default_decoder.decode(s)
  File "/usr/lib/python3.10/json/decoder.py", line 337, in decode
    obj, end = self.raw_decode(s, idx=_w(s, 0).end())
  File "/usr/lib/python3.10/json/decoder.py", line 355, in raw_decode
    raise JSONDecodeError("Expecting value", s, err.value) from None
json.decoder.JSONDecodeError: Expecting value: line 1 column 1 (char 0)

During handling of the above exception, another exception occurred:

Traceback (most recent call last):
  File "/home/frappe/frappe-bench/apps/frappe/frappe/utils/sentry.py", line 121, in capture_exception
    scope.set_context("JSON Body", frappe.request.json)
  File "/home/frappe/frappe-bench/env/lib/python3.10/site-packages/werkzeug/wrappers/request.py", line 558, in json
    return self.get_json()
  File "/home/frappe/frappe-bench/env/lib/python3.10/site-packages/werkzeug/wrappers/request.py", line 620, in get_json
    rv = self.on_json_loading_failed(e)
  File "/home/frappe/frappe-bench/env/lib/python3.10/site-packages/werkzeug/wrappers/request.py", line 645, in on_json_loading_failed
    raise BadRequest(f"Failed to decode JSON object: {e}")
werkzeug.exceptions.BadRequest: 400 Bad Request: Failed to decode JSON object: Expecting value: line 1 column 1 (char 0)
2024-11-27 07:45:19,080 ERROR frappe New Exception collected in error log
Site: erp.grupoatu.com
Form Dict: {'filters': "{'lead_id':'CRMLead(CRM-LEAD-2024-73486)'}", 'limit_page_length': 20}
2024-11-27 07:45:19,258 ERROR frappe Failed to capture exception
Site: erp.grupoatu.com
Form Dict: {'filters': "{'lead_id':'CRMLead(CRM-LEAD-2024-73486)'}", 'limit_page_length': 20}
Traceback (most recent call last):
  File "/home/frappe/frappe-bench/env/lib/python3.10/site-packages/werkzeug/wrappers/request.py", line 611, in get_json
    rv = self.json_module.loads(data)
  File "/usr/lib/python3.10/json/__init__.py", line 346, in loads
    return _default_decoder.decode(s)
  File "/usr/lib/python3.10/json/decoder.py", line 337, in decode
    obj, end = self.raw_decode(s, idx=_w(s, 0).end())
  File "/usr/lib/python3.10/json/decoder.py", line 355, in raw_decode
    raise JSONDecodeError("Expecting value", s, err.value) from None
json.decoder.JSONDecodeError: Expecting value: line 1 column 1 (char 0)

During handling of the above exception, another exception occurred:

Traceback (most recent call last):
  File "/home/frappe/frappe-bench/apps/frappe/frappe/utils/sentry.py", line 121, in capture_exception
    scope.set_context("JSON Body", frappe.request.json)
  File "/home/frappe/frappe-bench/env/lib/python3.10/site-packages/werkzeug/wrappers/request.py", line 558, in json
    return self.get_json()
  File "/home/frappe/frappe-bench/env/lib/python3.10/site-packages/werkzeug/wrappers/request.py", line 620, in get_json
    rv = self.on_json_loading_failed(e)
  File "/home/frappe/frappe-bench/env/lib/python3.10/site-packages/werkzeug/wrappers/request.py", line 645, in on_json_loading_failed
    raise BadRequest(f"Failed to decode JSON object: {e}")
werkzeug.exceptions.BadRequest: 400 Bad Request: Failed to decode JSON object: Expecting value: line 1 column 1 (char 0)
2024-11-27 07:45:19,259 ERROR frappe New Exception collected in error log
Site: erp.grupoatu.com
Form Dict: {'filters': "{'lead_id':'CRMLead(CRM-LEAD-2024-73486)'}", 'limit_page_length': 20}
2024-11-27 07:45:19,495 ERROR frappe Failed to capture exception
Site: erp.grupoatu.com
Form Dict: {'filters': "{'lead_id':'CRMLead(CRM-LEAD-2024-73486)'}", 'limit_page_length': 20}
Traceback (most recent call last):
  File "/home/frappe/frappe-bench/env/lib/python3.10/site-packages/werkzeug/wrappers/request.py", line 611, in get_json
    rv = self.json_module.loads(data)
  File "/usr/lib/python3.10/json/__init__.py", line 346, in loads
    return _default_decoder.decode(s)
  File "/usr/lib/python3.10/json/decoder.py", line 337, in decode
    obj, end = self.raw_decode(s, idx=_w(s, 0).end())
  File "/usr/lib/python3.10/json/decoder.py", line 355, in raw_decode
    raise JSONDecodeError("Expecting value", s, err.value) from None
json.decoder.JSONDecodeError: Expecting value: line 1 column 1 (char 0)

During handling of the above exception, another exception occurred:

Traceback (most recent call last):
  File "/home/frappe/frappe-bench/apps/frappe/frappe/utils/sentry.py", line 121, in capture_exception
    scope.set_context("JSON Body", frappe.request.json)
  File "/home/frappe/frappe-bench/env/lib/python3.10/site-packages/werkzeug/wrappers/request.py", line 558, in json
    return self.get_json()
  File "/home/frappe/frappe-bench/env/lib/python3.10/site-packages/werkzeug/wrappers/request.py", line 620, in get_json
    rv = self.on_json_loading_failed(e)
  File "/home/frappe/frappe-bench/env/lib/python3.10/site-packages/werkzeug/wrappers/request.py", line 645, in on_json_loading_failed
    raise BadRequest(f"Failed to decode JSON object: {e}")
werkzeug.exceptions.BadRequest: 400 Bad Request: Failed to decode JSON object: Expecting value: line 1 column 1 (char 0)
2024-11-27 07:45:19,497 ERROR frappe New Exception collected in error log
Site: erp.grupoatu.com
Form Dict: {'filters': "{'lead_id':'CRMLead(CRM-LEAD-2024-73486)'}", 'limit_page_length': 20}
2024-11-27 07:45:19,752 ERROR frappe Failed to capture exception
Site: erp.grupoatu.com
Form Dict: {'filters': "{'lead_id':'CRMLead(CRM-LEAD-2024-73486)'}", 'limit_page_length': 20}
Traceback (most recent call last):
  File "/home/frappe/frappe-bench/env/lib/python3.10/site-packages/werkzeug/wrappers/request.py", line 611, in get_json
    rv = self.json_module.loads(data)
  File "/usr/lib/python3.10/json/__init__.py", line 346, in loads
    return _default_decoder.decode(s)
  File "/usr/lib/python3.10/json/decoder.py", line 337, in decode
    obj, end = self.raw_decode(s, idx=_w(s, 0).end())
  File "/usr/lib/python3.10/json/decoder.py", line 355, in raw_decode
    raise JSONDecodeError("Expecting value", s, err.value) from None
json.decoder.JSONDecodeError: Expecting value: line 1 column 1 (char 0)

During handling of the above exception, another exception occurred:

Traceback (most recent call last):
  File "/home/frappe/frappe-bench/apps/frappe/frappe/utils/sentry.py", line 121, in capture_exception
    scope.set_context("JSON Body", frappe.request.json)
  File "/home/frappe/frappe-bench/env/lib/python3.10/site-packages/werkzeug/wrappers/request.py", line 558, in json
    return self.get_json()
  File "/home/frappe/frappe-bench/env/lib/python3.10/site-packages/werkzeug/wrappers/request.py", line 620, in get_json
    rv = self.on_json_loading_failed(e)
  File "/home/frappe/frappe-bench/env/lib/python3.10/site-packages/werkzeug/wrappers/request.py", line 645, in on_json_loading_failed
    raise BadRequest(f"Failed to decode JSON object: {e}")
werkzeug.exceptions.BadRequest: 400 Bad Request: Failed to decode JSON object: Expecting value: line 1 column 1 (char 0)
2024-11-27 07:45:19,754 ERROR frappe New Exception collected in error log
Site: erp.grupoatu.com
Form Dict: {'filters': "{'lead_id':'CRMLead(CRM-LEAD-2024-73486)'}", 'limit_page_length': 20}
2024-11-27 07:45:19,927 ERROR frappe Failed to capture exception
Site: erp.grupoatu.com
Form Dict: {'filters': "{'lead_id':'CRMLead(CRM-LEAD-2024-73486)'}", 'limit_page_length': 20}
Traceback (most recent call last):
  File "/home/frappe/frappe-bench/env/lib/python3.10/site-packages/werkzeug/wrappers/request.py", line 611, in get_json
    rv = self.json_module.loads(data)
  File "/usr/lib/python3.10/json/__init__.py", line 346, in loads
    return _default_decoder.decode(s)
  File "/usr/lib/python3.10/json/decoder.py", line 337, in decode
    obj, end = self.raw_decode(s, idx=_w(s, 0).end())
  File "/usr/lib/python3.10/json/decoder.py", line 355, in raw_decode
    raise JSONDecodeError("Expecting value", s, err.value) from None
json.decoder.JSONDecodeError: Expecting value: line 1 column 1 (char 0)

During handling of the above exception, another exception occurred:

Traceback (most recent call last):
  File "/home/frappe/frappe-bench/apps/frappe/frappe/utils/sentry.py", line 121, in capture_exception
    scope.set_context("JSON Body", frappe.request.json)
  File "/home/frappe/frappe-bench/env/lib/python3.10/site-packages/werkzeug/wrappers/request.py", line 558, in json
    return self.get_json()
  File "/home/frappe/frappe-bench/env/lib/python3.10/site-packages/werkzeug/wrappers/request.py", line 620, in get_json
    rv = self.on_json_loading_failed(e)
  File "/home/frappe/frappe-bench/env/lib/python3.10/site-packages/werkzeug/wrappers/request.py", line 645, in on_json_loading_failed
    raise BadRequest(f"Failed to decode JSON object: {e}")
werkzeug.exceptions.BadRequest: 400 Bad Request: Failed to decode JSON object: Expecting value: line 1 column 1 (char 0)
2024-11-27 07:45:19,929 ERROR frappe New Exception collected in error log
Site: erp.grupoatu.com
Form Dict: {'filters': "{'lead_id':'CRMLead(CRM-LEAD-2024-73486)'}", 'limit_page_length': 20}
2024-11-27 07:46:55,850 ERROR frappe Failed to capture exception
Site: erp.grupoatu.com
Form Dict: {'filters': "{'lead_id':'CRM-LEAD-2024-77696'}", 'limit_page_length': 20}
Traceback (most recent call last):
  File "/home/frappe/frappe-bench/env/lib/python3.10/site-packages/werkzeug/wrappers/request.py", line 611, in get_json
    rv = self.json_module.loads(data)
  File "/usr/lib/python3.10/json/__init__.py", line 346, in loads
    return _default_decoder.decode(s)
  File "/usr/lib/python3.10/json/decoder.py", line 337, in decode
    obj, end = self.raw_decode(s, idx=_w(s, 0).end())
  File "/usr/lib/python3.10/json/decoder.py", line 355, in raw_decode
    raise JSONDecodeError("Expecting value", s, err.value) from None
json.decoder.JSONDecodeError: Expecting value: line 1 column 1 (char 0)

During handling of the above exception, another exception occurred:

Traceback (most recent call last):
  File "/home/frappe/frappe-bench/apps/frappe/frappe/utils/sentry.py", line 121, in capture_exception
    scope.set_context("JSON Body", frappe.request.json)
  File "/home/frappe/frappe-bench/env/lib/python3.10/site-packages/werkzeug/wrappers/request.py", line 558, in json
    return self.get_json()
  File "/home/frappe/frappe-bench/env/lib/python3.10/site-packages/werkzeug/wrappers/request.py", line 620, in get_json
    rv = self.on_json_loading_failed(e)
  File "/home/frappe/frappe-bench/env/lib/python3.10/site-packages/werkzeug/wrappers/request.py", line 645, in on_json_loading_failed
    raise BadRequest(f"Failed to decode JSON object: {e}")
werkzeug.exceptions.BadRequest: 400 Bad Request: Failed to decode JSON object: Expecting value: line 1 column 1 (char 0)
2024-11-27 07:46:55,852 ERROR frappe New Exception collected in error log
Site: erp.grupoatu.com
Form Dict: {'filters': "{'lead_id':'CRM-LEAD-2024-77696'}", 'limit_page_length': 20}
2024-11-27 07:49:21,270 ERROR frappe Failed to capture exception
Site: erp.grupoatu.com
Form Dict: {'filters': "{'lead_id':'CRMLead(CRM-LEAD-2024-73486)'}", 'limit_page_length': 20}
Traceback (most recent call last):
  File "/home/frappe/frappe-bench/env/lib/python3.10/site-packages/werkzeug/wrappers/request.py", line 611, in get_json
    rv = self.json_module.loads(data)
  File "/usr/lib/python3.10/json/__init__.py", line 346, in loads
    return _default_decoder.decode(s)
  File "/usr/lib/python3.10/json/decoder.py", line 337, in decode
    obj, end = self.raw_decode(s, idx=_w(s, 0).end())
  File "/usr/lib/python3.10/json/decoder.py", line 355, in raw_decode
    raise JSONDecodeError("Expecting value", s, err.value) from None
json.decoder.JSONDecodeError: Expecting value: line 1 column 1 (char 0)

During handling of the above exception, another exception occurred:

Traceback (most recent call last):
  File "/home/frappe/frappe-bench/apps/frappe/frappe/utils/sentry.py", line 121, in capture_exception
    scope.set_context("JSON Body", frappe.request.json)
  File "/home/frappe/frappe-bench/env/lib/python3.10/site-packages/werkzeug/wrappers/request.py", line 558, in json
    return self.get_json()
  File "/home/frappe/frappe-bench/env/lib/python3.10/site-packages/werkzeug/wrappers/request.py", line 620, in get_json
    rv = self.on_json_loading_failed(e)
  File "/home/frappe/frappe-bench/env/lib/python3.10/site-packages/werkzeug/wrappers/request.py", line 645, in on_json_loading_failed
    raise BadRequest(f"Failed to decode JSON object: {e}")
werkzeug.exceptions.BadRequest: 400 Bad Request: Failed to decode JSON object: Expecting value: line 1 column 1 (char 0)
2024-11-27 07:49:21,272 ERROR frappe New Exception collected in error log
Site: erp.grupoatu.com
Form Dict: {'filters': "{'lead_id':'CRMLead(CRM-LEAD-2024-73486)'}", 'limit_page_length': 20}
2024-11-27 07:49:21,456 ERROR frappe Failed to capture exception
Site: erp.grupoatu.com
Form Dict: {'filters': "{'lead_id':'CRMLead(CRM-LEAD-2024-73486)'}", 'limit_page_length': 20}
Traceback (most recent call last):
  File "/home/frappe/frappe-bench/env/lib/python3.10/site-packages/werkzeug/wrappers/request.py", line 611, in get_json
    rv = self.json_module.loads(data)
  File "/usr/lib/python3.10/json/__init__.py", line 346, in loads
    return _default_decoder.decode(s)
  File "/usr/lib/python3.10/json/decoder.py", line 337, in decode
    obj, end = self.raw_decode(s, idx=_w(s, 0).end())
  File "/usr/lib/python3.10/json/decoder.py", line 355, in raw_decode
    raise JSONDecodeError("Expecting value", s, err.value) from None
json.decoder.JSONDecodeError: Expecting value: line 1 column 1 (char 0)

During handling of the above exception, another exception occurred:

Traceback (most recent call last):
  File "/home/frappe/frappe-bench/apps/frappe/frappe/utils/sentry.py", line 121, in capture_exception
    scope.set_context("JSON Body", frappe.request.json)
  File "/home/frappe/frappe-bench/env/lib/python3.10/site-packages/werkzeug/wrappers/request.py", line 558, in json
    return self.get_json()
  File "/home/frappe/frappe-bench/env/lib/python3.10/site-packages/werkzeug/wrappers/request.py", line 620, in get_json
    rv = self.on_json_loading_failed(e)
  File "/home/frappe/frappe-bench/env/lib/python3.10/site-packages/werkzeug/wrappers/request.py", line 645, in on_json_loading_failed
    raise BadRequest(f"Failed to decode JSON object: {e}")
werkzeug.exceptions.BadRequest: 400 Bad Request: Failed to decode JSON object: Expecting value: line 1 column 1 (char 0)
2024-11-27 07:49:21,458 ERROR frappe New Exception collected in error log
Site: erp.grupoatu.com
Form Dict: {'filters': "{'lead_id':'CRMLead(CRM-LEAD-2024-73486)'}", 'limit_page_length': 20}
2024-11-27 07:49:21,633 ERROR frappe Failed to capture exception
Site: erp.grupoatu.com
Form Dict: {'filters': "{'lead_id':'CRMLead(CRM-LEAD-2024-73486)'}", 'limit_page_length': 20}
Traceback (most recent call last):
  File "/home/frappe/frappe-bench/env/lib/python3.10/site-packages/werkzeug/wrappers/request.py", line 611, in get_json
    rv = self.json_module.loads(data)
  File "/usr/lib/python3.10/json/__init__.py", line 346, in loads
    return _default_decoder.decode(s)
  File "/usr/lib/python3.10/json/decoder.py", line 337, in decode
    obj, end = self.raw_decode(s, idx=_w(s, 0).end())
  File "/usr/lib/python3.10/json/decoder.py", line 355, in raw_decode
    raise JSONDecodeError("Expecting value", s, err.value) from None
json.decoder.JSONDecodeError: Expecting value: line 1 column 1 (char 0)

During handling of the above exception, another exception occurred:

Traceback (most recent call last):
  File "/home/frappe/frappe-bench/apps/frappe/frappe/utils/sentry.py", line 121, in capture_exception
    scope.set_context("JSON Body", frappe.request.json)
  File "/home/frappe/frappe-bench/env/lib/python3.10/site-packages/werkzeug/wrappers/request.py", line 558, in json
    return self.get_json()
  File "/home/frappe/frappe-bench/env/lib/python3.10/site-packages/werkzeug/wrappers/request.py", line 620, in get_json
    rv = self.on_json_loading_failed(e)
  File "/home/frappe/frappe-bench/env/lib/python3.10/site-packages/werkzeug/wrappers/request.py", line 645, in on_json_loading_failed
    raise BadRequest(f"Failed to decode JSON object: {e}")
werkzeug.exceptions.BadRequest: 400 Bad Request: Failed to decode JSON object: Expecting value: line 1 column 1 (char 0)
2024-11-27 07:49:21,635 ERROR frappe New Exception collected in error log
Site: erp.grupoatu.com
Form Dict: {'filters': "{'lead_id':'CRMLead(CRM-LEAD-2024-73486)'}", 'limit_page_length': 20}
2024-11-27 07:49:21,835 ERROR frappe Failed to capture exception
Site: erp.grupoatu.com
Form Dict: {'filters': "{'lead_id':'CRMLead(CRM-LEAD-2024-73486)'}", 'limit_page_length': 20}
Traceback (most recent call last):
  File "/home/frappe/frappe-bench/env/lib/python3.10/site-packages/werkzeug/wrappers/request.py", line 611, in get_json
    rv = self.json_module.loads(data)
  File "/usr/lib/python3.10/json/__init__.py", line 346, in loads
    return _default_decoder.decode(s)
  File "/usr/lib/python3.10/json/decoder.py", line 337, in decode
    obj, end = self.raw_decode(s, idx=_w(s, 0).end())
  File "/usr/lib/python3.10/json/decoder.py", line 355, in raw_decode
    raise JSONDecodeError("Expecting value", s, err.value) from None
json.decoder.JSONDecodeError: Expecting value: line 1 column 1 (char 0)

During handling of the above exception, another exception occurred:

Traceback (most recent call last):
  File "/home/frappe/frappe-bench/apps/frappe/frappe/utils/sentry.py", line 121, in capture_exception
    scope.set_context("JSON Body", frappe.request.json)
  File "/home/frappe/frappe-bench/env/lib/python3.10/site-packages/werkzeug/wrappers/request.py", line 558, in json
    return self.get_json()
  File "/home/frappe/frappe-bench/env/lib/python3.10/site-packages/werkzeug/wrappers/request.py", line 620, in get_json
    rv = self.on_json_loading_failed(e)
  File "/home/frappe/frappe-bench/env/lib/python3.10/site-packages/werkzeug/wrappers/request.py", line 645, in on_json_loading_failed
    raise BadRequest(f"Failed to decode JSON object: {e}")
werkzeug.exceptions.BadRequest: 400 Bad Request: Failed to decode JSON object: Expecting value: line 1 column 1 (char 0)
