2024-11-22 10:07:51,550 ERROR frappe Failed to capture exception
Site: erp.grupoatu.com
Form Dict: {}
Traceback (most recent call last):
  File "/home/frappe/frappe-bench/apps/frappe/frappe/utils/sentry.py", line 116, in capture_exception
    set_scope(scope)
  File "/home/frappe/frappe-bench/apps/frappe/frappe/utils/sentry.py", line 70, in set_scope
    path = frappe.request.path
  File "/home/frappe/frappe-bench/env/lib/python3.10/site-packages/werkzeug/local.py", line 311, in __get__
    obj = instance._get_current_object()
  File "/home/frappe/frappe-bench/env/lib/python3.10/site-packages/werkzeug/local.py", line 490, in _get_current_object
    raise RuntimeError(unbound_message) from None
RuntimeError: object is not bound
2024-11-22 10:07:51,576 ERROR frappe Failed to capture exception
Site: erp.grupoatu.com
Form Dict: {}
Traceback (most recent call last):
  File "/home/frappe/frappe-bench/apps/frappe/frappe/utils/sentry.py", line 116, in capture_exception
    set_scope(scope)
  File "/home/frappe/frappe-bench/apps/frappe/frappe/utils/sentry.py", line 70, in set_scope
    path = frappe.request.path
  File "/home/frappe/frappe-bench/env/lib/python3.10/site-packages/werkzeug/local.py", line 311, in __get__
    obj = instance._get_current_object()
  File "/home/frappe/frappe-bench/env/lib/python3.10/site-packages/werkzeug/local.py", line 490, in _get_current_object
    raise RuntimeError(unbound_message) from None
RuntimeError: object is not bound
2024-11-22 10:07:51,590 ERROR frappe Failed to capture exception
Site: erp.grupoatu.com
Form Dict: {}
Traceback (most recent call last):
  File "/home/frappe/frappe-bench/apps/frappe/frappe/utils/sentry.py", line 116, in capture_exception
    set_scope(scope)
  File "/home/frappe/frappe-bench/apps/frappe/frappe/utils/sentry.py", line 70, in set_scope
    path = frappe.request.path
  File "/home/frappe/frappe-bench/env/lib/python3.10/site-packages/werkzeug/local.py", line 311, in __get__
    obj = instance._get_current_object()
  File "/home/frappe/frappe-bench/env/lib/python3.10/site-packages/werkzeug/local.py", line 490, in _get_current_object
    raise RuntimeError(unbound_message) from None
RuntimeError: object is not bound
2024-11-22 10:07:51,604 ERROR frappe Failed to capture exception
Site: erp.grupoatu.com
Form Dict: {}
Traceback (most recent call last):
  File "/home/frappe/frappe-bench/apps/frappe/frappe/utils/sentry.py", line 116, in capture_exception
    set_scope(scope)
  File "/home/frappe/frappe-bench/apps/frappe/frappe/utils/sentry.py", line 70, in set_scope
    path = frappe.request.path
  File "/home/frappe/frappe-bench/env/lib/python3.10/site-packages/werkzeug/local.py", line 311, in __get__
    obj = instance._get_current_object()
  File "/home/frappe/frappe-bench/env/lib/python3.10/site-packages/werkzeug/local.py", line 490, in _get_current_object
    raise RuntimeError(unbound_message) from None
RuntimeError: object is not bound
2024-11-22 10:07:51,618 ERROR frappe Failed to capture exception
Site: erp.grupoatu.com
Form Dict: {}
Traceback (most recent call last):
  File "/home/frappe/frappe-bench/apps/frappe/frappe/utils/sentry.py", line 116, in capture_exception
    set_scope(scope)
  File "/home/frappe/frappe-bench/apps/frappe/frappe/utils/sentry.py", line 70, in set_scope
    path = frappe.request.path
  File "/home/frappe/frappe-bench/env/lib/python3.10/site-packages/werkzeug/local.py", line 311, in __get__
    obj = instance._get_current_object()
  File "/home/frappe/frappe-bench/env/lib/python3.10/site-packages/werkzeug/local.py", line 490, in _get_current_object
    raise RuntimeError(unbound_message) from None
RuntimeError: object is not bound
2024-11-22 10:07:51,632 ERROR frappe Failed to capture exception
Site: erp.grupoatu.com
Form Dict: {}
Traceback (most recent call last):
  File "/home/frappe/frappe-bench/apps/frappe/frappe/utils/sentry.py", line 116, in capture_exception
    set_scope(scope)
  File "/home/frappe/frappe-bench/apps/frappe/frappe/utils/sentry.py", line 70, in set_scope
    path = frappe.request.path
  File "/home/frappe/frappe-bench/env/lib/python3.10/site-packages/werkzeug/local.py", line 311, in __get__
    obj = instance._get_current_object()
  File "/home/frappe/frappe-bench/env/lib/python3.10/site-packages/werkzeug/local.py", line 490, in _get_current_object
    raise RuntimeError(unbound_message) from None
RuntimeError: object is not bound
2024-11-22 10:07:51,648 ERROR frappe Failed to capture exception
Site: erp.grupoatu.com
Form Dict: {}
Traceback (most recent call last):
  File "/home/frappe/frappe-bench/apps/frappe/frappe/utils/sentry.py", line 116, in capture_exception
    set_scope(scope)
  File "/home/frappe/frappe-bench/apps/frappe/frappe/utils/sentry.py", line 70, in set_scope
    path = frappe.request.path
  File "/home/frappe/frappe-bench/env/lib/python3.10/site-packages/werkzeug/local.py", line 311, in __get__
    obj = instance._get_current_object()
  File "/home/frappe/frappe-bench/env/lib/python3.10/site-packages/werkzeug/local.py", line 490, in _get_current_object
    raise RuntimeError(unbound_message) from None
RuntimeError: object is not bound
2024-11-22 10:07:51,662 ERROR frappe Failed to capture exception
Site: erp.grupoatu.com
Form Dict: {}
Traceback (most recent call last):
  File "/home/frappe/frappe-bench/apps/frappe/frappe/utils/sentry.py", line 116, in capture_exception
    set_scope(scope)
  File "/home/frappe/frappe-bench/apps/frappe/frappe/utils/sentry.py", line 70, in set_scope
    path = frappe.request.path
  File "/home/frappe/frappe-bench/env/lib/python3.10/site-packages/werkzeug/local.py", line 311, in __get__
    obj = instance._get_current_object()
  File "/home/frappe/frappe-bench/env/lib/python3.10/site-packages/werkzeug/local.py", line 490, in _get_current_object
    raise RuntimeError(unbound_message) from None
RuntimeError: object is not bound
2024-11-22 10:07:51,677 ERROR frappe Failed to capture exception
Site: erp.grupoatu.com
Form Dict: {}
Traceback (most recent call last):
  File "/home/frappe/frappe-bench/apps/frappe/frappe/utils/sentry.py", line 116, in capture_exception
    set_scope(scope)
  File "/home/frappe/frappe-bench/apps/frappe/frappe/utils/sentry.py", line 70, in set_scope
    path = frappe.request.path
  File "/home/frappe/frappe-bench/env/lib/python3.10/site-packages/werkzeug/local.py", line 311, in __get__
    obj = instance._get_current_object()
  File "/home/frappe/frappe-bench/env/lib/python3.10/site-packages/werkzeug/local.py", line 490, in _get_current_object
    raise RuntimeError(unbound_message) from None
RuntimeError: object is not bound
2024-11-22 10:07:51,691 ERROR frappe Failed to capture exception
Site: erp.grupoatu.com
Form Dict: {}
Traceback (most recent call last):
  File "/home/frappe/frappe-bench/apps/frappe/frappe/utils/sentry.py", line 116, in capture_exception
    set_scope(scope)
  File "/home/frappe/frappe-bench/apps/frappe/frappe/utils/sentry.py", line 70, in set_scope
    path = frappe.request.path
  File "/home/frappe/frappe-bench/env/lib/python3.10/site-packages/werkzeug/local.py", line 311, in __get__
    obj = instance._get_current_object()
  File "/home/frappe/frappe-bench/env/lib/python3.10/site-packages/werkzeug/local.py", line 490, in _get_current_object
    raise RuntimeError(unbound_message) from None
RuntimeError: object is not bound
2024-11-22 10:07:51,705 ERROR frappe Failed to capture exception
Site: erp.grupoatu.com
Form Dict: {}
Traceback (most recent call last):
  File "/home/frappe/frappe-bench/apps/frappe/frappe/utils/sentry.py", line 116, in capture_exception
    set_scope(scope)
  File "/home/frappe/frappe-bench/apps/frappe/frappe/utils/sentry.py", line 70, in set_scope
    path = frappe.request.path
  File "/home/frappe/frappe-bench/env/lib/python3.10/site-packages/werkzeug/local.py", line 311, in __get__
    obj = instance._get_current_object()
  File "/home/frappe/frappe-bench/env/lib/python3.10/site-packages/werkzeug/local.py", line 490, in _get_current_object
    raise RuntimeError(unbound_message) from None
RuntimeError: object is not bound
2024-11-22 10:07:51,719 ERROR frappe Failed to capture exception
Site: erp.grupoatu.com
Form Dict: {}
Traceback (most recent call last):
  File "/home/frappe/frappe-bench/apps/frappe/frappe/utils/sentry.py", line 116, in capture_exception
    set_scope(scope)
  File "/home/frappe/frappe-bench/apps/frappe/frappe/utils/sentry.py", line 70, in set_scope
    path = frappe.request.path
  File "/home/frappe/frappe-bench/env/lib/python3.10/site-packages/werkzeug/local.py", line 311, in __get__
    obj = instance._get_current_object()
  File "/home/frappe/frappe-bench/env/lib/python3.10/site-packages/werkzeug/local.py", line 490, in _get_current_object
    raise RuntimeError(unbound_message) from None
RuntimeError: object is not bound
2024-11-22 10:07:51,733 ERROR frappe Failed to capture exception
Site: erp.grupoatu.com
Form Dict: {}
Traceback (most recent call last):
  File "/home/frappe/frappe-bench/apps/frappe/frappe/utils/sentry.py", line 116, in capture_exception
    set_scope(scope)
  File "/home/frappe/frappe-bench/apps/frappe/frappe/utils/sentry.py", line 70, in set_scope
    path = frappe.request.path
  File "/home/frappe/frappe-bench/env/lib/python3.10/site-packages/werkzeug/local.py", line 311, in __get__
    obj = instance._get_current_object()
  File "/home/frappe/frappe-bench/env/lib/python3.10/site-packages/werkzeug/local.py", line 490, in _get_current_object
    raise RuntimeError(unbound_message) from None
RuntimeError: object is not bound
2024-11-22 10:07:51,746 ERROR frappe Failed to capture exception
Site: erp.grupoatu.com
Form Dict: {}
Traceback (most recent call last):
  File "/home/frappe/frappe-bench/apps/frappe/frappe/utils/sentry.py", line 116, in capture_exception
    set_scope(scope)
  File "/home/frappe/frappe-bench/apps/frappe/frappe/utils/sentry.py", line 70, in set_scope
    path = frappe.request.path
  File "/home/frappe/frappe-bench/env/lib/python3.10/site-packages/werkzeug/local.py", line 311, in __get__
    obj = instance._get_current_object()
  File "/home/frappe/frappe-bench/env/lib/python3.10/site-packages/werkzeug/local.py", line 490, in _get_current_object
    raise RuntimeError(unbound_message) from None
RuntimeError: object is not bound
2024-11-22 10:07:51,758 ERROR frappe Failed to capture exception
Site: erp.grupoatu.com
Form Dict: {}
Traceback (most recent call last):
  File "/home/frappe/frappe-bench/apps/frappe/frappe/utils/sentry.py", line 116, in capture_exception
    set_scope(scope)
  File "/home/frappe/frappe-bench/apps/frappe/frappe/utils/sentry.py", line 70, in set_scope
    path = frappe.request.path
  File "/home/frappe/frappe-bench/env/lib/python3.10/site-packages/werkzeug/local.py", line 311, in __get__
    obj = instance._get_current_object()
  File "/home/frappe/frappe-bench/env/lib/python3.10/site-packages/werkzeug/local.py", line 490, in _get_current_object
    raise RuntimeError(unbound_message) from None
RuntimeError: object is not bound
2024-11-22 10:07:51,771 ERROR frappe Failed to capture exception
Site: erp.grupoatu.com
Form Dict: {}
Traceback (most recent call last):
  File "/home/frappe/frappe-bench/apps/frappe/frappe/utils/sentry.py", line 116, in capture_exception
    set_scope(scope)
  File "/home/frappe/frappe-bench/apps/frappe/frappe/utils/sentry.py", line 70, in set_scope
    path = frappe.request.path
  File "/home/frappe/frappe-bench/env/lib/python3.10/site-packages/werkzeug/local.py", line 311, in __get__
    obj = instance._get_current_object()
  File "/home/frappe/frappe-bench/env/lib/python3.10/site-packages/werkzeug/local.py", line 490, in _get_current_object
    raise RuntimeError(unbound_message) from None
RuntimeError: object is not bound
2024-11-22 10:07:51,784 ERROR frappe Failed to capture exception
Site: erp.grupoatu.com
Form Dict: {}
Traceback (most recent call last):
  File "/home/frappe/frappe-bench/apps/frappe/frappe/utils/sentry.py", line 116, in capture_exception
    set_scope(scope)
  File "/home/frappe/frappe-bench/apps/frappe/frappe/utils/sentry.py", line 70, in set_scope
    path = frappe.request.path
  File "/home/frappe/frappe-bench/env/lib/python3.10/site-packages/werkzeug/local.py", line 311, in __get__
    obj = instance._get_current_object()
  File "/home/frappe/frappe-bench/env/lib/python3.10/site-packages/werkzeug/local.py", line 490, in _get_current_object
    raise RuntimeError(unbound_message) from None
RuntimeError: object is not bound
2024-11-22 10:07:51,797 ERROR frappe Failed to capture exception
Site: erp.grupoatu.com
Form Dict: {}
Traceback (most recent call last):
  File "/home/frappe/frappe-bench/apps/frappe/frappe/utils/sentry.py", line 116, in capture_exception
    set_scope(scope)
  File "/home/frappe/frappe-bench/apps/frappe/frappe/utils/sentry.py", line 70, in set_scope
    path = frappe.request.path
  File "/home/frappe/frappe-bench/env/lib/python3.10/site-packages/werkzeug/local.py", line 311, in __get__
    obj = instance._get_current_object()
  File "/home/frappe/frappe-bench/env/lib/python3.10/site-packages/werkzeug/local.py", line 490, in _get_current_object
    raise RuntimeError(unbound_message) from None
RuntimeError: object is not bound
2024-11-22 10:07:51,810 ERROR frappe Failed to capture exception
Site: erp.grupoatu.com
Form Dict: {}
Traceback (most recent call last):
  File "/home/frappe/frappe-bench/apps/frappe/frappe/utils/sentry.py", line 116, in capture_exception
    set_scope(scope)
  File "/home/frappe/frappe-bench/apps/frappe/frappe/utils/sentry.py", line 70, in set_scope
    path = frappe.request.path
  File "/home/frappe/frappe-bench/env/lib/python3.10/site-packages/werkzeug/local.py", line 311, in __get__
    obj = instance._get_current_object()
  File "/home/frappe/frappe-bench/env/lib/python3.10/site-packages/werkzeug/local.py", line 490, in _get_current_object
    raise RuntimeError(unbound_message) from None
RuntimeError: object is not bound
2024-11-22 10:07:51,823 ERROR frappe Failed to capture exception
Site: erp.grupoatu.com
Form Dict: {}
Traceback (most recent call last):
  File "/home/frappe/frappe-bench/apps/frappe/frappe/utils/sentry.py", line 116, in capture_exception
    set_scope(scope)
  File "/home/frappe/frappe-bench/apps/frappe/frappe/utils/sentry.py", line 70, in set_scope
    path = frappe.request.path
  File "/home/frappe/frappe-bench/env/lib/python3.10/site-packages/werkzeug/local.py", line 311, in __get__
    obj = instance._get_current_object()
  File "/home/frappe/frappe-bench/env/lib/python3.10/site-packages/werkzeug/local.py", line 490, in _get_current_object
    raise RuntimeError(unbound_message) from None
RuntimeError: object is not bound
2024-11-22 10:07:51,837 ERROR frappe Failed to capture exception
Site: erp.grupoatu.com
Form Dict: {}
Traceback (most recent call last):
  File "/home/frappe/frappe-bench/apps/frappe/frappe/utils/sentry.py", line 116, in capture_exception
    set_scope(scope)
  File "/home/frappe/frappe-bench/apps/frappe/frappe/utils/sentry.py", line 70, in set_scope
    path = frappe.request.path
  File "/home/frappe/frappe-bench/env/lib/python3.10/site-packages/werkzeug/local.py", line 311, in __get__
    obj = instance._get_current_object()
  File "/home/frappe/frappe-bench/env/lib/python3.10/site-packages/werkzeug/local.py", line 490, in _get_current_object
    raise RuntimeError(unbound_message) from None
RuntimeError: object is not bound
2024-11-22 10:07:51,850 ERROR frappe Failed to capture exception
Site: erp.grupoatu.com
Form Dict: {}
Traceback (most recent call last):
  File "/home/frappe/frappe-bench/apps/frappe/frappe/utils/sentry.py", line 116, in capture_exception
    set_scope(scope)
  File "/home/frappe/frappe-bench/apps/frappe/frappe/utils/sentry.py", line 70, in set_scope
    path = frappe.request.path
  File "/home/frappe/frappe-bench/env/lib/python3.10/site-packages/werkzeug/local.py", line 311, in __get__
    obj = instance._get_current_object()
  File "/home/frappe/frappe-bench/env/lib/python3.10/site-packages/werkzeug/local.py", line 490, in _get_current_object
    raise RuntimeError(unbound_message) from None
RuntimeError: object is not bound
2024-11-22 10:07:51,864 ERROR frappe Failed to capture exception
Site: erp.grupoatu.com
Form Dict: {}
Traceback (most recent call last):
  File "/home/frappe/frappe-bench/apps/frappe/frappe/utils/sentry.py", line 116, in capture_exception
    set_scope(scope)
  File "/home/frappe/frappe-bench/apps/frappe/frappe/utils/sentry.py", line 70, in set_scope
    path = frappe.request.path
  File "/home/frappe/frappe-bench/env/lib/python3.10/site-packages/werkzeug/local.py", line 311, in __get__
    obj = instance._get_current_object()
  File "/home/frappe/frappe-bench/env/lib/python3.10/site-packages/werkzeug/local.py", line 490, in _get_current_object
    raise RuntimeError(unbound_message) from None
RuntimeError: object is not bound
2024-11-22 10:07:51,877 ERROR frappe Failed to capture exception
Site: erp.grupoatu.com
Form Dict: {}
Traceback (most recent call last):
  File "/home/frappe/frappe-bench/apps/frappe/frappe/utils/sentry.py", line 116, in capture_exception
    set_scope(scope)
  File "/home/frappe/frappe-bench/apps/frappe/frappe/utils/sentry.py", line 70, in set_scope
    path = frappe.request.path
  File "/home/frappe/frappe-bench/env/lib/python3.10/site-packages/werkzeug/local.py", line 311, in __get__
    obj = instance._get_current_object()
  File "/home/frappe/frappe-bench/env/lib/python3.10/site-packages/werkzeug/local.py", line 490, in _get_current_object
    raise RuntimeError(unbound_message) from None
RuntimeError: object is not bound
2024-11-22 10:07:51,891 ERROR frappe Failed to capture exception
Site: erp.grupoatu.com
Form Dict: {}
Traceback (most recent call last):
  File "/home/frappe/frappe-bench/apps/frappe/frappe/utils/sentry.py", line 116, in capture_exception
    set_scope(scope)
  File "/home/frappe/frappe-bench/apps/frappe/frappe/utils/sentry.py", line 70, in set_scope
    path = frappe.request.path
  File "/home/frappe/frappe-bench/env/lib/python3.10/site-packages/werkzeug/local.py", line 311, in __get__
    obj = instance._get_current_object()
  File "/home/frappe/frappe-bench/env/lib/python3.10/site-packages/werkzeug/local.py", line 490, in _get_current_object
    raise RuntimeError(unbound_message) from None
RuntimeError: object is not bound
2024-11-22 10:07:51,904 ERROR frappe Failed to capture exception
Site: erp.grupoatu.com
Form Dict: {}
Traceback (most recent call last):
  File "/home/frappe/frappe-bench/apps/frappe/frappe/utils/sentry.py", line 116, in capture_exception
    set_scope(scope)
  File "/home/frappe/frappe-bench/apps/frappe/frappe/utils/sentry.py", line 70, in set_scope
    path = frappe.request.path
  File "/home/frappe/frappe-bench/env/lib/python3.10/site-packages/werkzeug/local.py", line 311, in __get__
    obj = instance._get_current_object()
  File "/home/frappe/frappe-bench/env/lib/python3.10/site-packages/werkzeug/local.py", line 490, in _get_current_object
    raise RuntimeError(unbound_message) from None
RuntimeError: object is not bound
2024-11-22 10:07:51,918 ERROR frappe Failed to capture exception
Site: erp.grupoatu.com
Form Dict: {}
Traceback (most recent call last):
  File "/home/frappe/frappe-bench/apps/frappe/frappe/utils/sentry.py", line 116, in capture_exception
    set_scope(scope)
  File "/home/frappe/frappe-bench/apps/frappe/frappe/utils/sentry.py", line 70, in set_scope
    path = frappe.request.path
  File "/home/frappe/frappe-bench/env/lib/python3.10/site-packages/werkzeug/local.py", line 311, in __get__
    obj = instance._get_current_object()
  File "/home/frappe/frappe-bench/env/lib/python3.10/site-packages/werkzeug/local.py", line 490, in _get_current_object
    raise RuntimeError(unbound_message) from None
RuntimeError: object is not bound
2024-11-22 10:07:51,932 ERROR frappe Failed to capture exception
Site: erp.grupoatu.com
Form Dict: {}
Traceback (most recent call last):
  File "/home/frappe/frappe-bench/apps/frappe/frappe/utils/sentry.py", line 116, in capture_exception
    set_scope(scope)
  File "/home/frappe/frappe-bench/apps/frappe/frappe/utils/sentry.py", line 70, in set_scope
    path = frappe.request.path
  File "/home/frappe/frappe-bench/env/lib/python3.10/site-packages/werkzeug/local.py", line 311, in __get__
    obj = instance._get_current_object()
  File "/home/frappe/frappe-bench/env/lib/python3.10/site-packages/werkzeug/local.py", line 490, in _get_current_object
    raise RuntimeError(unbound_message) from None
RuntimeError: object is not bound
2024-11-22 10:07:51,947 ERROR frappe Failed to capture exception
Site: erp.grupoatu.com
Form Dict: {}
Traceback (most recent call last):
  File "/home/frappe/frappe-bench/apps/frappe/frappe/utils/sentry.py", line 116, in capture_exception
    set_scope(scope)
  File "/home/frappe/frappe-bench/apps/frappe/frappe/utils/sentry.py", line 70, in set_scope
    path = frappe.request.path
  File "/home/frappe/frappe-bench/env/lib/python3.10/site-packages/werkzeug/local.py", line 311, in __get__
    obj = instance._get_current_object()
  File "/home/frappe/frappe-bench/env/lib/python3.10/site-packages/werkzeug/local.py", line 490, in _get_current_object
    raise RuntimeError(unbound_message) from None
RuntimeError: object is not bound
2024-11-22 10:07:51,960 ERROR frappe Failed to capture exception
Site: erp.grupoatu.com
Form Dict: {}
Traceback (most recent call last):
  File "/home/frappe/frappe-bench/apps/frappe/frappe/utils/sentry.py", line 116, in capture_exception
    set_scope(scope)
  File "/home/frappe/frappe-bench/apps/frappe/frappe/utils/sentry.py", line 70, in set_scope
    path = frappe.request.path
  File "/home/frappe/frappe-bench/env/lib/python3.10/site-packages/werkzeug/local.py", line 311, in __get__
    obj = instance._get_current_object()
  File "/home/frappe/frappe-bench/env/lib/python3.10/site-packages/werkzeug/local.py", line 490, in _get_current_object
    raise RuntimeError(unbound_message) from None
RuntimeError: object is not bound
2024-11-22 10:07:51,972 ERROR frappe Failed to capture exception
Site: erp.grupoatu.com
Form Dict: {}
Traceback (most recent call last):
  File "/home/frappe/frappe-bench/apps/frappe/frappe/utils/sentry.py", line 116, in capture_exception
    set_scope(scope)
  File "/home/frappe/frappe-bench/apps/frappe/frappe/utils/sentry.py", line 70, in set_scope
    path = frappe.request.path
  File "/home/frappe/frappe-bench/env/lib/python3.10/site-packages/werkzeug/local.py", line 311, in __get__
    obj = instance._get_current_object()
  File "/home/frappe/frappe-bench/env/lib/python3.10/site-packages/werkzeug/local.py", line 490, in _get_current_object
    raise RuntimeError(unbound_message) from None
RuntimeError: object is not bound
2024-11-22 10:07:51,984 ERROR frappe Failed to capture exception
Site: erp.grupoatu.com
Form Dict: {}
Traceback (most recent call last):
  File "/home/frappe/frappe-bench/apps/frappe/frappe/utils/sentry.py", line 116, in capture_exception
    set_scope(scope)
  File "/home/frappe/frappe-bench/apps/frappe/frappe/utils/sentry.py", line 70, in set_scope
    path = frappe.request.path
  File "/home/frappe/frappe-bench/env/lib/python3.10/site-packages/werkzeug/local.py", line 311, in __get__
    obj = instance._get_current_object()
  File "/home/frappe/frappe-bench/env/lib/python3.10/site-packages/werkzeug/local.py", line 490, in _get_current_object
    raise RuntimeError(unbound_message) from None
RuntimeError: object is not bound
2024-11-22 10:07:51,997 ERROR frappe Failed to capture exception
Site: erp.grupoatu.com
Form Dict: {}
Traceback (most recent call last):
  File "/home/frappe/frappe-bench/apps/frappe/frappe/utils/sentry.py", line 116, in capture_exception
    set_scope(scope)
  File "/home/frappe/frappe-bench/apps/frappe/frappe/utils/sentry.py", line 70, in set_scope
    path = frappe.request.path
  File "/home/frappe/frappe-bench/env/lib/python3.10/site-packages/werkzeug/local.py", line 311, in __get__
    obj = instance._get_current_object()
  File "/home/frappe/frappe-bench/env/lib/python3.10/site-packages/werkzeug/local.py", line 490, in _get_current_object
    raise RuntimeError(unbound_message) from None
RuntimeError: object is not bound
2024-11-22 10:07:52,011 ERROR frappe Failed to capture exception
Site: erp.grupoatu.com
Form Dict: {}
Traceback (most recent call last):
  File "/home/frappe/frappe-bench/apps/frappe/frappe/utils/sentry.py", line 116, in capture_exception
    set_scope(scope)
  File "/home/frappe/frappe-bench/apps/frappe/frappe/utils/sentry.py", line 70, in set_scope
    path = frappe.request.path
  File "/home/frappe/frappe-bench/env/lib/python3.10/site-packages/werkzeug/local.py", line 311, in __get__
    obj = instance._get_current_object()
  File "/home/frappe/frappe-bench/env/lib/python3.10/site-packages/werkzeug/local.py", line 490, in _get_current_object
    raise RuntimeError(unbound_message) from None
RuntimeError: object is not bound
2024-11-22 10:07:52,026 ERROR frappe Failed to capture exception
Site: erp.grupoatu.com
Form Dict: {}
Traceback (most recent call last):
  File "/home/frappe/frappe-bench/apps/frappe/frappe/utils/sentry.py", line 116, in capture_exception
    set_scope(scope)
  File "/home/frappe/frappe-bench/apps/frappe/frappe/utils/sentry.py", line 70, in set_scope
    path = frappe.request.path
  File "/home/frappe/frappe-bench/env/lib/python3.10/site-packages/werkzeug/local.py", line 311, in __get__
    obj = instance._get_current_object()
  File "/home/frappe/frappe-bench/env/lib/python3.10/site-packages/werkzeug/local.py", line 490, in _get_current_object
    raise RuntimeError(unbound_message) from None
RuntimeError: object is not bound
2024-11-22 10:07:52,042 ERROR frappe Failed to capture exception
Site: erp.grupoatu.com
Form Dict: {}
Traceback (most recent call last):
  File "/home/frappe/frappe-bench/apps/frappe/frappe/utils/sentry.py", line 116, in capture_exception
    set_scope(scope)
  File "/home/frappe/frappe-bench/apps/frappe/frappe/utils/sentry.py", line 70, in set_scope
    path = frappe.request.path
  File "/home/frappe/frappe-bench/env/lib/python3.10/site-packages/werkzeug/local.py", line 311, in __get__
    obj = instance._get_current_object()
  File "/home/frappe/frappe-bench/env/lib/python3.10/site-packages/werkzeug/local.py", line 490, in _get_current_object
    raise RuntimeError(unbound_message) from None
RuntimeError: object is not bound
2024-11-22 10:07:52,055 ERROR frappe Failed to capture exception
Site: erp.grupoatu.com
Form Dict: {}
Traceback (most recent call last):
  File "/home/frappe/frappe-bench/apps/frappe/frappe/utils/sentry.py", line 116, in capture_exception
    set_scope(scope)
  File "/home/frappe/frappe-bench/apps/frappe/frappe/utils/sentry.py", line 70, in set_scope
    path = frappe.request.path
  File "/home/frappe/frappe-bench/env/lib/python3.10/site-packages/werkzeug/local.py", line 311, in __get__
    obj = instance._get_current_object()
  File "/home/frappe/frappe-bench/env/lib/python3.10/site-packages/werkzeug/local.py", line 490, in _get_current_object
    raise RuntimeError(unbound_message) from None
RuntimeError: object is not bound
2024-11-22 10:07:52,069 ERROR frappe Failed to capture exception
Site: erp.grupoatu.com
Form Dict: {}
Traceback (most recent call last):
  File "/home/frappe/frappe-bench/apps/frappe/frappe/utils/sentry.py", line 116, in capture_exception
    set_scope(scope)
  File "/home/frappe/frappe-bench/apps/frappe/frappe/utils/sentry.py", line 70, in set_scope
    path = frappe.request.path
  File "/home/frappe/frappe-bench/env/lib/python3.10/site-packages/werkzeug/local.py", line 311, in __get__
    obj = instance._get_current_object()
  File "/home/frappe/frappe-bench/env/lib/python3.10/site-packages/werkzeug/local.py", line 490, in _get_current_object
    raise RuntimeError(unbound_message) from None
RuntimeError: object is not bound
2024-11-22 10:07:52,087 ERROR frappe Failed to capture exception
Site: erp.grupoatu.com
Form Dict: {}
Traceback (most recent call last):
  File "/home/frappe/frappe-bench/apps/frappe/frappe/utils/sentry.py", line 116, in capture_exception
    set_scope(scope)
  File "/home/frappe/frappe-bench/apps/frappe/frappe/utils/sentry.py", line 70, in set_scope
    path = frappe.request.path
  File "/home/frappe/frappe-bench/env/lib/python3.10/site-packages/werkzeug/local.py", line 311, in __get__
    obj = instance._get_current_object()
  File "/home/frappe/frappe-bench/env/lib/python3.10/site-packages/werkzeug/local.py", line 490, in _get_current_object
    raise RuntimeError(unbound_message) from None
RuntimeError: object is not bound
2024-11-22 10:07:52,104 ERROR frappe Failed to capture exception
Site: erp.grupoatu.com
Form Dict: {}
Traceback (most recent call last):
  File "/home/frappe/frappe-bench/apps/frappe/frappe/utils/sentry.py", line 116, in capture_exception
    set_scope(scope)
  File "/home/frappe/frappe-bench/apps/frappe/frappe/utils/sentry.py", line 70, in set_scope
    path = frappe.request.path
  File "/home/frappe/frappe-bench/env/lib/python3.10/site-packages/werkzeug/local.py", line 311, in __get__
    obj = instance._get_current_object()
  File "/home/frappe/frappe-bench/env/lib/python3.10/site-packages/werkzeug/local.py", line 490, in _get_current_object
    raise RuntimeError(unbound_message) from None
RuntimeError: object is not bound
2024-11-22 10:13:27,916 ERROR frappe Failed to capture exception
Site: erp.grupoatu.com
Form Dict: {}
Traceback (most recent call last):
  File "/home/frappe/frappe-bench/apps/frappe/frappe/utils/sentry.py", line 116, in capture_exception
    set_scope(scope)
  File "/home/frappe/frappe-bench/apps/frappe/frappe/utils/sentry.py", line 70, in set_scope
    path = frappe.request.path
  File "/home/frappe/frappe-bench/env/lib/python3.10/site-packages/werkzeug/local.py", line 311, in __get__
    obj = instance._get_current_object()
  File "/home/frappe/frappe-bench/env/lib/python3.10/site-packages/werkzeug/local.py", line 490, in _get_current_object
    raise RuntimeError(unbound_message) from None
RuntimeError: object is not bound
2024-11-22 10:16:00,496 ERROR frappe Failed to capture exception
Site: erp.grupoatu.com
Form Dict: {}
Traceback (most recent call last):
  File "/home/frappe/frappe-bench/apps/frappe/frappe/utils/sentry.py", line 116, in capture_exception
    set_scope(scope)
  File "/home/frappe/frappe-bench/apps/frappe/frappe/utils/sentry.py", line 70, in set_scope
    path = frappe.request.path
  File "/home/frappe/frappe-bench/env/lib/python3.10/site-packages/werkzeug/local.py", line 311, in __get__
    obj = instance._get_current_object()
  File "/home/frappe/frappe-bench/env/lib/python3.10/site-packages/werkzeug/local.py", line 490, in _get_current_object
    raise RuntimeError(unbound_message) from None
RuntimeError: object is not bound
2024-11-22 10:19:41,092 ERROR frappe Failed to capture exception
Site: erp.grupoatu.com
Form Dict: {}
Traceback (most recent call last):
  File "/home/frappe/frappe-bench/apps/frappe/frappe/utils/sentry.py", line 116, in capture_exception
    set_scope(scope)
  File "/home/frappe/frappe-bench/apps/frappe/frappe/utils/sentry.py", line 70, in set_scope
    path = frappe.request.path
  File "/home/frappe/frappe-bench/env/lib/python3.10/site-packages/werkzeug/local.py", line 311, in __get__
    obj = instance._get_current_object()
  File "/home/frappe/frappe-bench/env/lib/python3.10/site-packages/werkzeug/local.py", line 490, in _get_current_object
    raise RuntimeError(unbound_message) from None
RuntimeError: object is not bound
2024-11-22 10:27:45,408 ERROR frappe Failed to capture exception
Site: erp.grupoatu.com
Form Dict: {}
Traceback (most recent call last):
  File "/home/frappe/frappe-bench/apps/frappe/frappe/utils/sentry.py", line 116, in capture_exception
    set_scope(scope)
  File "/home/frappe/frappe-bench/apps/frappe/frappe/utils/sentry.py", line 70, in set_scope
    path = frappe.request.path
  File "/home/frappe/frappe-bench/env/lib/python3.10/site-packages/werkzeug/local.py", line 311, in __get__
    obj = instance._get_current_object()
  File "/home/frappe/frappe-bench/env/lib/python3.10/site-packages/werkzeug/local.py", line 490, in _get_current_object
    raise RuntimeError(unbound_message) from None
RuntimeError: object is not bound
