2024-11-22 10:07:43,742 ERROR frappe Failed to capture exception
Site: erp.grupoatu.com
Form Dict: {}
Traceback (most recent call last):
  File "/home/frappe/frappe-bench/apps/frappe/frappe/utils/sentry.py", line 116, in capture_exception
    set_scope(scope)
  File "/home/frappe/frappe-bench/apps/frappe/frappe/utils/sentry.py", line 70, in set_scope
    path = frappe.request.path
  File "/home/frappe/frappe-bench/env/lib/python3.10/site-packages/werkzeug/local.py", line 311, in __get__
    obj = instance._get_current_object()
  File "/home/frappe/frappe-bench/env/lib/python3.10/site-packages/werkzeug/local.py", line 490, in _get_current_object
    raise RuntimeError(unbound_message) from None
RuntimeError: object is not bound
2024-11-22 10:07:43,759 ERROR frappe Failed to capture exception
Site: erp.grupoatu.com
Form Dict: {}
Traceback (most recent call last):
  File "/home/frappe/frappe-bench/apps/frappe/frappe/utils/sentry.py", line 116, in capture_exception
    set_scope(scope)
  File "/home/frappe/frappe-bench/apps/frappe/frappe/utils/sentry.py", line 70, in set_scope
    path = frappe.request.path
  File "/home/frappe/frappe-bench/env/lib/python3.10/site-packages/werkzeug/local.py", line 311, in __get__
    obj = instance._get_current_object()
  File "/home/frappe/frappe-bench/env/lib/python3.10/site-packages/werkzeug/local.py", line 490, in _get_current_object
    raise RuntimeError(unbound_message) from None
RuntimeError: object is not bound
2024-11-22 10:07:43,773 ERROR frappe Failed to capture exception
Site: erp.grupoatu.com
Form Dict: {}
Traceback (most recent call last):
  File "/home/frappe/frappe-bench/apps/frappe/frappe/utils/sentry.py", line 116, in capture_exception
    set_scope(scope)
  File "/home/frappe/frappe-bench/apps/frappe/frappe/utils/sentry.py", line 70, in set_scope
    path = frappe.request.path
  File "/home/frappe/frappe-bench/env/lib/python3.10/site-packages/werkzeug/local.py", line 311, in __get__
    obj = instance._get_current_object()
  File "/home/frappe/frappe-bench/env/lib/python3.10/site-packages/werkzeug/local.py", line 490, in _get_current_object
    raise RuntimeError(unbound_message) from None
RuntimeError: object is not bound
2024-11-22 10:07:43,789 ERROR frappe Failed to capture exception
Site: erp.grupoatu.com
Form Dict: {}
Traceback (most recent call last):
  File "/home/frappe/frappe-bench/apps/frappe/frappe/utils/sentry.py", line 116, in capture_exception
    set_scope(scope)
  File "/home/frappe/frappe-bench/apps/frappe/frappe/utils/sentry.py", line 70, in set_scope
    path = frappe.request.path
  File "/home/frappe/frappe-bench/env/lib/python3.10/site-packages/werkzeug/local.py", line 311, in __get__
    obj = instance._get_current_object()
  File "/home/frappe/frappe-bench/env/lib/python3.10/site-packages/werkzeug/local.py", line 490, in _get_current_object
    raise RuntimeError(unbound_message) from None
RuntimeError: object is not bound
2024-11-22 10:07:43,803 ERROR frappe Failed to capture exception
Site: erp.grupoatu.com
Form Dict: {}
Traceback (most recent call last):
  File "/home/frappe/frappe-bench/apps/frappe/frappe/utils/sentry.py", line 116, in capture_exception
    set_scope(scope)
  File "/home/frappe/frappe-bench/apps/frappe/frappe/utils/sentry.py", line 70, in set_scope
    path = frappe.request.path
  File "/home/frappe/frappe-bench/env/lib/python3.10/site-packages/werkzeug/local.py", line 311, in __get__
    obj = instance._get_current_object()
  File "/home/frappe/frappe-bench/env/lib/python3.10/site-packages/werkzeug/local.py", line 490, in _get_current_object
    raise RuntimeError(unbound_message) from None
RuntimeError: object is not bound
2024-11-22 10:07:43,816 ERROR frappe Failed to capture exception
Site: erp.grupoatu.com
Form Dict: {}
Traceback (most recent call last):
  File "/home/frappe/frappe-bench/apps/frappe/frappe/utils/sentry.py", line 116, in capture_exception
    set_scope(scope)
  File "/home/frappe/frappe-bench/apps/frappe/frappe/utils/sentry.py", line 70, in set_scope
    path = frappe.request.path
  File "/home/frappe/frappe-bench/env/lib/python3.10/site-packages/werkzeug/local.py", line 311, in __get__
    obj = instance._get_current_object()
  File "/home/frappe/frappe-bench/env/lib/python3.10/site-packages/werkzeug/local.py", line 490, in _get_current_object
    raise RuntimeError(unbound_message) from None
RuntimeError: object is not bound
2024-11-22 10:07:43,831 ERROR frappe Failed to capture exception
Site: erp.grupoatu.com
Form Dict: {}
Traceback (most recent call last):
  File "/home/frappe/frappe-bench/apps/frappe/frappe/utils/sentry.py", line 116, in capture_exception
    set_scope(scope)
  File "/home/frappe/frappe-bench/apps/frappe/frappe/utils/sentry.py", line 70, in set_scope
    path = frappe.request.path
  File "/home/frappe/frappe-bench/env/lib/python3.10/site-packages/werkzeug/local.py", line 311, in __get__
    obj = instance._get_current_object()
  File "/home/frappe/frappe-bench/env/lib/python3.10/site-packages/werkzeug/local.py", line 490, in _get_current_object
    raise RuntimeError(unbound_message) from None
RuntimeError: object is not bound
2024-11-22 10:07:43,844 ERROR frappe Failed to capture exception
Site: erp.grupoatu.com
Form Dict: {}
Traceback (most recent call last):
  File "/home/frappe/frappe-bench/apps/frappe/frappe/utils/sentry.py", line 116, in capture_exception
    set_scope(scope)
  File "/home/frappe/frappe-bench/apps/frappe/frappe/utils/sentry.py", line 70, in set_scope
    path = frappe.request.path
  File "/home/frappe/frappe-bench/env/lib/python3.10/site-packages/werkzeug/local.py", line 311, in __get__
    obj = instance._get_current_object()
  File "/home/frappe/frappe-bench/env/lib/python3.10/site-packages/werkzeug/local.py", line 490, in _get_current_object
    raise RuntimeError(unbound_message) from None
RuntimeError: object is not bound
2024-11-22 10:07:43,856 ERROR frappe Failed to capture exception
Site: erp.grupoatu.com
Form Dict: {}
Traceback (most recent call last):
  File "/home/frappe/frappe-bench/apps/frappe/frappe/utils/sentry.py", line 116, in capture_exception
    set_scope(scope)
  File "/home/frappe/frappe-bench/apps/frappe/frappe/utils/sentry.py", line 70, in set_scope
    path = frappe.request.path
  File "/home/frappe/frappe-bench/env/lib/python3.10/site-packages/werkzeug/local.py", line 311, in __get__
    obj = instance._get_current_object()
  File "/home/frappe/frappe-bench/env/lib/python3.10/site-packages/werkzeug/local.py", line 490, in _get_current_object
    raise RuntimeError(unbound_message) from None
RuntimeError: object is not bound
2024-11-22 10:07:43,869 ERROR frappe Failed to capture exception
Site: erp.grupoatu.com
Form Dict: {}
Traceback (most recent call last):
  File "/home/frappe/frappe-bench/apps/frappe/frappe/utils/sentry.py", line 116, in capture_exception
    set_scope(scope)
  File "/home/frappe/frappe-bench/apps/frappe/frappe/utils/sentry.py", line 70, in set_scope
    path = frappe.request.path
  File "/home/frappe/frappe-bench/env/lib/python3.10/site-packages/werkzeug/local.py", line 311, in __get__
    obj = instance._get_current_object()
  File "/home/frappe/frappe-bench/env/lib/python3.10/site-packages/werkzeug/local.py", line 490, in _get_current_object
    raise RuntimeError(unbound_message) from None
RuntimeError: object is not bound
2024-11-22 10:07:43,886 ERROR frappe Failed to capture exception
Site: erp.grupoatu.com
Form Dict: {}
Traceback (most recent call last):
  File "/home/frappe/frappe-bench/apps/frappe/frappe/utils/sentry.py", line 116, in capture_exception
    set_scope(scope)
  File "/home/frappe/frappe-bench/apps/frappe/frappe/utils/sentry.py", line 70, in set_scope
    path = frappe.request.path
  File "/home/frappe/frappe-bench/env/lib/python3.10/site-packages/werkzeug/local.py", line 311, in __get__
    obj = instance._get_current_object()
  File "/home/frappe/frappe-bench/env/lib/python3.10/site-packages/werkzeug/local.py", line 490, in _get_current_object
    raise RuntimeError(unbound_message) from None
RuntimeError: object is not bound
2024-11-22 10:07:43,903 ERROR frappe Failed to capture exception
Site: erp.grupoatu.com
Form Dict: {}
Traceback (most recent call last):
  File "/home/frappe/frappe-bench/apps/frappe/frappe/utils/sentry.py", line 116, in capture_exception
    set_scope(scope)
  File "/home/frappe/frappe-bench/apps/frappe/frappe/utils/sentry.py", line 70, in set_scope
    path = frappe.request.path
  File "/home/frappe/frappe-bench/env/lib/python3.10/site-packages/werkzeug/local.py", line 311, in __get__
    obj = instance._get_current_object()
  File "/home/frappe/frappe-bench/env/lib/python3.10/site-packages/werkzeug/local.py", line 490, in _get_current_object
    raise RuntimeError(unbound_message) from None
RuntimeError: object is not bound
2024-11-22 10:07:43,916 ERROR frappe Failed to capture exception
Site: erp.grupoatu.com
Form Dict: {}
Traceback (most recent call last):
  File "/home/frappe/frappe-bench/apps/frappe/frappe/utils/sentry.py", line 116, in capture_exception
    set_scope(scope)
  File "/home/frappe/frappe-bench/apps/frappe/frappe/utils/sentry.py", line 70, in set_scope
    path = frappe.request.path
  File "/home/frappe/frappe-bench/env/lib/python3.10/site-packages/werkzeug/local.py", line 311, in __get__
    obj = instance._get_current_object()
  File "/home/frappe/frappe-bench/env/lib/python3.10/site-packages/werkzeug/local.py", line 490, in _get_current_object
    raise RuntimeError(unbound_message) from None
RuntimeError: object is not bound
2024-11-22 10:07:43,929 ERROR frappe Failed to capture exception
Site: erp.grupoatu.com
Form Dict: {}
Traceback (most recent call last):
  File "/home/frappe/frappe-bench/apps/frappe/frappe/utils/sentry.py", line 116, in capture_exception
    set_scope(scope)
  File "/home/frappe/frappe-bench/apps/frappe/frappe/utils/sentry.py", line 70, in set_scope
    path = frappe.request.path
  File "/home/frappe/frappe-bench/env/lib/python3.10/site-packages/werkzeug/local.py", line 311, in __get__
    obj = instance._get_current_object()
  File "/home/frappe/frappe-bench/env/lib/python3.10/site-packages/werkzeug/local.py", line 490, in _get_current_object
    raise RuntimeError(unbound_message) from None
RuntimeError: object is not bound
2024-11-22 10:07:43,942 ERROR frappe Failed to capture exception
Site: erp.grupoatu.com
Form Dict: {}
Traceback (most recent call last):
  File "/home/frappe/frappe-bench/apps/frappe/frappe/utils/sentry.py", line 116, in capture_exception
    set_scope(scope)
  File "/home/frappe/frappe-bench/apps/frappe/frappe/utils/sentry.py", line 70, in set_scope
    path = frappe.request.path
  File "/home/frappe/frappe-bench/env/lib/python3.10/site-packages/werkzeug/local.py", line 311, in __get__
    obj = instance._get_current_object()
  File "/home/frappe/frappe-bench/env/lib/python3.10/site-packages/werkzeug/local.py", line 490, in _get_current_object
    raise RuntimeError(unbound_message) from None
RuntimeError: object is not bound
2024-11-22 10:07:43,955 ERROR frappe Failed to capture exception
Site: erp.grupoatu.com
Form Dict: {}
Traceback (most recent call last):
  File "/home/frappe/frappe-bench/apps/frappe/frappe/utils/sentry.py", line 116, in capture_exception
    set_scope(scope)
  File "/home/frappe/frappe-bench/apps/frappe/frappe/utils/sentry.py", line 70, in set_scope
    path = frappe.request.path
  File "/home/frappe/frappe-bench/env/lib/python3.10/site-packages/werkzeug/local.py", line 311, in __get__
    obj = instance._get_current_object()
  File "/home/frappe/frappe-bench/env/lib/python3.10/site-packages/werkzeug/local.py", line 490, in _get_current_object
    raise RuntimeError(unbound_message) from None
RuntimeError: object is not bound
2024-11-22 10:07:43,967 ERROR frappe Failed to capture exception
Site: erp.grupoatu.com
Form Dict: {}
Traceback (most recent call last):
  File "/home/frappe/frappe-bench/apps/frappe/frappe/utils/sentry.py", line 116, in capture_exception
    set_scope(scope)
  File "/home/frappe/frappe-bench/apps/frappe/frappe/utils/sentry.py", line 70, in set_scope
    path = frappe.request.path
  File "/home/frappe/frappe-bench/env/lib/python3.10/site-packages/werkzeug/local.py", line 311, in __get__
    obj = instance._get_current_object()
  File "/home/frappe/frappe-bench/env/lib/python3.10/site-packages/werkzeug/local.py", line 490, in _get_current_object
    raise RuntimeError(unbound_message) from None
RuntimeError: object is not bound
2024-11-22 10:07:43,980 ERROR frappe Failed to capture exception
Site: erp.grupoatu.com
Form Dict: {}
Traceback (most recent call last):
  File "/home/frappe/frappe-bench/apps/frappe/frappe/utils/sentry.py", line 116, in capture_exception
    set_scope(scope)
  File "/home/frappe/frappe-bench/apps/frappe/frappe/utils/sentry.py", line 70, in set_scope
    path = frappe.request.path
  File "/home/frappe/frappe-bench/env/lib/python3.10/site-packages/werkzeug/local.py", line 311, in __get__
    obj = instance._get_current_object()
  File "/home/frappe/frappe-bench/env/lib/python3.10/site-packages/werkzeug/local.py", line 490, in _get_current_object
    raise RuntimeError(unbound_message) from None
RuntimeError: object is not bound
2024-11-22 10:07:43,994 ERROR frappe Failed to capture exception
Site: erp.grupoatu.com
Form Dict: {}
Traceback (most recent call last):
  File "/home/frappe/frappe-bench/apps/frappe/frappe/utils/sentry.py", line 116, in capture_exception
    set_scope(scope)
  File "/home/frappe/frappe-bench/apps/frappe/frappe/utils/sentry.py", line 70, in set_scope
    path = frappe.request.path
  File "/home/frappe/frappe-bench/env/lib/python3.10/site-packages/werkzeug/local.py", line 311, in __get__
    obj = instance._get_current_object()
  File "/home/frappe/frappe-bench/env/lib/python3.10/site-packages/werkzeug/local.py", line 490, in _get_current_object
    raise RuntimeError(unbound_message) from None
RuntimeError: object is not bound
2024-11-22 10:07:44,008 ERROR frappe Failed to capture exception
Site: erp.grupoatu.com
Form Dict: {}
Traceback (most recent call last):
  File "/home/frappe/frappe-bench/apps/frappe/frappe/utils/sentry.py", line 116, in capture_exception
    set_scope(scope)
  File "/home/frappe/frappe-bench/apps/frappe/frappe/utils/sentry.py", line 70, in set_scope
    path = frappe.request.path
  File "/home/frappe/frappe-bench/env/lib/python3.10/site-packages/werkzeug/local.py", line 311, in __get__
    obj = instance._get_current_object()
  File "/home/frappe/frappe-bench/env/lib/python3.10/site-packages/werkzeug/local.py", line 490, in _get_current_object
    raise RuntimeError(unbound_message) from None
RuntimeError: object is not bound
2024-11-22 10:07:44,022 ERROR frappe Failed to capture exception
Site: erp.grupoatu.com
Form Dict: {}
Traceback (most recent call last):
  File "/home/frappe/frappe-bench/apps/frappe/frappe/utils/sentry.py", line 116, in capture_exception
    set_scope(scope)
  File "/home/frappe/frappe-bench/apps/frappe/frappe/utils/sentry.py", line 70, in set_scope
    path = frappe.request.path
  File "/home/frappe/frappe-bench/env/lib/python3.10/site-packages/werkzeug/local.py", line 311, in __get__
    obj = instance._get_current_object()
  File "/home/frappe/frappe-bench/env/lib/python3.10/site-packages/werkzeug/local.py", line 490, in _get_current_object
    raise RuntimeError(unbound_message) from None
RuntimeError: object is not bound
2024-11-22 10:07:44,037 ERROR frappe Failed to capture exception
Site: erp.grupoatu.com
Form Dict: {}
Traceback (most recent call last):
  File "/home/frappe/frappe-bench/apps/frappe/frappe/utils/sentry.py", line 116, in capture_exception
    set_scope(scope)
  File "/home/frappe/frappe-bench/apps/frappe/frappe/utils/sentry.py", line 70, in set_scope
    path = frappe.request.path
  File "/home/frappe/frappe-bench/env/lib/python3.10/site-packages/werkzeug/local.py", line 311, in __get__
    obj = instance._get_current_object()
  File "/home/frappe/frappe-bench/env/lib/python3.10/site-packages/werkzeug/local.py", line 490, in _get_current_object
    raise RuntimeError(unbound_message) from None
RuntimeError: object is not bound
2024-11-22 10:07:44,050 ERROR frappe Failed to capture exception
Site: erp.grupoatu.com
Form Dict: {}
Traceback (most recent call last):
  File "/home/frappe/frappe-bench/apps/frappe/frappe/utils/sentry.py", line 116, in capture_exception
    set_scope(scope)
  File "/home/frappe/frappe-bench/apps/frappe/frappe/utils/sentry.py", line 70, in set_scope
    path = frappe.request.path
  File "/home/frappe/frappe-bench/env/lib/python3.10/site-packages/werkzeug/local.py", line 311, in __get__
    obj = instance._get_current_object()
  File "/home/frappe/frappe-bench/env/lib/python3.10/site-packages/werkzeug/local.py", line 490, in _get_current_object
    raise RuntimeError(unbound_message) from None
RuntimeError: object is not bound
2024-11-22 10:07:44,071 ERROR frappe Failed to capture exception
Site: erp.grupoatu.com
Form Dict: {}
Traceback (most recent call last):
  File "/home/frappe/frappe-bench/apps/frappe/frappe/utils/sentry.py", line 116, in capture_exception
    set_scope(scope)
  File "/home/frappe/frappe-bench/apps/frappe/frappe/utils/sentry.py", line 70, in set_scope
    path = frappe.request.path
  File "/home/frappe/frappe-bench/env/lib/python3.10/site-packages/werkzeug/local.py", line 311, in __get__
    obj = instance._get_current_object()
  File "/home/frappe/frappe-bench/env/lib/python3.10/site-packages/werkzeug/local.py", line 490, in _get_current_object
    raise RuntimeError(unbound_message) from None
RuntimeError: object is not bound
2024-11-22 10:07:44,091 ERROR frappe Failed to capture exception
Site: erp.grupoatu.com
Form Dict: {}
Traceback (most recent call last):
  File "/home/frappe/frappe-bench/apps/frappe/frappe/utils/sentry.py", line 116, in capture_exception
    set_scope(scope)
  File "/home/frappe/frappe-bench/apps/frappe/frappe/utils/sentry.py", line 70, in set_scope
    path = frappe.request.path
  File "/home/frappe/frappe-bench/env/lib/python3.10/site-packages/werkzeug/local.py", line 311, in __get__
    obj = instance._get_current_object()
  File "/home/frappe/frappe-bench/env/lib/python3.10/site-packages/werkzeug/local.py", line 490, in _get_current_object
    raise RuntimeError(unbound_message) from None
RuntimeError: object is not bound
2024-11-22 10:07:44,110 ERROR frappe Failed to capture exception
Site: erp.grupoatu.com
Form Dict: {}
Traceback (most recent call last):
  File "/home/frappe/frappe-bench/apps/frappe/frappe/utils/sentry.py", line 116, in capture_exception
    set_scope(scope)
  File "/home/frappe/frappe-bench/apps/frappe/frappe/utils/sentry.py", line 70, in set_scope
    path = frappe.request.path
  File "/home/frappe/frappe-bench/env/lib/python3.10/site-packages/werkzeug/local.py", line 311, in __get__
    obj = instance._get_current_object()
  File "/home/frappe/frappe-bench/env/lib/python3.10/site-packages/werkzeug/local.py", line 490, in _get_current_object
    raise RuntimeError(unbound_message) from None
RuntimeError: object is not bound
2024-11-22 10:07:44,129 ERROR frappe Failed to capture exception
Site: erp.grupoatu.com
Form Dict: {}
Traceback (most recent call last):
  File "/home/frappe/frappe-bench/apps/frappe/frappe/utils/sentry.py", line 116, in capture_exception
    set_scope(scope)
  File "/home/frappe/frappe-bench/apps/frappe/frappe/utils/sentry.py", line 70, in set_scope
    path = frappe.request.path
  File "/home/frappe/frappe-bench/env/lib/python3.10/site-packages/werkzeug/local.py", line 311, in __get__
    obj = instance._get_current_object()
  File "/home/frappe/frappe-bench/env/lib/python3.10/site-packages/werkzeug/local.py", line 490, in _get_current_object
    raise RuntimeError(unbound_message) from None
RuntimeError: object is not bound
2024-11-22 10:07:44,144 ERROR frappe Failed to capture exception
Site: erp.grupoatu.com
Form Dict: {}
Traceback (most recent call last):
  File "/home/frappe/frappe-bench/apps/frappe/frappe/utils/sentry.py", line 116, in capture_exception
    set_scope(scope)
  File "/home/frappe/frappe-bench/apps/frappe/frappe/utils/sentry.py", line 70, in set_scope
    path = frappe.request.path
  File "/home/frappe/frappe-bench/env/lib/python3.10/site-packages/werkzeug/local.py", line 311, in __get__
    obj = instance._get_current_object()
  File "/home/frappe/frappe-bench/env/lib/python3.10/site-packages/werkzeug/local.py", line 490, in _get_current_object
    raise RuntimeError(unbound_message) from None
RuntimeError: object is not bound
2024-11-22 10:07:44,156 ERROR frappe Failed to capture exception
Site: erp.grupoatu.com
Form Dict: {}
Traceback (most recent call last):
  File "/home/frappe/frappe-bench/apps/frappe/frappe/utils/sentry.py", line 116, in capture_exception
    set_scope(scope)
  File "/home/frappe/frappe-bench/apps/frappe/frappe/utils/sentry.py", line 70, in set_scope
    path = frappe.request.path
  File "/home/frappe/frappe-bench/env/lib/python3.10/site-packages/werkzeug/local.py", line 311, in __get__
    obj = instance._get_current_object()
  File "/home/frappe/frappe-bench/env/lib/python3.10/site-packages/werkzeug/local.py", line 490, in _get_current_object
    raise RuntimeError(unbound_message) from None
RuntimeError: object is not bound
2024-11-22 10:07:44,169 ERROR frappe Failed to capture exception
Site: erp.grupoatu.com
Form Dict: {}
Traceback (most recent call last):
  File "/home/frappe/frappe-bench/apps/frappe/frappe/utils/sentry.py", line 116, in capture_exception
    set_scope(scope)
  File "/home/frappe/frappe-bench/apps/frappe/frappe/utils/sentry.py", line 70, in set_scope
    path = frappe.request.path
  File "/home/frappe/frappe-bench/env/lib/python3.10/site-packages/werkzeug/local.py", line 311, in __get__
    obj = instance._get_current_object()
  File "/home/frappe/frappe-bench/env/lib/python3.10/site-packages/werkzeug/local.py", line 490, in _get_current_object
    raise RuntimeError(unbound_message) from None
RuntimeError: object is not bound
2024-11-22 10:07:44,182 ERROR frappe Failed to capture exception
Site: erp.grupoatu.com
Form Dict: {}
Traceback (most recent call last):
  File "/home/frappe/frappe-bench/apps/frappe/frappe/utils/sentry.py", line 116, in capture_exception
    set_scope(scope)
  File "/home/frappe/frappe-bench/apps/frappe/frappe/utils/sentry.py", line 70, in set_scope
    path = frappe.request.path
  File "/home/frappe/frappe-bench/env/lib/python3.10/site-packages/werkzeug/local.py", line 311, in __get__
    obj = instance._get_current_object()
  File "/home/frappe/frappe-bench/env/lib/python3.10/site-packages/werkzeug/local.py", line 490, in _get_current_object
    raise RuntimeError(unbound_message) from None
RuntimeError: object is not bound
2024-11-22 10:07:44,194 ERROR frappe Failed to capture exception
Site: erp.grupoatu.com
Form Dict: {}
Traceback (most recent call last):
  File "/home/frappe/frappe-bench/apps/frappe/frappe/utils/sentry.py", line 116, in capture_exception
    set_scope(scope)
  File "/home/frappe/frappe-bench/apps/frappe/frappe/utils/sentry.py", line 70, in set_scope
    path = frappe.request.path
  File "/home/frappe/frappe-bench/env/lib/python3.10/site-packages/werkzeug/local.py", line 311, in __get__
    obj = instance._get_current_object()
  File "/home/frappe/frappe-bench/env/lib/python3.10/site-packages/werkzeug/local.py", line 490, in _get_current_object
    raise RuntimeError(unbound_message) from None
RuntimeError: object is not bound
2024-11-22 10:07:44,207 ERROR frappe Failed to capture exception
Site: erp.grupoatu.com
Form Dict: {}
Traceback (most recent call last):
  File "/home/frappe/frappe-bench/apps/frappe/frappe/utils/sentry.py", line 116, in capture_exception
    set_scope(scope)
  File "/home/frappe/frappe-bench/apps/frappe/frappe/utils/sentry.py", line 70, in set_scope
    path = frappe.request.path
  File "/home/frappe/frappe-bench/env/lib/python3.10/site-packages/werkzeug/local.py", line 311, in __get__
    obj = instance._get_current_object()
  File "/home/frappe/frappe-bench/env/lib/python3.10/site-packages/werkzeug/local.py", line 490, in _get_current_object
    raise RuntimeError(unbound_message) from None
RuntimeError: object is not bound
2024-11-22 10:07:44,220 ERROR frappe Failed to capture exception
Site: erp.grupoatu.com
Form Dict: {}
Traceback (most recent call last):
  File "/home/frappe/frappe-bench/apps/frappe/frappe/utils/sentry.py", line 116, in capture_exception
    set_scope(scope)
  File "/home/frappe/frappe-bench/apps/frappe/frappe/utils/sentry.py", line 70, in set_scope
    path = frappe.request.path
  File "/home/frappe/frappe-bench/env/lib/python3.10/site-packages/werkzeug/local.py", line 311, in __get__
    obj = instance._get_current_object()
  File "/home/frappe/frappe-bench/env/lib/python3.10/site-packages/werkzeug/local.py", line 490, in _get_current_object
    raise RuntimeError(unbound_message) from None
RuntimeError: object is not bound
2024-11-22 10:07:44,233 ERROR frappe Failed to capture exception
Site: erp.grupoatu.com
Form Dict: {}
Traceback (most recent call last):
  File "/home/frappe/frappe-bench/apps/frappe/frappe/utils/sentry.py", line 116, in capture_exception
    set_scope(scope)
  File "/home/frappe/frappe-bench/apps/frappe/frappe/utils/sentry.py", line 70, in set_scope
    path = frappe.request.path
  File "/home/frappe/frappe-bench/env/lib/python3.10/site-packages/werkzeug/local.py", line 311, in __get__
    obj = instance._get_current_object()
  File "/home/frappe/frappe-bench/env/lib/python3.10/site-packages/werkzeug/local.py", line 490, in _get_current_object
    raise RuntimeError(unbound_message) from None
RuntimeError: object is not bound
2024-11-22 10:07:44,247 ERROR frappe Failed to capture exception
Site: erp.grupoatu.com
Form Dict: {}
Traceback (most recent call last):
  File "/home/frappe/frappe-bench/apps/frappe/frappe/utils/sentry.py", line 116, in capture_exception
    set_scope(scope)
  File "/home/frappe/frappe-bench/apps/frappe/frappe/utils/sentry.py", line 70, in set_scope
    path = frappe.request.path
  File "/home/frappe/frappe-bench/env/lib/python3.10/site-packages/werkzeug/local.py", line 311, in __get__
    obj = instance._get_current_object()
  File "/home/frappe/frappe-bench/env/lib/python3.10/site-packages/werkzeug/local.py", line 490, in _get_current_object
    raise RuntimeError(unbound_message) from None
RuntimeError: object is not bound
2024-11-22 10:07:44,261 ERROR frappe Failed to capture exception
Site: erp.grupoatu.com
Form Dict: {}
Traceback (most recent call last):
  File "/home/frappe/frappe-bench/apps/frappe/frappe/utils/sentry.py", line 116, in capture_exception
    set_scope(scope)
  File "/home/frappe/frappe-bench/apps/frappe/frappe/utils/sentry.py", line 70, in set_scope
    path = frappe.request.path
  File "/home/frappe/frappe-bench/env/lib/python3.10/site-packages/werkzeug/local.py", line 311, in __get__
    obj = instance._get_current_object()
  File "/home/frappe/frappe-bench/env/lib/python3.10/site-packages/werkzeug/local.py", line 490, in _get_current_object
    raise RuntimeError(unbound_message) from None
RuntimeError: object is not bound
2024-11-22 10:07:44,275 ERROR frappe Failed to capture exception
Site: erp.grupoatu.com
Form Dict: {}
Traceback (most recent call last):
  File "/home/frappe/frappe-bench/apps/frappe/frappe/utils/sentry.py", line 116, in capture_exception
    set_scope(scope)
  File "/home/frappe/frappe-bench/apps/frappe/frappe/utils/sentry.py", line 70, in set_scope
    path = frappe.request.path
  File "/home/frappe/frappe-bench/env/lib/python3.10/site-packages/werkzeug/local.py", line 311, in __get__
    obj = instance._get_current_object()
  File "/home/frappe/frappe-bench/env/lib/python3.10/site-packages/werkzeug/local.py", line 490, in _get_current_object
    raise RuntimeError(unbound_message) from None
RuntimeError: object is not bound
2024-11-22 10:07:44,288 ERROR frappe Failed to capture exception
Site: erp.grupoatu.com
Form Dict: {}
Traceback (most recent call last):
  File "/home/frappe/frappe-bench/apps/frappe/frappe/utils/sentry.py", line 116, in capture_exception
    set_scope(scope)
  File "/home/frappe/frappe-bench/apps/frappe/frappe/utils/sentry.py", line 70, in set_scope
    path = frappe.request.path
  File "/home/frappe/frappe-bench/env/lib/python3.10/site-packages/werkzeug/local.py", line 311, in __get__
    obj = instance._get_current_object()
  File "/home/frappe/frappe-bench/env/lib/python3.10/site-packages/werkzeug/local.py", line 490, in _get_current_object
    raise RuntimeError(unbound_message) from None
RuntimeError: object is not bound
2024-11-22 10:07:44,306 ERROR frappe Failed to capture exception
Site: erp.grupoatu.com
Form Dict: {}
Traceback (most recent call last):
  File "/home/frappe/frappe-bench/apps/frappe/frappe/utils/sentry.py", line 116, in capture_exception
    set_scope(scope)
  File "/home/frappe/frappe-bench/apps/frappe/frappe/utils/sentry.py", line 70, in set_scope
    path = frappe.request.path
  File "/home/frappe/frappe-bench/env/lib/python3.10/site-packages/werkzeug/local.py", line 311, in __get__
    obj = instance._get_current_object()
  File "/home/frappe/frappe-bench/env/lib/python3.10/site-packages/werkzeug/local.py", line 490, in _get_current_object
    raise RuntimeError(unbound_message) from None
RuntimeError: object is not bound
2024-11-22 10:07:44,327 ERROR frappe Failed to capture exception
Site: erp.grupoatu.com
Form Dict: {}
Traceback (most recent call last):
  File "/home/frappe/frappe-bench/apps/frappe/frappe/utils/sentry.py", line 116, in capture_exception
    set_scope(scope)
  File "/home/frappe/frappe-bench/apps/frappe/frappe/utils/sentry.py", line 70, in set_scope
    path = frappe.request.path
  File "/home/frappe/frappe-bench/env/lib/python3.10/site-packages/werkzeug/local.py", line 311, in __get__
    obj = instance._get_current_object()
  File "/home/frappe/frappe-bench/env/lib/python3.10/site-packages/werkzeug/local.py", line 490, in _get_current_object
    raise RuntimeError(unbound_message) from None
RuntimeError: object is not bound
2024-11-22 10:07:44,348 ERROR frappe Failed to capture exception
Site: erp.grupoatu.com
Form Dict: {}
Traceback (most recent call last):
  File "/home/frappe/frappe-bench/apps/frappe/frappe/utils/sentry.py", line 116, in capture_exception
    set_scope(scope)
  File "/home/frappe/frappe-bench/apps/frappe/frappe/utils/sentry.py", line 70, in set_scope
    path = frappe.request.path
  File "/home/frappe/frappe-bench/env/lib/python3.10/site-packages/werkzeug/local.py", line 311, in __get__
    obj = instance._get_current_object()
  File "/home/frappe/frappe-bench/env/lib/python3.10/site-packages/werkzeug/local.py", line 490, in _get_current_object
    raise RuntimeError(unbound_message) from None
RuntimeError: object is not bound
2024-11-22 10:07:44,369 ERROR frappe Failed to capture exception
Site: erp.grupoatu.com
Form Dict: {}
Traceback (most recent call last):
  File "/home/frappe/frappe-bench/apps/frappe/frappe/utils/sentry.py", line 116, in capture_exception
    set_scope(scope)
  File "/home/frappe/frappe-bench/apps/frappe/frappe/utils/sentry.py", line 70, in set_scope
    path = frappe.request.path
  File "/home/frappe/frappe-bench/env/lib/python3.10/site-packages/werkzeug/local.py", line 311, in __get__
    obj = instance._get_current_object()
  File "/home/frappe/frappe-bench/env/lib/python3.10/site-packages/werkzeug/local.py", line 490, in _get_current_object
    raise RuntimeError(unbound_message) from None
RuntimeError: object is not bound
2024-11-22 10:07:44,390 ERROR frappe Failed to capture exception
Site: erp.grupoatu.com
Form Dict: {}
Traceback (most recent call last):
  File "/home/frappe/frappe-bench/apps/frappe/frappe/utils/sentry.py", line 116, in capture_exception
    set_scope(scope)
  File "/home/frappe/frappe-bench/apps/frappe/frappe/utils/sentry.py", line 70, in set_scope
    path = frappe.request.path
  File "/home/frappe/frappe-bench/env/lib/python3.10/site-packages/werkzeug/local.py", line 311, in __get__
    obj = instance._get_current_object()
  File "/home/frappe/frappe-bench/env/lib/python3.10/site-packages/werkzeug/local.py", line 490, in _get_current_object
    raise RuntimeError(unbound_message) from None
RuntimeError: object is not bound
2024-11-22 10:07:44,410 ERROR frappe Failed to capture exception
Site: erp.grupoatu.com
Form Dict: {}
Traceback (most recent call last):
  File "/home/frappe/frappe-bench/apps/frappe/frappe/utils/sentry.py", line 116, in capture_exception
    set_scope(scope)
  File "/home/frappe/frappe-bench/apps/frappe/frappe/utils/sentry.py", line 70, in set_scope
    path = frappe.request.path
  File "/home/frappe/frappe-bench/env/lib/python3.10/site-packages/werkzeug/local.py", line 311, in __get__
    obj = instance._get_current_object()
  File "/home/frappe/frappe-bench/env/lib/python3.10/site-packages/werkzeug/local.py", line 490, in _get_current_object
    raise RuntimeError(unbound_message) from None
RuntimeError: object is not bound
2024-11-22 10:07:44,431 ERROR frappe Failed to capture exception
Site: erp.grupoatu.com
Form Dict: {}
Traceback (most recent call last):
  File "/home/frappe/frappe-bench/apps/frappe/frappe/utils/sentry.py", line 116, in capture_exception
    set_scope(scope)
  File "/home/frappe/frappe-bench/apps/frappe/frappe/utils/sentry.py", line 70, in set_scope
    path = frappe.request.path
  File "/home/frappe/frappe-bench/env/lib/python3.10/site-packages/werkzeug/local.py", line 311, in __get__
    obj = instance._get_current_object()
  File "/home/frappe/frappe-bench/env/lib/python3.10/site-packages/werkzeug/local.py", line 490, in _get_current_object
    raise RuntimeError(unbound_message) from None
RuntimeError: object is not bound
2024-11-22 10:07:44,452 ERROR frappe Failed to capture exception
Site: erp.grupoatu.com
Form Dict: {}
Traceback (most recent call last):
  File "/home/frappe/frappe-bench/apps/frappe/frappe/utils/sentry.py", line 116, in capture_exception
    set_scope(scope)
  File "/home/frappe/frappe-bench/apps/frappe/frappe/utils/sentry.py", line 70, in set_scope
    path = frappe.request.path
  File "/home/frappe/frappe-bench/env/lib/python3.10/site-packages/werkzeug/local.py", line 311, in __get__
    obj = instance._get_current_object()
  File "/home/frappe/frappe-bench/env/lib/python3.10/site-packages/werkzeug/local.py", line 490, in _get_current_object
    raise RuntimeError(unbound_message) from None
RuntimeError: object is not bound
2024-11-22 10:07:44,466 ERROR frappe Failed to capture exception
Site: erp.grupoatu.com
Form Dict: {}
Traceback (most recent call last):
  File "/home/frappe/frappe-bench/apps/frappe/frappe/utils/sentry.py", line 116, in capture_exception
    set_scope(scope)
  File "/home/frappe/frappe-bench/apps/frappe/frappe/utils/sentry.py", line 70, in set_scope
    path = frappe.request.path
  File "/home/frappe/frappe-bench/env/lib/python3.10/site-packages/werkzeug/local.py", line 311, in __get__
    obj = instance._get_current_object()
  File "/home/frappe/frappe-bench/env/lib/python3.10/site-packages/werkzeug/local.py", line 490, in _get_current_object
    raise RuntimeError(unbound_message) from None
RuntimeError: object is not bound
2024-11-22 10:07:44,479 ERROR frappe Failed to capture exception
Site: erp.grupoatu.com
Form Dict: {}
Traceback (most recent call last):
  File "/home/frappe/frappe-bench/apps/frappe/frappe/utils/sentry.py", line 116, in capture_exception
    set_scope(scope)
  File "/home/frappe/frappe-bench/apps/frappe/frappe/utils/sentry.py", line 70, in set_scope
    path = frappe.request.path
  File "/home/frappe/frappe-bench/env/lib/python3.10/site-packages/werkzeug/local.py", line 311, in __get__
    obj = instance._get_current_object()
  File "/home/frappe/frappe-bench/env/lib/python3.10/site-packages/werkzeug/local.py", line 490, in _get_current_object
    raise RuntimeError(unbound_message) from None
RuntimeError: object is not bound
2024-11-22 10:07:44,492 ERROR frappe Failed to capture exception
Site: erp.grupoatu.com
Form Dict: {}
Traceback (most recent call last):
  File "/home/frappe/frappe-bench/apps/frappe/frappe/utils/sentry.py", line 116, in capture_exception
    set_scope(scope)
  File "/home/frappe/frappe-bench/apps/frappe/frappe/utils/sentry.py", line 70, in set_scope
    path = frappe.request.path
  File "/home/frappe/frappe-bench/env/lib/python3.10/site-packages/werkzeug/local.py", line 311, in __get__
    obj = instance._get_current_object()
  File "/home/frappe/frappe-bench/env/lib/python3.10/site-packages/werkzeug/local.py", line 490, in _get_current_object
    raise RuntimeError(unbound_message) from None
RuntimeError: object is not bound
2024-11-22 10:07:44,506 ERROR frappe Failed to capture exception
Site: erp.grupoatu.com
Form Dict: {}
Traceback (most recent call last):
  File "/home/frappe/frappe-bench/apps/frappe/frappe/utils/sentry.py", line 116, in capture_exception
    set_scope(scope)
  File "/home/frappe/frappe-bench/apps/frappe/frappe/utils/sentry.py", line 70, in set_scope
    path = frappe.request.path
  File "/home/frappe/frappe-bench/env/lib/python3.10/site-packages/werkzeug/local.py", line 311, in __get__
    obj = instance._get_current_object()
  File "/home/frappe/frappe-bench/env/lib/python3.10/site-packages/werkzeug/local.py", line 490, in _get_current_object
    raise RuntimeError(unbound_message) from None
RuntimeError: object is not bound
2024-11-22 10:07:44,520 ERROR frappe Failed to capture exception
Site: erp.grupoatu.com
Form Dict: {}
Traceback (most recent call last):
  File "/home/frappe/frappe-bench/apps/frappe/frappe/utils/sentry.py", line 116, in capture_exception
    set_scope(scope)
  File "/home/frappe/frappe-bench/apps/frappe/frappe/utils/sentry.py", line 70, in set_scope
    path = frappe.request.path
  File "/home/frappe/frappe-bench/env/lib/python3.10/site-packages/werkzeug/local.py", line 311, in __get__
    obj = instance._get_current_object()
  File "/home/frappe/frappe-bench/env/lib/python3.10/site-packages/werkzeug/local.py", line 490, in _get_current_object
    raise RuntimeError(unbound_message) from None
RuntimeError: object is not bound
2024-11-22 10:07:44,533 ERROR frappe Failed to capture exception
Site: erp.grupoatu.com
Form Dict: {}
Traceback (most recent call last):
  File "/home/frappe/frappe-bench/apps/frappe/frappe/utils/sentry.py", line 116, in capture_exception
    set_scope(scope)
  File "/home/frappe/frappe-bench/apps/frappe/frappe/utils/sentry.py", line 70, in set_scope
    path = frappe.request.path
  File "/home/frappe/frappe-bench/env/lib/python3.10/site-packages/werkzeug/local.py", line 311, in __get__
    obj = instance._get_current_object()
  File "/home/frappe/frappe-bench/env/lib/python3.10/site-packages/werkzeug/local.py", line 490, in _get_current_object
    raise RuntimeError(unbound_message) from None
RuntimeError: object is not bound
2024-11-22 10:07:44,546 ERROR frappe Failed to capture exception
Site: erp.grupoatu.com
Form Dict: {}
Traceback (most recent call last):
  File "/home/frappe/frappe-bench/apps/frappe/frappe/utils/sentry.py", line 116, in capture_exception
    set_scope(scope)
  File "/home/frappe/frappe-bench/apps/frappe/frappe/utils/sentry.py", line 70, in set_scope
    path = frappe.request.path
  File "/home/frappe/frappe-bench/env/lib/python3.10/site-packages/werkzeug/local.py", line 311, in __get__
    obj = instance._get_current_object()
  File "/home/frappe/frappe-bench/env/lib/python3.10/site-packages/werkzeug/local.py", line 490, in _get_current_object
    raise RuntimeError(unbound_message) from None
RuntimeError: object is not bound
2024-11-22 10:07:44,560 ERROR frappe Failed to capture exception
Site: erp.grupoatu.com
Form Dict: {}
Traceback (most recent call last):
  File "/home/frappe/frappe-bench/apps/frappe/frappe/utils/sentry.py", line 116, in capture_exception
    set_scope(scope)
  File "/home/frappe/frappe-bench/apps/frappe/frappe/utils/sentry.py", line 70, in set_scope
    path = frappe.request.path
  File "/home/frappe/frappe-bench/env/lib/python3.10/site-packages/werkzeug/local.py", line 311, in __get__
    obj = instance._get_current_object()
  File "/home/frappe/frappe-bench/env/lib/python3.10/site-packages/werkzeug/local.py", line 490, in _get_current_object
    raise RuntimeError(unbound_message) from None
RuntimeError: object is not bound
2024-11-22 10:07:44,575 ERROR frappe Failed to capture exception
Site: erp.grupoatu.com
Form Dict: {}
Traceback (most recent call last):
  File "/home/frappe/frappe-bench/apps/frappe/frappe/utils/sentry.py", line 116, in capture_exception
    set_scope(scope)
  File "/home/frappe/frappe-bench/apps/frappe/frappe/utils/sentry.py", line 70, in set_scope
    path = frappe.request.path
  File "/home/frappe/frappe-bench/env/lib/python3.10/site-packages/werkzeug/local.py", line 311, in __get__
    obj = instance._get_current_object()
  File "/home/frappe/frappe-bench/env/lib/python3.10/site-packages/werkzeug/local.py", line 490, in _get_current_object
    raise RuntimeError(unbound_message) from None
RuntimeError: object is not bound
2024-11-22 10:07:44,587 ERROR frappe Failed to capture exception
Site: erp.grupoatu.com
Form Dict: {}
Traceback (most recent call last):
  File "/home/frappe/frappe-bench/apps/frappe/frappe/utils/sentry.py", line 116, in capture_exception
    set_scope(scope)
  File "/home/frappe/frappe-bench/apps/frappe/frappe/utils/sentry.py", line 70, in set_scope
    path = frappe.request.path
  File "/home/frappe/frappe-bench/env/lib/python3.10/site-packages/werkzeug/local.py", line 311, in __get__
    obj = instance._get_current_object()
  File "/home/frappe/frappe-bench/env/lib/python3.10/site-packages/werkzeug/local.py", line 490, in _get_current_object
    raise RuntimeError(unbound_message) from None
RuntimeError: object is not bound
2024-11-22 10:07:44,600 ERROR frappe Failed to capture exception
Site: erp.grupoatu.com
Form Dict: {}
Traceback (most recent call last):
  File "/home/frappe/frappe-bench/apps/frappe/frappe/utils/sentry.py", line 116, in capture_exception
    set_scope(scope)
  File "/home/frappe/frappe-bench/apps/frappe/frappe/utils/sentry.py", line 70, in set_scope
    path = frappe.request.path
  File "/home/frappe/frappe-bench/env/lib/python3.10/site-packages/werkzeug/local.py", line 311, in __get__
    obj = instance._get_current_object()
  File "/home/frappe/frappe-bench/env/lib/python3.10/site-packages/werkzeug/local.py", line 490, in _get_current_object
    raise RuntimeError(unbound_message) from None
RuntimeError: object is not bound
2024-11-22 10:07:44,613 ERROR frappe Failed to capture exception
Site: erp.grupoatu.com
Form Dict: {}
Traceback (most recent call last):
  File "/home/frappe/frappe-bench/apps/frappe/frappe/utils/sentry.py", line 116, in capture_exception
    set_scope(scope)
  File "/home/frappe/frappe-bench/apps/frappe/frappe/utils/sentry.py", line 70, in set_scope
    path = frappe.request.path
  File "/home/frappe/frappe-bench/env/lib/python3.10/site-packages/werkzeug/local.py", line 311, in __get__
    obj = instance._get_current_object()
  File "/home/frappe/frappe-bench/env/lib/python3.10/site-packages/werkzeug/local.py", line 490, in _get_current_object
    raise RuntimeError(unbound_message) from None
RuntimeError: object is not bound
2024-11-22 10:07:44,626 ERROR frappe Failed to capture exception
Site: erp.grupoatu.com
Form Dict: {}
Traceback (most recent call last):
  File "/home/frappe/frappe-bench/apps/frappe/frappe/utils/sentry.py", line 116, in capture_exception
    set_scope(scope)
  File "/home/frappe/frappe-bench/apps/frappe/frappe/utils/sentry.py", line 70, in set_scope
    path = frappe.request.path
  File "/home/frappe/frappe-bench/env/lib/python3.10/site-packages/werkzeug/local.py", line 311, in __get__
    obj = instance._get_current_object()
  File "/home/frappe/frappe-bench/env/lib/python3.10/site-packages/werkzeug/local.py", line 490, in _get_current_object
    raise RuntimeError(unbound_message) from None
RuntimeError: object is not bound
2024-11-22 10:07:44,639 ERROR frappe Failed to capture exception
Site: erp.grupoatu.com
Form Dict: {}
Traceback (most recent call last):
  File "/home/frappe/frappe-bench/apps/frappe/frappe/utils/sentry.py", line 116, in capture_exception
    set_scope(scope)
  File "/home/frappe/frappe-bench/apps/frappe/frappe/utils/sentry.py", line 70, in set_scope
    path = frappe.request.path
  File "/home/frappe/frappe-bench/env/lib/python3.10/site-packages/werkzeug/local.py", line 311, in __get__
    obj = instance._get_current_object()
  File "/home/frappe/frappe-bench/env/lib/python3.10/site-packages/werkzeug/local.py", line 490, in _get_current_object
    raise RuntimeError(unbound_message) from None
RuntimeError: object is not bound
2024-11-22 10:07:44,653 ERROR frappe Failed to capture exception
Site: erp.grupoatu.com
Form Dict: {}
Traceback (most recent call last):
  File "/home/frappe/frappe-bench/apps/frappe/frappe/utils/sentry.py", line 116, in capture_exception
    set_scope(scope)
  File "/home/frappe/frappe-bench/apps/frappe/frappe/utils/sentry.py", line 70, in set_scope
    path = frappe.request.path
  File "/home/frappe/frappe-bench/env/lib/python3.10/site-packages/werkzeug/local.py", line 311, in __get__
    obj = instance._get_current_object()
  File "/home/frappe/frappe-bench/env/lib/python3.10/site-packages/werkzeug/local.py", line 490, in _get_current_object
    raise RuntimeError(unbound_message) from None
RuntimeError: object is not bound
2024-11-22 10:07:44,667 ERROR frappe Failed to capture exception
Site: erp.grupoatu.com
Form Dict: {}
Traceback (most recent call last):
  File "/home/frappe/frappe-bench/apps/frappe/frappe/utils/sentry.py", line 116, in capture_exception
    set_scope(scope)
  File "/home/frappe/frappe-bench/apps/frappe/frappe/utils/sentry.py", line 70, in set_scope
    path = frappe.request.path
  File "/home/frappe/frappe-bench/env/lib/python3.10/site-packages/werkzeug/local.py", line 311, in __get__
    obj = instance._get_current_object()
  File "/home/frappe/frappe-bench/env/lib/python3.10/site-packages/werkzeug/local.py", line 490, in _get_current_object
    raise RuntimeError(unbound_message) from None
RuntimeError: object is not bound
2024-11-22 10:07:44,681 ERROR frappe Failed to capture exception
Site: erp.grupoatu.com
Form Dict: {}
Traceback (most recent call last):
  File "/home/frappe/frappe-bench/apps/frappe/frappe/utils/sentry.py", line 116, in capture_exception
    set_scope(scope)
  File "/home/frappe/frappe-bench/apps/frappe/frappe/utils/sentry.py", line 70, in set_scope
    path = frappe.request.path
  File "/home/frappe/frappe-bench/env/lib/python3.10/site-packages/werkzeug/local.py", line 311, in __get__
    obj = instance._get_current_object()
  File "/home/frappe/frappe-bench/env/lib/python3.10/site-packages/werkzeug/local.py", line 490, in _get_current_object
    raise RuntimeError(unbound_message) from None
RuntimeError: object is not bound
2024-11-22 10:07:44,694 ERROR frappe Failed to capture exception
Site: erp.grupoatu.com
Form Dict: {}
Traceback (most recent call last):
  File "/home/frappe/frappe-bench/apps/frappe/frappe/utils/sentry.py", line 116, in capture_exception
    set_scope(scope)
  File "/home/frappe/frappe-bench/apps/frappe/frappe/utils/sentry.py", line 70, in set_scope
    path = frappe.request.path
  File "/home/frappe/frappe-bench/env/lib/python3.10/site-packages/werkzeug/local.py", line 311, in __get__
    obj = instance._get_current_object()
  File "/home/frappe/frappe-bench/env/lib/python3.10/site-packages/werkzeug/local.py", line 490, in _get_current_object
    raise RuntimeError(unbound_message) from None
RuntimeError: object is not bound
2024-11-22 10:07:44,708 ERROR frappe Failed to capture exception
Site: erp.grupoatu.com
Form Dict: {}
Traceback (most recent call last):
  File "/home/frappe/frappe-bench/apps/frappe/frappe/utils/sentry.py", line 116, in capture_exception
    set_scope(scope)
  File "/home/frappe/frappe-bench/apps/frappe/frappe/utils/sentry.py", line 70, in set_scope
    path = frappe.request.path
  File "/home/frappe/frappe-bench/env/lib/python3.10/site-packages/werkzeug/local.py", line 311, in __get__
    obj = instance._get_current_object()
  File "/home/frappe/frappe-bench/env/lib/python3.10/site-packages/werkzeug/local.py", line 490, in _get_current_object
    raise RuntimeError(unbound_message) from None
RuntimeError: object is not bound
2024-11-22 10:07:44,721 ERROR frappe Failed to capture exception
Site: erp.grupoatu.com
Form Dict: {}
Traceback (most recent call last):
  File "/home/frappe/frappe-bench/apps/frappe/frappe/utils/sentry.py", line 116, in capture_exception
    set_scope(scope)
  File "/home/frappe/frappe-bench/apps/frappe/frappe/utils/sentry.py", line 70, in set_scope
    path = frappe.request.path
  File "/home/frappe/frappe-bench/env/lib/python3.10/site-packages/werkzeug/local.py", line 311, in __get__
    obj = instance._get_current_object()
  File "/home/frappe/frappe-bench/env/lib/python3.10/site-packages/werkzeug/local.py", line 490, in _get_current_object
    raise RuntimeError(unbound_message) from None
RuntimeError: object is not bound
2024-11-22 10:07:44,734 ERROR frappe Failed to capture exception
Site: erp.grupoatu.com
Form Dict: {}
Traceback (most recent call last):
  File "/home/frappe/frappe-bench/apps/frappe/frappe/utils/sentry.py", line 116, in capture_exception
    set_scope(scope)
  File "/home/frappe/frappe-bench/apps/frappe/frappe/utils/sentry.py", line 70, in set_scope
    path = frappe.request.path
  File "/home/frappe/frappe-bench/env/lib/python3.10/site-packages/werkzeug/local.py", line 311, in __get__
    obj = instance._get_current_object()
  File "/home/frappe/frappe-bench/env/lib/python3.10/site-packages/werkzeug/local.py", line 490, in _get_current_object
    raise RuntimeError(unbound_message) from None
RuntimeError: object is not bound
2024-11-22 10:07:44,747 ERROR frappe Failed to capture exception
Site: erp.grupoatu.com
Form Dict: {}
Traceback (most recent call last):
  File "/home/frappe/frappe-bench/apps/frappe/frappe/utils/sentry.py", line 116, in capture_exception
    set_scope(scope)
  File "/home/frappe/frappe-bench/apps/frappe/frappe/utils/sentry.py", line 70, in set_scope
    path = frappe.request.path
  File "/home/frappe/frappe-bench/env/lib/python3.10/site-packages/werkzeug/local.py", line 311, in __get__
    obj = instance._get_current_object()
  File "/home/frappe/frappe-bench/env/lib/python3.10/site-packages/werkzeug/local.py", line 490, in _get_current_object
    raise RuntimeError(unbound_message) from None
RuntimeError: object is not bound
2024-11-22 10:07:44,762 ERROR frappe Failed to capture exception
Site: erp.grupoatu.com
Form Dict: {}
Traceback (most recent call last):
  File "/home/frappe/frappe-bench/apps/frappe/frappe/utils/sentry.py", line 116, in capture_exception
    set_scope(scope)
  File "/home/frappe/frappe-bench/apps/frappe/frappe/utils/sentry.py", line 70, in set_scope
    path = frappe.request.path
  File "/home/frappe/frappe-bench/env/lib/python3.10/site-packages/werkzeug/local.py", line 311, in __get__
    obj = instance._get_current_object()
  File "/home/frappe/frappe-bench/env/lib/python3.10/site-packages/werkzeug/local.py", line 490, in _get_current_object
    raise RuntimeError(unbound_message) from None
RuntimeError: object is not bound
2024-11-22 10:07:44,776 ERROR frappe Failed to capture exception
Site: erp.grupoatu.com
Form Dict: {}
Traceback (most recent call last):
  File "/home/frappe/frappe-bench/apps/frappe/frappe/utils/sentry.py", line 116, in capture_exception
    set_scope(scope)
  File "/home/frappe/frappe-bench/apps/frappe/frappe/utils/sentry.py", line 70, in set_scope
    path = frappe.request.path
  File "/home/frappe/frappe-bench/env/lib/python3.10/site-packages/werkzeug/local.py", line 311, in __get__
    obj = instance._get_current_object()
  File "/home/frappe/frappe-bench/env/lib/python3.10/site-packages/werkzeug/local.py", line 490, in _get_current_object
    raise RuntimeError(unbound_message) from None
RuntimeError: object is not bound
2024-11-22 10:07:44,789 ERROR frappe Failed to capture exception
Site: erp.grupoatu.com
Form Dict: {}
Traceback (most recent call last):
  File "/home/frappe/frappe-bench/apps/frappe/frappe/utils/sentry.py", line 116, in capture_exception
    set_scope(scope)
  File "/home/frappe/frappe-bench/apps/frappe/frappe/utils/sentry.py", line 70, in set_scope
    path = frappe.request.path
  File "/home/frappe/frappe-bench/env/lib/python3.10/site-packages/werkzeug/local.py", line 311, in __get__
    obj = instance._get_current_object()
  File "/home/frappe/frappe-bench/env/lib/python3.10/site-packages/werkzeug/local.py", line 490, in _get_current_object
    raise RuntimeError(unbound_message) from None
RuntimeError: object is not bound
2024-11-22 10:07:44,802 ERROR frappe Failed to capture exception
Site: erp.grupoatu.com
Form Dict: {}
Traceback (most recent call last):
  File "/home/frappe/frappe-bench/apps/frappe/frappe/utils/sentry.py", line 116, in capture_exception
    set_scope(scope)
  File "/home/frappe/frappe-bench/apps/frappe/frappe/utils/sentry.py", line 70, in set_scope
    path = frappe.request.path
  File "/home/frappe/frappe-bench/env/lib/python3.10/site-packages/werkzeug/local.py", line 311, in __get__
    obj = instance._get_current_object()
  File "/home/frappe/frappe-bench/env/lib/python3.10/site-packages/werkzeug/local.py", line 490, in _get_current_object
    raise RuntimeError(unbound_message) from None
RuntimeError: object is not bound
2024-11-22 10:07:44,814 ERROR frappe Failed to capture exception
Site: erp.grupoatu.com
Form Dict: {}
Traceback (most recent call last):
  File "/home/frappe/frappe-bench/apps/frappe/frappe/utils/sentry.py", line 116, in capture_exception
    set_scope(scope)
  File "/home/frappe/frappe-bench/apps/frappe/frappe/utils/sentry.py", line 70, in set_scope
    path = frappe.request.path
  File "/home/frappe/frappe-bench/env/lib/python3.10/site-packages/werkzeug/local.py", line 311, in __get__
    obj = instance._get_current_object()
  File "/home/frappe/frappe-bench/env/lib/python3.10/site-packages/werkzeug/local.py", line 490, in _get_current_object
    raise RuntimeError(unbound_message) from None
RuntimeError: object is not bound
2024-11-22 10:07:44,827 ERROR frappe Failed to capture exception
Site: erp.grupoatu.com
Form Dict: {}
Traceback (most recent call last):
  File "/home/frappe/frappe-bench/apps/frappe/frappe/utils/sentry.py", line 116, in capture_exception
    set_scope(scope)
  File "/home/frappe/frappe-bench/apps/frappe/frappe/utils/sentry.py", line 70, in set_scope
    path = frappe.request.path
  File "/home/frappe/frappe-bench/env/lib/python3.10/site-packages/werkzeug/local.py", line 311, in __get__
    obj = instance._get_current_object()
  File "/home/frappe/frappe-bench/env/lib/python3.10/site-packages/werkzeug/local.py", line 490, in _get_current_object
    raise RuntimeError(unbound_message) from None
RuntimeError: object is not bound
2024-11-22 10:07:44,839 ERROR frappe Failed to capture exception
Site: erp.grupoatu.com
Form Dict: {}
Traceback (most recent call last):
  File "/home/frappe/frappe-bench/apps/frappe/frappe/utils/sentry.py", line 116, in capture_exception
    set_scope(scope)
  File "/home/frappe/frappe-bench/apps/frappe/frappe/utils/sentry.py", line 70, in set_scope
    path = frappe.request.path
  File "/home/frappe/frappe-bench/env/lib/python3.10/site-packages/werkzeug/local.py", line 311, in __get__
    obj = instance._get_current_object()
  File "/home/frappe/frappe-bench/env/lib/python3.10/site-packages/werkzeug/local.py", line 490, in _get_current_object
    raise RuntimeError(unbound_message) from None
RuntimeError: object is not bound
2024-11-22 10:07:44,852 ERROR frappe Failed to capture exception
Site: erp.grupoatu.com
Form Dict: {}
Traceback (most recent call last):
  File "/home/frappe/frappe-bench/apps/frappe/frappe/utils/sentry.py", line 116, in capture_exception
    set_scope(scope)
  File "/home/frappe/frappe-bench/apps/frappe/frappe/utils/sentry.py", line 70, in set_scope
    path = frappe.request.path
  File "/home/frappe/frappe-bench/env/lib/python3.10/site-packages/werkzeug/local.py", line 311, in __get__
    obj = instance._get_current_object()
  File "/home/frappe/frappe-bench/env/lib/python3.10/site-packages/werkzeug/local.py", line 490, in _get_current_object
    raise RuntimeError(unbound_message) from None
RuntimeError: object is not bound
2024-11-22 10:07:44,864 ERROR frappe Failed to capture exception
Site: erp.grupoatu.com
Form Dict: {}
Traceback (most recent call last):
  File "/home/frappe/frappe-bench/apps/frappe/frappe/utils/sentry.py", line 116, in capture_exception
    set_scope(scope)
  File "/home/frappe/frappe-bench/apps/frappe/frappe/utils/sentry.py", line 70, in set_scope
    path = frappe.request.path
  File "/home/frappe/frappe-bench/env/lib/python3.10/site-packages/werkzeug/local.py", line 311, in __get__
    obj = instance._get_current_object()
  File "/home/frappe/frappe-bench/env/lib/python3.10/site-packages/werkzeug/local.py", line 490, in _get_current_object
    raise RuntimeError(unbound_message) from None
RuntimeError: object is not bound
2024-11-22 10:07:44,876 ERROR frappe Failed to capture exception
Site: erp.grupoatu.com
Form Dict: {}
Traceback (most recent call last):
  File "/home/frappe/frappe-bench/apps/frappe/frappe/utils/sentry.py", line 116, in capture_exception
    set_scope(scope)
  File "/home/frappe/frappe-bench/apps/frappe/frappe/utils/sentry.py", line 70, in set_scope
    path = frappe.request.path
  File "/home/frappe/frappe-bench/env/lib/python3.10/site-packages/werkzeug/local.py", line 311, in __get__
    obj = instance._get_current_object()
  File "/home/frappe/frappe-bench/env/lib/python3.10/site-packages/werkzeug/local.py", line 490, in _get_current_object
    raise RuntimeError(unbound_message) from None
RuntimeError: object is not bound
2024-11-22 10:07:44,888 ERROR frappe Failed to capture exception
Site: erp.grupoatu.com
Form Dict: {}
Traceback (most recent call last):
  File "/home/frappe/frappe-bench/apps/frappe/frappe/utils/sentry.py", line 116, in capture_exception
    set_scope(scope)
  File "/home/frappe/frappe-bench/apps/frappe/frappe/utils/sentry.py", line 70, in set_scope
    path = frappe.request.path
  File "/home/frappe/frappe-bench/env/lib/python3.10/site-packages/werkzeug/local.py", line 311, in __get__
    obj = instance._get_current_object()
  File "/home/frappe/frappe-bench/env/lib/python3.10/site-packages/werkzeug/local.py", line 490, in _get_current_object
    raise RuntimeError(unbound_message) from None
RuntimeError: object is not bound
2024-11-22 10:07:44,902 ERROR frappe Failed to capture exception
Site: erp.grupoatu.com
Form Dict: {}
Traceback (most recent call last):
  File "/home/frappe/frappe-bench/apps/frappe/frappe/utils/sentry.py", line 116, in capture_exception
    set_scope(scope)
  File "/home/frappe/frappe-bench/apps/frappe/frappe/utils/sentry.py", line 70, in set_scope
    path = frappe.request.path
  File "/home/frappe/frappe-bench/env/lib/python3.10/site-packages/werkzeug/local.py", line 311, in __get__
    obj = instance._get_current_object()
  File "/home/frappe/frappe-bench/env/lib/python3.10/site-packages/werkzeug/local.py", line 490, in _get_current_object
    raise RuntimeError(unbound_message) from None
RuntimeError: object is not bound
2024-11-22 10:07:44,914 ERROR frappe Failed to capture exception
Site: erp.grupoatu.com
Form Dict: {}
Traceback (most recent call last):
  File "/home/frappe/frappe-bench/apps/frappe/frappe/utils/sentry.py", line 116, in capture_exception
    set_scope(scope)
  File "/home/frappe/frappe-bench/apps/frappe/frappe/utils/sentry.py", line 70, in set_scope
    path = frappe.request.path
  File "/home/frappe/frappe-bench/env/lib/python3.10/site-packages/werkzeug/local.py", line 311, in __get__
    obj = instance._get_current_object()
  File "/home/frappe/frappe-bench/env/lib/python3.10/site-packages/werkzeug/local.py", line 490, in _get_current_object
    raise RuntimeError(unbound_message) from None
RuntimeError: object is not bound
2024-11-22 10:07:44,927 ERROR frappe Failed to capture exception
Site: erp.grupoatu.com
Form Dict: {}
Traceback (most recent call last):
  File "/home/frappe/frappe-bench/apps/frappe/frappe/utils/sentry.py", line 116, in capture_exception
    set_scope(scope)
  File "/home/frappe/frappe-bench/apps/frappe/frappe/utils/sentry.py", line 70, in set_scope
    path = frappe.request.path
  File "/home/frappe/frappe-bench/env/lib/python3.10/site-packages/werkzeug/local.py", line 311, in __get__
    obj = instance._get_current_object()
  File "/home/frappe/frappe-bench/env/lib/python3.10/site-packages/werkzeug/local.py", line 490, in _get_current_object
    raise RuntimeError(unbound_message) from None
RuntimeError: object is not bound
2024-11-22 10:07:44,941 ERROR frappe Failed to capture exception
Site: erp.grupoatu.com
Form Dict: {}
Traceback (most recent call last):
  File "/home/frappe/frappe-bench/apps/frappe/frappe/utils/sentry.py", line 116, in capture_exception
    set_scope(scope)
  File "/home/frappe/frappe-bench/apps/frappe/frappe/utils/sentry.py", line 70, in set_scope
    path = frappe.request.path
  File "/home/frappe/frappe-bench/env/lib/python3.10/site-packages/werkzeug/local.py", line 311, in __get__
    obj = instance._get_current_object()
  File "/home/frappe/frappe-bench/env/lib/python3.10/site-packages/werkzeug/local.py", line 490, in _get_current_object
    raise RuntimeError(unbound_message) from None
RuntimeError: object is not bound
2024-11-22 10:07:44,957 ERROR frappe Failed to capture exception
Site: erp.grupoatu.com
Form Dict: {}
Traceback (most recent call last):
  File "/home/frappe/frappe-bench/apps/frappe/frappe/utils/sentry.py", line 116, in capture_exception
    set_scope(scope)
  File "/home/frappe/frappe-bench/apps/frappe/frappe/utils/sentry.py", line 70, in set_scope
    path = frappe.request.path
  File "/home/frappe/frappe-bench/env/lib/python3.10/site-packages/werkzeug/local.py", line 311, in __get__
    obj = instance._get_current_object()
  File "/home/frappe/frappe-bench/env/lib/python3.10/site-packages/werkzeug/local.py", line 490, in _get_current_object
    raise RuntimeError(unbound_message) from None
RuntimeError: object is not bound
2024-11-22 10:07:44,970 ERROR frappe Failed to capture exception
Site: erp.grupoatu.com
Form Dict: {}
Traceback (most recent call last):
  File "/home/frappe/frappe-bench/apps/frappe/frappe/utils/sentry.py", line 116, in capture_exception
    set_scope(scope)
  File "/home/frappe/frappe-bench/apps/frappe/frappe/utils/sentry.py", line 70, in set_scope
    path = frappe.request.path
  File "/home/frappe/frappe-bench/env/lib/python3.10/site-packages/werkzeug/local.py", line 311, in __get__
    obj = instance._get_current_object()
  File "/home/frappe/frappe-bench/env/lib/python3.10/site-packages/werkzeug/local.py", line 490, in _get_current_object
    raise RuntimeError(unbound_message) from None
RuntimeError: object is not bound
2024-11-22 10:07:44,983 ERROR frappe Failed to capture exception
Site: erp.grupoatu.com
Form Dict: {}
Traceback (most recent call last):
  File "/home/frappe/frappe-bench/apps/frappe/frappe/utils/sentry.py", line 116, in capture_exception
    set_scope(scope)
  File "/home/frappe/frappe-bench/apps/frappe/frappe/utils/sentry.py", line 70, in set_scope
    path = frappe.request.path
  File "/home/frappe/frappe-bench/env/lib/python3.10/site-packages/werkzeug/local.py", line 311, in __get__
    obj = instance._get_current_object()
  File "/home/frappe/frappe-bench/env/lib/python3.10/site-packages/werkzeug/local.py", line 490, in _get_current_object
    raise RuntimeError(unbound_message) from None
RuntimeError: object is not bound
2024-11-22 10:07:44,997 ERROR frappe Failed to capture exception
Site: erp.grupoatu.com
Form Dict: {}
Traceback (most recent call last):
  File "/home/frappe/frappe-bench/apps/frappe/frappe/utils/sentry.py", line 116, in capture_exception
    set_scope(scope)
  File "/home/frappe/frappe-bench/apps/frappe/frappe/utils/sentry.py", line 70, in set_scope
    path = frappe.request.path
  File "/home/frappe/frappe-bench/env/lib/python3.10/site-packages/werkzeug/local.py", line 311, in __get__
    obj = instance._get_current_object()
  File "/home/frappe/frappe-bench/env/lib/python3.10/site-packages/werkzeug/local.py", line 490, in _get_current_object
    raise RuntimeError(unbound_message) from None
RuntimeError: object is not bound
2024-11-22 10:07:45,015 ERROR frappe Failed to capture exception
Site: erp.grupoatu.com
Form Dict: {}
Traceback (most recent call last):
  File "/home/frappe/frappe-bench/apps/frappe/frappe/utils/sentry.py", line 116, in capture_exception
    set_scope(scope)
  File "/home/frappe/frappe-bench/apps/frappe/frappe/utils/sentry.py", line 70, in set_scope
    path = frappe.request.path
  File "/home/frappe/frappe-bench/env/lib/python3.10/site-packages/werkzeug/local.py", line 311, in __get__
    obj = instance._get_current_object()
  File "/home/frappe/frappe-bench/env/lib/python3.10/site-packages/werkzeug/local.py", line 490, in _get_current_object
    raise RuntimeError(unbound_message) from None
RuntimeError: object is not bound
2024-11-22 10:07:45,031 ERROR frappe Failed to capture exception
Site: erp.grupoatu.com
Form Dict: {}
Traceback (most recent call last):
  File "/home/frappe/frappe-bench/apps/frappe/frappe/utils/sentry.py", line 116, in capture_exception
    set_scope(scope)
  File "/home/frappe/frappe-bench/apps/frappe/frappe/utils/sentry.py", line 70, in set_scope
    path = frappe.request.path
  File "/home/frappe/frappe-bench/env/lib/python3.10/site-packages/werkzeug/local.py", line 311, in __get__
    obj = instance._get_current_object()
  File "/home/frappe/frappe-bench/env/lib/python3.10/site-packages/werkzeug/local.py", line 490, in _get_current_object
    raise RuntimeError(unbound_message) from None
RuntimeError: object is not bound
2024-11-22 10:07:45,044 ERROR frappe Failed to capture exception
Site: erp.grupoatu.com
Form Dict: {}
Traceback (most recent call last):
  File "/home/frappe/frappe-bench/apps/frappe/frappe/utils/sentry.py", line 116, in capture_exception
    set_scope(scope)
  File "/home/frappe/frappe-bench/apps/frappe/frappe/utils/sentry.py", line 70, in set_scope
    path = frappe.request.path
  File "/home/frappe/frappe-bench/env/lib/python3.10/site-packages/werkzeug/local.py", line 311, in __get__
    obj = instance._get_current_object()
  File "/home/frappe/frappe-bench/env/lib/python3.10/site-packages/werkzeug/local.py", line 490, in _get_current_object
    raise RuntimeError(unbound_message) from None
RuntimeError: object is not bound
2024-11-22 10:07:45,057 ERROR frappe Failed to capture exception
Site: erp.grupoatu.com
Form Dict: {}
Traceback (most recent call last):
  File "/home/frappe/frappe-bench/apps/frappe/frappe/utils/sentry.py", line 116, in capture_exception
    set_scope(scope)
  File "/home/frappe/frappe-bench/apps/frappe/frappe/utils/sentry.py", line 70, in set_scope
    path = frappe.request.path
  File "/home/frappe/frappe-bench/env/lib/python3.10/site-packages/werkzeug/local.py", line 311, in __get__
    obj = instance._get_current_object()
  File "/home/frappe/frappe-bench/env/lib/python3.10/site-packages/werkzeug/local.py", line 490, in _get_current_object
    raise RuntimeError(unbound_message) from None
RuntimeError: object is not bound
2024-11-22 10:07:45,070 ERROR frappe Failed to capture exception
Site: erp.grupoatu.com
Form Dict: {}
Traceback (most recent call last):
  File "/home/frappe/frappe-bench/apps/frappe/frappe/utils/sentry.py", line 116, in capture_exception
    set_scope(scope)
  File "/home/frappe/frappe-bench/apps/frappe/frappe/utils/sentry.py", line 70, in set_scope
    path = frappe.request.path
  File "/home/frappe/frappe-bench/env/lib/python3.10/site-packages/werkzeug/local.py", line 311, in __get__
    obj = instance._get_current_object()
  File "/home/frappe/frappe-bench/env/lib/python3.10/site-packages/werkzeug/local.py", line 490, in _get_current_object
    raise RuntimeError(unbound_message) from None
RuntimeError: object is not bound
2024-11-22 10:07:45,083 ERROR frappe Failed to capture exception
Site: erp.grupoatu.com
Form Dict: {}
Traceback (most recent call last):
  File "/home/frappe/frappe-bench/apps/frappe/frappe/utils/sentry.py", line 116, in capture_exception
    set_scope(scope)
  File "/home/frappe/frappe-bench/apps/frappe/frappe/utils/sentry.py", line 70, in set_scope
    path = frappe.request.path
  File "/home/frappe/frappe-bench/env/lib/python3.10/site-packages/werkzeug/local.py", line 311, in __get__
    obj = instance._get_current_object()
  File "/home/frappe/frappe-bench/env/lib/python3.10/site-packages/werkzeug/local.py", line 490, in _get_current_object
    raise RuntimeError(unbound_message) from None
RuntimeError: object is not bound
2024-11-22 10:07:45,096 ERROR frappe Failed to capture exception
Site: erp.grupoatu.com
Form Dict: {}
Traceback (most recent call last):
  File "/home/frappe/frappe-bench/apps/frappe/frappe/utils/sentry.py", line 116, in capture_exception
    set_scope(scope)
  File "/home/frappe/frappe-bench/apps/frappe/frappe/utils/sentry.py", line 70, in set_scope
    path = frappe.request.path
  File "/home/frappe/frappe-bench/env/lib/python3.10/site-packages/werkzeug/local.py", line 311, in __get__
    obj = instance._get_current_object()
  File "/home/frappe/frappe-bench/env/lib/python3.10/site-packages/werkzeug/local.py", line 490, in _get_current_object
    raise RuntimeError(unbound_message) from None
RuntimeError: object is not bound
2024-11-22 10:07:45,110 ERROR frappe Failed to capture exception
Site: erp.grupoatu.com
Form Dict: {}
Traceback (most recent call last):
  File "/home/frappe/frappe-bench/apps/frappe/frappe/utils/sentry.py", line 116, in capture_exception
    set_scope(scope)
  File "/home/frappe/frappe-bench/apps/frappe/frappe/utils/sentry.py", line 70, in set_scope
    path = frappe.request.path
  File "/home/frappe/frappe-bench/env/lib/python3.10/site-packages/werkzeug/local.py", line 311, in __get__
    obj = instance._get_current_object()
  File "/home/frappe/frappe-bench/env/lib/python3.10/site-packages/werkzeug/local.py", line 490, in _get_current_object
    raise RuntimeError(unbound_message) from None
RuntimeError: object is not bound
2024-11-22 10:07:45,124 ERROR frappe Failed to capture exception
Site: erp.grupoatu.com
Form Dict: {}
Traceback (most recent call last):
  File "/home/frappe/frappe-bench/apps/frappe/frappe/utils/sentry.py", line 116, in capture_exception
    set_scope(scope)
  File "/home/frappe/frappe-bench/apps/frappe/frappe/utils/sentry.py", line 70, in set_scope
    path = frappe.request.path
  File "/home/frappe/frappe-bench/env/lib/python3.10/site-packages/werkzeug/local.py", line 311, in __get__
    obj = instance._get_current_object()
  File "/home/frappe/frappe-bench/env/lib/python3.10/site-packages/werkzeug/local.py", line 490, in _get_current_object
    raise RuntimeError(unbound_message) from None
RuntimeError: object is not bound
2024-11-22 10:07:45,136 ERROR frappe Failed to capture exception
Site: erp.grupoatu.com
Form Dict: {}
Traceback (most recent call last):
  File "/home/frappe/frappe-bench/apps/frappe/frappe/utils/sentry.py", line 116, in capture_exception
    set_scope(scope)
  File "/home/frappe/frappe-bench/apps/frappe/frappe/utils/sentry.py", line 70, in set_scope
    path = frappe.request.path
  File "/home/frappe/frappe-bench/env/lib/python3.10/site-packages/werkzeug/local.py", line 311, in __get__
    obj = instance._get_current_object()
  File "/home/frappe/frappe-bench/env/lib/python3.10/site-packages/werkzeug/local.py", line 490, in _get_current_object
    raise RuntimeError(unbound_message) from None
RuntimeError: object is not bound
2024-11-22 10:07:45,149 ERROR frappe Failed to capture exception
Site: erp.grupoatu.com
Form Dict: {}
Traceback (most recent call last):
  File "/home/frappe/frappe-bench/apps/frappe/frappe/utils/sentry.py", line 116, in capture_exception
    set_scope(scope)
  File "/home/frappe/frappe-bench/apps/frappe/frappe/utils/sentry.py", line 70, in set_scope
    path = frappe.request.path
  File "/home/frappe/frappe-bench/env/lib/python3.10/site-packages/werkzeug/local.py", line 311, in __get__
    obj = instance._get_current_object()
  File "/home/frappe/frappe-bench/env/lib/python3.10/site-packages/werkzeug/local.py", line 490, in _get_current_object
    raise RuntimeError(unbound_message) from None
RuntimeError: object is not bound
2024-11-22 10:07:45,163 ERROR frappe Failed to capture exception
Site: erp.grupoatu.com
Form Dict: {}
Traceback (most recent call last):
  File "/home/frappe/frappe-bench/apps/frappe/frappe/utils/sentry.py", line 116, in capture_exception
    set_scope(scope)
  File "/home/frappe/frappe-bench/apps/frappe/frappe/utils/sentry.py", line 70, in set_scope
    path = frappe.request.path
  File "/home/frappe/frappe-bench/env/lib/python3.10/site-packages/werkzeug/local.py", line 311, in __get__
    obj = instance._get_current_object()
  File "/home/frappe/frappe-bench/env/lib/python3.10/site-packages/werkzeug/local.py", line 490, in _get_current_object
    raise RuntimeError(unbound_message) from None
RuntimeError: object is not bound
2024-11-22 10:07:45,176 ERROR frappe Failed to capture exception
Site: erp.grupoatu.com
Form Dict: {}
Traceback (most recent call last):
  File "/home/frappe/frappe-bench/apps/frappe/frappe/utils/sentry.py", line 116, in capture_exception
    set_scope(scope)
  File "/home/frappe/frappe-bench/apps/frappe/frappe/utils/sentry.py", line 70, in set_scope
    path = frappe.request.path
  File "/home/frappe/frappe-bench/env/lib/python3.10/site-packages/werkzeug/local.py", line 311, in __get__
    obj = instance._get_current_object()
  File "/home/frappe/frappe-bench/env/lib/python3.10/site-packages/werkzeug/local.py", line 490, in _get_current_object
    raise RuntimeError(unbound_message) from None
RuntimeError: object is not bound
2024-11-22 10:07:45,191 ERROR frappe Failed to capture exception
Site: erp.grupoatu.com
Form Dict: {}
Traceback (most recent call last):
  File "/home/frappe/frappe-bench/apps/frappe/frappe/utils/sentry.py", line 116, in capture_exception
    set_scope(scope)
  File "/home/frappe/frappe-bench/apps/frappe/frappe/utils/sentry.py", line 70, in set_scope
    path = frappe.request.path
  File "/home/frappe/frappe-bench/env/lib/python3.10/site-packages/werkzeug/local.py", line 311, in __get__
    obj = instance._get_current_object()
  File "/home/frappe/frappe-bench/env/lib/python3.10/site-packages/werkzeug/local.py", line 490, in _get_current_object
    raise RuntimeError(unbound_message) from None
RuntimeError: object is not bound
2024-11-22 10:07:45,206 ERROR frappe Failed to capture exception
Site: erp.grupoatu.com
Form Dict: {}
Traceback (most recent call last):
  File "/home/frappe/frappe-bench/apps/frappe/frappe/utils/sentry.py", line 116, in capture_exception
    set_scope(scope)
  File "/home/frappe/frappe-bench/apps/frappe/frappe/utils/sentry.py", line 70, in set_scope
    path = frappe.request.path
  File "/home/frappe/frappe-bench/env/lib/python3.10/site-packages/werkzeug/local.py", line 311, in __get__
    obj = instance._get_current_object()
  File "/home/frappe/frappe-bench/env/lib/python3.10/site-packages/werkzeug/local.py", line 490, in _get_current_object
    raise RuntimeError(unbound_message) from None
RuntimeError: object is not bound
2024-11-22 10:07:45,221 ERROR frappe Failed to capture exception
Site: erp.grupoatu.com
Form Dict: {}
Traceback (most recent call last):
  File "/home/frappe/frappe-bench/apps/frappe/frappe/utils/sentry.py", line 116, in capture_exception
    set_scope(scope)
  File "/home/frappe/frappe-bench/apps/frappe/frappe/utils/sentry.py", line 70, in set_scope
    path = frappe.request.path
  File "/home/frappe/frappe-bench/env/lib/python3.10/site-packages/werkzeug/local.py", line 311, in __get__
    obj = instance._get_current_object()
  File "/home/frappe/frappe-bench/env/lib/python3.10/site-packages/werkzeug/local.py", line 490, in _get_current_object
    raise RuntimeError(unbound_message) from None
RuntimeError: object is not bound
2024-11-22 10:07:45,236 ERROR frappe Failed to capture exception
Site: erp.grupoatu.com
Form Dict: {}
Traceback (most recent call last):
  File "/home/frappe/frappe-bench/apps/frappe/frappe/utils/sentry.py", line 116, in capture_exception
    set_scope(scope)
  File "/home/frappe/frappe-bench/apps/frappe/frappe/utils/sentry.py", line 70, in set_scope
    path = frappe.request.path
  File "/home/frappe/frappe-bench/env/lib/python3.10/site-packages/werkzeug/local.py", line 311, in __get__
    obj = instance._get_current_object()
  File "/home/frappe/frappe-bench/env/lib/python3.10/site-packages/werkzeug/local.py", line 490, in _get_current_object
    raise RuntimeError(unbound_message) from None
RuntimeError: object is not bound
2024-11-22 10:07:45,251 ERROR frappe Failed to capture exception
Site: erp.grupoatu.com
Form Dict: {}
Traceback (most recent call last):
  File "/home/frappe/frappe-bench/apps/frappe/frappe/utils/sentry.py", line 116, in capture_exception
    set_scope(scope)
  File "/home/frappe/frappe-bench/apps/frappe/frappe/utils/sentry.py", line 70, in set_scope
    path = frappe.request.path
  File "/home/frappe/frappe-bench/env/lib/python3.10/site-packages/werkzeug/local.py", line 311, in __get__
    obj = instance._get_current_object()
  File "/home/frappe/frappe-bench/env/lib/python3.10/site-packages/werkzeug/local.py", line 490, in _get_current_object
    raise RuntimeError(unbound_message) from None
RuntimeError: object is not bound
2024-11-22 10:07:45,265 ERROR frappe Failed to capture exception
Site: erp.grupoatu.com
Form Dict: {}
Traceback (most recent call last):
  File "/home/frappe/frappe-bench/apps/frappe/frappe/utils/sentry.py", line 116, in capture_exception
    set_scope(scope)
  File "/home/frappe/frappe-bench/apps/frappe/frappe/utils/sentry.py", line 70, in set_scope
    path = frappe.request.path
  File "/home/frappe/frappe-bench/env/lib/python3.10/site-packages/werkzeug/local.py", line 311, in __get__
    obj = instance._get_current_object()
  File "/home/frappe/frappe-bench/env/lib/python3.10/site-packages/werkzeug/local.py", line 490, in _get_current_object
    raise RuntimeError(unbound_message) from None
RuntimeError: object is not bound
2024-11-22 10:07:45,281 ERROR frappe Failed to capture exception
Site: erp.grupoatu.com
Form Dict: {}
Traceback (most recent call last):
  File "/home/frappe/frappe-bench/apps/frappe/frappe/utils/sentry.py", line 116, in capture_exception
    set_scope(scope)
  File "/home/frappe/frappe-bench/apps/frappe/frappe/utils/sentry.py", line 70, in set_scope
    path = frappe.request.path
  File "/home/frappe/frappe-bench/env/lib/python3.10/site-packages/werkzeug/local.py", line 311, in __get__
    obj = instance._get_current_object()
  File "/home/frappe/frappe-bench/env/lib/python3.10/site-packages/werkzeug/local.py", line 490, in _get_current_object
    raise RuntimeError(unbound_message) from None
RuntimeError: object is not bound
2024-11-22 10:07:45,299 ERROR frappe Failed to capture exception
Site: erp.grupoatu.com
Form Dict: {}
Traceback (most recent call last):
  File "/home/frappe/frappe-bench/apps/frappe/frappe/utils/sentry.py", line 116, in capture_exception
    set_scope(scope)
  File "/home/frappe/frappe-bench/apps/frappe/frappe/utils/sentry.py", line 70, in set_scope
    path = frappe.request.path
  File "/home/frappe/frappe-bench/env/lib/python3.10/site-packages/werkzeug/local.py", line 311, in __get__
    obj = instance._get_current_object()
  File "/home/frappe/frappe-bench/env/lib/python3.10/site-packages/werkzeug/local.py", line 490, in _get_current_object
    raise RuntimeError(unbound_message) from None
RuntimeError: object is not bound
2024-11-22 10:07:45,314 ERROR frappe Failed to capture exception
Site: erp.grupoatu.com
Form Dict: {}
Traceback (most recent call last):
  File "/home/frappe/frappe-bench/apps/frappe/frappe/utils/sentry.py", line 116, in capture_exception
    set_scope(scope)
  File "/home/frappe/frappe-bench/apps/frappe/frappe/utils/sentry.py", line 70, in set_scope
    path = frappe.request.path
  File "/home/frappe/frappe-bench/env/lib/python3.10/site-packages/werkzeug/local.py", line 311, in __get__
    obj = instance._get_current_object()
  File "/home/frappe/frappe-bench/env/lib/python3.10/site-packages/werkzeug/local.py", line 490, in _get_current_object
    raise RuntimeError(unbound_message) from None
RuntimeError: object is not bound
2024-11-22 10:07:45,328 ERROR frappe Failed to capture exception
Site: erp.grupoatu.com
Form Dict: {}
Traceback (most recent call last):
  File "/home/frappe/frappe-bench/apps/frappe/frappe/utils/sentry.py", line 116, in capture_exception
    set_scope(scope)
  File "/home/frappe/frappe-bench/apps/frappe/frappe/utils/sentry.py", line 70, in set_scope
    path = frappe.request.path
  File "/home/frappe/frappe-bench/env/lib/python3.10/site-packages/werkzeug/local.py", line 311, in __get__
    obj = instance._get_current_object()
  File "/home/frappe/frappe-bench/env/lib/python3.10/site-packages/werkzeug/local.py", line 490, in _get_current_object
    raise RuntimeError(unbound_message) from None
RuntimeError: object is not bound
2024-11-22 10:07:45,342 ERROR frappe Failed to capture exception
Site: erp.grupoatu.com
Form Dict: {}
Traceback (most recent call last):
  File "/home/frappe/frappe-bench/apps/frappe/frappe/utils/sentry.py", line 116, in capture_exception
    set_scope(scope)
  File "/home/frappe/frappe-bench/apps/frappe/frappe/utils/sentry.py", line 70, in set_scope
    path = frappe.request.path
  File "/home/frappe/frappe-bench/env/lib/python3.10/site-packages/werkzeug/local.py", line 311, in __get__
    obj = instance._get_current_object()
  File "/home/frappe/frappe-bench/env/lib/python3.10/site-packages/werkzeug/local.py", line 490, in _get_current_object
    raise RuntimeError(unbound_message) from None
RuntimeError: object is not bound
2024-11-22 10:07:45,356 ERROR frappe Failed to capture exception
Site: erp.grupoatu.com
Form Dict: {}
Traceback (most recent call last):
  File "/home/frappe/frappe-bench/apps/frappe/frappe/utils/sentry.py", line 116, in capture_exception
    set_scope(scope)
  File "/home/frappe/frappe-bench/apps/frappe/frappe/utils/sentry.py", line 70, in set_scope
    path = frappe.request.path
  File "/home/frappe/frappe-bench/env/lib/python3.10/site-packages/werkzeug/local.py", line 311, in __get__
    obj = instance._get_current_object()
  File "/home/frappe/frappe-bench/env/lib/python3.10/site-packages/werkzeug/local.py", line 490, in _get_current_object
    raise RuntimeError(unbound_message) from None
RuntimeError: object is not bound
2024-11-22 10:07:45,370 ERROR frappe Failed to capture exception
Site: erp.grupoatu.com
Form Dict: {}
Traceback (most recent call last):
  File "/home/frappe/frappe-bench/apps/frappe/frappe/utils/sentry.py", line 116, in capture_exception
    set_scope(scope)
  File "/home/frappe/frappe-bench/apps/frappe/frappe/utils/sentry.py", line 70, in set_scope
    path = frappe.request.path
  File "/home/frappe/frappe-bench/env/lib/python3.10/site-packages/werkzeug/local.py", line 311, in __get__
    obj = instance._get_current_object()
  File "/home/frappe/frappe-bench/env/lib/python3.10/site-packages/werkzeug/local.py", line 490, in _get_current_object
    raise RuntimeError(unbound_message) from None
RuntimeError: object is not bound
2024-11-22 10:07:45,384 ERROR frappe Failed to capture exception
Site: erp.grupoatu.com
Form Dict: {}
Traceback (most recent call last):
  File "/home/frappe/frappe-bench/apps/frappe/frappe/utils/sentry.py", line 116, in capture_exception
    set_scope(scope)
  File "/home/frappe/frappe-bench/apps/frappe/frappe/utils/sentry.py", line 70, in set_scope
    path = frappe.request.path
  File "/home/frappe/frappe-bench/env/lib/python3.10/site-packages/werkzeug/local.py", line 311, in __get__
    obj = instance._get_current_object()
  File "/home/frappe/frappe-bench/env/lib/python3.10/site-packages/werkzeug/local.py", line 490, in _get_current_object
    raise RuntimeError(unbound_message) from None
RuntimeError: object is not bound
2024-11-22 10:07:45,397 ERROR frappe Failed to capture exception
Site: erp.grupoatu.com
Form Dict: {}
Traceback (most recent call last):
  File "/home/frappe/frappe-bench/apps/frappe/frappe/utils/sentry.py", line 116, in capture_exception
    set_scope(scope)
  File "/home/frappe/frappe-bench/apps/frappe/frappe/utils/sentry.py", line 70, in set_scope
    path = frappe.request.path
  File "/home/frappe/frappe-bench/env/lib/python3.10/site-packages/werkzeug/local.py", line 311, in __get__
    obj = instance._get_current_object()
  File "/home/frappe/frappe-bench/env/lib/python3.10/site-packages/werkzeug/local.py", line 490, in _get_current_object
    raise RuntimeError(unbound_message) from None
RuntimeError: object is not bound
2024-11-22 10:07:45,411 ERROR frappe Failed to capture exception
Site: erp.grupoatu.com
Form Dict: {}
Traceback (most recent call last):
  File "/home/frappe/frappe-bench/apps/frappe/frappe/utils/sentry.py", line 116, in capture_exception
    set_scope(scope)
  File "/home/frappe/frappe-bench/apps/frappe/frappe/utils/sentry.py", line 70, in set_scope
    path = frappe.request.path
  File "/home/frappe/frappe-bench/env/lib/python3.10/site-packages/werkzeug/local.py", line 311, in __get__
    obj = instance._get_current_object()
  File "/home/frappe/frappe-bench/env/lib/python3.10/site-packages/werkzeug/local.py", line 490, in _get_current_object
    raise RuntimeError(unbound_message) from None
RuntimeError: object is not bound
2024-11-22 10:07:45,424 ERROR frappe Failed to capture exception
Site: erp.grupoatu.com
Form Dict: {}
Traceback (most recent call last):
  File "/home/frappe/frappe-bench/apps/frappe/frappe/utils/sentry.py", line 116, in capture_exception
    set_scope(scope)
  File "/home/frappe/frappe-bench/apps/frappe/frappe/utils/sentry.py", line 70, in set_scope
    path = frappe.request.path
  File "/home/frappe/frappe-bench/env/lib/python3.10/site-packages/werkzeug/local.py", line 311, in __get__
    obj = instance._get_current_object()
  File "/home/frappe/frappe-bench/env/lib/python3.10/site-packages/werkzeug/local.py", line 490, in _get_current_object
    raise RuntimeError(unbound_message) from None
RuntimeError: object is not bound
2024-11-22 10:07:45,437 ERROR frappe Failed to capture exception
Site: erp.grupoatu.com
Form Dict: {}
Traceback (most recent call last):
  File "/home/frappe/frappe-bench/apps/frappe/frappe/utils/sentry.py", line 116, in capture_exception
    set_scope(scope)
  File "/home/frappe/frappe-bench/apps/frappe/frappe/utils/sentry.py", line 70, in set_scope
    path = frappe.request.path
  File "/home/frappe/frappe-bench/env/lib/python3.10/site-packages/werkzeug/local.py", line 311, in __get__
    obj = instance._get_current_object()
  File "/home/frappe/frappe-bench/env/lib/python3.10/site-packages/werkzeug/local.py", line 490, in _get_current_object
    raise RuntimeError(unbound_message) from None
RuntimeError: object is not bound
2024-11-22 10:07:45,450 ERROR frappe Failed to capture exception
Site: erp.grupoatu.com
Form Dict: {}
Traceback (most recent call last):
  File "/home/frappe/frappe-bench/apps/frappe/frappe/utils/sentry.py", line 116, in capture_exception
    set_scope(scope)
  File "/home/frappe/frappe-bench/apps/frappe/frappe/utils/sentry.py", line 70, in set_scope
    path = frappe.request.path
  File "/home/frappe/frappe-bench/env/lib/python3.10/site-packages/werkzeug/local.py", line 311, in __get__
    obj = instance._get_current_object()
  File "/home/frappe/frappe-bench/env/lib/python3.10/site-packages/werkzeug/local.py", line 490, in _get_current_object
    raise RuntimeError(unbound_message) from None
RuntimeError: object is not bound
2024-11-22 10:07:45,464 ERROR frappe Failed to capture exception
Site: erp.grupoatu.com
Form Dict: {}
Traceback (most recent call last):
  File "/home/frappe/frappe-bench/apps/frappe/frappe/utils/sentry.py", line 116, in capture_exception
    set_scope(scope)
  File "/home/frappe/frappe-bench/apps/frappe/frappe/utils/sentry.py", line 70, in set_scope
    path = frappe.request.path
  File "/home/frappe/frappe-bench/env/lib/python3.10/site-packages/werkzeug/local.py", line 311, in __get__
    obj = instance._get_current_object()
  File "/home/frappe/frappe-bench/env/lib/python3.10/site-packages/werkzeug/local.py", line 490, in _get_current_object
    raise RuntimeError(unbound_message) from None
RuntimeError: object is not bound
2024-11-22 10:07:45,478 ERROR frappe Failed to capture exception
Site: erp.grupoatu.com
Form Dict: {}
Traceback (most recent call last):
  File "/home/frappe/frappe-bench/apps/frappe/frappe/utils/sentry.py", line 116, in capture_exception
    set_scope(scope)
  File "/home/frappe/frappe-bench/apps/frappe/frappe/utils/sentry.py", line 70, in set_scope
    path = frappe.request.path
  File "/home/frappe/frappe-bench/env/lib/python3.10/site-packages/werkzeug/local.py", line 311, in __get__
    obj = instance._get_current_object()
  File "/home/frappe/frappe-bench/env/lib/python3.10/site-packages/werkzeug/local.py", line 490, in _get_current_object
    raise RuntimeError(unbound_message) from None
RuntimeError: object is not bound
2024-11-22 10:07:45,493 ERROR frappe Failed to capture exception
Site: erp.grupoatu.com
Form Dict: {}
Traceback (most recent call last):
  File "/home/frappe/frappe-bench/apps/frappe/frappe/utils/sentry.py", line 116, in capture_exception
    set_scope(scope)
  File "/home/frappe/frappe-bench/apps/frappe/frappe/utils/sentry.py", line 70, in set_scope
    path = frappe.request.path
  File "/home/frappe/frappe-bench/env/lib/python3.10/site-packages/werkzeug/local.py", line 311, in __get__
    obj = instance._get_current_object()
  File "/home/frappe/frappe-bench/env/lib/python3.10/site-packages/werkzeug/local.py", line 490, in _get_current_object
    raise RuntimeError(unbound_message) from None
RuntimeError: object is not bound
2024-11-22 10:07:45,507 ERROR frappe Failed to capture exception
Site: erp.grupoatu.com
Form Dict: {}
Traceback (most recent call last):
  File "/home/frappe/frappe-bench/apps/frappe/frappe/utils/sentry.py", line 116, in capture_exception
    set_scope(scope)
  File "/home/frappe/frappe-bench/apps/frappe/frappe/utils/sentry.py", line 70, in set_scope
    path = frappe.request.path
  File "/home/frappe/frappe-bench/env/lib/python3.10/site-packages/werkzeug/local.py", line 311, in __get__
    obj = instance._get_current_object()
  File "/home/frappe/frappe-bench/env/lib/python3.10/site-packages/werkzeug/local.py", line 490, in _get_current_object
    raise RuntimeError(unbound_message) from None
RuntimeError: object is not bound
2024-11-22 10:07:45,521 ERROR frappe Failed to capture exception
Site: erp.grupoatu.com
Form Dict: {}
Traceback (most recent call last):
  File "/home/frappe/frappe-bench/apps/frappe/frappe/utils/sentry.py", line 116, in capture_exception
    set_scope(scope)
  File "/home/frappe/frappe-bench/apps/frappe/frappe/utils/sentry.py", line 70, in set_scope
    path = frappe.request.path
  File "/home/frappe/frappe-bench/env/lib/python3.10/site-packages/werkzeug/local.py", line 311, in __get__
    obj = instance._get_current_object()
  File "/home/frappe/frappe-bench/env/lib/python3.10/site-packages/werkzeug/local.py", line 490, in _get_current_object
    raise RuntimeError(unbound_message) from None
RuntimeError: object is not bound
2024-11-22 10:07:45,534 ERROR frappe Failed to capture exception
Site: erp.grupoatu.com
Form Dict: {}
Traceback (most recent call last):
  File "/home/frappe/frappe-bench/apps/frappe/frappe/utils/sentry.py", line 116, in capture_exception
    set_scope(scope)
  File "/home/frappe/frappe-bench/apps/frappe/frappe/utils/sentry.py", line 70, in set_scope
    path = frappe.request.path
  File "/home/frappe/frappe-bench/env/lib/python3.10/site-packages/werkzeug/local.py", line 311, in __get__
    obj = instance._get_current_object()
  File "/home/frappe/frappe-bench/env/lib/python3.10/site-packages/werkzeug/local.py", line 490, in _get_current_object
    raise RuntimeError(unbound_message) from None
RuntimeError: object is not bound
2024-11-22 10:07:45,548 ERROR frappe Failed to capture exception
Site: erp.grupoatu.com
Form Dict: {}
Traceback (most recent call last):
  File "/home/frappe/frappe-bench/apps/frappe/frappe/utils/sentry.py", line 116, in capture_exception
    set_scope(scope)
  File "/home/frappe/frappe-bench/apps/frappe/frappe/utils/sentry.py", line 70, in set_scope
    path = frappe.request.path
  File "/home/frappe/frappe-bench/env/lib/python3.10/site-packages/werkzeug/local.py", line 311, in __get__
    obj = instance._get_current_object()
  File "/home/frappe/frappe-bench/env/lib/python3.10/site-packages/werkzeug/local.py", line 490, in _get_current_object
    raise RuntimeError(unbound_message) from None
RuntimeError: object is not bound
2024-11-22 10:07:45,561 ERROR frappe Failed to capture exception
Site: erp.grupoatu.com
Form Dict: {}
Traceback (most recent call last):
  File "/home/frappe/frappe-bench/apps/frappe/frappe/utils/sentry.py", line 116, in capture_exception
    set_scope(scope)
  File "/home/frappe/frappe-bench/apps/frappe/frappe/utils/sentry.py", line 70, in set_scope
    path = frappe.request.path
  File "/home/frappe/frappe-bench/env/lib/python3.10/site-packages/werkzeug/local.py", line 311, in __get__
    obj = instance._get_current_object()
  File "/home/frappe/frappe-bench/env/lib/python3.10/site-packages/werkzeug/local.py", line 490, in _get_current_object
    raise RuntimeError(unbound_message) from None
RuntimeError: object is not bound
2024-11-22 10:07:45,574 ERROR frappe Failed to capture exception
Site: erp.grupoatu.com
Form Dict: {}
Traceback (most recent call last):
  File "/home/frappe/frappe-bench/apps/frappe/frappe/utils/sentry.py", line 116, in capture_exception
    set_scope(scope)
  File "/home/frappe/frappe-bench/apps/frappe/frappe/utils/sentry.py", line 70, in set_scope
    path = frappe.request.path
  File "/home/frappe/frappe-bench/env/lib/python3.10/site-packages/werkzeug/local.py", line 311, in __get__
    obj = instance._get_current_object()
  File "/home/frappe/frappe-bench/env/lib/python3.10/site-packages/werkzeug/local.py", line 490, in _get_current_object
    raise RuntimeError(unbound_message) from None
RuntimeError: object is not bound
2024-11-22 10:07:45,588 ERROR frappe Failed to capture exception
Site: erp.grupoatu.com
Form Dict: {}
Traceback (most recent call last):
  File "/home/frappe/frappe-bench/apps/frappe/frappe/utils/sentry.py", line 116, in capture_exception
    set_scope(scope)
  File "/home/frappe/frappe-bench/apps/frappe/frappe/utils/sentry.py", line 70, in set_scope
    path = frappe.request.path
  File "/home/frappe/frappe-bench/env/lib/python3.10/site-packages/werkzeug/local.py", line 311, in __get__
    obj = instance._get_current_object()
  File "/home/frappe/frappe-bench/env/lib/python3.10/site-packages/werkzeug/local.py", line 490, in _get_current_object
    raise RuntimeError(unbound_message) from None
RuntimeError: object is not bound
2024-11-22 10:07:45,602 ERROR frappe Failed to capture exception
Site: erp.grupoatu.com
Form Dict: {}
Traceback (most recent call last):
  File "/home/frappe/frappe-bench/apps/frappe/frappe/utils/sentry.py", line 116, in capture_exception
    set_scope(scope)
  File "/home/frappe/frappe-bench/apps/frappe/frappe/utils/sentry.py", line 70, in set_scope
    path = frappe.request.path
  File "/home/frappe/frappe-bench/env/lib/python3.10/site-packages/werkzeug/local.py", line 311, in __get__
    obj = instance._get_current_object()
  File "/home/frappe/frappe-bench/env/lib/python3.10/site-packages/werkzeug/local.py", line 490, in _get_current_object
    raise RuntimeError(unbound_message) from None
RuntimeError: object is not bound
2024-11-22 10:07:45,615 ERROR frappe Failed to capture exception
Site: erp.grupoatu.com
Form Dict: {}
Traceback (most recent call last):
  File "/home/frappe/frappe-bench/apps/frappe/frappe/utils/sentry.py", line 116, in capture_exception
    set_scope(scope)
  File "/home/frappe/frappe-bench/apps/frappe/frappe/utils/sentry.py", line 70, in set_scope
    path = frappe.request.path
  File "/home/frappe/frappe-bench/env/lib/python3.10/site-packages/werkzeug/local.py", line 311, in __get__
    obj = instance._get_current_object()
  File "/home/frappe/frappe-bench/env/lib/python3.10/site-packages/werkzeug/local.py", line 490, in _get_current_object
    raise RuntimeError(unbound_message) from None
RuntimeError: object is not bound
2024-11-22 10:07:45,628 ERROR frappe Failed to capture exception
Site: erp.grupoatu.com
Form Dict: {}
Traceback (most recent call last):
  File "/home/frappe/frappe-bench/apps/frappe/frappe/utils/sentry.py", line 116, in capture_exception
    set_scope(scope)
  File "/home/frappe/frappe-bench/apps/frappe/frappe/utils/sentry.py", line 70, in set_scope
    path = frappe.request.path
  File "/home/frappe/frappe-bench/env/lib/python3.10/site-packages/werkzeug/local.py", line 311, in __get__
    obj = instance._get_current_object()
  File "/home/frappe/frappe-bench/env/lib/python3.10/site-packages/werkzeug/local.py", line 490, in _get_current_object
    raise RuntimeError(unbound_message) from None
RuntimeError: object is not bound
2024-11-22 10:07:45,642 ERROR frappe Failed to capture exception
Site: erp.grupoatu.com
Form Dict: {}
Traceback (most recent call last):
  File "/home/frappe/frappe-bench/apps/frappe/frappe/utils/sentry.py", line 116, in capture_exception
    set_scope(scope)
  File "/home/frappe/frappe-bench/apps/frappe/frappe/utils/sentry.py", line 70, in set_scope
    path = frappe.request.path
  File "/home/frappe/frappe-bench/env/lib/python3.10/site-packages/werkzeug/local.py", line 311, in __get__
    obj = instance._get_current_object()
  File "/home/frappe/frappe-bench/env/lib/python3.10/site-packages/werkzeug/local.py", line 490, in _get_current_object
    raise RuntimeError(unbound_message) from None
RuntimeError: object is not bound
2024-11-22 10:07:45,655 ERROR frappe Failed to capture exception
Site: erp.grupoatu.com
Form Dict: {}
Traceback (most recent call last):
  File "/home/frappe/frappe-bench/apps/frappe/frappe/utils/sentry.py", line 116, in capture_exception
    set_scope(scope)
  File "/home/frappe/frappe-bench/apps/frappe/frappe/utils/sentry.py", line 70, in set_scope
    path = frappe.request.path
  File "/home/frappe/frappe-bench/env/lib/python3.10/site-packages/werkzeug/local.py", line 311, in __get__
    obj = instance._get_current_object()
  File "/home/frappe/frappe-bench/env/lib/python3.10/site-packages/werkzeug/local.py", line 490, in _get_current_object
    raise RuntimeError(unbound_message) from None
RuntimeError: object is not bound
